/*******************************************************************************
 * AbyssalCraft
 * Copyright (c) 2012 - 2018 Shinoow.
 * All rights reserved. This program and the accompanying materials
 * are made available under the terms of the GNU Lesser Public License v3
 * which accompanies this distribution, and is available at
 * http://www.gnu.org/licenses/lgpl-3.0.txt
 *
 * Contributors:
 *     Shinoow -  implementation
 ******************************************************************************/
package com.shinoow.abyssalcraft.common.structures.dreadlands;

import java.util.Random;

import com.shinoow.abyssalcraft.api.block.ACBlocks;
import com.shinoow.abyssalcraft.api.item.ACItems;
import com.shinoow.abyssalcraft.lib.ACConfig;

import net.minecraft.init.Blocks;
import net.minecraft.item.ItemStack;
import net.minecraft.tileentity.TileEntityChest;
import net.minecraft.util.math.BlockPos;
import net.minecraft.util.text.TextFormatting;
import net.minecraft.world.World;
import net.minecraft.world.gen.feature.WorldGenerator;

public class chagarothlair extends WorldGenerator {

	public chagarothlair() { }

	@Override
	public boolean generate(World world, Random rand, BlockPos pos) {

		int i = pos.getX();
		int j = pos.getY();
		int k = pos.getZ();

		world.setBlockState(new BlockPos(i - 24, j + 4, k - 30), ACBlocks.dreadstone_brick.getDefaultState(), 2);
		world.setBlockState(new BlockPos(i - 24, j + 4, k - 29), ACBlocks.dreadstone_brick.getDefaultState(), 2);
		world.setBlockState(new BlockPos(i - 24, j + 4, k - 28), ACBlocks.dreadstone_brick.getDefaultState(), 2);
		world.setBlockState(new BlockPos(i - 24, j + 4, k - 27), ACBlocks.dreadstone_brick.getDefaultState(), 2);
		world.setBlockState(new BlockPos(i - 24, j + 4, k - 26), ACBlocks.dreadstone_brick.getDefaultState(), 2);
		world.setBlockState(new BlockPos(i - 24, j + 4, k - 25), ACBlocks.dreadstone_brick.getDefaultState(), 2);
		world.setBlockState(new BlockPos(i - 24, j + 4, k - 24), ACBlocks.dreadstone_brick.getDefaultState(), 2);
		world.setBlockState(new BlockPos(i - 24, j + 4, k - 23), ACBlocks.dreadstone_brick.getDefaultState(), 2);
		world.setBlockState(new BlockPos(i - 24, j + 4, k - 22), ACBlocks.dreadstone_brick.getDefaultState(), 2);
		world.setBlockState(new BlockPos(i - 24, j + 5, k - 30), ACBlocks.dreadstone_brick.getDefaultState(), 2);
		world.setBlockState(new BlockPos(i - 24, j + 5, k - 29), ACBlocks.dreadstone_brick.getDefaultState(), 2);
		world.setBlockState(new BlockPos(i - 24, j + 5, k - 28), ACBlocks.dreadstone_brick.getDefaultState(), 2);
		world.setBlockState(new BlockPos(i - 24, j + 5, k - 27), ACBlocks.dreadstone_brick.getDefaultState(), 2);
		world.setBlockState(new BlockPos(i - 24, j + 5, k - 26), ACBlocks.dreadstone_brick.getDefaultState(), 2);
		world.setBlockState(new BlockPos(i - 24, j + 5, k - 25), ACBlocks.dreadstone_brick.getDefaultState(), 2);
		world.setBlockState(new BlockPos(i - 24, j + 5, k - 24), ACBlocks.dreadstone_brick.getDefaultState(), 2);
		world.setBlockState(new BlockPos(i - 24, j + 5, k - 23), ACBlocks.dreadstone_brick.getDefaultState(), 2);
		world.setBlockState(new BlockPos(i - 24, j + 5, k - 22), ACBlocks.dreadstone_brick.getDefaultState(), 2);
		world.setBlockState(new BlockPos(i - 24, j + 6, k - 30), ACBlocks.dreadstone_brick.getDefaultState(), 2);
		world.setBlockState(new BlockPos(i - 24, j + 6, k - 29), ACBlocks.dreadstone_brick.getDefaultState(), 2);
		world.setBlockState(new BlockPos(i - 24, j + 6, k - 28), ACBlocks.dreadstone_brick.getDefaultState(), 2);
		world.setBlockState(new BlockPos(i - 24, j + 6, k - 27), ACBlocks.dreadstone_brick.getDefaultState(), 2);
		world.setBlockState(new BlockPos(i - 24, j + 6, k - 26), ACBlocks.dreadstone_brick.getDefaultState(), 2);
		world.setBlockState(new BlockPos(i - 24, j + 6, k - 25), ACBlocks.dreadstone_brick.getDefaultState(), 2);
		world.setBlockState(new BlockPos(i - 24, j + 6, k - 24), ACBlocks.dreadstone_brick.getDefaultState(), 2);
		world.setBlockState(new BlockPos(i - 24, j + 6, k - 23), ACBlocks.dreadstone_brick.getDefaultState(), 2);
		world.setBlockState(new BlockPos(i - 24, j + 6, k - 22), ACBlocks.dreadstone_brick.getDefaultState(), 2);
		world.setBlockState(new BlockPos(i - 24, j + 7, k - 30), ACBlocks.dreadstone_brick.getDefaultState(), 2);
		world.setBlockState(new BlockPos(i - 24, j + 7, k - 29), ACBlocks.dreadstone_brick.getDefaultState(), 2);
		world.setBlockState(new BlockPos(i - 24, j + 7, k - 28), ACBlocks.dreadstone_brick.getDefaultState(), 2);
		world.setBlockState(new BlockPos(i - 24, j + 7, k - 27), ACBlocks.dreadstone_brick.getDefaultState(), 2);
		world.setBlockState(new BlockPos(i - 24, j + 7, k - 26), ACBlocks.dreadstone_brick.getDefaultState(), 2);
		world.setBlockState(new BlockPos(i - 24, j + 7, k - 25), ACBlocks.dreadstone_brick.getDefaultState(), 2);
		world.setBlockState(new BlockPos(i - 24, j + 7, k - 24), ACBlocks.dreadstone_brick.getDefaultState(), 2);
		world.setBlockState(new BlockPos(i - 24, j + 7, k - 23), ACBlocks.dreadstone_brick.getDefaultState(), 2);
		world.setBlockState(new BlockPos(i - 24, j + 7, k - 22), ACBlocks.dreadstone_brick.getDefaultState(), 2);
		world.setBlockState(new BlockPos(i - 24, j + 8, k - 30), ACBlocks.dreadstone_brick.getDefaultState(), 2);
		world.setBlockState(new BlockPos(i - 24, j + 8, k - 29), ACBlocks.dreadstone_brick.getDefaultState(), 2);
		world.setBlockState(new BlockPos(i - 24, j + 8, k - 28), ACBlocks.dreadstone_brick.getDefaultState(), 2);
		world.setBlockState(new BlockPos(i - 24, j + 8, k - 27), ACBlocks.dreadstone_brick.getDefaultState(), 2);
		world.setBlockState(new BlockPos(i - 24, j + 8, k - 26), ACBlocks.dreadstone_brick.getDefaultState(), 2);
		world.setBlockState(new BlockPos(i - 24, j + 8, k - 25), ACBlocks.dreadstone_brick.getDefaultState(), 2);
		world.setBlockState(new BlockPos(i - 24, j + 8, k - 24), ACBlocks.dreadstone_brick.getDefaultState(), 2);
		world.setBlockState(new BlockPos(i - 24, j + 8, k - 23), ACBlocks.dreadstone_brick.getDefaultState(), 2);
		world.setBlockState(new BlockPos(i - 24, j + 8, k - 22), ACBlocks.dreadstone_brick.getDefaultState(), 2);
		world.setBlockState(new BlockPos(i - 23, j + 3, k - 29), ACBlocks.dreadstone_brick.getDefaultState(), 2);
		world.setBlockState(new BlockPos(i - 23, j + 3, k - 28), ACBlocks.dreadstone_brick.getDefaultState(), 2);
		world.setBlockState(new BlockPos(i - 23, j + 3, k - 27), ACBlocks.dreadstone_brick.getDefaultState(), 2);
		world.setBlockState(new BlockPos(i - 23, j + 3, k - 26), ACBlocks.dreadstone_brick.getDefaultState(), 2);
		world.setBlockState(new BlockPos(i - 23, j + 3, k - 25), ACBlocks.dreadstone_brick.getDefaultState(), 2);
		world.setBlockState(new BlockPos(i - 23, j + 3, k - 24), ACBlocks.dreadstone_brick.getDefaultState(), 2);
		world.setBlockState(new BlockPos(i - 23, j + 3, k - 23), ACBlocks.dreadstone_brick.getDefaultState(), 2);
		world.setBlockState(new BlockPos(i - 23, j + 4, k - 30), ACBlocks.dreadstone_brick.getDefaultState(), 2);
		world.setBlockState(new BlockPos(i - 23, j + 4, k - 28), Blocks.ANVIL.getDefaultState(), 2);
		world.setBlockState(new BlockPos(i - 23, j + 4, k - 26), Blocks.CRAFTING_TABLE.getDefaultState(), 2);
		world.setBlockState(new BlockPos(i - 23, j + 4, k - 24), Blocks.FURNACE.getStateFromMeta(1), 2); //TODO: 1
		world.setBlockState(new BlockPos(i - 23, j + 4, k - 22), ACBlocks.dreadstone_brick.getDefaultState(), 2);
		world.setBlockState(new BlockPos(i - 23, j + 5, k - 30), ACBlocks.dreadstone_brick.getDefaultState(), 2);
		world.setBlockState(new BlockPos(i - 23, j + 5, k - 22), ACBlocks.dreadstone_brick.getDefaultState(), 2);
		world.setBlockState(new BlockPos(i - 23, j + 6, k - 30), ACBlocks.dreadstone_brick.getDefaultState(), 2);
		world.setBlockState(new BlockPos(i - 23, j + 6, k - 29), ACBlocks.dreadstone_brick.getDefaultState(), 2);
		world.setBlockState(new BlockPos(i - 23, j + 6, k - 28), ACBlocks.dreadstone_brick.getDefaultState(), 2);
		world.setBlockState(new BlockPos(i - 23, j + 6, k - 27), ACBlocks.dreadstone_brick.getDefaultState(), 2);
		world.setBlockState(new BlockPos(i - 23, j + 6, k - 26), ACBlocks.dreadstone_brick.getDefaultState(), 2);
		world.setBlockState(new BlockPos(i - 23, j + 6, k - 25), ACBlocks.dreadstone_brick.getDefaultState(), 2);
		world.setBlockState(new BlockPos(i - 23, j + 6, k - 24), ACBlocks.dreadstone_brick.getDefaultState(), 2);
		world.setBlockState(new BlockPos(i - 23, j + 6, k - 23), ACBlocks.dreadstone_brick.getDefaultState(), 2);
		world.setBlockState(new BlockPos(i - 23, j + 6, k - 22), ACBlocks.dreadstone_brick.getDefaultState(), 2);
		world.setBlockState(new BlockPos(i - 23, j + 7, k - 30), ACBlocks.dreadstone_brick.getDefaultState(), 2);
		world.setBlockState(new BlockPos(i - 23, j + 7, k - 22), ACBlocks.dreadstone_brick.getDefaultState(), 2);
		world.setBlockState(new BlockPos(i - 23, j + 8, k - 30), ACBlocks.dreadstone_brick.getDefaultState(), 2);
		world.setBlockState(new BlockPos(i - 23, j + 8, k - 29), ACBlocks.dreadstone_brick.getDefaultState(), 2);
		world.setBlockState(new BlockPos(i - 23, j + 8, k - 28), ACBlocks.dreadstone_brick.getDefaultState(), 2);
		world.setBlockState(new BlockPos(i - 23, j + 8, k - 27), ACBlocks.dreadstone_brick.getDefaultState(), 2);
		world.setBlockState(new BlockPos(i - 23, j + 8, k - 26), ACBlocks.dreadstone_brick.getDefaultState(), 2);
		world.setBlockState(new BlockPos(i - 23, j + 8, k - 25), ACBlocks.dreadstone_brick.getDefaultState(), 2);
		world.setBlockState(new BlockPos(i - 23, j + 8, k - 24), ACBlocks.dreadstone_brick.getDefaultState(), 2);
		world.setBlockState(new BlockPos(i - 23, j + 8, k - 23), ACBlocks.dreadstone_brick.getDefaultState(), 2);
		world.setBlockState(new BlockPos(i - 23, j + 8, k - 22), ACBlocks.dreadstone_brick.getDefaultState(), 2);
		world.setBlockState(new BlockPos(i - 22, j + 3, k - 29), ACBlocks.dreadstone_brick.getDefaultState(), 2);
		world.setBlockState(new BlockPos(i - 22, j + 3, k - 28), ACBlocks.dreadstone_brick.getDefaultState(), 2);
		world.setBlockState(new BlockPos(i - 22, j + 3, k - 27), ACBlocks.dreadstone_brick.getDefaultState(), 2);
		world.setBlockState(new BlockPos(i - 22, j + 3, k - 26), ACBlocks.dreadstone_brick.getDefaultState(), 2);
		world.setBlockState(new BlockPos(i - 22, j + 3, k - 25), ACBlocks.dreadstone_brick.getDefaultState(), 2);
		world.setBlockState(new BlockPos(i - 22, j + 3, k - 24), ACBlocks.dreadstone_brick.getDefaultState(), 2);
		world.setBlockState(new BlockPos(i - 22, j + 3, k - 23), ACBlocks.dreadstone_brick.getDefaultState(), 2);
		world.setBlockState(new BlockPos(i - 22, j + 4, k - 41), ACBlocks.dreadstone_brick.getDefaultState(), 2);
		world.setBlockState(new BlockPos(i - 22, j + 4, k - 40), ACBlocks.dreadstone_brick.getDefaultState(), 2);
		world.setBlockState(new BlockPos(i - 22, j + 4, k - 39), ACBlocks.dreadstone_brick.getDefaultState(), 2);
		world.setBlockState(new BlockPos(i - 22, j + 4, k - 38), ACBlocks.dreadstone_brick.getDefaultState(), 2);
		world.setBlockState(new BlockPos(i - 22, j + 4, k - 37), ACBlocks.dreadstone_brick.getDefaultState(), 2);
		world.setBlockState(new BlockPos(i - 22, j + 4, k - 36), ACBlocks.dreadstone_brick.getDefaultState(), 2);
		world.setBlockState(new BlockPos(i - 22, j + 4, k - 35), ACBlocks.dreadstone_brick.getDefaultState(), 2);
		world.setBlockState(new BlockPos(i - 22, j + 4, k - 34), ACBlocks.dreadstone_brick.getDefaultState(), 2);
		world.setBlockState(new BlockPos(i - 22, j + 4, k - 33), ACBlocks.dreadstone_brick.getDefaultState(), 2);
		world.setBlockState(new BlockPos(i - 22, j + 4, k - 32), ACBlocks.dreadstone_brick.getDefaultState(), 2);
		world.setBlockState(new BlockPos(i - 22, j + 4, k - 31), ACBlocks.dreadstone_brick.getDefaultState(), 2);
		world.setBlockState(new BlockPos(i - 22, j + 4, k - 30), ACBlocks.dreadstone_brick.getDefaultState(), 2);
		world.setBlockState(new BlockPos(i - 22, j + 4, k - 22), ACBlocks.dreadstone_brick.getDefaultState(), 2);
		world.setBlockState(new BlockPos(i - 22, j + 5, k - 41), ACBlocks.dreadstone_brick.getDefaultState(), 2);
		world.setBlockState(new BlockPos(i - 22, j + 5, k - 40), ACBlocks.dreadstone_brick.getDefaultState(), 2);
		world.setBlockState(new BlockPos(i - 22, j + 5, k - 39), ACBlocks.dreadstone_brick.getDefaultState(), 2);
		world.setBlockState(new BlockPos(i - 22, j + 5, k - 38), ACBlocks.dreadstone_brick.getDefaultState(), 2);
		world.setBlockState(new BlockPos(i - 22, j + 5, k - 37), ACBlocks.dreadstone_brick.getDefaultState(), 2);
		world.setBlockState(new BlockPos(i - 22, j + 5, k - 36), ACBlocks.dreadstone_brick.getDefaultState(), 2);
		world.setBlockState(new BlockPos(i - 22, j + 5, k - 35), ACBlocks.dreadstone_brick.getDefaultState(), 2);
		world.setBlockState(new BlockPos(i - 22, j + 5, k - 34), ACBlocks.dreadstone_brick.getDefaultState(), 2);
		world.setBlockState(new BlockPos(i - 22, j + 5, k - 33), ACBlocks.dreadstone_brick.getDefaultState(), 2);
		world.setBlockState(new BlockPos(i - 22, j + 5, k - 32), ACBlocks.dreadstone_brick.getDefaultState(), 2);
		world.setBlockState(new BlockPos(i - 22, j + 5, k - 31), ACBlocks.dreadstone_brick.getDefaultState(), 2);
		world.setBlockState(new BlockPos(i - 22, j + 5, k - 30), ACBlocks.dreadstone_brick.getDefaultState(), 2);
		world.setBlockState(new BlockPos(i - 22, j + 5, k - 22), ACBlocks.dreadstone_brick.getDefaultState(), 2);
		world.setBlockState(new BlockPos(i - 22, j + 6, k - 41), ACBlocks.dreadstone_brick.getDefaultState(), 2);
		world.setBlockState(new BlockPos(i - 22, j + 6, k - 40), ACBlocks.dreadstone_brick.getDefaultState(), 2);
		world.setBlockState(new BlockPos(i - 22, j + 6, k - 39), ACBlocks.dreadstone_brick.getDefaultState(), 2);
		world.setBlockState(new BlockPos(i - 22, j + 6, k - 38), ACBlocks.dreadstone_brick.getDefaultState(), 2);
		world.setBlockState(new BlockPos(i - 22, j + 6, k - 37), ACBlocks.dreadstone_brick.getDefaultState(), 2);
		world.setBlockState(new BlockPos(i - 22, j + 6, k - 36), ACBlocks.dreadstone_brick.getDefaultState(), 2);
		world.setBlockState(new BlockPos(i - 22, j + 6, k - 35), ACBlocks.dreadstone_brick.getDefaultState(), 2);
		world.setBlockState(new BlockPos(i - 22, j + 6, k - 34), ACBlocks.dreadstone_brick.getDefaultState(), 2);
		world.setBlockState(new BlockPos(i - 22, j + 6, k - 33), ACBlocks.dreadstone_brick.getDefaultState(), 2);
		world.setBlockState(new BlockPos(i - 22, j + 6, k - 32), ACBlocks.dreadstone_brick.getDefaultState(), 2);
		world.setBlockState(new BlockPos(i - 22, j + 6, k - 31), ACBlocks.dreadstone_brick.getDefaultState(), 2);
		world.setBlockState(new BlockPos(i - 22, j + 6, k - 30), ACBlocks.dreadstone_brick.getDefaultState(), 2);
		world.setBlockState(new BlockPos(i - 22, j + 6, k - 22), ACBlocks.dreadstone_brick.getDefaultState(), 2);
		world.setBlockState(new BlockPos(i - 22, j + 7, k - 41), ACBlocks.dreadstone_brick.getDefaultState(), 2);
		world.setBlockState(new BlockPos(i - 22, j + 7, k - 40), ACBlocks.dreadstone_brick.getDefaultState(), 2);
		world.setBlockState(new BlockPos(i - 22, j + 7, k - 39), ACBlocks.dreadstone_brick.getDefaultState(), 2);
		world.setBlockState(new BlockPos(i - 22, j + 7, k - 38), ACBlocks.dreadstone_brick.getDefaultState(), 2);
		world.setBlockState(new BlockPos(i - 22, j + 7, k - 37), ACBlocks.dreadstone_brick.getDefaultState(), 2);
		world.setBlockState(new BlockPos(i - 22, j + 7, k - 36), ACBlocks.dreadstone_brick.getDefaultState(), 2);
		world.setBlockState(new BlockPos(i - 22, j + 7, k - 35), ACBlocks.dreadstone_brick.getDefaultState(), 2);
		world.setBlockState(new BlockPos(i - 22, j + 7, k - 34), ACBlocks.dreadstone_brick.getDefaultState(), 2);
		world.setBlockState(new BlockPos(i - 22, j + 7, k - 33), ACBlocks.dreadstone_brick.getDefaultState(), 2);
		world.setBlockState(new BlockPos(i - 22, j + 7, k - 32), ACBlocks.dreadstone_brick.getDefaultState(), 2);
		world.setBlockState(new BlockPos(i - 22, j + 7, k - 31), ACBlocks.dreadstone_brick.getDefaultState(), 2);
		world.setBlockState(new BlockPos(i - 22, j + 7, k - 30), ACBlocks.dreadstone_brick.getDefaultState(), 2);
		world.setBlockState(new BlockPos(i - 22, j + 7, k - 22), ACBlocks.dreadstone_brick.getDefaultState(), 2);
		world.setBlockState(new BlockPos(i - 22, j + 8, k - 41), ACBlocks.dreadstone_brick.getDefaultState(), 2);
		world.setBlockState(new BlockPos(i - 22, j + 8, k - 40), ACBlocks.dreadstone_brick.getDefaultState(), 2);
		world.setBlockState(new BlockPos(i - 22, j + 8, k - 39), ACBlocks.dreadstone_brick.getDefaultState(), 2);
		world.setBlockState(new BlockPos(i - 22, j + 8, k - 38), ACBlocks.dreadstone_brick.getDefaultState(), 2);
		world.setBlockState(new BlockPos(i - 22, j + 8, k - 37), ACBlocks.dreadstone_brick.getDefaultState(), 2);
		world.setBlockState(new BlockPos(i - 22, j + 8, k - 36), ACBlocks.dreadstone_brick.getDefaultState(), 2);
		world.setBlockState(new BlockPos(i - 22, j + 8, k - 35), ACBlocks.dreadstone_brick.getDefaultState(), 2);
		world.setBlockState(new BlockPos(i - 22, j + 8, k - 34), ACBlocks.dreadstone_brick.getDefaultState(), 2);
		world.setBlockState(new BlockPos(i - 22, j + 8, k - 33), ACBlocks.dreadstone_brick.getDefaultState(), 2);
		world.setBlockState(new BlockPos(i - 22, j + 8, k - 32), ACBlocks.dreadstone_brick.getDefaultState(), 2);
		world.setBlockState(new BlockPos(i - 22, j + 8, k - 31), ACBlocks.dreadstone_brick.getDefaultState(), 2);
		world.setBlockState(new BlockPos(i - 22, j + 8, k - 30), ACBlocks.dreadstone_brick.getDefaultState(), 2);
		world.setBlockState(new BlockPos(i - 22, j + 8, k - 29), ACBlocks.dreadstone_brick.getDefaultState(), 2);
		world.setBlockState(new BlockPos(i - 22, j + 8, k - 28), ACBlocks.dreadstone_brick.getDefaultState(), 2);
		world.setBlockState(new BlockPos(i - 22, j + 8, k - 27), ACBlocks.dreadstone_brick.getDefaultState(), 2);
		world.setBlockState(new BlockPos(i - 22, j + 8, k - 26), ACBlocks.dreadstone_brick.getDefaultState(), 2);
		world.setBlockState(new BlockPos(i - 22, j + 8, k - 25), ACBlocks.dreadstone_brick.getDefaultState(), 2);
		world.setBlockState(new BlockPos(i - 22, j + 8, k - 24), ACBlocks.dreadstone_brick.getDefaultState(), 2);
		world.setBlockState(new BlockPos(i - 22, j + 8, k - 23), ACBlocks.dreadstone_brick.getDefaultState(), 2);
		world.setBlockState(new BlockPos(i - 22, j + 8, k - 22), ACBlocks.dreadstone_brick.getDefaultState(), 2);
		world.setBlockState(new BlockPos(i - 22, j + 9, k - 41), ACBlocks.dreadstone_brick.getDefaultState(), 2);
		world.setBlockState(new BlockPos(i - 22, j + 9, k - 40), ACBlocks.dreadstone_brick.getDefaultState(), 2);
		world.setBlockState(new BlockPos(i - 22, j + 9, k - 39), ACBlocks.dreadstone_brick.getDefaultState(), 2);
		world.setBlockState(new BlockPos(i - 22, j + 9, k - 38), ACBlocks.dreadstone_brick.getDefaultState(), 2);
		world.setBlockState(new BlockPos(i - 22, j + 9, k - 37), ACBlocks.dreadstone_brick.getDefaultState(), 2);
		world.setBlockState(new BlockPos(i - 22, j + 9, k - 36), ACBlocks.dreadstone_brick.getDefaultState(), 2);
		world.setBlockState(new BlockPos(i - 22, j + 9, k - 35), ACBlocks.dreadstone_brick.getDefaultState(), 2);
		world.setBlockState(new BlockPos(i - 22, j + 9, k - 34), ACBlocks.dreadstone_brick.getDefaultState(), 2);
		world.setBlockState(new BlockPos(i - 22, j + 10, k - 41), ACBlocks.dreadstone_brick.getDefaultState(), 2);
		world.setBlockState(new BlockPos(i - 22, j + 10, k - 40), ACBlocks.dreadstone_brick.getDefaultState(), 2);
		world.setBlockState(new BlockPos(i - 22, j + 10, k - 39), ACBlocks.dreadstone_brick.getDefaultState(), 2);
		world.setBlockState(new BlockPos(i - 22, j + 10, k - 38), ACBlocks.dreadstone_brick.getDefaultState(), 2);
		world.setBlockState(new BlockPos(i - 22, j + 10, k - 37), ACBlocks.dreadstone_brick.getDefaultState(), 2);
		world.setBlockState(new BlockPos(i - 22, j + 10, k - 36), ACBlocks.dreadstone_brick.getDefaultState(), 2);
		world.setBlockState(new BlockPos(i - 22, j + 10, k - 35), ACBlocks.dreadstone_brick.getDefaultState(), 2);
		world.setBlockState(new BlockPos(i - 21, j + 3, k - 40), ACBlocks.dreadstone_brick.getDefaultState(), 2);
		world.setBlockState(new BlockPos(i - 21, j + 3, k - 39), ACBlocks.dreadstone_brick.getDefaultState(), 2);
		world.setBlockState(new BlockPos(i - 21, j + 3, k - 38), ACBlocks.dreadstone_brick.getDefaultState(), 2);
		world.setBlockState(new BlockPos(i - 21, j + 3, k - 37), ACBlocks.dreadstone_brick.getDefaultState(), 2);
		world.setBlockState(new BlockPos(i - 21, j + 3, k - 36), ACBlocks.dreadstone_brick.getDefaultState(), 2);
		world.setBlockState(new BlockPos(i - 21, j + 3, k - 35), ACBlocks.dreadstone_brick.getDefaultState(), 2);
		world.setBlockState(new BlockPos(i - 21, j + 3, k - 34), ACBlocks.dreadstone_brick.getDefaultState(), 2);
		world.setBlockState(new BlockPos(i - 21, j + 3, k - 33), ACBlocks.dreadstone_brick.getDefaultState(), 2);
		world.setBlockState(new BlockPos(i - 21, j + 3, k - 32), ACBlocks.dreadstone_brick.getDefaultState(), 2);
		world.setBlockState(new BlockPos(i - 21, j + 3, k - 31), ACBlocks.dreadstone_brick.getDefaultState(), 2);
		world.setBlockState(new BlockPos(i - 21, j + 3, k - 30), ACBlocks.dreadstone_brick.getDefaultState(), 2);
		world.setBlockState(new BlockPos(i - 21, j + 3, k - 29), ACBlocks.dreadstone_brick.getDefaultState(), 2);
		world.setBlockState(new BlockPos(i - 21, j + 3, k - 28), ACBlocks.dreadstone_brick.getDefaultState(), 2);
		world.setBlockState(new BlockPos(i - 21, j + 3, k - 27), ACBlocks.dreadstone_brick.getDefaultState(), 2);
		world.setBlockState(new BlockPos(i - 21, j + 3, k - 26), ACBlocks.dreadstone_brick.getDefaultState(), 2);
		world.setBlockState(new BlockPos(i - 21, j + 3, k - 25), ACBlocks.dreadstone_brick.getDefaultState(), 2);
		world.setBlockState(new BlockPos(i - 21, j + 3, k - 24), ACBlocks.dreadstone_brick.getDefaultState(), 2);
		world.setBlockState(new BlockPos(i - 21, j + 3, k - 23), ACBlocks.dreadstone_brick.getDefaultState(), 2);
		world.setBlockState(new BlockPos(i - 21, j + 4, k - 41), ACBlocks.dreadstone_brick.getDefaultState(), 2);
		world.setBlockState(new BlockPos(i - 21, j + 4, k - 22), ACBlocks.dreadstone_brick.getDefaultState(), 2);
		world.setBlockState(new BlockPos(i - 21, j + 5, k - 41), ACBlocks.dreadstone_brick.getDefaultState(), 2);
		world.setBlockState(new BlockPos(i - 21, j + 5, k - 22), ACBlocks.dreadstone_brick.getDefaultState(), 2);
		world.setBlockState(new BlockPos(i - 21, j + 6, k - 41), ACBlocks.dreadstone_brick.getDefaultState(), 2);
		world.setBlockState(new BlockPos(i - 21, j + 6, k - 22), ACBlocks.dreadstone_brick.getDefaultState(), 2);
		world.setBlockState(new BlockPos(i - 21, j + 7, k - 41), ACBlocks.dreadstone_brick.getDefaultState(), 2);
		world.setBlockState(new BlockPos(i - 21, j + 7, k - 22), ACBlocks.dreadstone_brick.getDefaultState(), 2);
		world.setBlockState(new BlockPos(i - 21, j + 8, k - 41), ACBlocks.dreadstone_brick.getDefaultState(), 2);
		world.setBlockState(new BlockPos(i - 21, j + 8, k - 33), ACBlocks.dreadstone_brick.getDefaultState(), 2);
		world.setBlockState(new BlockPos(i - 21, j + 8, k - 32), ACBlocks.dreadstone_brick.getDefaultState(), 2);
		world.setBlockState(new BlockPos(i - 21, j + 8, k - 31), ACBlocks.dreadstone_brick.getDefaultState(), 2);
		world.setBlockState(new BlockPos(i - 21, j + 8, k - 30), ACBlocks.dreadstone_brick.getDefaultState(), 2);
		world.setBlockState(new BlockPos(i - 21, j + 8, k - 29), ACBlocks.dreadstone_brick.getDefaultState(), 2);
		world.setBlockState(new BlockPos(i - 21, j + 8, k - 28), ACBlocks.dreadstone_brick.getDefaultState(), 2);
		world.setBlockState(new BlockPos(i - 21, j + 8, k - 27), ACBlocks.dreadstone_brick.getDefaultState(), 2);
		world.setBlockState(new BlockPos(i - 21, j + 8, k - 26), ACBlocks.dreadstone_brick.getDefaultState(), 2);
		world.setBlockState(new BlockPos(i - 21, j + 8, k - 25), ACBlocks.dreadstone_brick.getDefaultState(), 2);
		world.setBlockState(new BlockPos(i - 21, j + 8, k - 24), ACBlocks.dreadstone_brick.getDefaultState(), 2);
		world.setBlockState(new BlockPos(i - 21, j + 8, k - 23), ACBlocks.dreadstone_brick.getDefaultState(), 2);
		world.setBlockState(new BlockPos(i - 21, j + 8, k - 22), ACBlocks.dreadstone_brick.getDefaultState(), 2);
		world.setBlockState(new BlockPos(i - 21, j + 9, k - 41), ACBlocks.dreadstone_brick.getDefaultState(), 2);
		world.setBlockState(new BlockPos(i - 21, j + 9, k - 34), ACBlocks.dreadstone_brick.getDefaultState(), 2);
		world.setBlockState(new BlockPos(i - 21, j + 10, k - 41), ACBlocks.dreadstone_brick.getDefaultState(), 2);
		world.setBlockState(new BlockPos(i - 21, j + 10, k - 40), ACBlocks.dreadstone_brick.getDefaultState(), 2);
		world.setBlockState(new BlockPos(i - 21, j + 10, k - 39), ACBlocks.dreadstone_brick.getDefaultState(), 2);
		world.setBlockState(new BlockPos(i - 21, j + 10, k - 38), ACBlocks.dreadstone_brick.getDefaultState(), 2);
		world.setBlockState(new BlockPos(i - 21, j + 10, k - 37), ACBlocks.dreadstone_brick.getDefaultState(), 2);
		world.setBlockState(new BlockPos(i - 21, j + 10, k - 36), ACBlocks.dreadstone_brick.getDefaultState(), 2);
		world.setBlockState(new BlockPos(i - 21, j + 10, k - 35), ACBlocks.dreadstone_brick.getDefaultState(), 2);
		world.setBlockState(new BlockPos(i - 20, j + 3, k - 40), ACBlocks.dreadstone_brick.getDefaultState(), 2);
		world.setBlockState(new BlockPos(i - 20, j + 3, k - 39), ACBlocks.dreadstone_brick.getDefaultState(), 2);
		world.setBlockState(new BlockPos(i - 20, j + 3, k - 38), ACBlocks.dreadstone_brick.getDefaultState(), 2);
		world.setBlockState(new BlockPos(i - 20, j + 3, k - 37), ACBlocks.dreadstone_brick.getDefaultState(), 2);
		world.setBlockState(new BlockPos(i - 20, j + 3, k - 36), ACBlocks.dreadstone_brick.getDefaultState(), 2);
		world.setBlockState(new BlockPos(i - 20, j + 3, k - 35), ACBlocks.dreadstone_brick.getDefaultState(), 2);
		world.setBlockState(new BlockPos(i - 20, j + 3, k - 34), ACBlocks.dreadstone_brick.getDefaultState(), 2);
		world.setBlockState(new BlockPos(i - 20, j + 3, k - 33), ACBlocks.dreadstone_brick.getDefaultState(), 2);
		world.setBlockState(new BlockPos(i - 20, j + 3, k - 32), ACBlocks.dreadstone_brick.getDefaultState(), 2);
		world.setBlockState(new BlockPos(i - 20, j + 3, k - 31), ACBlocks.dreadstone_brick.getDefaultState(), 2);
		world.setBlockState(new BlockPos(i - 20, j + 3, k - 30), ACBlocks.dreadstone_brick.getDefaultState(), 2);
		world.setBlockState(new BlockPos(i - 20, j + 3, k - 29), ACBlocks.dreadstone_brick.getDefaultState(), 2);
		world.setBlockState(new BlockPos(i - 20, j + 3, k - 28), ACBlocks.dreadstone_brick.getDefaultState(), 2);
		world.setBlockState(new BlockPos(i - 20, j + 3, k - 27), ACBlocks.dreadstone_brick.getDefaultState(), 2);
		world.setBlockState(new BlockPos(i - 20, j + 3, k - 26), ACBlocks.dreadstone_brick.getDefaultState(), 2);
		world.setBlockState(new BlockPos(i - 20, j + 3, k - 25), ACBlocks.dreadstone_brick.getDefaultState(), 2);
		world.setBlockState(new BlockPos(i - 20, j + 3, k - 24), ACBlocks.dreadstone_brick.getDefaultState(), 2);
		world.setBlockState(new BlockPos(i - 20, j + 3, k - 23), ACBlocks.dreadstone_brick.getDefaultState(), 2);
		world.setBlockState(new BlockPos(i - 20, j + 4, k - 41), ACBlocks.dreadstone_brick.getDefaultState(), 2);
		world.setBlockState(new BlockPos(i - 20, j + 4, k - 26), ACBlocks.dreadguard_spawner.getDefaultState(), 2);
		world.setBlockState(new BlockPos(i - 20, j + 4, k - 22), ACBlocks.dreadstone_brick.getDefaultState(), 2);
		world.setBlockState(new BlockPos(i - 20, j + 5, k - 41), ACBlocks.dreadstone_brick.getDefaultState(), 2);
		world.setBlockState(new BlockPos(i - 20, j + 5, k - 22), ACBlocks.dreadstone_brick.getDefaultState(), 2);
		world.setBlockState(new BlockPos(i - 20, j + 6, k - 41), ACBlocks.dreadstone_brick.getDefaultState(), 2);
		world.setBlockState(new BlockPos(i - 20, j + 6, k - 22), ACBlocks.dreadstone_brick.getDefaultState(), 2);
		world.setBlockState(new BlockPos(i - 20, j + 7, k - 41), ACBlocks.dreadstone_brick.getDefaultState(), 2);
		world.setBlockState(new BlockPos(i - 20, j + 7, k - 22), ACBlocks.dreadstone_brick.getDefaultState(), 2);
		world.setBlockState(new BlockPos(i - 20, j + 8, k - 41), ACBlocks.dreadstone_brick.getDefaultState(), 2);
		world.setBlockState(new BlockPos(i - 20, j + 8, k - 33), ACBlocks.dreadstone_brick.getDefaultState(), 2);
		world.setBlockState(new BlockPos(i - 20, j + 8, k - 32), ACBlocks.dreadstone_brick.getDefaultState(), 2);
		world.setBlockState(new BlockPos(i - 20, j + 8, k - 31), ACBlocks.dreadstone_brick.getDefaultState(), 2);
		world.setBlockState(new BlockPos(i - 20, j + 8, k - 30), ACBlocks.dreadstone_brick.getDefaultState(), 2);
		world.setBlockState(new BlockPos(i - 20, j + 8, k - 29), ACBlocks.dreadstone_brick.getDefaultState(), 2);
		world.setBlockState(new BlockPos(i - 20, j + 8, k - 28), ACBlocks.dreadstone_brick.getDefaultState(), 2);
		world.setBlockState(new BlockPos(i - 20, j + 8, k - 27), ACBlocks.dreadstone_brick.getDefaultState(), 2);
		world.setBlockState(new BlockPos(i - 20, j + 8, k - 26), ACBlocks.dreadstone_brick.getDefaultState(), 2);
		world.setBlockState(new BlockPos(i - 20, j + 8, k - 25), ACBlocks.dreadstone_brick.getDefaultState(), 2);
		world.setBlockState(new BlockPos(i - 20, j + 8, k - 24), ACBlocks.dreadstone_brick.getDefaultState(), 2);
		world.setBlockState(new BlockPos(i - 20, j + 8, k - 23), ACBlocks.dreadstone_brick.getDefaultState(), 2);
		world.setBlockState(new BlockPos(i - 20, j + 8, k - 22), ACBlocks.dreadstone_brick.getDefaultState(), 2);
		world.setBlockState(new BlockPos(i - 20, j + 9, k - 41), ACBlocks.dreadstone_brick.getDefaultState(), 2);
		world.setBlockState(new BlockPos(i - 20, j + 9, k - 34), ACBlocks.dreadstone_brick.getDefaultState(), 2);
		world.setBlockState(new BlockPos(i - 20, j + 10, k - 41), ACBlocks.dreadstone_brick.getDefaultState(), 2);
		world.setBlockState(new BlockPos(i - 20, j + 10, k - 40), ACBlocks.dreadstone_brick.getDefaultState(), 2);
		world.setBlockState(new BlockPos(i - 20, j + 10, k - 39), ACBlocks.dreadstone_brick.getDefaultState(), 2);
		world.setBlockState(new BlockPos(i - 20, j + 10, k - 38), ACBlocks.dreadstone_brick.getDefaultState(), 2);
		world.setBlockState(new BlockPos(i - 20, j + 10, k - 37), ACBlocks.dreadstone_brick.getDefaultState(), 2);
		world.setBlockState(new BlockPos(i - 20, j + 10, k - 36), ACBlocks.dreadstone_brick.getDefaultState(), 2);
		world.setBlockState(new BlockPos(i - 20, j + 10, k - 35), ACBlocks.dreadstone_brick.getDefaultState(), 2);
		world.setBlockState(new BlockPos(i - 19, j + 3, k - 40), ACBlocks.dreadstone_brick.getDefaultState(), 2);
		world.setBlockState(new BlockPos(i - 19, j + 3, k - 39), ACBlocks.dreadstone_brick.getDefaultState(), 2);
		world.setBlockState(new BlockPos(i - 19, j + 3, k - 38), ACBlocks.dreadstone_brick.getDefaultState(), 2);
		world.setBlockState(new BlockPos(i - 19, j + 3, k - 37), ACBlocks.dreadstone_brick.getDefaultState(), 2);
		world.setBlockState(new BlockPos(i - 19, j + 3, k - 36), ACBlocks.dreadstone_brick.getDefaultState(), 2);
		world.setBlockState(new BlockPos(i - 19, j + 3, k - 35), ACBlocks.dreadstone_brick.getDefaultState(), 2);
		world.setBlockState(new BlockPos(i - 19, j + 3, k - 34), ACBlocks.dreadstone_brick.getDefaultState(), 2);
		world.setBlockState(new BlockPos(i - 19, j + 3, k - 33), ACBlocks.dreadstone_brick.getDefaultState(), 2);
		world.setBlockState(new BlockPos(i - 19, j + 3, k - 32), ACBlocks.dreadstone_brick.getDefaultState(), 2);
		world.setBlockState(new BlockPos(i - 19, j + 3, k - 31), ACBlocks.dreadstone_brick.getDefaultState(), 2);
		world.setBlockState(new BlockPos(i - 19, j + 3, k - 30), ACBlocks.dreadstone_brick.getDefaultState(), 2);
		world.setBlockState(new BlockPos(i - 19, j + 3, k - 29), ACBlocks.dreadstone_brick.getDefaultState(), 2);
		world.setBlockState(new BlockPos(i - 19, j + 3, k - 28), ACBlocks.dreadstone_brick.getDefaultState(), 2);
		world.setBlockState(new BlockPos(i - 19, j + 3, k - 27), ACBlocks.dreadstone_brick.getDefaultState(), 2);
		world.setBlockState(new BlockPos(i - 19, j + 3, k - 26), ACBlocks.dreadstone_brick.getDefaultState(), 2);
		world.setBlockState(new BlockPos(i - 19, j + 3, k - 25), ACBlocks.dreadstone_brick.getDefaultState(), 2);
		world.setBlockState(new BlockPos(i - 19, j + 3, k - 24), ACBlocks.dreadstone_brick.getDefaultState(), 2);
		world.setBlockState(new BlockPos(i - 19, j + 3, k - 23), ACBlocks.dreadstone_brick.getDefaultState(), 2);
		world.setBlockState(new BlockPos(i - 19, j + 4, k - 41), ACBlocks.dreadstone_brick.getDefaultState(), 2);
		world.setBlockState(new BlockPos(i - 19, j + 4, k - 22), ACBlocks.dreadstone_brick.getDefaultState(), 2);
		world.setBlockState(new BlockPos(i - 19, j + 5, k - 41), ACBlocks.dreadstone_brick.getDefaultState(), 2);
		world.setBlockState(new BlockPos(i - 19, j + 5, k - 22), ACBlocks.dreadstone_brick.getDefaultState(), 2);
		world.setBlockState(new BlockPos(i - 19, j + 6, k - 41), ACBlocks.dreadstone_brick.getDefaultState(), 2);
		world.setBlockState(new BlockPos(i - 19, j + 6, k - 22), ACBlocks.dreadstone_brick.getDefaultState(), 2);
		world.setBlockState(new BlockPos(i - 19, j + 7, k - 41), ACBlocks.dreadstone_brick.getDefaultState(), 2);
		world.setBlockState(new BlockPos(i - 19, j + 7, k - 22), ACBlocks.dreadstone_brick.getDefaultState(), 2);
		world.setBlockState(new BlockPos(i - 19, j + 8, k - 41), ACBlocks.dreadstone_brick.getDefaultState(), 2);
		world.setBlockState(new BlockPos(i - 19, j + 8, k - 33), ACBlocks.dreadstone_brick.getDefaultState(), 2);
		world.setBlockState(new BlockPos(i - 19, j + 8, k - 32), ACBlocks.dreadstone_brick.getDefaultState(), 2);
		world.setBlockState(new BlockPos(i - 19, j + 8, k - 31), ACBlocks.dreadstone_brick.getDefaultState(), 2);
		world.setBlockState(new BlockPos(i - 19, j + 8, k - 30), ACBlocks.dreadstone_brick.getDefaultState(), 2);
		world.setBlockState(new BlockPos(i - 19, j + 8, k - 29), ACBlocks.dreadstone_brick.getDefaultState(), 2);
		world.setBlockState(new BlockPos(i - 19, j + 8, k - 28), ACBlocks.dreadstone_brick.getDefaultState(), 2);
		world.setBlockState(new BlockPos(i - 19, j + 8, k - 27), ACBlocks.dreadstone_brick.getDefaultState(), 2);
		world.setBlockState(new BlockPos(i - 19, j + 8, k - 26), ACBlocks.dreadstone_brick.getDefaultState(), 2);
		world.setBlockState(new BlockPos(i - 19, j + 8, k - 25), ACBlocks.dreadstone_brick.getDefaultState(), 2);
		world.setBlockState(new BlockPos(i - 19, j + 8, k - 24), ACBlocks.dreadstone_brick.getDefaultState(), 2);
		world.setBlockState(new BlockPos(i - 19, j + 8, k - 23), ACBlocks.dreadstone_brick.getDefaultState(), 2);
		world.setBlockState(new BlockPos(i - 19, j + 8, k - 22), ACBlocks.dreadstone_brick.getDefaultState(), 2);
		world.setBlockState(new BlockPos(i - 19, j + 9, k - 41), ACBlocks.dreadstone_brick.getDefaultState(), 2);
		world.setBlockState(new BlockPos(i - 19, j + 9, k - 34), ACBlocks.dreadstone_brick.getDefaultState(), 2);
		world.setBlockState(new BlockPos(i - 19, j + 10, k - 41), ACBlocks.dreadstone_brick.getDefaultState(), 2);
		world.setBlockState(new BlockPos(i - 19, j + 10, k - 40), ACBlocks.dreadstone_brick.getDefaultState(), 2);
		world.setBlockState(new BlockPos(i - 19, j + 10, k - 39), ACBlocks.dreadstone_brick.getDefaultState(), 2);
		world.setBlockState(new BlockPos(i - 19, j + 10, k - 38), ACBlocks.dreadstone_brick.getDefaultState(), 2);
		world.setBlockState(new BlockPos(i - 19, j + 10, k - 37), ACBlocks.dreadstone_brick.getDefaultState(), 2);
		world.setBlockState(new BlockPos(i - 19, j + 10, k - 36), ACBlocks.dreadstone_brick.getDefaultState(), 2);
		world.setBlockState(new BlockPos(i - 19, j + 10, k - 35), ACBlocks.dreadstone_brick.getDefaultState(), 2);
		world.setBlockState(new BlockPos(i - 18, j + 3, k - 40), ACBlocks.dreadstone_brick.getDefaultState(), 2);
		world.setBlockState(new BlockPos(i - 18, j + 3, k - 39), ACBlocks.dreadstone_brick.getDefaultState(), 2);
		world.setBlockState(new BlockPos(i - 18, j + 3, k - 38), ACBlocks.dreadstone_brick.getDefaultState(), 2);
		world.setBlockState(new BlockPos(i - 18, j + 3, k - 37), ACBlocks.dreadstone_brick.getDefaultState(), 2);
		world.setBlockState(new BlockPos(i - 18, j + 3, k - 36), ACBlocks.dreadstone_brick.getDefaultState(), 2);
		world.setBlockState(new BlockPos(i - 18, j + 3, k - 35), ACBlocks.dreadstone_brick.getDefaultState(), 2);
		world.setBlockState(new BlockPos(i - 18, j + 3, k - 34), ACBlocks.dreadstone_brick.getDefaultState(), 2);
		world.setBlockState(new BlockPos(i - 18, j + 3, k - 33), ACBlocks.dreadstone_brick.getDefaultState(), 2);
		world.setBlockState(new BlockPos(i - 18, j + 3, k - 32), ACBlocks.dreadstone_brick.getDefaultState(), 2);
		world.setBlockState(new BlockPos(i - 18, j + 3, k - 31), ACBlocks.dreadstone_brick.getDefaultState(), 2);
		world.setBlockState(new BlockPos(i - 18, j + 3, k - 30), ACBlocks.dreadstone_brick.getDefaultState(), 2);
		world.setBlockState(new BlockPos(i - 18, j + 3, k - 29), ACBlocks.dreadstone_brick.getDefaultState(), 2);
		world.setBlockState(new BlockPos(i - 18, j + 3, k - 28), ACBlocks.dreadstone_brick.getDefaultState(), 2);
		world.setBlockState(new BlockPos(i - 18, j + 3, k - 27), ACBlocks.dreadstone_brick.getDefaultState(), 2);
		world.setBlockState(new BlockPos(i - 18, j + 3, k - 26), ACBlocks.dreadstone_brick.getDefaultState(), 2);
		world.setBlockState(new BlockPos(i - 18, j + 3, k - 25), ACBlocks.dreadstone_brick.getDefaultState(), 2);
		world.setBlockState(new BlockPos(i - 18, j + 3, k - 24), ACBlocks.dreadstone_brick.getDefaultState(), 2);
		world.setBlockState(new BlockPos(i - 18, j + 3, k - 23), ACBlocks.dreadstone_brick.getDefaultState(), 2);
		world.setBlockState(new BlockPos(i - 18, j + 4, k - 41), ACBlocks.dreadstone_brick.getDefaultState(), 2);
		world.setBlockState(new BlockPos(i - 18, j + 4, k - 22), ACBlocks.dreadstone_brick.getDefaultState(), 2);
		world.setBlockState(new BlockPos(i - 18, j + 5, k - 41), ACBlocks.dreadstone_brick.getDefaultState(), 2);
		world.setBlockState(new BlockPos(i - 18, j + 5, k - 22), ACBlocks.dreadstone_brick.getDefaultState(), 2);
		world.setBlockState(new BlockPos(i - 18, j + 6, k - 41), ACBlocks.dreadstone_brick.getDefaultState(), 2);
		world.setBlockState(new BlockPos(i - 18, j + 6, k - 22), ACBlocks.dreadstone_brick.getDefaultState(), 2);
		world.setBlockState(new BlockPos(i - 18, j + 7, k - 41), ACBlocks.dreadstone_brick.getDefaultState(), 2);
		world.setBlockState(new BlockPos(i - 18, j + 7, k - 22), ACBlocks.dreadstone_brick.getDefaultState(), 2);
		world.setBlockState(new BlockPos(i - 18, j + 8, k - 41), ACBlocks.dreadstone_brick.getDefaultState(), 2);
		world.setBlockState(new BlockPos(i - 18, j + 8, k - 33), ACBlocks.dreadstone_brick.getDefaultState(), 2);
		world.setBlockState(new BlockPos(i - 18, j + 8, k - 32), ACBlocks.dreadstone_brick.getDefaultState(), 2);
		world.setBlockState(new BlockPos(i - 18, j + 8, k - 31), ACBlocks.dreadstone_brick.getDefaultState(), 2);
		world.setBlockState(new BlockPos(i - 18, j + 8, k - 30), ACBlocks.dreadstone_brick.getDefaultState(), 2);
		world.setBlockState(new BlockPos(i - 18, j + 8, k - 29), ACBlocks.dreadstone_brick.getDefaultState(), 2);
		world.setBlockState(new BlockPos(i - 18, j + 8, k - 28), ACBlocks.dreadstone_brick.getDefaultState(), 2);
		world.setBlockState(new BlockPos(i - 18, j + 8, k - 27), ACBlocks.dreadstone_brick.getDefaultState(), 2);
		world.setBlockState(new BlockPos(i - 18, j + 8, k - 26), ACBlocks.dreadstone_brick.getDefaultState(), 2);
		world.setBlockState(new BlockPos(i - 18, j + 8, k - 25), ACBlocks.dreadstone_brick.getDefaultState(), 2);
		world.setBlockState(new BlockPos(i - 18, j + 8, k - 24), ACBlocks.dreadstone_brick.getDefaultState(), 2);
		world.setBlockState(new BlockPos(i - 18, j + 8, k - 23), ACBlocks.dreadstone_brick.getDefaultState(), 2);
		world.setBlockState(new BlockPos(i - 18, j + 8, k - 22), ACBlocks.dreadstone_brick.getDefaultState(), 2);
		world.setBlockState(new BlockPos(i - 18, j + 9, k - 41), ACBlocks.dreadstone_brick.getDefaultState(), 2);
		world.setBlockState(new BlockPos(i - 18, j + 9, k - 34), ACBlocks.dreadstone_brick.getDefaultState(), 2);
		world.setBlockState(new BlockPos(i - 18, j + 10, k - 41), ACBlocks.dreadstone_brick.getDefaultState(), 2);
		world.setBlockState(new BlockPos(i - 18, j + 10, k - 40), ACBlocks.dreadstone_brick.getDefaultState(), 2);
		world.setBlockState(new BlockPos(i - 18, j + 10, k - 39), ACBlocks.dreadstone_brick.getDefaultState(), 2);
		world.setBlockState(new BlockPos(i - 18, j + 10, k - 38), ACBlocks.dreadstone_brick.getDefaultState(), 2);
		world.setBlockState(new BlockPos(i - 18, j + 10, k - 37), ACBlocks.dreadstone_brick.getDefaultState(), 2);
		world.setBlockState(new BlockPos(i - 18, j + 10, k - 36), ACBlocks.dreadstone_brick.getDefaultState(), 2);
		world.setBlockState(new BlockPos(i - 18, j + 10, k - 35), ACBlocks.dreadstone_brick.getDefaultState(), 2);
		world.setBlockState(new BlockPos(i - 17, j + 3, k - 40), ACBlocks.dreadstone_brick.getDefaultState(), 2);
		world.setBlockState(new BlockPos(i - 17, j + 3, k - 39), ACBlocks.dreadstone_brick.getDefaultState(), 2);
		world.setBlockState(new BlockPos(i - 17, j + 3, k - 38), ACBlocks.dreadstone_brick.getDefaultState(), 2);
		world.setBlockState(new BlockPos(i - 17, j + 3, k - 37), ACBlocks.dreadstone_brick.getDefaultState(), 2);
		world.setBlockState(new BlockPos(i - 17, j + 3, k - 29), ACBlocks.dreadstone_brick.getDefaultState(), 2);
		world.setBlockState(new BlockPos(i - 17, j + 3, k - 28), ACBlocks.dreadstone_brick.getDefaultState(), 2);
		world.setBlockState(new BlockPos(i - 17, j + 3, k - 27), ACBlocks.dreadstone_brick.getDefaultState(), 2);
		world.setBlockState(new BlockPos(i - 17, j + 3, k - 26), ACBlocks.dreadstone_brick.getDefaultState(), 2);
		world.setBlockState(new BlockPos(i - 17, j + 3, k - 25), ACBlocks.dreadstone_brick.getDefaultState(), 2);
		world.setBlockState(new BlockPos(i - 17, j + 3, k - 24), ACBlocks.dreadstone_brick.getDefaultState(), 2);
		world.setBlockState(new BlockPos(i - 17, j + 3, k - 23), ACBlocks.dreadstone_brick.getDefaultState(), 2);
		world.setBlockState(new BlockPos(i - 17, j + 4, k - 41), ACBlocks.dreadstone_brick.getDefaultState(), 2);
		world.setBlockState(new BlockPos(i - 17, j + 4, k - 36), ACBlocks.dreadstone_brick.getDefaultState(), 2);
		world.setBlockState(new BlockPos(i - 17, j + 4, k - 35), ACBlocks.dreadstone_brick.getDefaultState(), 2);
		world.setBlockState(new BlockPos(i - 17, j + 4, k - 34), ACBlocks.dreadstone_brick.getDefaultState(), 2);
		world.setBlockState(new BlockPos(i - 17, j + 4, k - 33), ACBlocks.dreadstone_brick.getDefaultState(), 2);
		world.setBlockState(new BlockPos(i - 17, j + 4, k - 32), ACBlocks.dreadstone_brick.getDefaultState(), 2);
		world.setBlockState(new BlockPos(i - 17, j + 4, k - 31), ACBlocks.dreadstone_brick.getDefaultState(), 2);
		world.setBlockState(new BlockPos(i - 17, j + 4, k - 30), ACBlocks.dreadstone_brick.getDefaultState(), 2);
		world.setBlockState(new BlockPos(i - 17, j + 4, k - 22), ACBlocks.dreadstone_brick.getDefaultState(), 2);
		world.setBlockState(new BlockPos(i - 17, j + 5, k - 41), ACBlocks.dreadstone_brick.getDefaultState(), 2);
		world.setBlockState(new BlockPos(i - 17, j + 5, k - 36), ACBlocks.dreadstone_brick.getDefaultState(), 2);
		world.setBlockState(new BlockPos(i - 17, j + 5, k - 35), ACBlocks.dreadstone_brick.getDefaultState(), 2);
		world.setBlockState(new BlockPos(i - 17, j + 5, k - 34), ACBlocks.dreadstone_brick.getDefaultState(), 2);
		world.setBlockState(new BlockPos(i - 17, j + 5, k - 33), ACBlocks.dreadstone_brick.getDefaultState(), 2);
		world.setBlockState(new BlockPos(i - 17, j + 5, k - 32), ACBlocks.dreadstone_brick.getDefaultState(), 2);
		world.setBlockState(new BlockPos(i - 17, j + 5, k - 31), ACBlocks.dreadstone_brick.getDefaultState(), 2);
		world.setBlockState(new BlockPos(i - 17, j + 5, k - 30), ACBlocks.dreadstone_brick.getDefaultState(), 2);
		world.setBlockState(new BlockPos(i - 17, j + 5, k - 22), ACBlocks.dreadstone_brick.getDefaultState(), 2);
		world.setBlockState(new BlockPos(i - 17, j + 6, k - 41), ACBlocks.dreadstone_brick.getDefaultState(), 2);
		world.setBlockState(new BlockPos(i - 17, j + 6, k - 36), ACBlocks.dreadstone_brick.getDefaultState(), 2);
		world.setBlockState(new BlockPos(i - 17, j + 6, k - 35), ACBlocks.dreadstone_brick.getDefaultState(), 2);
		world.setBlockState(new BlockPos(i - 17, j + 6, k - 34), ACBlocks.dreadstone_brick.getDefaultState(), 2);
		world.setBlockState(new BlockPos(i - 17, j + 6, k - 33), ACBlocks.dreadstone_brick.getDefaultState(), 2);
		world.setBlockState(new BlockPos(i - 17, j + 6, k - 32), ACBlocks.dreadstone_brick.getDefaultState(), 2);
		world.setBlockState(new BlockPos(i - 17, j + 6, k - 31), ACBlocks.dreadstone_brick.getDefaultState(), 2);
		world.setBlockState(new BlockPos(i - 17, j + 6, k - 30), ACBlocks.dreadstone_brick.getDefaultState(), 2);
		world.setBlockState(new BlockPos(i - 17, j + 6, k - 22), ACBlocks.dreadstone_brick.getDefaultState(), 2);
		world.setBlockState(new BlockPos(i - 17, j + 7, k - 41), ACBlocks.dreadstone_brick.getDefaultState(), 2);
		world.setBlockState(new BlockPos(i - 17, j + 7, k - 36), ACBlocks.dreadstone_brick.getDefaultState(), 2);
		world.setBlockState(new BlockPos(i - 17, j + 7, k - 35), ACBlocks.dreadstone_brick.getDefaultState(), 2);
		world.setBlockState(new BlockPos(i - 17, j + 7, k - 34), ACBlocks.dreadstone_brick.getDefaultState(), 2);
		world.setBlockState(new BlockPos(i - 17, j + 7, k - 33), ACBlocks.dreadstone_brick.getDefaultState(), 2);
		world.setBlockState(new BlockPos(i - 17, j + 7, k - 32), ACBlocks.dreadstone_brick.getDefaultState(), 2);
		world.setBlockState(new BlockPos(i - 17, j + 7, k - 31), ACBlocks.dreadstone_brick.getDefaultState(), 2);
		world.setBlockState(new BlockPos(i - 17, j + 7, k - 30), ACBlocks.dreadstone_brick.getDefaultState(), 2);
		world.setBlockState(new BlockPos(i - 17, j + 7, k - 22), ACBlocks.dreadstone_brick.getDefaultState(), 2);
		world.setBlockState(new BlockPos(i - 17, j + 8, k - 41), ACBlocks.dreadstone_brick.getDefaultState(), 2);
		world.setBlockState(new BlockPos(i - 17, j + 8, k - 36), ACBlocks.dreadstone_brick.getDefaultState(), 2);
		world.setBlockState(new BlockPos(i - 17, j + 8, k - 35), ACBlocks.dreadstone_brick.getDefaultState(), 2);
		world.setBlockState(new BlockPos(i - 17, j + 8, k - 34), ACBlocks.dreadstone_brick.getDefaultState(), 2);
		world.setBlockState(new BlockPos(i - 17, j + 8, k - 33), ACBlocks.dreadstone_brick.getDefaultState(), 2);
		world.setBlockState(new BlockPos(i - 17, j + 8, k - 32), ACBlocks.dreadstone_brick.getDefaultState(), 2);
		world.setBlockState(new BlockPos(i - 17, j + 8, k - 31), ACBlocks.dreadstone_brick.getDefaultState(), 2);
		world.setBlockState(new BlockPos(i - 17, j + 8, k - 30), ACBlocks.dreadstone_brick.getDefaultState(), 2);
		world.setBlockState(new BlockPos(i - 17, j + 8, k - 29), ACBlocks.dreadstone_brick.getDefaultState(), 2);
		world.setBlockState(new BlockPos(i - 17, j + 8, k - 28), ACBlocks.dreadstone_brick.getDefaultState(), 2);
		world.setBlockState(new BlockPos(i - 17, j + 8, k - 27), ACBlocks.dreadstone_brick.getDefaultState(), 2);
		world.setBlockState(new BlockPos(i - 17, j + 8, k - 26), ACBlocks.dreadstone_brick.getDefaultState(), 2);
		world.setBlockState(new BlockPos(i - 17, j + 8, k - 25), ACBlocks.dreadstone_brick.getDefaultState(), 2);
		world.setBlockState(new BlockPos(i - 17, j + 8, k - 24), ACBlocks.dreadstone_brick.getDefaultState(), 2);
		world.setBlockState(new BlockPos(i - 17, j + 8, k - 23), ACBlocks.dreadstone_brick.getDefaultState(), 2);
		world.setBlockState(new BlockPos(i - 17, j + 8, k - 22), ACBlocks.dreadstone_brick.getDefaultState(), 2);
		world.setBlockState(new BlockPos(i - 17, j + 9, k - 41), ACBlocks.dreadstone_brick.getDefaultState(), 2);
		world.setBlockState(new BlockPos(i - 17, j + 9, k - 36), ACBlocks.dreadstone_brick.getDefaultState(), 2);
		world.setBlockState(new BlockPos(i - 17, j + 9, k - 35), ACBlocks.dreadstone_brick.getDefaultState(), 2);
		world.setBlockState(new BlockPos(i - 17, j + 9, k - 34), ACBlocks.dreadstone_brick.getDefaultState(), 2);
		world.setBlockState(new BlockPos(i - 17, j + 10, k - 41), ACBlocks.dreadstone_brick.getDefaultState(), 2);
		world.setBlockState(new BlockPos(i - 17, j + 10, k - 40), ACBlocks.dreadstone_brick.getDefaultState(), 2);
		world.setBlockState(new BlockPos(i - 17, j + 10, k - 39), ACBlocks.dreadstone_brick.getDefaultState(), 2);
		world.setBlockState(new BlockPos(i - 17, j + 10, k - 38), ACBlocks.dreadstone_brick.getDefaultState(), 2);
		world.setBlockState(new BlockPos(i - 17, j + 10, k - 37), ACBlocks.dreadstone_brick.getDefaultState(), 2);
		world.setBlockState(new BlockPos(i - 17, j + 10, k - 36), ACBlocks.dreadstone_brick.getDefaultState(), 2);
		world.setBlockState(new BlockPos(i - 17, j + 10, k - 35), ACBlocks.dreadstone_brick.getDefaultState(), 2);
		world.setBlockState(new BlockPos(i - 17, j + 11, k - 41), ACBlocks.dreadstone_brick.getDefaultState(), 2);
		world.setBlockState(new BlockPos(i - 17, j + 11, k - 40), ACBlocks.dreadstone_brick_fence.getDefaultState(), 2);
		world.setBlockState(new BlockPos(i - 17, j + 11, k - 39), ACBlocks.dreadstone_brick_fence.getDefaultState(), 2);
		world.setBlockState(new BlockPos(i - 17, j + 11, k - 38), ACBlocks.dreadstone_brick_fence.getDefaultState(), 2);
		world.setBlockState(new BlockPos(i - 17, j + 11, k - 37), ACBlocks.dreadstone_brick_fence.getDefaultState(), 2);
		world.setBlockState(new BlockPos(i - 17, j + 11, k - 36), ACBlocks.dreadstone_brick.getDefaultState(), 2);
		world.setBlockState(new BlockPos(i - 17, j + 12, k - 41), ACBlocks.dreadstone_brick.getDefaultState(), 2);
		world.setBlockState(new BlockPos(i - 17, j + 12, k - 40), ACBlocks.dreadstone_brick.getDefaultState(), 2);
		world.setBlockState(new BlockPos(i - 17, j + 12, k - 39), ACBlocks.dreadstone_brick.getDefaultState(), 2);
		world.setBlockState(new BlockPos(i - 17, j + 12, k - 38), ACBlocks.dreadstone_brick.getDefaultState(), 2);
		world.setBlockState(new BlockPos(i - 17, j + 12, k - 37), ACBlocks.dreadstone_brick.getDefaultState(), 2);
		world.setBlockState(new BlockPos(i - 17, j + 12, k - 36), ACBlocks.dreadstone_brick.getDefaultState(), 2);
		world.setBlockState(new BlockPos(i - 17, j + 13, k - 41), ACBlocks.dreadstone_brick.getDefaultState(), 2);
		world.setBlockState(new BlockPos(i - 17, j + 13, k - 40), ACBlocks.dreadstone_brick_fence.getDefaultState(), 2);
		world.setBlockState(new BlockPos(i - 17, j + 13, k - 39), ACBlocks.dreadstone_brick_fence.getDefaultState(), 2);
		world.setBlockState(new BlockPos(i - 17, j + 13, k - 38), ACBlocks.dreadstone_brick_fence.getDefaultState(), 2);
		world.setBlockState(new BlockPos(i - 17, j + 13, k - 37), ACBlocks.dreadstone_brick_fence.getDefaultState(), 2);
		world.setBlockState(new BlockPos(i - 17, j + 13, k - 36), ACBlocks.dreadstone_brick.getDefaultState(), 2);
		world.setBlockState(new BlockPos(i - 17, j + 14, k - 41), ACBlocks.dreadstone_brick.getDefaultState(), 2);
		world.setBlockState(new BlockPos(i - 17, j + 14, k - 40), ACBlocks.dreadstone_brick.getDefaultState(), 2);
		world.setBlockState(new BlockPos(i - 17, j + 14, k - 39), ACBlocks.dreadstone_brick.getDefaultState(), 2);
		world.setBlockState(new BlockPos(i - 17, j + 14, k - 38), ACBlocks.dreadstone_brick.getDefaultState(), 2);
		world.setBlockState(new BlockPos(i - 17, j + 14, k - 37), ACBlocks.dreadstone_brick.getDefaultState(), 2);
		world.setBlockState(new BlockPos(i - 17, j + 14, k - 36), ACBlocks.dreadstone_brick.getDefaultState(), 2);
		world.setBlockState(new BlockPos(i - 16, j + 3, k - 40), ACBlocks.dreadstone_brick.getDefaultState(), 2);
		world.setBlockState(new BlockPos(i - 16, j + 3, k - 39), ACBlocks.dreadstone_brick.getDefaultState(), 2);
		world.setBlockState(new BlockPos(i - 16, j + 3, k - 38), ACBlocks.dreadstone_brick.getDefaultState(), 2);
		world.setBlockState(new BlockPos(i - 16, j + 3, k - 37), ACBlocks.dreadstone_brick.getDefaultState(), 2);
		world.setBlockState(new BlockPos(i - 16, j + 3, k - 29), ACBlocks.dreadstone_brick.getDefaultState(), 2);
		world.setBlockState(new BlockPos(i - 16, j + 3, k - 28), ACBlocks.dreadstone_brick.getDefaultState(), 2);
		world.setBlockState(new BlockPos(i - 16, j + 3, k - 27), ACBlocks.dreadstone_brick.getDefaultState(), 2);
		world.setBlockState(new BlockPos(i - 16, j + 3, k - 26), ACBlocks.dreadstone_brick.getDefaultState(), 2);
		world.setBlockState(new BlockPos(i - 16, j + 3, k - 25), ACBlocks.dreadstone_brick.getDefaultState(), 2);
		world.setBlockState(new BlockPos(i - 16, j + 3, k - 24), ACBlocks.dreadstone_brick.getDefaultState(), 2);
		world.setBlockState(new BlockPos(i - 16, j + 3, k - 23), ACBlocks.dreadstone_brick.getDefaultState(), 2);
		world.setBlockState(new BlockPos(i - 16, j + 4, k - 41), ACBlocks.dreadstone_brick.getDefaultState(), 2);
		world.setBlockState(new BlockPos(i - 16, j + 4, k - 36), ACBlocks.dreadstone_brick.getDefaultState(), 2);
		world.setBlockState(new BlockPos(i - 16, j + 4, k - 30), ACBlocks.dreadstone_brick.getDefaultState(), 2);
		world.setBlockState(new BlockPos(i - 16, j + 4, k - 22), ACBlocks.dreadstone_brick.getDefaultState(), 2);
		world.setBlockState(new BlockPos(i - 16, j + 5, k - 41), ACBlocks.dreadstone_brick.getDefaultState(), 2);
		world.setBlockState(new BlockPos(i - 16, j + 5, k - 36), ACBlocks.dreadstone_brick.getDefaultState(), 2);
		world.setBlockState(new BlockPos(i - 16, j + 5, k - 30), ACBlocks.dreadstone_brick.getDefaultState(), 2);
		world.setBlockState(new BlockPos(i - 16, j + 5, k - 22), ACBlocks.dreadstone_brick.getDefaultState(), 2);
		world.setBlockState(new BlockPos(i - 16, j + 6, k - 41), ACBlocks.dreadstone_brick.getDefaultState(), 2);
		world.setBlockState(new BlockPos(i - 16, j + 6, k - 36), ACBlocks.dreadstone_brick.getDefaultState(), 2);
		world.setBlockState(new BlockPos(i - 16, j + 6, k - 30), ACBlocks.dreadstone_brick.getDefaultState(), 2);
		world.setBlockState(new BlockPos(i - 16, j + 6, k - 22), ACBlocks.dreadstone_brick.getDefaultState(), 2);
		world.setBlockState(new BlockPos(i - 16, j + 7, k - 41), ACBlocks.dreadstone_brick.getDefaultState(), 2);
		world.setBlockState(new BlockPos(i - 16, j + 7, k - 36), ACBlocks.dreadstone_brick.getDefaultState(), 2);
		world.setBlockState(new BlockPos(i - 16, j + 7, k - 30), ACBlocks.dreadstone_brick.getDefaultState(), 2);
		world.setBlockState(new BlockPos(i - 16, j + 7, k - 22), ACBlocks.dreadstone_brick.getDefaultState(), 2);
		world.setBlockState(new BlockPos(i - 16, j + 8, k - 41), ACBlocks.dreadstone_brick.getDefaultState(), 2);
		world.setBlockState(new BlockPos(i - 16, j + 8, k - 36), ACBlocks.dreadstone_brick.getDefaultState(), 2);
		world.setBlockState(new BlockPos(i - 16, j + 8, k - 30), ACBlocks.dreadstone_brick.getDefaultState(), 2);
		world.setBlockState(new BlockPos(i - 16, j + 8, k - 29), ACBlocks.dreadstone_brick.getDefaultState(), 2);
		world.setBlockState(new BlockPos(i - 16, j + 8, k - 28), ACBlocks.dreadstone_brick.getDefaultState(), 2);
		world.setBlockState(new BlockPos(i - 16, j + 8, k - 27), ACBlocks.dreadstone_brick.getDefaultState(), 2);
		world.setBlockState(new BlockPos(i - 16, j + 8, k - 26), ACBlocks.dreadstone_brick.getDefaultState(), 2);
		world.setBlockState(new BlockPos(i - 16, j + 8, k - 25), ACBlocks.dreadstone_brick.getDefaultState(), 2);
		world.setBlockState(new BlockPos(i - 16, j + 8, k - 24), ACBlocks.dreadstone_brick.getDefaultState(), 2);
		world.setBlockState(new BlockPos(i - 16, j + 8, k - 23), ACBlocks.dreadstone_brick.getDefaultState(), 2);
		world.setBlockState(new BlockPos(i - 16, j + 8, k - 22), ACBlocks.dreadstone_brick.getDefaultState(), 2);
		world.setBlockState(new BlockPos(i - 16, j + 9, k - 41), ACBlocks.dreadstone_brick.getDefaultState(), 2);
		world.setBlockState(new BlockPos(i - 16, j + 9, k - 36), ACBlocks.dreadstone_brick.getDefaultState(), 2);
		world.setBlockState(new BlockPos(i - 16, j + 10, k - 41), ACBlocks.dreadstone_brick.getDefaultState(), 2);
		world.setBlockState(new BlockPos(i - 16, j + 10, k - 36), ACBlocks.dreadstone_brick.getDefaultState(), 2);
		world.setBlockState(new BlockPos(i - 16, j + 11, k - 41), ACBlocks.dreadstone_brick.getDefaultState(), 2);
		world.setBlockState(new BlockPos(i - 16, j + 11, k - 36), ACBlocks.dreadstone_brick.getDefaultState(), 2);
		world.setBlockState(new BlockPos(i - 16, j + 12, k - 41), ACBlocks.dreadstone_brick.getDefaultState(), 2);
		world.setBlockState(new BlockPos(i - 16, j + 12, k - 36), ACBlocks.dreadstone_brick.getDefaultState(), 2);
		world.setBlockState(new BlockPos(i - 16, j + 13, k - 41), ACBlocks.dreadstone_brick.getDefaultState(), 2);
		world.setBlockState(new BlockPos(i - 16, j + 13, k - 36), ACBlocks.dreadstone_brick.getDefaultState(), 2);
		world.setBlockState(new BlockPos(i - 16, j + 14, k - 41), ACBlocks.dreadstone_brick.getDefaultState(), 2);
		world.setBlockState(new BlockPos(i - 16, j + 14, k - 40), ACBlocks.dreadstone_brick.getDefaultState(), 2);
		world.setBlockState(new BlockPos(i - 16, j + 14, k - 39), ACBlocks.dreadstone_brick.getDefaultState(), 2);
		world.setBlockState(new BlockPos(i - 16, j + 14, k - 38), ACBlocks.dreadstone_brick.getDefaultState(), 2);
		world.setBlockState(new BlockPos(i - 16, j + 14, k - 37), ACBlocks.dreadstone_brick.getDefaultState(), 2);
		world.setBlockState(new BlockPos(i - 16, j + 14, k - 36), ACBlocks.dreadstone_brick.getDefaultState(), 2);
		world.setBlockState(new BlockPos(i - 15, j + 3, k - 40), ACBlocks.dreadstone_brick.getDefaultState(), 2);
		world.setBlockState(new BlockPos(i - 15, j + 3, k - 39), ACBlocks.dreadstone_brick.getDefaultState(), 2);
		world.setBlockState(new BlockPos(i - 15, j + 3, k - 38), ACBlocks.dreadstone_brick.getDefaultState(), 2);
		world.setBlockState(new BlockPos(i - 15, j + 3, k - 37), ACBlocks.dreadstone_brick.getDefaultState(), 2);
		world.setBlockState(new BlockPos(i - 15, j + 3, k - 29), ACBlocks.dreadstone_brick.getDefaultState(), 2);
		world.setBlockState(new BlockPos(i - 15, j + 3, k - 28), ACBlocks.dreadstone_brick.getDefaultState(), 2);
		world.setBlockState(new BlockPos(i - 15, j + 3, k - 27), ACBlocks.dreadstone_brick.getDefaultState(), 2);
		world.setBlockState(new BlockPos(i - 15, j + 3, k - 26), ACBlocks.dreadstone_brick.getDefaultState(), 2);
		world.setBlockState(new BlockPos(i - 15, j + 3, k - 25), ACBlocks.dreadstone_brick.getDefaultState(), 2);
		world.setBlockState(new BlockPos(i - 15, j + 3, k - 24), ACBlocks.dreadstone_brick.getDefaultState(), 2);
		world.setBlockState(new BlockPos(i - 15, j + 3, k - 23), ACBlocks.dreadstone_brick.getDefaultState(), 2);
		world.setBlockState(new BlockPos(i - 15, j + 4, k - 41), ACBlocks.dreadstone_brick.getDefaultState(), 2);
		world.setBlockState(new BlockPos(i - 15, j + 4, k - 36), ACBlocks.dreadstone_brick.getDefaultState(), 2);
		world.setBlockState(new BlockPos(i - 15, j + 4, k - 30), ACBlocks.dreadstone_brick.getDefaultState(), 2);
		world.setBlockState(new BlockPos(i - 15, j + 4, k - 22), ACBlocks.dreadstone_brick.getDefaultState(), 2);
		world.setBlockState(new BlockPos(i - 15, j + 5, k - 41), ACBlocks.dreadstone_brick.getDefaultState(), 2);
		world.setBlockState(new BlockPos(i - 15, j + 5, k - 36), ACBlocks.dreadstone_brick.getDefaultState(), 2);
		world.setBlockState(new BlockPos(i - 15, j + 5, k - 30), ACBlocks.dreadstone_brick.getDefaultState(), 2);
		world.setBlockState(new BlockPos(i - 15, j + 5, k - 22), ACBlocks.dreadstone_brick.getDefaultState(), 2);
		world.setBlockState(new BlockPos(i - 15, j + 6, k - 41), ACBlocks.dreadstone_brick.getDefaultState(), 2);
		world.setBlockState(new BlockPos(i - 15, j + 6, k - 36), ACBlocks.dreadstone_brick.getDefaultState(), 2);
		world.setBlockState(new BlockPos(i - 15, j + 6, k - 30), ACBlocks.dreadstone_brick.getDefaultState(), 2);
		world.setBlockState(new BlockPos(i - 15, j + 6, k - 22), ACBlocks.dreadstone_brick.getDefaultState(), 2);
		world.setBlockState(new BlockPos(i - 15, j + 7, k - 41), ACBlocks.dreadstone_brick.getDefaultState(), 2);
		world.setBlockState(new BlockPos(i - 15, j + 7, k - 36), ACBlocks.dreadstone_brick.getDefaultState(), 2);
		world.setBlockState(new BlockPos(i - 15, j + 7, k - 30), ACBlocks.dreadstone_brick.getDefaultState(), 2);
		world.setBlockState(new BlockPos(i - 15, j + 7, k - 22), ACBlocks.dreadstone_brick.getDefaultState(), 2);
		world.setBlockState(new BlockPos(i - 15, j + 8, k - 41), ACBlocks.dreadstone_brick.getDefaultState(), 2);
		world.setBlockState(new BlockPos(i - 15, j + 8, k - 36), ACBlocks.dreadstone_brick.getDefaultState(), 2);
		world.setBlockState(new BlockPos(i - 15, j + 8, k - 30), ACBlocks.dreadstone_brick.getDefaultState(), 2);
		world.setBlockState(new BlockPos(i - 15, j + 8, k - 29), ACBlocks.dreadstone_brick.getDefaultState(), 2);
		world.setBlockState(new BlockPos(i - 15, j + 8, k - 28), ACBlocks.dreadstone_brick.getDefaultState(), 2);
		world.setBlockState(new BlockPos(i - 15, j + 8, k - 27), ACBlocks.dreadstone_brick.getDefaultState(), 2);
		world.setBlockState(new BlockPos(i - 15, j + 8, k - 26), ACBlocks.dreadstone_brick.getDefaultState(), 2);
		world.setBlockState(new BlockPos(i - 15, j + 8, k - 25), ACBlocks.dreadstone_brick.getDefaultState(), 2);
		world.setBlockState(new BlockPos(i - 15, j + 8, k - 24), ACBlocks.dreadstone_brick.getDefaultState(), 2);
		world.setBlockState(new BlockPos(i - 15, j + 8, k - 23), ACBlocks.dreadstone_brick.getDefaultState(), 2);
		world.setBlockState(new BlockPos(i - 15, j + 8, k - 22), ACBlocks.dreadstone_brick.getDefaultState(), 2);
		world.setBlockState(new BlockPos(i - 15, j + 9, k - 41), ACBlocks.dreadstone_brick.getDefaultState(), 2);
		world.setBlockState(new BlockPos(i - 15, j + 9, k - 36), ACBlocks.dreadstone_brick.getDefaultState(), 2);
		world.setBlockState(new BlockPos(i - 15, j + 10, k - 41), ACBlocks.dreadstone_brick.getDefaultState(), 2);
		world.setBlockState(new BlockPos(i - 15, j + 10, k - 36), ACBlocks.dreadstone_brick.getDefaultState(), 2);
		world.setBlockState(new BlockPos(i - 15, j + 11, k - 41), ACBlocks.dreadstone_brick.getDefaultState(), 2);
		world.setBlockState(new BlockPos(i - 15, j + 11, k - 36), ACBlocks.dreadstone_brick.getDefaultState(), 2);
		world.setBlockState(new BlockPos(i - 15, j + 12, k - 41), ACBlocks.dreadstone_brick.getDefaultState(), 2);
		world.setBlockState(new BlockPos(i - 15, j + 12, k - 36), ACBlocks.dreadstone_brick.getDefaultState(), 2);
		world.setBlockState(new BlockPos(i - 15, j + 13, k - 41), ACBlocks.dreadstone_brick.getDefaultState(), 2);
		world.setBlockState(new BlockPos(i - 15, j + 13, k - 36), ACBlocks.dreadstone_brick.getDefaultState(), 2);
		world.setBlockState(new BlockPos(i - 15, j + 14, k - 41), ACBlocks.dreadstone_brick.getDefaultState(), 2);
		world.setBlockState(new BlockPos(i - 15, j + 14, k - 40), ACBlocks.dreadstone_brick.getDefaultState(), 2);
		world.setBlockState(new BlockPos(i - 15, j + 14, k - 39), ACBlocks.dreadstone_brick.getDefaultState(), 2);
		world.setBlockState(new BlockPos(i - 15, j + 14, k - 38), ACBlocks.dreadstone_brick.getDefaultState(), 2);
		world.setBlockState(new BlockPos(i - 15, j + 14, k - 37), ACBlocks.dreadstone_brick.getDefaultState(), 2);
		world.setBlockState(new BlockPos(i - 15, j + 14, k - 36), ACBlocks.dreadstone_brick.getDefaultState(), 2);
		world.setBlockState(new BlockPos(i - 14, j + 3, k - 40), ACBlocks.dreadstone_brick.getDefaultState(), 2);
		world.setBlockState(new BlockPos(i - 14, j + 3, k - 39), ACBlocks.dreadstone_brick.getDefaultState(), 2);
		world.setBlockState(new BlockPos(i - 14, j + 3, k - 38), ACBlocks.dreadstone_brick.getDefaultState(), 2);
		world.setBlockState(new BlockPos(i - 14, j + 3, k - 37), ACBlocks.dreadstone_brick.getDefaultState(), 2);
		world.setBlockState(new BlockPos(i - 14, j + 3, k - 29), ACBlocks.dreadstone_brick.getDefaultState(), 2);
		world.setBlockState(new BlockPos(i - 14, j + 3, k - 28), ACBlocks.dreadstone_brick.getDefaultState(), 2);
		world.setBlockState(new BlockPos(i - 14, j + 3, k - 27), ACBlocks.dreadstone_brick.getDefaultState(), 2);
		world.setBlockState(new BlockPos(i - 14, j + 3, k - 26), ACBlocks.dreadstone_brick.getDefaultState(), 2);
		world.setBlockState(new BlockPos(i - 14, j + 3, k - 25), ACBlocks.dreadstone_brick.getDefaultState(), 2);
		world.setBlockState(new BlockPos(i - 14, j + 3, k - 24), ACBlocks.dreadstone_brick.getDefaultState(), 2);
		world.setBlockState(new BlockPos(i - 14, j + 3, k - 23), ACBlocks.dreadstone_brick.getDefaultState(), 2);
		world.setBlockState(new BlockPos(i - 14, j + 4, k - 41), ACBlocks.dreadstone_brick.getDefaultState(), 2);
		world.setBlockState(new BlockPos(i - 14, j + 4, k - 39), ACBlocks.dreadguard_spawner.getDefaultState(), 2);
		world.setBlockState(new BlockPos(i - 14, j + 4, k - 36), ACBlocks.dreadstone_brick.getDefaultState(), 2);
		world.setBlockState(new BlockPos(i - 14, j + 4, k - 30), ACBlocks.dreadstone_brick.getDefaultState(), 2);
		world.setBlockState(new BlockPos(i - 14, j + 4, k - 29), ACBlocks.dreadstone_brick.getDefaultState(), 2);
		world.setBlockState(new BlockPos(i - 14, j + 4, k - 28), ACBlocks.dreadstone_brick.getDefaultState(), 2);
		world.setBlockState(new BlockPos(i - 14, j + 4, k - 27), ACBlocks.dreadstone_brick.getDefaultState(), 2);
		if(ACConfig.dreadstone_brick_slab)
			world.setBlockState(new BlockPos(i - 14, j + 4, k - 26), ACBlocks.dreadstone_brick_slab.getDefaultState(), 2); //TODO: 5
		world.setBlockState(new BlockPos(i - 14, j + 4, k - 25), ACBlocks.dreadstone_brick.getDefaultState(), 2);
		world.setBlockState(new BlockPos(i - 14, j + 4, k - 24), ACBlocks.dreadstone_brick.getDefaultState(), 2);
		world.setBlockState(new BlockPos(i - 14, j + 4, k - 23), ACBlocks.dreadstone_brick.getDefaultState(), 2);
		world.setBlockState(new BlockPos(i - 14, j + 4, k - 22), ACBlocks.dreadstone_brick.getDefaultState(), 2);
		world.setBlockState(new BlockPos(i - 14, j + 5, k - 41), ACBlocks.dreadstone_brick.getDefaultState(), 2);
		world.setBlockState(new BlockPos(i - 14, j + 5, k - 36), ACBlocks.dreadstone_brick.getDefaultState(), 2);
		world.setBlockState(new BlockPos(i - 14, j + 5, k - 30), ACBlocks.dreadstone_brick.getDefaultState(), 2);
		world.setBlockState(new BlockPos(i - 14, j + 5, k - 22), ACBlocks.dreadstone_brick.getDefaultState(), 2);
		world.setBlockState(new BlockPos(i - 14, j + 6, k - 41), ACBlocks.dreadstone_brick.getDefaultState(), 2);
		world.setBlockState(new BlockPos(i - 14, j + 6, k - 36), ACBlocks.dreadstone_brick.getDefaultState(), 2);
		world.setBlockState(new BlockPos(i - 14, j + 6, k - 30), ACBlocks.dreadstone_brick.getDefaultState(), 2);
		world.setBlockState(new BlockPos(i - 14, j + 6, k - 22), ACBlocks.dreadstone_brick.getDefaultState(), 2);
		world.setBlockState(new BlockPos(i - 14, j + 7, k - 41), ACBlocks.dreadstone_brick.getDefaultState(), 2);
		world.setBlockState(new BlockPos(i - 14, j + 7, k - 36), ACBlocks.dreadstone_brick.getDefaultState(), 2);
		world.setBlockState(new BlockPos(i - 14, j + 7, k - 30), ACBlocks.dreadstone_brick.getDefaultState(), 2);
		world.setBlockState(new BlockPos(i - 14, j + 7, k - 22), ACBlocks.dreadstone_brick.getDefaultState(), 2);
		world.setBlockState(new BlockPos(i - 14, j + 8, k - 41), ACBlocks.dreadstone_brick.getDefaultState(), 2);
		world.setBlockState(new BlockPos(i - 14, j + 8, k - 36), ACBlocks.dreadstone_brick.getDefaultState(), 2);
		world.setBlockState(new BlockPos(i - 14, j + 8, k - 30), ACBlocks.dreadstone_brick.getDefaultState(), 2);
		world.setBlockState(new BlockPos(i - 14, j + 8, k - 29), ACBlocks.dreadstone_brick.getDefaultState(), 2);
		world.setBlockState(new BlockPos(i - 14, j + 8, k - 28), ACBlocks.dreadstone_brick.getDefaultState(), 2);
		world.setBlockState(new BlockPos(i - 14, j + 8, k - 27), ACBlocks.dreadstone_brick.getDefaultState(), 2);
		world.setBlockState(new BlockPos(i - 14, j + 8, k - 26), ACBlocks.dreadstone_brick.getDefaultState(), 2);
		world.setBlockState(new BlockPos(i - 14, j + 8, k - 25), ACBlocks.dreadstone_brick.getDefaultState(), 2);
		world.setBlockState(new BlockPos(i - 14, j + 8, k - 24), ACBlocks.dreadstone_brick.getDefaultState(), 2);
		world.setBlockState(new BlockPos(i - 14, j + 8, k - 23), ACBlocks.dreadstone_brick.getDefaultState(), 2);
		world.setBlockState(new BlockPos(i - 14, j + 8, k - 22), ACBlocks.dreadstone_brick.getDefaultState(), 2);
		world.setBlockState(new BlockPos(i - 14, j + 9, k - 41), ACBlocks.dreadstone_brick.getDefaultState(), 2);
		world.setBlockState(new BlockPos(i - 14, j + 9, k - 36), ACBlocks.dreadstone_brick.getDefaultState(), 2);
		world.setBlockState(new BlockPos(i - 14, j + 10, k - 41), ACBlocks.dreadstone_brick.getDefaultState(), 2);
		world.setBlockState(new BlockPos(i - 14, j + 10, k - 36), ACBlocks.dreadstone_brick.getDefaultState(), 2);
		world.setBlockState(new BlockPos(i - 14, j + 11, k - 41), ACBlocks.dreadstone_brick.getDefaultState(), 2);
		world.setBlockState(new BlockPos(i - 14, j + 11, k - 36), ACBlocks.dreadstone_brick.getDefaultState(), 2);
		world.setBlockState(new BlockPos(i - 14, j + 12, k - 41), ACBlocks.dreadstone_brick.getDefaultState(), 2);
		world.setBlockState(new BlockPos(i - 14, j + 12, k - 36), ACBlocks.dreadstone_brick.getDefaultState(), 2);
		world.setBlockState(new BlockPos(i - 14, j + 13, k - 41), ACBlocks.dreadstone_brick.getDefaultState(), 2);
		world.setBlockState(new BlockPos(i - 14, j + 13, k - 36), ACBlocks.dreadstone_brick.getDefaultState(), 2);
		world.setBlockState(new BlockPos(i - 14, j + 14, k - 41), ACBlocks.dreadstone_brick.getDefaultState(), 2);
		world.setBlockState(new BlockPos(i - 14, j + 14, k - 40), ACBlocks.dreadstone_brick.getDefaultState(), 2);
		world.setBlockState(new BlockPos(i - 14, j + 14, k - 39), ACBlocks.dreadstone_brick.getDefaultState(), 2);
		world.setBlockState(new BlockPos(i - 14, j + 14, k - 38), ACBlocks.dreadstone_brick.getDefaultState(), 2);
		world.setBlockState(new BlockPos(i - 14, j + 14, k - 37), ACBlocks.dreadstone_brick.getDefaultState(), 2);
		world.setBlockState(new BlockPos(i - 14, j + 14, k - 36), ACBlocks.dreadstone_brick.getDefaultState(), 2);
		world.setBlockState(new BlockPos(i - 13, j + 3, k - 40), ACBlocks.dreadstone_brick.getDefaultState(), 2);
		world.setBlockState(new BlockPos(i - 13, j + 3, k - 39), ACBlocks.dreadstone_brick.getDefaultState(), 2);
		world.setBlockState(new BlockPos(i - 13, j + 3, k - 38), ACBlocks.dreadstone_brick.getDefaultState(), 2);
		world.setBlockState(new BlockPos(i - 13, j + 3, k - 37), ACBlocks.dreadstone_brick.getDefaultState(), 2);
		world.setBlockState(new BlockPos(i - 13, j + 3, k - 29), ACBlocks.dreadstone_brick.getDefaultState(), 2);
		world.setBlockState(new BlockPos(i - 13, j + 3, k - 28), ACBlocks.dreadstone_brick.getDefaultState(), 2);
		world.setBlockState(new BlockPos(i - 13, j + 3, k - 27), ACBlocks.dreadstone_brick.getDefaultState(), 2);
		world.setBlockState(new BlockPos(i - 13, j + 3, k - 26), ACBlocks.dreadstone_brick.getDefaultState(), 2);
		world.setBlockState(new BlockPos(i - 13, j + 3, k - 25), ACBlocks.dreadstone_brick.getDefaultState(), 2);
		world.setBlockState(new BlockPos(i - 13, j + 3, k - 24), ACBlocks.dreadstone_brick.getDefaultState(), 2);
		world.setBlockState(new BlockPos(i - 13, j + 3, k - 23), ACBlocks.dreadstone_brick.getDefaultState(), 2);
		world.setBlockState(new BlockPos(i - 13, j + 4, k - 41), ACBlocks.dreadstone_brick.getDefaultState(), 2);
		world.setBlockState(new BlockPos(i - 13, j + 4, k - 36), ACBlocks.dreadstone_brick.getDefaultState(), 2);
		world.setBlockState(new BlockPos(i - 13, j + 4, k - 30), ACBlocks.dreadstone_brick.getDefaultState(), 2);
		world.setBlockState(new BlockPos(i - 13, j + 4, k - 29), Blocks.LAVA.getDefaultState(), 2);
		world.setBlockState(new BlockPos(i - 13, j + 4, k - 28), Blocks.LAVA.getDefaultState(), 2);
		world.setBlockState(new BlockPos(i - 13, j + 4, k - 27), ACBlocks.dreadstone_brick.getDefaultState(), 2);
		world.setBlockState(new BlockPos(i - 13, j + 4, k - 26), ACBlocks.dreadstone_brick.getDefaultState(), 2);
		world.setBlockState(new BlockPos(i - 13, j + 4, k - 25), ACBlocks.dreadstone_brick.getDefaultState(), 2);
		world.setBlockState(new BlockPos(i - 13, j + 4, k - 24), Blocks.LAVA.getDefaultState(), 2);
		world.setBlockState(new BlockPos(i - 13, j + 4, k - 23), Blocks.LAVA.getDefaultState(), 2);
		world.setBlockState(new BlockPos(i - 13, j + 4, k - 22), ACBlocks.dreadstone_brick.getDefaultState(), 2);
		world.setBlockState(new BlockPos(i - 13, j + 5, k - 41), ACBlocks.dreadstone_brick.getDefaultState(), 2);
		world.setBlockState(new BlockPos(i - 13, j + 5, k - 36), ACBlocks.dreadstone_brick.getDefaultState(), 2);
		world.setBlockState(new BlockPos(i - 13, j + 5, k - 30), ACBlocks.dreadstone_brick.getDefaultState(), 2);
		world.setBlockState(new BlockPos(i - 13, j + 5, k - 27), ACBlocks.dreadstone_brick.getDefaultState(), 2);
		world.setBlockState(new BlockPos(i - 13, j + 5, k - 26), ACBlocks.crystallizer_idle.getStateFromMeta(4), 2); //TODO: 4
		world.setBlockState(new BlockPos(i - 13, j + 5, k - 25), ACBlocks.dreadstone_brick.getDefaultState(), 2);
		world.setBlockState(new BlockPos(i - 13, j + 5, k - 22), ACBlocks.dreadstone_brick.getDefaultState(), 2);
		world.setBlockState(new BlockPos(i - 13, j + 6, k - 41), ACBlocks.dreadstone_brick.getDefaultState(), 2);
		world.setBlockState(new BlockPos(i - 13, j + 6, k - 36), ACBlocks.dreadstone_brick.getDefaultState(), 2);
		world.setBlockState(new BlockPos(i - 13, j + 6, k - 30), ACBlocks.dreadstone_brick.getDefaultState(), 2);
		world.setBlockState(new BlockPos(i - 13, j + 6, k - 27), ACBlocks.dreadstone_brick.getDefaultState(), 2);
		world.setBlockState(new BlockPos(i - 13, j + 6, k - 26), ACBlocks.dreadstone_brick.getDefaultState(), 2);
		world.setBlockState(new BlockPos(i - 13, j + 6, k - 25), ACBlocks.dreadstone_brick.getDefaultState(), 2);
		world.setBlockState(new BlockPos(i - 13, j + 6, k - 22), ACBlocks.dreadstone_brick.getDefaultState(), 2);
		world.setBlockState(new BlockPos(i - 13, j + 7, k - 41), ACBlocks.dreadstone_brick.getDefaultState(), 2);
		world.setBlockState(new BlockPos(i - 13, j + 7, k - 36), ACBlocks.dreadstone_brick.getDefaultState(), 2);
		world.setBlockState(new BlockPos(i - 13, j + 7, k - 30), ACBlocks.dreadstone_brick.getDefaultState(), 2);
		world.setBlockState(new BlockPos(i - 13, j + 7, k - 22), ACBlocks.dreadstone_brick.getDefaultState(), 2);
		world.setBlockState(new BlockPos(i - 13, j + 8, k - 41), ACBlocks.dreadstone_brick.getDefaultState(), 2);
		world.setBlockState(new BlockPos(i - 13, j + 8, k - 36), ACBlocks.dreadstone_brick.getDefaultState(), 2);
		world.setBlockState(new BlockPos(i - 13, j + 8, k - 30), ACBlocks.dreadstone_brick.getDefaultState(), 2);
		world.setBlockState(new BlockPos(i - 13, j + 8, k - 29), ACBlocks.dreadstone_brick.getDefaultState(), 2);
		world.setBlockState(new BlockPos(i - 13, j + 8, k - 28), ACBlocks.dreadstone_brick.getDefaultState(), 2);
		world.setBlockState(new BlockPos(i - 13, j + 8, k - 27), ACBlocks.dreadstone_brick.getDefaultState(), 2);
		world.setBlockState(new BlockPos(i - 13, j + 8, k - 26), ACBlocks.dreadstone_brick.getDefaultState(), 2);
		world.setBlockState(new BlockPos(i - 13, j + 8, k - 25), ACBlocks.dreadstone_brick.getDefaultState(), 2);
		world.setBlockState(new BlockPos(i - 13, j + 8, k - 24), ACBlocks.dreadstone_brick.getDefaultState(), 2);
		world.setBlockState(new BlockPos(i - 13, j + 8, k - 23), ACBlocks.dreadstone_brick.getDefaultState(), 2);
		world.setBlockState(new BlockPos(i - 13, j + 8, k - 22), ACBlocks.dreadstone_brick.getDefaultState(), 2);
		world.setBlockState(new BlockPos(i - 13, j + 9, k - 41), ACBlocks.dreadstone_brick.getDefaultState(), 2);
		world.setBlockState(new BlockPos(i - 13, j + 9, k - 36), ACBlocks.dreadstone_brick.getDefaultState(), 2);
		world.setBlockState(new BlockPos(i - 13, j + 10, k - 41), ACBlocks.dreadstone_brick.getDefaultState(), 2);
		world.setBlockState(new BlockPos(i - 13, j + 10, k - 36), ACBlocks.dreadstone_brick.getDefaultState(), 2);
		world.setBlockState(new BlockPos(i - 13, j + 11, k - 41), ACBlocks.dreadstone_brick.getDefaultState(), 2);
		world.setBlockState(new BlockPos(i - 13, j + 11, k - 36), ACBlocks.dreadstone_brick.getDefaultState(), 2);
		world.setBlockState(new BlockPos(i - 13, j + 12, k - 41), ACBlocks.dreadstone_brick.getDefaultState(), 2);
		world.setBlockState(new BlockPos(i - 13, j + 12, k - 36), ACBlocks.dreadstone_brick.getDefaultState(), 2);
		world.setBlockState(new BlockPos(i - 13, j + 13, k - 41), ACBlocks.dreadstone_brick.getDefaultState(), 2);
		world.setBlockState(new BlockPos(i - 13, j + 13, k - 36), ACBlocks.dreadstone_brick.getDefaultState(), 2);
		world.setBlockState(new BlockPos(i - 13, j + 14, k - 41), ACBlocks.dreadstone_brick.getDefaultState(), 2);
		world.setBlockState(new BlockPos(i - 13, j + 14, k - 40), ACBlocks.dreadstone_brick.getDefaultState(), 2);
		world.setBlockState(new BlockPos(i - 13, j + 14, k - 39), ACBlocks.dreadstone_brick.getDefaultState(), 2);
		world.setBlockState(new BlockPos(i - 13, j + 14, k - 38), ACBlocks.dreadstone_brick.getDefaultState(), 2);
		world.setBlockState(new BlockPos(i - 13, j + 14, k - 37), ACBlocks.dreadstone_brick.getDefaultState(), 2);
		world.setBlockState(new BlockPos(i - 13, j + 14, k - 36), ACBlocks.dreadstone_brick.getDefaultState(), 2);
		world.setBlockState(new BlockPos(i - 12, j + 3, k - 40), ACBlocks.dreadstone_brick.getDefaultState(), 2);
		world.setBlockState(new BlockPos(i - 12, j + 3, k - 39), ACBlocks.dreadstone_brick.getDefaultState(), 2);
		world.setBlockState(new BlockPos(i - 12, j + 3, k - 38), ACBlocks.dreadstone_brick.getDefaultState(), 2);
		world.setBlockState(new BlockPos(i - 12, j + 3, k - 37), ACBlocks.dreadstone_brick.getDefaultState(), 2);
		world.setBlockState(new BlockPos(i - 12, j + 4, k - 41), ACBlocks.dreadstone_brick.getDefaultState(), 2);
		world.setBlockState(new BlockPos(i - 12, j + 4, k - 36), ACBlocks.dreadstone_brick.getDefaultState(), 2);
		world.setBlockState(new BlockPos(i - 12, j + 4, k - 30), ACBlocks.dreadstone_brick.getDefaultState(), 2);
		world.setBlockState(new BlockPos(i - 12, j + 4, k - 29), ACBlocks.dreadstone_brick.getDefaultState(), 2);
		world.setBlockState(new BlockPos(i - 12, j + 4, k - 28), ACBlocks.dreadstone_brick.getDefaultState(), 2);
		world.setBlockState(new BlockPos(i - 12, j + 4, k - 27), ACBlocks.dreadstone_brick.getDefaultState(), 2);
		world.setBlockState(new BlockPos(i - 12, j + 4, k - 26), ACBlocks.dreadstone_brick.getDefaultState(), 2);
		world.setBlockState(new BlockPos(i - 12, j + 4, k - 25), ACBlocks.dreadstone_brick.getDefaultState(), 2);
		world.setBlockState(new BlockPos(i - 12, j + 4, k - 24), ACBlocks.dreadstone_brick.getDefaultState(), 2);
		world.setBlockState(new BlockPos(i - 12, j + 4, k - 23), ACBlocks.dreadstone_brick.getDefaultState(), 2);
		world.setBlockState(new BlockPos(i - 12, j + 4, k - 22), ACBlocks.dreadstone_brick.getDefaultState(), 2);
		world.setBlockState(new BlockPos(i - 12, j + 5, k - 41), ACBlocks.dreadstone_brick.getDefaultState(), 2);
		world.setBlockState(new BlockPos(i - 12, j + 5, k - 36), ACBlocks.dreadstone_brick.getDefaultState(), 2);
		world.setBlockState(new BlockPos(i - 12, j + 5, k - 30), ACBlocks.dreadstone_brick.getDefaultState(), 2);
		world.setBlockState(new BlockPos(i - 12, j + 5, k - 29), ACBlocks.dreadstone_brick.getDefaultState(), 2);
		world.setBlockState(new BlockPos(i - 12, j + 5, k - 28), ACBlocks.dreadstone_brick.getDefaultState(), 2);
		world.setBlockState(new BlockPos(i - 12, j + 5, k - 27), ACBlocks.dreadstone_brick.getDefaultState(), 2);
		world.setBlockState(new BlockPos(i - 12, j + 5, k - 26), ACBlocks.dreadstone_brick.getDefaultState(), 2);
		world.setBlockState(new BlockPos(i - 12, j + 5, k - 25), ACBlocks.dreadstone_brick.getDefaultState(), 2);
		world.setBlockState(new BlockPos(i - 12, j + 5, k - 24), ACBlocks.dreadstone_brick.getDefaultState(), 2);
		world.setBlockState(new BlockPos(i - 12, j + 5, k - 23), ACBlocks.dreadstone_brick.getDefaultState(), 2);
		world.setBlockState(new BlockPos(i - 12, j + 5, k - 22), ACBlocks.dreadstone_brick.getDefaultState(), 2);
		world.setBlockState(new BlockPos(i - 12, j + 6, k - 41), ACBlocks.dreadstone_brick.getDefaultState(), 2);
		world.setBlockState(new BlockPos(i - 12, j + 6, k - 36), ACBlocks.dreadstone_brick.getDefaultState(), 2);
		world.setBlockState(new BlockPos(i - 12, j + 6, k - 30), ACBlocks.dreadstone_brick.getDefaultState(), 2);
		world.setBlockState(new BlockPos(i - 12, j + 6, k - 29), ACBlocks.dreadstone_brick.getDefaultState(), 2);
		world.setBlockState(new BlockPos(i - 12, j + 6, k - 28), ACBlocks.dreadstone_brick.getDefaultState(), 2);
		world.setBlockState(new BlockPos(i - 12, j + 6, k - 27), ACBlocks.dreadstone_brick.getDefaultState(), 2);
		world.setBlockState(new BlockPos(i - 12, j + 6, k - 26), ACBlocks.dreadstone_brick.getDefaultState(), 2);
		world.setBlockState(new BlockPos(i - 12, j + 6, k - 25), ACBlocks.dreadstone_brick.getDefaultState(), 2);
		world.setBlockState(new BlockPos(i - 12, j + 6, k - 24), ACBlocks.dreadstone_brick.getDefaultState(), 2);
		world.setBlockState(new BlockPos(i - 12, j + 6, k - 23), ACBlocks.dreadstone_brick.getDefaultState(), 2);
		world.setBlockState(new BlockPos(i - 12, j + 6, k - 22), ACBlocks.dreadstone_brick.getDefaultState(), 2);
		world.setBlockState(new BlockPos(i - 12, j + 7, k - 41), ACBlocks.dreadstone_brick.getDefaultState(), 2);
		world.setBlockState(new BlockPos(i - 12, j + 7, k - 36), ACBlocks.dreadstone_brick.getDefaultState(), 2);
		world.setBlockState(new BlockPos(i - 12, j + 7, k - 30), ACBlocks.dreadstone_brick.getDefaultState(), 2);
		world.setBlockState(new BlockPos(i - 12, j + 7, k - 29), ACBlocks.dreadstone_brick.getDefaultState(), 2);
		world.setBlockState(new BlockPos(i - 12, j + 7, k - 28), ACBlocks.dreadstone_brick.getDefaultState(), 2);
		world.setBlockState(new BlockPos(i - 12, j + 7, k - 27), ACBlocks.dreadstone_brick.getDefaultState(), 2);
		world.setBlockState(new BlockPos(i - 12, j + 7, k - 26), ACBlocks.dreadstone_brick.getDefaultState(), 2);
		world.setBlockState(new BlockPos(i - 12, j + 7, k - 25), ACBlocks.dreadstone_brick.getDefaultState(), 2);
		world.setBlockState(new BlockPos(i - 12, j + 7, k - 24), ACBlocks.dreadstone_brick.getDefaultState(), 2);
		world.setBlockState(new BlockPos(i - 12, j + 7, k - 23), ACBlocks.dreadstone_brick.getDefaultState(), 2);
		world.setBlockState(new BlockPos(i - 12, j + 7, k - 22), ACBlocks.dreadstone_brick.getDefaultState(), 2);
		world.setBlockState(new BlockPos(i - 12, j + 8, k - 41), ACBlocks.dreadstone_brick.getDefaultState(), 2);
		world.setBlockState(new BlockPos(i - 12, j + 8, k - 36), ACBlocks.dreadstone_brick.getDefaultState(), 2);
		world.setBlockState(new BlockPos(i - 12, j + 8, k - 30), ACBlocks.dreadstone_brick.getDefaultState(), 2);
		world.setBlockState(new BlockPos(i - 12, j + 8, k - 29), ACBlocks.dreadstone_brick.getDefaultState(), 2);
		world.setBlockState(new BlockPos(i - 12, j + 8, k - 28), ACBlocks.dreadstone_brick.getDefaultState(), 2);
		world.setBlockState(new BlockPos(i - 12, j + 8, k - 27), ACBlocks.dreadstone_brick.getDefaultState(), 2);
		world.setBlockState(new BlockPos(i - 12, j + 8, k - 26), ACBlocks.dreadstone_brick.getDefaultState(), 2);
		world.setBlockState(new BlockPos(i - 12, j + 8, k - 25), ACBlocks.dreadstone_brick.getDefaultState(), 2);
		world.setBlockState(new BlockPos(i - 12, j + 8, k - 24), ACBlocks.dreadstone_brick.getDefaultState(), 2);
		world.setBlockState(new BlockPos(i - 12, j + 8, k - 23), ACBlocks.dreadstone_brick.getDefaultState(), 2);
		world.setBlockState(new BlockPos(i - 12, j + 8, k - 22), ACBlocks.dreadstone_brick.getDefaultState(), 2);
		world.setBlockState(new BlockPos(i - 12, j + 9, k - 41), ACBlocks.dreadstone_brick.getDefaultState(), 2);
		world.setBlockState(new BlockPos(i - 12, j + 9, k - 36), ACBlocks.dreadstone_brick.getDefaultState(), 2);
		world.setBlockState(new BlockPos(i - 12, j + 10, k - 41), ACBlocks.dreadstone_brick.getDefaultState(), 2);
		world.setBlockState(new BlockPos(i - 12, j + 10, k - 36), ACBlocks.dreadstone_brick.getDefaultState(), 2);
		world.setBlockState(new BlockPos(i - 12, j + 11, k - 41), ACBlocks.dreadstone_brick.getDefaultState(), 2);
		world.setBlockState(new BlockPos(i - 12, j + 11, k - 36), ACBlocks.dreadstone_brick.getDefaultState(), 2);
		world.setBlockState(new BlockPos(i - 12, j + 12, k - 41), ACBlocks.dreadstone_brick.getDefaultState(), 2);
		world.setBlockState(new BlockPos(i - 12, j + 12, k - 36), ACBlocks.dreadstone_brick.getDefaultState(), 2);
		world.setBlockState(new BlockPos(i - 12, j + 13, k - 41), ACBlocks.dreadstone_brick.getDefaultState(), 2);
		world.setBlockState(new BlockPos(i - 12, j + 13, k - 36), ACBlocks.dreadstone_brick.getDefaultState(), 2);
		world.setBlockState(new BlockPos(i - 12, j + 14, k - 41), ACBlocks.dreadstone_brick.getDefaultState(), 2);
		world.setBlockState(new BlockPos(i - 12, j + 14, k - 40), ACBlocks.dreadstone_brick.getDefaultState(), 2);
		world.setBlockState(new BlockPos(i - 12, j + 14, k - 39), ACBlocks.dreadstone_brick.getDefaultState(), 2);
		world.setBlockState(new BlockPos(i - 12, j + 14, k - 38), ACBlocks.dreadstone_brick.getDefaultState(), 2);
		world.setBlockState(new BlockPos(i - 12, j + 14, k - 37), ACBlocks.dreadstone_brick.getDefaultState(), 2);
		world.setBlockState(new BlockPos(i - 12, j + 14, k - 36), ACBlocks.dreadstone_brick.getDefaultState(), 2);
		world.setBlockState(new BlockPos(i - 11, j + 3, k - 40), ACBlocks.dreadstone_brick.getDefaultState(), 2);
		world.setBlockState(new BlockPos(i - 11, j + 3, k - 39), ACBlocks.dreadstone_brick.getDefaultState(), 2);
		world.setBlockState(new BlockPos(i - 11, j + 3, k - 38), ACBlocks.dreadstone_brick.getDefaultState(), 2);
		world.setBlockState(new BlockPos(i - 11, j + 3, k - 37), ACBlocks.dreadstone_brick.getDefaultState(), 2);
		world.setBlockState(new BlockPos(i - 11, j + 4, k - 41), ACBlocks.dreadstone_brick.getDefaultState(), 2);
		world.setBlockState(new BlockPos(i - 11, j + 4, k - 36), ACBlocks.dreadstone_brick.getDefaultState(), 2);
		world.setBlockState(new BlockPos(i - 11, j + 5, k - 41), ACBlocks.dreadstone_brick.getDefaultState(), 2);
		world.setBlockState(new BlockPos(i - 11, j + 5, k - 36), ACBlocks.dreadstone_brick.getDefaultState(), 2);
		world.setBlockState(new BlockPos(i - 11, j + 6, k - 41), ACBlocks.dreadstone_brick.getDefaultState(), 2);
		world.setBlockState(new BlockPos(i - 11, j + 6, k - 36), ACBlocks.dreadstone_brick.getDefaultState(), 2);
		world.setBlockState(new BlockPos(i - 11, j + 7, k - 41), ACBlocks.dreadstone_brick.getDefaultState(), 2);
		world.setBlockState(new BlockPos(i - 11, j + 7, k - 36), ACBlocks.dreadstone_brick.getDefaultState(), 2);
		world.setBlockState(new BlockPos(i - 11, j + 8, k - 41), ACBlocks.dreadstone_brick.getDefaultState(), 2);
		world.setBlockState(new BlockPos(i - 11, j + 8, k - 36), ACBlocks.dreadstone_brick.getDefaultState(), 2);
		world.setBlockState(new BlockPos(i - 11, j + 9, k - 41), ACBlocks.dreadstone_brick.getDefaultState(), 2);
		world.setBlockState(new BlockPos(i - 11, j + 9, k - 36), ACBlocks.dreadstone_brick.getDefaultState(), 2);
		world.setBlockState(new BlockPos(i - 11, j + 10, k - 41), ACBlocks.dreadstone_brick.getDefaultState(), 2);
		world.setBlockState(new BlockPos(i - 11, j + 10, k - 36), ACBlocks.dreadstone_brick.getDefaultState(), 2);
		world.setBlockState(new BlockPos(i - 11, j + 11, k - 41), ACBlocks.dreadstone_brick.getDefaultState(), 2);
		world.setBlockState(new BlockPos(i - 11, j + 11, k - 36), ACBlocks.dreadstone_brick.getDefaultState(), 2);
		world.setBlockState(new BlockPos(i - 11, j + 12, k - 41), ACBlocks.dreadstone_brick.getDefaultState(), 2);
		world.setBlockState(new BlockPos(i - 11, j + 12, k - 36), ACBlocks.dreadstone_brick.getDefaultState(), 2);
		world.setBlockState(new BlockPos(i - 11, j + 13, k - 41), ACBlocks.dreadstone_brick.getDefaultState(), 2);
		world.setBlockState(new BlockPos(i - 11, j + 13, k - 36), ACBlocks.dreadstone_brick.getDefaultState(), 2);
		world.setBlockState(new BlockPos(i - 11, j + 14, k - 41), ACBlocks.dreadstone_brick.getDefaultState(), 2);
		world.setBlockState(new BlockPos(i - 11, j + 14, k - 40), ACBlocks.dreadstone_brick.getDefaultState(), 2);
		world.setBlockState(new BlockPos(i - 11, j + 14, k - 39), ACBlocks.dreadstone_brick.getDefaultState(), 2);
		world.setBlockState(new BlockPos(i - 11, j + 14, k - 38), ACBlocks.dreadstone_brick.getDefaultState(), 2);
		world.setBlockState(new BlockPos(i - 11, j + 14, k - 37), ACBlocks.dreadstone_brick.getDefaultState(), 2);
		world.setBlockState(new BlockPos(i - 11, j + 14, k - 36), ACBlocks.dreadstone_brick.getDefaultState(), 2);
		world.setBlockState(new BlockPos(i - 10, j + 3, k - 40), ACBlocks.dreadstone_brick.getDefaultState(), 2);
		world.setBlockState(new BlockPos(i - 10, j + 3, k - 39), ACBlocks.dreadstone_brick.getDefaultState(), 2);
		world.setBlockState(new BlockPos(i - 10, j + 3, k - 38), ACBlocks.dreadstone_brick.getDefaultState(), 2);
		world.setBlockState(new BlockPos(i - 10, j + 3, k - 37), ACBlocks.dreadstone_brick.getDefaultState(), 2);
		world.setBlockState(new BlockPos(i - 10, j + 4, k - 41), ACBlocks.dreadstone_brick.getDefaultState(), 2);
		world.setBlockState(new BlockPos(i - 10, j + 4, k - 36), ACBlocks.dreadstone_brick.getDefaultState(), 2);
		world.setBlockState(new BlockPos(i - 10, j + 5, k - 41), ACBlocks.dreadstone_brick.getDefaultState(), 2);
		world.setBlockState(new BlockPos(i - 10, j + 5, k - 36), ACBlocks.dreadstone_brick.getDefaultState(), 2);
		world.setBlockState(new BlockPos(i - 10, j + 6, k - 41), ACBlocks.dreadstone_brick.getDefaultState(), 2);
		world.setBlockState(new BlockPos(i - 10, j + 6, k - 36), ACBlocks.dreadstone_brick.getDefaultState(), 2);
		world.setBlockState(new BlockPos(i - 10, j + 7, k - 41), ACBlocks.dreadstone_brick.getDefaultState(), 2);
		world.setBlockState(new BlockPos(i - 10, j + 7, k - 36), ACBlocks.dreadstone_brick.getDefaultState(), 2);
		world.setBlockState(new BlockPos(i - 10, j + 8, k - 41), ACBlocks.dreadstone_brick.getDefaultState(), 2);
		world.setBlockState(new BlockPos(i - 10, j + 8, k - 36), ACBlocks.dreadstone_brick.getDefaultState(), 2);
		world.setBlockState(new BlockPos(i - 10, j + 9, k - 41), ACBlocks.dreadstone_brick.getDefaultState(), 2);
		world.setBlockState(new BlockPos(i - 10, j + 9, k - 36), ACBlocks.dreadstone_brick.getDefaultState(), 2);
		world.setBlockState(new BlockPos(i - 10, j + 10, k - 41), ACBlocks.dreadstone_brick.getDefaultState(), 2);
		world.setBlockState(new BlockPos(i - 10, j + 10, k - 36), ACBlocks.dreadstone_brick.getDefaultState(), 2);
		world.setBlockState(new BlockPos(i - 10, j + 11, k - 41), ACBlocks.dreadstone_brick.getDefaultState(), 2);
		world.setBlockState(new BlockPos(i - 10, j + 11, k - 36), ACBlocks.dreadstone_brick.getDefaultState(), 2);
		world.setBlockState(new BlockPos(i - 10, j + 12, k - 41), ACBlocks.dreadstone_brick.getDefaultState(), 2);
		world.setBlockState(new BlockPos(i - 10, j + 12, k - 36), ACBlocks.dreadstone_brick.getDefaultState(), 2);
		world.setBlockState(new BlockPos(i - 10, j + 13, k - 41), ACBlocks.dreadstone_brick.getDefaultState(), 2);
		world.setBlockState(new BlockPos(i - 10, j + 13, k - 36), ACBlocks.dreadstone_brick.getDefaultState(), 2);
		world.setBlockState(new BlockPos(i - 10, j + 14, k - 41), ACBlocks.dreadstone_brick.getDefaultState(), 2);
		world.setBlockState(new BlockPos(i - 10, j + 14, k - 40), ACBlocks.dreadstone_brick.getDefaultState(), 2);
		world.setBlockState(new BlockPos(i - 10, j + 14, k - 39), ACBlocks.dreadstone_brick.getDefaultState(), 2);
		world.setBlockState(new BlockPos(i - 10, j + 14, k - 38), ACBlocks.dreadstone_brick.getDefaultState(), 2);
		world.setBlockState(new BlockPos(i - 10, j + 14, k - 37), ACBlocks.dreadstone_brick.getDefaultState(), 2);
		world.setBlockState(new BlockPos(i - 10, j + 14, k - 36), ACBlocks.dreadstone_brick.getDefaultState(), 2);
		world.setBlockState(new BlockPos(i - 9, j - 15, k - 63), ACBlocks.stone.getStateFromMeta(2), 2);
		world.setBlockState(new BlockPos(i - 9, j - 14, k - 63), ACBlocks.stone.getStateFromMeta(2), 2);
		world.setBlockState(new BlockPos(i - 9, j - 13, k - 63), ACBlocks.stone.getStateFromMeta(2), 2);
		world.setBlockState(new BlockPos(i - 9, j - 12, k - 63), ACBlocks.stone.getStateFromMeta(2), 2);
		world.setBlockState(new BlockPos(i - 9, j - 11, k - 63), ACBlocks.stone.getStateFromMeta(2), 2);
		world.setBlockState(new BlockPos(i - 9, j - 10, k - 63), ACBlocks.stone.getStateFromMeta(2), 2);
		world.setBlockState(new BlockPos(i - 9, j - 9, k - 63), ACBlocks.stone.getStateFromMeta(2), 2);
		world.setBlockState(new BlockPos(i - 9, j - 8, k - 63), ACBlocks.stone.getStateFromMeta(2), 2);
		world.setBlockState(new BlockPos(i - 9, j - 7, k - 63), ACBlocks.stone.getStateFromMeta(2), 2);
		world.setBlockState(new BlockPos(i - 9, j + 3, k - 40), ACBlocks.dreadstone_brick.getDefaultState(), 2);
		world.setBlockState(new BlockPos(i - 9, j + 3, k - 39), ACBlocks.dreadstone_brick.getDefaultState(), 2);
		world.setBlockState(new BlockPos(i - 9, j + 3, k - 38), ACBlocks.dreadstone_brick.getDefaultState(), 2);
		world.setBlockState(new BlockPos(i - 9, j + 3, k - 37), ACBlocks.dreadstone_brick.getDefaultState(), 2);
		world.setBlockState(new BlockPos(i - 9, j + 4, k - 41), ACBlocks.dreadstone_brick.getDefaultState(), 2);
		world.setBlockState(new BlockPos(i - 9, j + 4, k - 36), ACBlocks.dreadstone_brick.getDefaultState(), 2);
		world.setBlockState(new BlockPos(i - 9, j + 5, k - 41), ACBlocks.dreadstone_brick.getDefaultState(), 2);
		world.setBlockState(new BlockPos(i - 9, j + 5, k - 36), ACBlocks.dreadstone_brick.getDefaultState(), 2);
		world.setBlockState(new BlockPos(i - 9, j + 6, k - 41), ACBlocks.dreadstone_brick.getDefaultState(), 2);
		world.setBlockState(new BlockPos(i - 9, j + 6, k - 36), ACBlocks.dreadstone_brick.getDefaultState(), 2);
		world.setBlockState(new BlockPos(i - 9, j + 7, k - 41), ACBlocks.dreadstone_brick.getDefaultState(), 2);
		world.setBlockState(new BlockPos(i - 9, j + 7, k - 36), ACBlocks.dreadstone_brick.getDefaultState(), 2);
		world.setBlockState(new BlockPos(i - 9, j + 8, k - 41), ACBlocks.dreadstone_brick.getDefaultState(), 2);
		world.setBlockState(new BlockPos(i - 9, j + 8, k - 36), ACBlocks.dreadstone_brick.getDefaultState(), 2);
		world.setBlockState(new BlockPos(i - 9, j + 9, k - 41), ACBlocks.dreadstone_brick.getDefaultState(), 2);
		world.setBlockState(new BlockPos(i - 9, j + 9, k - 36), ACBlocks.dreadstone_brick.getDefaultState(), 2);
		world.setBlockState(new BlockPos(i - 9, j + 10, k - 41), ACBlocks.dreadstone_brick.getDefaultState(), 2);
		world.setBlockState(new BlockPos(i - 9, j + 10, k - 36), ACBlocks.dreadstone_brick.getDefaultState(), 2);
		world.setBlockState(new BlockPos(i - 9, j + 11, k - 41), ACBlocks.dreadstone_brick.getDefaultState(), 2);
		world.setBlockState(new BlockPos(i - 9, j + 11, k - 36), ACBlocks.dreadstone_brick.getDefaultState(), 2);
		world.setBlockState(new BlockPos(i - 9, j + 12, k - 41), ACBlocks.dreadstone_brick.getDefaultState(), 2);
		world.setBlockState(new BlockPos(i - 9, j + 12, k - 36), ACBlocks.dreadstone_brick.getDefaultState(), 2);
		world.setBlockState(new BlockPos(i - 9, j + 13, k - 41), ACBlocks.dreadstone_brick.getDefaultState(), 2);
		world.setBlockState(new BlockPos(i - 9, j + 13, k - 36), ACBlocks.dreadstone_brick.getDefaultState(), 2);
		world.setBlockState(new BlockPos(i - 9, j + 14, k - 41), ACBlocks.dreadstone_brick.getDefaultState(), 2);
		world.setBlockState(new BlockPos(i - 9, j + 14, k - 40), ACBlocks.dreadstone_brick.getDefaultState(), 2);
		world.setBlockState(new BlockPos(i - 9, j + 14, k - 39), ACBlocks.dreadstone_brick.getDefaultState(), 2);
		world.setBlockState(new BlockPos(i - 9, j + 14, k - 38), ACBlocks.dreadstone_brick.getDefaultState(), 2);
		world.setBlockState(new BlockPos(i - 9, j + 14, k - 37), ACBlocks.dreadstone_brick.getDefaultState(), 2);
		world.setBlockState(new BlockPos(i - 9, j + 14, k - 36), ACBlocks.dreadstone_brick.getDefaultState(), 2);
		world.setBlockState(new BlockPos(i - 8, j - 15, k - 67), ACBlocks.stone.getStateFromMeta(2), 2);
		world.setBlockState(new BlockPos(i - 8, j - 15, k - 65), ACBlocks.stone.getStateFromMeta(2), 2);
		world.setBlockState(new BlockPos(i - 8, j - 15, k - 64), ACBlocks.stone.getStateFromMeta(2), 2);
		world.setBlockState(new BlockPos(i - 8, j - 15, k - 63), ACBlocks.stone.getStateFromMeta(2), 2);
		world.setBlockState(new BlockPos(i - 8, j - 15, k - 62), ACBlocks.stone.getStateFromMeta(2), 2);
		world.setBlockState(new BlockPos(i - 8, j - 15, k - 61), ACBlocks.stone.getStateFromMeta(2), 2);
		world.setBlockState(new BlockPos(i - 8, j - 14, k - 67), ACBlocks.stone.getStateFromMeta(2), 2);
		world.setBlockState(new BlockPos(i - 8, j - 14, k - 65), ACBlocks.stone.getStateFromMeta(2), 2);
		world.setBlockState(new BlockPos(i - 8, j - 14, k - 64), ACBlocks.stone.getStateFromMeta(2), 2);
		world.setBlockState(new BlockPos(i - 8, j - 14, k - 63), ACBlocks.stone.getStateFromMeta(2), 2);
		world.setBlockState(new BlockPos(i - 8, j - 14, k - 62), ACBlocks.stone.getStateFromMeta(2), 2);
		world.setBlockState(new BlockPos(i - 8, j - 14, k - 61), ACBlocks.stone.getStateFromMeta(2), 2);
		world.setBlockState(new BlockPos(i - 8, j - 13, k - 67), ACBlocks.stone.getStateFromMeta(2), 2);
		world.setBlockState(new BlockPos(i - 8, j - 13, k - 65), ACBlocks.stone.getStateFromMeta(2), 2);
		world.setBlockState(new BlockPos(i - 8, j - 13, k - 64), ACBlocks.stone.getStateFromMeta(2), 2);
		world.setBlockState(new BlockPos(i - 8, j - 13, k - 63), ACBlocks.stone.getStateFromMeta(2), 2);
		world.setBlockState(new BlockPos(i - 8, j - 13, k - 62), ACBlocks.stone.getStateFromMeta(2), 2);
		world.setBlockState(new BlockPos(i - 8, j - 13, k - 61), ACBlocks.stone.getStateFromMeta(2), 2);
		world.setBlockState(new BlockPos(i - 8, j - 12, k - 67), ACBlocks.stone.getStateFromMeta(2), 2);
		world.setBlockState(new BlockPos(i - 8, j - 12, k - 65), ACBlocks.stone.getStateFromMeta(2), 2);
		world.setBlockState(new BlockPos(i - 8, j - 12, k - 64), ACBlocks.stone.getStateFromMeta(2), 2);
		world.setBlockState(new BlockPos(i - 8, j - 12, k - 62), ACBlocks.stone.getStateFromMeta(2), 2);
		world.setBlockState(new BlockPos(i - 8, j - 12, k - 61), ACBlocks.stone.getStateFromMeta(2), 2);
		world.setBlockState(new BlockPos(i - 8, j - 11, k - 67), ACBlocks.stone.getStateFromMeta(2), 2);
		world.setBlockState(new BlockPos(i - 8, j - 11, k - 65), ACBlocks.stone.getStateFromMeta(2), 2);
		world.setBlockState(new BlockPos(i - 8, j - 11, k - 64), ACBlocks.stone.getStateFromMeta(2), 2);
		world.setBlockState(new BlockPos(i - 8, j - 11, k - 62), ACBlocks.stone.getStateFromMeta(2), 2);
		world.setBlockState(new BlockPos(i - 8, j - 11, k - 61), ACBlocks.stone.getStateFromMeta(2), 2);
		world.setBlockState(new BlockPos(i - 8, j - 10, k - 67), ACBlocks.stone.getStateFromMeta(2), 2);
		world.setBlockState(new BlockPos(i - 8, j - 10, k - 65), ACBlocks.stone.getStateFromMeta(2), 2);
		world.setBlockState(new BlockPos(i - 8, j - 10, k - 64), ACBlocks.stone.getStateFromMeta(2), 2);
		world.setBlockState(new BlockPos(i - 8, j - 10, k - 62), ACBlocks.stone.getStateFromMeta(2), 2);
		world.setBlockState(new BlockPos(i - 8, j - 10, k - 61), ACBlocks.stone.getStateFromMeta(2), 2);
		world.setBlockState(new BlockPos(i - 8, j - 9, k - 67), ACBlocks.stone.getStateFromMeta(2), 2);
		world.setBlockState(new BlockPos(i - 8, j - 9, k - 65), ACBlocks.stone.getStateFromMeta(2), 2);
		world.setBlockState(new BlockPos(i - 8, j - 9, k - 64), ACBlocks.stone.getStateFromMeta(2), 2);
		world.setBlockState(new BlockPos(i - 8, j - 9, k - 62), ACBlocks.stone.getStateFromMeta(2), 2);
		world.setBlockState(new BlockPos(i - 8, j - 9, k - 61), ACBlocks.stone.getStateFromMeta(2), 2);
		world.setBlockState(new BlockPos(i - 8, j - 8, k - 67), ACBlocks.stone.getStateFromMeta(2), 2);
		world.setBlockState(new BlockPos(i - 8, j - 8, k - 65), ACBlocks.stone.getStateFromMeta(2), 2);
		world.setBlockState(new BlockPos(i - 8, j - 8, k - 64), ACBlocks.stone.getStateFromMeta(2), 2);
