/**AbyssalCraft
 *Copyright 2012-2014 Shinoow
 *
 *Licensed under the Apache License, Version 2.0 (the "License");
 *you may not use this file except in compliance with the License.
 *You may obtain a copy of the License at
 *
 *  http://www.apache.org/licenses/LICENSE-2.0
 *
 *Unless required by applicable law or agreed to in writing, software
 *distributed under the License is distributed on an "AS IS" BASIS,
 *WITHOUT WARRANTIES OR CONDITIONS OF ANY KIND, either express or implied.
 *See the License for the specific language governing permissions and
 *limitations under the License.
 */
package com.shinoow.abyssalcraft.common.structures.dreadlands;

import java.util.Random;

import net.minecraft.init.Blocks;
import net.minecraft.item.ItemStack;
import net.minecraft.tileentity.TileEntityChest;
import net.minecraft.util.EnumChatFormatting;
import net.minecraft.world.World;
import net.minecraft.world.gen.feature.WorldGenerator;

import com.shinoow.abyssalcraft.AbyssalCraft;

public class chagarothlair extends WorldGenerator {

	public chagarothlair() { }

	@Override
	public boolean generate(World world, Random rand, int i, int j, int k) {

		world.setBlock(i - 24, j + 4, k - 30, AbyssalCraft.dreadbrick, 0, 2);
		world.setBlock(i - 24, j + 4, k - 29, AbyssalCraft.dreadbrick, 0, 2);
		world.setBlock(i - 24, j + 4, k - 28, AbyssalCraft.dreadbrick, 0, 2);
		world.setBlock(i - 24, j + 4, k - 27, AbyssalCraft.dreadbrick, 0, 2);
		world.setBlock(i - 24, j + 4, k - 26, AbyssalCraft.dreadbrick, 0, 2);
		world.setBlock(i - 24, j + 4, k - 25, AbyssalCraft.dreadbrick, 0, 2);
		world.setBlock(i - 24, j + 4, k - 24, AbyssalCraft.dreadbrick, 0, 2);
		world.setBlock(i - 24, j + 4, k - 23, AbyssalCraft.dreadbrick, 0, 2);
		world.setBlock(i - 24, j + 4, k - 22, AbyssalCraft.dreadbrick, 0, 2);
		world.setBlock(i - 24, j + 5, k - 30, AbyssalCraft.dreadbrick, 0, 2);
		world.setBlock(i - 24, j + 5, k - 29, AbyssalCraft.dreadbrick, 0, 2);
		world.setBlock(i - 24, j + 5, k - 28, AbyssalCraft.dreadbrick, 0, 2);
		world.setBlock(i - 24, j + 5, k - 27, AbyssalCraft.dreadbrick, 0, 2);
		world.setBlock(i - 24, j + 5, k - 26, AbyssalCraft.dreadbrick, 0, 2);
		world.setBlock(i - 24, j + 5, k - 25, AbyssalCraft.dreadbrick, 0, 2);
		world.setBlock(i - 24, j + 5, k - 24, AbyssalCraft.dreadbrick, 0, 2);
		world.setBlock(i - 24, j + 5, k - 23, AbyssalCraft.dreadbrick, 0, 2);
		world.setBlock(i - 24, j + 5, k - 22, AbyssalCraft.dreadbrick, 0, 2);
		world.setBlock(i - 24, j + 6, k - 30, AbyssalCraft.dreadbrick, 0, 2);
		world.setBlock(i - 24, j + 6, k - 29, AbyssalCraft.dreadbrick, 0, 2);
		world.setBlock(i - 24, j + 6, k - 28, AbyssalCraft.dreadbrick, 0, 2);
		world.setBlock(i - 24, j + 6, k - 27, AbyssalCraft.dreadbrick, 0, 2);
		world.setBlock(i - 24, j + 6, k - 26, AbyssalCraft.dreadbrick, 0, 2);
		world.setBlock(i - 24, j + 6, k - 25, AbyssalCraft.dreadbrick, 0, 2);
		world.setBlock(i - 24, j + 6, k - 24, AbyssalCraft.dreadbrick, 0, 2);
		world.setBlock(i - 24, j + 6, k - 23, AbyssalCraft.dreadbrick, 0, 2);
		world.setBlock(i - 24, j + 6, k - 22, AbyssalCraft.dreadbrick, 0, 2);
		world.setBlock(i - 24, j + 7, k - 30, AbyssalCraft.dreadbrick, 0, 2);
		world.setBlock(i - 24, j + 7, k - 29, AbyssalCraft.dreadbrick, 0, 2);
		world.setBlock(i - 24, j + 7, k - 28, AbyssalCraft.dreadbrick, 0, 2);
		world.setBlock(i - 24, j + 7, k - 27, AbyssalCraft.dreadbrick, 0, 2);
		world.setBlock(i - 24, j + 7, k - 26, AbyssalCraft.dreadbrick, 0, 2);
		world.setBlock(i - 24, j + 7, k - 25, AbyssalCraft.dreadbrick, 0, 2);
		world.setBlock(i - 24, j + 7, k - 24, AbyssalCraft.dreadbrick, 0, 2);
		world.setBlock(i - 24, j + 7, k - 23, AbyssalCraft.dreadbrick, 0, 2);
		world.setBlock(i - 24, j + 7, k - 22, AbyssalCraft.dreadbrick, 0, 2);
		world.setBlock(i - 24, j + 8, k - 30, AbyssalCraft.dreadbrick, 0, 2);
		world.setBlock(i - 24, j + 8, k - 29, AbyssalCraft.dreadbrick, 0, 2);
		world.setBlock(i - 24, j + 8, k - 28, AbyssalCraft.dreadbrick, 0, 2);
		world.setBlock(i - 24, j + 8, k - 27, AbyssalCraft.dreadbrick, 0, 2);
		world.setBlock(i - 24, j + 8, k - 26, AbyssalCraft.dreadbrick, 0, 2);
		world.setBlock(i - 24, j + 8, k - 25, AbyssalCraft.dreadbrick, 0, 2);
		world.setBlock(i - 24, j + 8, k - 24, AbyssalCraft.dreadbrick, 0, 2);
		world.setBlock(i - 24, j + 8, k - 23, AbyssalCraft.dreadbrick, 0, 2);
		world.setBlock(i - 24, j + 8, k - 22, AbyssalCraft.dreadbrick, 0, 2);
		world.setBlock(i - 23, j + 3, k - 29, AbyssalCraft.dreadbrick, 0, 2);
		world.setBlock(i - 23, j + 3, k - 28, AbyssalCraft.dreadbrick, 0, 2);
		world.setBlock(i - 23, j + 3, k - 27, AbyssalCraft.dreadbrick, 0, 2);
		world.setBlock(i - 23, j + 3, k - 26, AbyssalCraft.dreadbrick, 0, 2);
		world.setBlock(i - 23, j + 3, k - 25, AbyssalCraft.dreadbrick, 0, 2);
		world.setBlock(i - 23, j + 3, k - 24, AbyssalCraft.dreadbrick, 0, 2);
		world.setBlock(i - 23, j + 3, k - 23, AbyssalCraft.dreadbrick, 0, 2);
		world.setBlock(i - 23, j + 4, k - 30, AbyssalCraft.dreadbrick, 0, 2);
		world.setBlock(i - 23, j + 4, k - 28, Blocks.anvil);
		world.setBlock(i - 23, j + 4, k - 26, Blocks.crafting_table);
		world.setBlock(i - 23, j + 4, k - 24, Blocks.furnace, 1, 2);
		world.setBlock(i - 23, j + 4, k - 22, AbyssalCraft.dreadbrick, 0, 2);
		world.setBlock(i - 23, j + 5, k - 30, AbyssalCraft.dreadbrick, 0, 2);
		world.setBlock(i - 23, j + 5, k - 22, AbyssalCraft.dreadbrick, 0, 2);
		world.setBlock(i - 23, j + 6, k - 30, AbyssalCraft.dreadbrick, 0, 2);
		world.setBlock(i - 23, j + 6, k - 29, AbyssalCraft.dreadbrick, 0, 2);
		world.setBlock(i - 23, j + 6, k - 28, AbyssalCraft.dreadbrick, 0, 2);
		world.setBlock(i - 23, j + 6, k - 27, AbyssalCraft.dreadbrick, 0, 2);
		world.setBlock(i - 23, j + 6, k - 26, AbyssalCraft.dreadbrick, 0, 2);
		world.setBlock(i - 23, j + 6, k - 25, AbyssalCraft.dreadbrick, 0, 2);
		world.setBlock(i - 23, j + 6, k - 24, AbyssalCraft.dreadbrick, 0, 2);
		world.setBlock(i - 23, j + 6, k - 23, AbyssalCraft.dreadbrick, 0, 2);
		world.setBlock(i - 23, j + 6, k - 22, AbyssalCraft.dreadbrick, 0, 2);
		world.setBlock(i - 23, j + 7, k - 30, AbyssalCraft.dreadbrick, 0, 2);
		world.setBlock(i - 23, j + 7, k - 22, AbyssalCraft.dreadbrick, 0, 2);
		world.setBlock(i - 23, j + 8, k - 30, AbyssalCraft.dreadbrick, 0, 2);
		world.setBlock(i - 23, j + 8, k - 29, AbyssalCraft.dreadbrick, 0, 2);
		world.setBlock(i - 23, j + 8, k - 28, AbyssalCraft.dreadbrick, 0, 2);
		world.setBlock(i - 23, j + 8, k - 27, AbyssalCraft.dreadbrick, 0, 2);
		world.setBlock(i - 23, j + 8, k - 26, AbyssalCraft.dreadbrick, 0, 2);
		world.setBlock(i - 23, j + 8, k - 25, AbyssalCraft.dreadbrick, 0, 2);
		world.setBlock(i - 23, j + 8, k - 24, AbyssalCraft.dreadbrick, 0, 2);
		world.setBlock(i - 23, j + 8, k - 23, AbyssalCraft.dreadbrick, 0, 2);
		world.setBlock(i - 23, j + 8, k - 22, AbyssalCraft.dreadbrick, 0, 2);
		world.setBlock(i - 22, j + 3, k - 29, AbyssalCraft.dreadbrick, 0, 2);
		world.setBlock(i - 22, j + 3, k - 28, AbyssalCraft.dreadbrick, 0, 2);
		world.setBlock(i - 22, j + 3, k - 27, AbyssalCraft.dreadbrick, 0, 2);
		world.setBlock(i - 22, j + 3, k - 26, AbyssalCraft.dreadbrick, 0, 2);
		world.setBlock(i - 22, j + 3, k - 25, AbyssalCraft.dreadbrick, 0, 2);
		world.setBlock(i - 22, j + 3, k - 24, AbyssalCraft.dreadbrick, 0, 2);
		world.setBlock(i - 22, j + 3, k - 23, AbyssalCraft.dreadbrick, 0, 2);
		world.setBlock(i - 22, j + 4, k - 41, AbyssalCraft.dreadbrick, 0, 2);
		world.setBlock(i - 22, j + 4, k - 40, AbyssalCraft.dreadbrick, 0, 2);
		world.setBlock(i - 22, j + 4, k - 39, AbyssalCraft.dreadbrick, 0, 2);
		world.setBlock(i - 22, j + 4, k - 38, AbyssalCraft.dreadbrick, 0, 2);
		world.setBlock(i - 22, j + 4, k - 37, AbyssalCraft.dreadbrick, 0, 2);
		world.setBlock(i - 22, j + 4, k - 36, AbyssalCraft.dreadbrick, 0, 2);
		world.setBlock(i - 22, j + 4, k - 35, AbyssalCraft.dreadbrick, 0, 2);
		world.setBlock(i - 22, j + 4, k - 34, AbyssalCraft.dreadbrick, 0, 2);
		world.setBlock(i - 22, j + 4, k - 33, AbyssalCraft.dreadbrick, 0, 2);
		world.setBlock(i - 22, j + 4, k - 32, AbyssalCraft.dreadbrick, 0, 2);
		world.setBlock(i - 22, j + 4, k - 31, AbyssalCraft.dreadbrick, 0, 2);
		world.setBlock(i - 22, j + 4, k - 30, AbyssalCraft.dreadbrick, 0, 2);
		world.setBlock(i - 22, j + 4, k - 22, AbyssalCraft.dreadbrick, 0, 2);
		world.setBlock(i - 22, j + 5, k - 41, AbyssalCraft.dreadbrick, 0, 2);
		world.setBlock(i - 22, j + 5, k - 40, AbyssalCraft.dreadbrick, 0, 2);
		world.setBlock(i - 22, j + 5, k - 39, AbyssalCraft.dreadbrick, 0, 2);
		world.setBlock(i - 22, j + 5, k - 38, AbyssalCraft.dreadbrick, 0, 2);
		world.setBlock(i - 22, j + 5, k - 37, AbyssalCraft.dreadbrick, 0, 2);
		world.setBlock(i - 22, j + 5, k - 36, AbyssalCraft.dreadbrick, 0, 2);
		world.setBlock(i - 22, j + 5, k - 35, AbyssalCraft.dreadbrick, 0, 2);
		world.setBlock(i - 22, j + 5, k - 34, AbyssalCraft.dreadbrick, 0, 2);
		world.setBlock(i - 22, j + 5, k - 33, AbyssalCraft.dreadbrick, 0, 2);
		world.setBlock(i - 22, j + 5, k - 32, AbyssalCraft.dreadbrick, 0, 2);
		world.setBlock(i - 22, j + 5, k - 31, AbyssalCraft.dreadbrick, 0, 2);
		world.setBlock(i - 22, j + 5, k - 30, AbyssalCraft.dreadbrick, 0, 2);
		world.setBlock(i - 22, j + 5, k - 22, AbyssalCraft.dreadbrick, 0, 2);
		world.setBlock(i - 22, j + 6, k - 41, AbyssalCraft.dreadbrick, 0, 2);
		world.setBlock(i - 22, j + 6, k - 40, AbyssalCraft.dreadbrick, 0, 2);
		world.setBlock(i - 22, j + 6, k - 39, AbyssalCraft.dreadbrick, 0, 2);
		world.setBlock(i - 22, j + 6, k - 38, AbyssalCraft.dreadbrick, 0, 2);
		world.setBlock(i - 22, j + 6, k - 37, AbyssalCraft.dreadbrick, 0, 2);
		world.setBlock(i - 22, j + 6, k - 36, AbyssalCraft.dreadbrick, 0, 2);
		world.setBlock(i - 22, j + 6, k - 35, AbyssalCraft.dreadbrick, 0, 2);
		world.setBlock(i - 22, j + 6, k - 34, AbyssalCraft.dreadbrick, 0, 2);
		world.setBlock(i - 22, j + 6, k - 33, AbyssalCraft.dreadbrick, 0, 2);
		world.setBlock(i - 22, j + 6, k - 32, AbyssalCraft.dreadbrick, 0, 2);
		world.setBlock(i - 22, j + 6, k - 31, AbyssalCraft.dreadbrick, 0, 2);
		world.setBlock(i - 22, j + 6, k - 30, AbyssalCraft.dreadbrick, 0, 2);
		world.setBlock(i - 22, j + 6, k - 22, AbyssalCraft.dreadbrick, 0, 2);
		world.setBlock(i - 22, j + 7, k - 41, AbyssalCraft.dreadbrick, 0, 2);
		world.setBlock(i - 22, j + 7, k - 40, AbyssalCraft.dreadbrick, 0, 2);
		world.setBlock(i - 22, j + 7, k - 39, AbyssalCraft.dreadbrick, 0, 2);
		world.setBlock(i - 22, j + 7, k - 38, AbyssalCraft.dreadbrick, 0, 2);
		world.setBlock(i - 22, j + 7, k - 37, AbyssalCraft.dreadbrick, 0, 2);
		world.setBlock(i - 22, j + 7, k - 36, AbyssalCraft.dreadbrick, 0, 2);
		world.setBlock(i - 22, j + 7, k - 35, AbyssalCraft.dreadbrick, 0, 2);
		world.setBlock(i - 22, j + 7, k - 34, AbyssalCraft.dreadbrick, 0, 2);
		world.setBlock(i - 22, j + 7, k - 33, AbyssalCraft.dreadbrick, 0, 2);
		world.setBlock(i - 22, j + 7, k - 32, AbyssalCraft.dreadbrick, 0, 2);
		world.setBlock(i - 22, j + 7, k - 31, AbyssalCraft.dreadbrick, 0, 2);
		world.setBlock(i - 22, j + 7, k - 30, AbyssalCraft.dreadbrick, 0, 2);
		world.setBlock(i - 22, j + 7, k - 22, AbyssalCraft.dreadbrick, 0, 2);
		world.setBlock(i - 22, j + 8, k - 41, AbyssalCraft.dreadbrick, 0, 2);
		world.setBlock(i - 22, j + 8, k - 40, AbyssalCraft.dreadbrick, 0, 2);
		world.setBlock(i - 22, j + 8, k - 39, AbyssalCraft.dreadbrick, 0, 2);
		world.setBlock(i - 22, j + 8, k - 38, AbyssalCraft.dreadbrick, 0, 2);
		world.setBlock(i - 22, j + 8, k - 37, AbyssalCraft.dreadbrick, 0, 2);
		world.setBlock(i - 22, j + 8, k - 36, AbyssalCraft.dreadbrick, 0, 2);
		world.setBlock(i - 22, j + 8, k - 35, AbyssalCraft.dreadbrick, 0, 2);
		world.setBlock(i - 22, j + 8, k - 34, AbyssalCraft.dreadbrick, 0, 2);
		world.setBlock(i - 22, j + 8, k - 33, AbyssalCraft.dreadbrick, 0, 2);
		world.setBlock(i - 22, j + 8, k - 32, AbyssalCraft.dreadbrick, 0, 2);
		world.setBlock(i - 22, j + 8, k - 31, AbyssalCraft.dreadbrick, 0, 2);
		world.setBlock(i - 22, j + 8, k - 30, AbyssalCraft.dreadbrick, 0, 2);
		world.setBlock(i - 22, j + 8, k - 29, AbyssalCraft.dreadbrick, 0, 2);
		world.setBlock(i - 22, j + 8, k - 28, AbyssalCraft.dreadbrick, 0, 2);
		world.setBlock(i - 22, j + 8, k - 27, AbyssalCraft.dreadbrick, 0, 2);
		world.setBlock(i - 22, j + 8, k - 26, AbyssalCraft.dreadbrick, 0, 2);
		world.setBlock(i - 22, j + 8, k - 25, AbyssalCraft.dreadbrick, 0, 2);
		world.setBlock(i - 22, j + 8, k - 24, AbyssalCraft.dreadbrick, 0, 2);
		world.setBlock(i - 22, j + 8, k - 23, AbyssalCraft.dreadbrick, 0, 2);
		world.setBlock(i - 22, j + 8, k - 22, AbyssalCraft.dreadbrick, 0, 2);
		world.setBlock(i - 22, j + 9, k - 41, AbyssalCraft.dreadbrick, 0, 2);
		world.setBlock(i - 22, j + 9, k - 40, AbyssalCraft.dreadbrick, 0, 2);
		world.setBlock(i - 22, j + 9, k - 39, AbyssalCraft.dreadbrick, 0, 2);
		world.setBlock(i - 22, j + 9, k - 38, AbyssalCraft.dreadbrick, 0, 2);
		world.setBlock(i - 22, j + 9, k - 37, AbyssalCraft.dreadbrick, 0, 2);
		world.setBlock(i - 22, j + 9, k - 36, AbyssalCraft.dreadbrick, 0, 2);
		world.setBlock(i - 22, j + 9, k - 35, AbyssalCraft.dreadbrick, 0, 2);
		world.setBlock(i - 22, j + 9, k - 34, AbyssalCraft.dreadbrick, 0, 2);
		world.setBlock(i - 22, j + 10, k - 41, AbyssalCraft.dreadbrick, 0, 2);
		world.setBlock(i - 22, j + 10, k - 40, AbyssalCraft.dreadbrick, 0, 2);
		world.setBlock(i - 22, j + 10, k - 39, AbyssalCraft.dreadbrick, 0, 2);
		world.setBlock(i - 22, j + 10, k - 38, AbyssalCraft.dreadbrick, 0, 2);
		world.setBlock(i - 22, j + 10, k - 37, AbyssalCraft.dreadbrick, 0, 2);
		world.setBlock(i - 22, j + 10, k - 36, AbyssalCraft.dreadbrick, 0, 2);
		world.setBlock(i - 22, j + 10, k - 35, AbyssalCraft.dreadbrick, 0, 2);
		world.setBlock(i - 21, j + 3, k - 40, AbyssalCraft.dreadbrick, 0, 2);
		world.setBlock(i - 21, j + 3, k - 39, AbyssalCraft.dreadbrick, 0, 2);
		world.setBlock(i - 21, j + 3, k - 38, AbyssalCraft.dreadbrick, 0, 2);
		world.setBlock(i - 21, j + 3, k - 37, AbyssalCraft.dreadbrick, 0, 2);
		world.setBlock(i - 21, j + 3, k - 36, AbyssalCraft.dreadbrick, 0, 2);
		world.setBlock(i - 21, j + 3, k - 35, AbyssalCraft.dreadbrick, 0, 2);
		world.setBlock(i - 21, j + 3, k - 34, AbyssalCraft.dreadbrick, 0, 2);
		world.setBlock(i - 21, j + 3, k - 33, AbyssalCraft.dreadbrick, 0, 2);
		world.setBlock(i - 21, j + 3, k - 32, AbyssalCraft.dreadbrick, 0, 2);
		world.setBlock(i - 21, j + 3, k - 31, AbyssalCraft.dreadbrick, 0, 2);
		world.setBlock(i - 21, j + 3, k - 30, AbyssalCraft.dreadbrick, 0, 2);
		world.setBlock(i - 21, j + 3, k - 29, AbyssalCraft.dreadbrick, 0, 2);
		world.setBlock(i - 21, j + 3, k - 28, AbyssalCraft.dreadbrick, 0, 2);
		world.setBlock(i - 21, j + 3, k - 27, AbyssalCraft.dreadbrick, 0, 2);
		world.setBlock(i - 21, j + 3, k - 26, AbyssalCraft.dreadbrick, 0, 2);
		world.setBlock(i - 21, j + 3, k - 25, AbyssalCraft.dreadbrick, 0, 2);
		world.setBlock(i - 21, j + 3, k - 24, AbyssalCraft.dreadbrick, 0, 2);
		world.setBlock(i - 21, j + 3, k - 23, AbyssalCraft.dreadbrick, 0, 2);
		world.setBlock(i - 21, j + 4, k - 41, AbyssalCraft.dreadbrick, 0, 2);
		world.setBlock(i - 21, j + 4, k - 22, AbyssalCraft.dreadbrick, 0, 2);
		world.setBlock(i - 21, j + 5, k - 41, AbyssalCraft.dreadbrick, 0, 2);
		world.setBlock(i - 21, j + 5, k - 22, AbyssalCraft.dreadbrick, 0, 2);
		world.setBlock(i - 21, j + 6, k - 41, AbyssalCraft.dreadbrick, 0, 2);
		world.setBlock(i - 21, j + 6, k - 22, AbyssalCraft.dreadbrick, 0, 2);
		world.setBlock(i - 21, j + 7, k - 41, AbyssalCraft.dreadbrick, 0, 2);
		world.setBlock(i - 21, j + 7, k - 22, AbyssalCraft.dreadbrick, 0, 2);
		world.setBlock(i - 21, j + 8, k - 41, AbyssalCraft.dreadbrick, 0, 2);
		world.setBlock(i - 21, j + 8, k - 33, AbyssalCraft.dreadbrick, 0, 2);
		world.setBlock(i - 21, j + 8, k - 32, AbyssalCraft.dreadbrick, 0, 2);
		world.setBlock(i - 21, j + 8, k - 31, AbyssalCraft.dreadbrick, 0, 2);
		world.setBlock(i - 21, j + 8, k - 30, AbyssalCraft.dreadbrick, 0, 2);
		world.setBlock(i - 21, j + 8, k - 29, AbyssalCraft.dreadbrick, 0, 2);
		world.setBlock(i - 21, j + 8, k - 28, AbyssalCraft.dreadbrick, 0, 2);
		world.setBlock(i - 21, j + 8, k - 27, AbyssalCraft.dreadbrick, 0, 2);
		world.setBlock(i - 21, j + 8, k - 26, AbyssalCraft.dreadbrick, 0, 2);
		world.setBlock(i - 21, j + 8, k - 25, AbyssalCraft.dreadbrick, 0, 2);
		world.setBlock(i - 21, j + 8, k - 24, AbyssalCraft.dreadbrick, 0, 2);
		world.setBlock(i - 21, j + 8, k - 23, AbyssalCraft.dreadbrick, 0, 2);
		world.setBlock(i - 21, j + 8, k - 22, AbyssalCraft.dreadbrick, 0, 2);
		world.setBlock(i - 21, j + 9, k - 41, AbyssalCraft.dreadbrick, 0, 2);
		world.setBlock(i - 21, j + 9, k - 34, AbyssalCraft.dreadbrick, 0, 2);
		world.setBlock(i - 21, j + 10, k - 41, AbyssalCraft.dreadbrick, 0, 2);
		world.setBlock(i - 21, j + 10, k - 40, AbyssalCraft.dreadbrick, 0, 2);
		world.setBlock(i - 21, j + 10, k - 39, AbyssalCraft.dreadbrick, 0, 2);
		world.setBlock(i - 21, j + 10, k - 38, AbyssalCraft.dreadbrick, 0, 2);
		world.setBlock(i - 21, j + 10, k - 37, AbyssalCraft.dreadbrick, 0, 2);
		world.setBlock(i - 21, j + 10, k - 36, AbyssalCraft.dreadbrick, 0, 2);
		world.setBlock(i - 21, j + 10, k - 35, AbyssalCraft.dreadbrick, 0, 2);
		world.setBlock(i - 20, j + 3, k - 40, AbyssalCraft.dreadbrick, 0, 2);
		world.setBlock(i - 20, j + 3, k - 39, AbyssalCraft.dreadbrick, 0, 2);
		world.setBlock(i - 20, j + 3, k - 38, AbyssalCraft.dreadbrick, 0, 2);
		world.setBlock(i - 20, j + 3, k - 37, AbyssalCraft.dreadbrick, 0, 2);
		world.setBlock(i - 20, j + 3, k - 36, AbyssalCraft.dreadbrick, 0, 2);
		world.setBlock(i - 20, j + 3, k - 35, AbyssalCraft.dreadbrick, 0, 2);
		world.setBlock(i - 20, j + 3, k - 34, AbyssalCraft.dreadbrick, 0, 2);
		world.setBlock(i - 20, j + 3, k - 33, AbyssalCraft.dreadbrick, 0, 2);
		world.setBlock(i - 20, j + 3, k - 32, AbyssalCraft.dreadbrick, 0, 2);
		world.setBlock(i - 20, j + 3, k - 31, AbyssalCraft.dreadbrick, 0, 2);
		world.setBlock(i - 20, j + 3, k - 30, AbyssalCraft.dreadbrick, 0, 2);
		world.setBlock(i - 20, j + 3, k - 29, AbyssalCraft.dreadbrick, 0, 2);
		world.setBlock(i - 20, j + 3, k - 28, AbyssalCraft.dreadbrick, 0, 2);
		world.setBlock(i - 20, j + 3, k - 27, AbyssalCraft.dreadbrick, 0, 2);
		world.setBlock(i - 20, j + 3, k - 26, AbyssalCraft.dreadbrick, 0, 2);
		world.setBlock(i - 20, j + 3, k - 25, AbyssalCraft.dreadbrick, 0, 2);
		world.setBlock(i - 20, j + 3, k - 24, AbyssalCraft.dreadbrick, 0, 2);
		world.setBlock(i - 20, j + 3, k - 23, AbyssalCraft.dreadbrick, 0, 2);
		world.setBlock(i - 20, j + 4, k - 41, AbyssalCraft.dreadbrick, 0, 2);
		world.setBlock(i - 20, j + 4, k - 26, AbyssalCraft.dreadguardspawner, 0, 2);
		world.setBlock(i - 20, j + 4, k - 22, AbyssalCraft.dreadbrick, 0, 2);
		world.setBlock(i - 20, j + 5, k - 41, AbyssalCraft.dreadbrick, 0, 2);
		world.setBlock(i - 20, j + 5, k - 22, AbyssalCraft.dreadbrick, 0, 2);
		world.setBlock(i - 20, j + 6, k - 41, AbyssalCraft.dreadbrick, 0, 2);
		world.setBlock(i - 20, j + 6, k - 22, AbyssalCraft.dreadbrick, 0, 2);
		world.setBlock(i - 20, j + 7, k - 41, AbyssalCraft.dreadbrick, 0, 2);
		world.setBlock(i - 20, j + 7, k - 22, AbyssalCraft.dreadbrick, 0, 2);
		world.setBlock(i - 20, j + 8, k - 41, AbyssalCraft.dreadbrick, 0, 2);
		world.setBlock(i - 20, j + 8, k - 33, AbyssalCraft.dreadbrick, 0, 2);
		world.setBlock(i - 20, j + 8, k - 32, AbyssalCraft.dreadbrick, 0, 2);
		world.setBlock(i - 20, j + 8, k - 31, AbyssalCraft.dreadbrick, 0, 2);
		world.setBlock(i - 20, j + 8, k - 30, AbyssalCraft.dreadbrick, 0, 2);
		world.setBlock(i - 20, j + 8, k - 29, AbyssalCraft.dreadbrick, 0, 2);
		world.setBlock(i - 20, j + 8, k - 28, AbyssalCraft.dreadbrick, 0, 2);
		world.setBlock(i - 20, j + 8, k - 27, AbyssalCraft.dreadbrick, 0, 2);
		world.setBlock(i - 20, j + 8, k - 26, AbyssalCraft.dreadbrick, 0, 2);
		world.setBlock(i - 20, j + 8, k - 25, AbyssalCraft.dreadbrick, 0, 2);
		world.setBlock(i - 20, j + 8, k - 24, AbyssalCraft.dreadbrick, 0, 2);
		world.setBlock(i - 20, j + 8, k - 23, AbyssalCraft.dreadbrick, 0, 2);
		world.setBlock(i - 20, j + 8, k - 22, AbyssalCraft.dreadbrick, 0, 2);
		world.setBlock(i - 20, j + 9, k - 41, AbyssalCraft.dreadbrick, 0, 2);
		world.setBlock(i - 20, j + 9, k - 34, AbyssalCraft.dreadbrick, 0, 2);
		world.setBlock(i - 20, j + 10, k - 41, AbyssalCraft.dreadbrick, 0, 2);
		world.setBlock(i - 20, j + 10, k - 40, AbyssalCraft.dreadbrick, 0, 2);
		world.setBlock(i - 20, j + 10, k - 39, AbyssalCraft.dreadbrick, 0, 2);
		world.setBlock(i - 20, j + 10, k - 38, AbyssalCraft.dreadbrick, 0, 2);
		world.setBlock(i - 20, j + 10, k - 37, AbyssalCraft.dreadbrick, 0, 2);
		world.setBlock(i - 20, j + 10, k - 36, AbyssalCraft.dreadbrick, 0, 2);
		world.setBlock(i - 20, j + 10, k - 35, AbyssalCraft.dreadbrick, 0, 2);
		world.setBlock(i - 19, j + 3, k - 40, AbyssalCraft.dreadbrick, 0, 2);
		world.setBlock(i - 19, j + 3, k - 39, AbyssalCraft.dreadbrick, 0, 2);
		world.setBlock(i - 19, j + 3, k - 38, AbyssalCraft.dreadbrick, 0, 2);
		world.setBlock(i - 19, j + 3, k - 37, AbyssalCraft.dreadbrick, 0, 2);
		world.setBlock(i - 19, j + 3, k - 36, AbyssalCraft.dreadbrick, 0, 2);
		world.setBlock(i - 19, j + 3, k - 35, AbyssalCraft.dreadbrick, 0, 2);
		world.setBlock(i - 19, j + 3, k - 34, AbyssalCraft.dreadbrick, 0, 2);
		world.setBlock(i - 19, j + 3, k - 33, AbyssalCraft.dreadbrick, 0, 2);
		world.setBlock(i - 19, j + 3, k - 32, AbyssalCraft.dreadbrick, 0, 2);
		world.setBlock(i - 19, j + 3, k - 31, AbyssalCraft.dreadbrick, 0, 2);
		world.setBlock(i - 19, j + 3, k - 30, AbyssalCraft.dreadbrick, 0, 2);
		world.setBlock(i - 19, j + 3, k - 29, AbyssalCraft.dreadbrick, 0, 2);
		world.setBlock(i - 19, j + 3, k - 28, AbyssalCraft.dreadbrick, 0, 2);
		world.setBlock(i - 19, j + 3, k - 27, AbyssalCraft.dreadbrick, 0, 2);
		world.setBlock(i - 19, j + 3, k - 26, AbyssalCraft.dreadbrick, 0, 2);
		world.setBlock(i - 19, j + 3, k - 25, AbyssalCraft.dreadbrick, 0, 2);
		world.setBlock(i - 19, j + 3, k - 24, AbyssalCraft.dreadbrick, 0, 2);
		world.setBlock(i - 19, j + 3, k - 23, AbyssalCraft.dreadbrick, 0, 2);
		world.setBlock(i - 19, j + 4, k - 41, AbyssalCraft.dreadbrick, 0, 2);
		world.setBlock(i - 19, j + 4, k - 22, AbyssalCraft.dreadbrick, 0, 2);
		world.setBlock(i - 19, j + 5, k - 41, AbyssalCraft.dreadbrick, 0, 2);
		world.setBlock(i - 19, j + 5, k - 22, AbyssalCraft.dreadbrick, 0, 2);
		world.setBlock(i - 19, j + 6, k - 41, AbyssalCraft.dreadbrick, 0, 2);
		world.setBlock(i - 19, j + 6, k - 22, AbyssalCraft.dreadbrick, 0, 2);
		world.setBlock(i - 19, j + 7, k - 41, AbyssalCraft.dreadbrick, 0, 2);
		world.setBlock(i - 19, j + 7, k - 22, AbyssalCraft.dreadbrick, 0, 2);
		world.setBlock(i - 19, j + 8, k - 41, AbyssalCraft.dreadbrick, 0, 2);
		world.setBlock(i - 19, j + 8, k - 33, AbyssalCraft.dreadbrick, 0, 2);
		world.setBlock(i - 19, j + 8, k - 32, AbyssalCraft.dreadbrick, 0, 2);
		world.setBlock(i - 19, j + 8, k - 31, AbyssalCraft.dreadbrick, 0, 2);
		world.setBlock(i - 19, j + 8, k - 30, AbyssalCraft.dreadbrick, 0, 2);
		world.setBlock(i - 19, j + 8, k - 29, AbyssalCraft.dreadbrick, 0, 2);
		world.setBlock(i - 19, j + 8, k - 28, AbyssalCraft.dreadbrick, 0, 2);
		world.setBlock(i - 19, j + 8, k - 27, AbyssalCraft.dreadbrick, 0, 2);
		world.setBlock(i - 19, j + 8, k - 26, AbyssalCraft.dreadbrick, 0, 2);
		world.setBlock(i - 19, j + 8, k - 25, AbyssalCraft.dreadbrick, 0, 2);
		world.setBlock(i - 19, j + 8, k - 24, AbyssalCraft.dreadbrick, 0, 2);
		world.setBlock(i - 19, j + 8, k - 23, AbyssalCraft.dreadbrick, 0, 2);
		world.setBlock(i - 19, j + 8, k - 22, AbyssalCraft.dreadbrick, 0, 2);
		world.setBlock(i - 19, j + 9, k - 41, AbyssalCraft.dreadbrick, 0, 2);
		world.setBlock(i - 19, j + 9, k - 34, AbyssalCraft.dreadbrick, 0, 2);
		world.setBlock(i - 19, j + 10, k - 41, AbyssalCraft.dreadbrick, 0, 2);
		world.setBlock(i - 19, j + 10, k - 40, AbyssalCraft.dreadbrick, 0, 2);
		world.setBlock(i - 19, j + 10, k - 39, AbyssalCraft.dreadbrick, 0, 2);
		world.setBlock(i - 19, j + 10, k - 38, AbyssalCraft.dreadbrick, 0, 2);
		world.setBlock(i - 19, j + 10, k - 37, AbyssalCraft.dreadbrick, 0, 2);
		world.setBlock(i - 19, j + 10, k - 36, AbyssalCraft.dreadbrick, 0, 2);
		world.setBlock(i - 19, j + 10, k - 35, AbyssalCraft.dreadbrick, 0, 2);
		world.setBlock(i - 18, j + 3, k - 40, AbyssalCraft.dreadbrick, 0, 2);
		world.setBlock(i - 18, j + 3, k - 39, AbyssalCraft.dreadbrick, 0, 2);
		world.setBlock(i - 18, j + 3, k - 38, AbyssalCraft.dreadbrick, 0, 2);
		world.setBlock(i - 18, j + 3, k - 37, AbyssalCraft.dreadbrick, 0, 2);
		world.setBlock(i - 18, j + 3, k - 36, AbyssalCraft.dreadbrick, 0, 2);
		world.setBlock(i - 18, j + 3, k - 35, AbyssalCraft.dreadbrick, 0, 2);
		world.setBlock(i - 18, j + 3, k - 34, AbyssalCraft.dreadbrick, 0, 2);
		world.setBlock(i - 18, j + 3, k - 33, AbyssalCraft.dreadbrick, 0, 2);
		world.setBlock(i - 18, j + 3, k - 32, AbyssalCraft.dreadbrick, 0, 2);
		world.setBlock(i - 18, j + 3, k - 31, AbyssalCraft.dreadbrick, 0, 2);
		world.setBlock(i - 18, j + 3, k - 30, AbyssalCraft.dreadbrick, 0, 2);
		world.setBlock(i - 18, j + 3, k - 29, AbyssalCraft.dreadbrick, 0, 2);
		world.setBlock(i - 18, j + 3, k - 28, AbyssalCraft.dreadbrick, 0, 2);
		world.setBlock(i - 18, j + 3, k - 27, AbyssalCraft.dreadbrick, 0, 2);
		world.setBlock(i - 18, j + 3, k - 26, AbyssalCraft.dreadbrick, 0, 2);
		world.setBlock(i - 18, j + 3, k - 25, AbyssalCraft.dreadbrick, 0, 2);
		world.setBlock(i - 18, j + 3, k - 24, AbyssalCraft.dreadbrick, 0, 2);
		world.setBlock(i - 18, j + 3, k - 23, AbyssalCraft.dreadbrick, 0, 2);
		world.setBlock(i - 18, j + 4, k - 41, AbyssalCraft.dreadbrick, 0, 2);
		world.setBlock(i - 18, j + 4, k - 22, AbyssalCraft.dreadbrick, 0, 2);
		world.setBlock(i - 18, j + 5, k - 41, AbyssalCraft.dreadbrick, 0, 2);
		world.setBlock(i - 18, j + 5, k - 22, AbyssalCraft.dreadbrick, 0, 2);
		world.setBlock(i - 18, j + 6, k - 41, AbyssalCraft.dreadbrick, 0, 2);
		world.setBlock(i - 18, j + 6, k - 22, AbyssalCraft.dreadbrick, 0, 2);
		world.setBlock(i - 18, j + 7, k - 41, AbyssalCraft.dreadbrick, 0, 2);
		world.setBlock(i - 18, j + 7, k - 22, AbyssalCraft.dreadbrick, 0, 2);
		world.setBlock(i - 18, j + 8, k - 41, AbyssalCraft.dreadbrick, 0, 2);
		world.setBlock(i - 18, j + 8, k - 33, AbyssalCraft.dreadbrick, 0, 2);
		world.setBlock(i - 18, j + 8, k - 32, AbyssalCraft.dreadbrick, 0, 2);
		world.setBlock(i - 18, j + 8, k - 31, AbyssalCraft.dreadbrick, 0, 2);
		world.setBlock(i - 18, j + 8, k - 30, AbyssalCraft.dreadbrick, 0, 2);
		world.setBlock(i - 18, j + 8, k - 29, AbyssalCraft.dreadbrick, 0, 2);
		world.setBlock(i - 18, j + 8, k - 28, AbyssalCraft.dreadbrick, 0, 2);
		world.setBlock(i - 18, j + 8, k - 27, AbyssalCraft.dreadbrick, 0, 2);
		world.setBlock(i - 18, j + 8, k - 26, AbyssalCraft.dreadbrick, 0, 2);
		world.setBlock(i - 18, j + 8, k - 25, AbyssalCraft.dreadbrick, 0, 2);
		world.setBlock(i - 18, j + 8, k - 24, AbyssalCraft.dreadbrick, 0, 2);
		world.setBlock(i - 18, j + 8, k - 23, AbyssalCraft.dreadbrick, 0, 2);
		world.setBlock(i - 18, j + 8, k - 22, AbyssalCraft.dreadbrick, 0, 2);
		world.setBlock(i - 18, j + 9, k - 41, AbyssalCraft.dreadbrick, 0, 2);
		world.setBlock(i - 18, j + 9, k - 34, AbyssalCraft.dreadbrick, 0, 2);
		world.setBlock(i - 18, j + 10, k - 41, AbyssalCraft.dreadbrick, 0, 2);
		world.setBlock(i - 18, j + 10, k - 40, AbyssalCraft.dreadbrick, 0, 2);
		world.setBlock(i - 18, j + 10, k - 39, AbyssalCraft.dreadbrick, 0, 2);
		world.setBlock(i - 18, j + 10, k - 38, AbyssalCraft.dreadbrick, 0, 2);
		world.setBlock(i - 18, j + 10, k - 37, AbyssalCraft.dreadbrick, 0, 2);
		world.setBlock(i - 18, j + 10, k - 36, AbyssalCraft.dreadbrick, 0, 2);
		world.setBlock(i - 18, j + 10, k - 35, AbyssalCraft.dreadbrick, 0, 2);
		world.setBlock(i - 17, j + 3, k - 40, AbyssalCraft.dreadbrick, 0, 2);
		world.setBlock(i - 17, j + 3, k - 39, AbyssalCraft.dreadbrick, 0, 2);
		world.setBlock(i - 17, j + 3, k - 38, AbyssalCraft.dreadbrick, 0, 2);
		world.setBlock(i - 17, j + 3, k - 37, AbyssalCraft.dreadbrick, 0, 2);
		world.setBlock(i - 17, j + 3, k - 29, AbyssalCraft.dreadbrick, 0, 2);
		world.setBlock(i - 17, j + 3, k - 28, AbyssalCraft.dreadbrick, 0, 2);
		world.setBlock(i - 17, j + 3, k - 27, AbyssalCraft.dreadbrick, 0, 2);
		world.setBlock(i - 17, j + 3, k - 26, AbyssalCraft.dreadbrick, 0, 2);
		world.setBlock(i - 17, j + 3, k - 25, AbyssalCraft.dreadbrick, 0, 2);
		world.setBlock(i - 17, j + 3, k - 24, AbyssalCraft.dreadbrick, 0, 2);
		world.setBlock(i - 17, j + 3, k - 23, AbyssalCraft.dreadbrick, 0, 2);
		world.setBlock(i - 17, j + 4, k - 41, AbyssalCraft.dreadbrick, 0, 2);
		world.setBlock(i - 17, j + 4, k - 36, AbyssalCraft.dreadbrick, 0, 2);
		world.setBlock(i - 17, j + 4, k - 35, AbyssalCraft.dreadbrick, 0, 2);
		world.setBlock(i - 17, j + 4, k - 34, AbyssalCraft.dreadbrick, 0, 2);
		world.setBlock(i - 17, j + 4, k - 33, AbyssalCraft.dreadbrick, 0, 2);
		world.setBlock(i - 17, j + 4, k - 32, AbyssalCraft.dreadbrick, 0, 2);
		world.setBlock(i - 17, j + 4, k - 31, AbyssalCraft.dreadbrick, 0, 2);
		world.setBlock(i - 17, j + 4, k - 30, AbyssalCraft.dreadbrick, 0, 2);
		world.setBlock(i - 17, j + 4, k - 22, AbyssalCraft.dreadbrick, 0, 2);
		world.setBlock(i - 17, j + 5, k - 41, AbyssalCraft.dreadbrick, 0, 2);
		world.setBlock(i - 17, j + 5, k - 36, AbyssalCraft.dreadbrick, 0, 2);
		world.setBlock(i - 17, j + 5, k - 35, AbyssalCraft.dreadbrick, 0, 2);
		world.setBlock(i - 17, j + 5, k - 34, AbyssalCraft.dreadbrick, 0, 2);
		world.setBlock(i - 17, j + 5, k - 33, AbyssalCraft.dreadbrick, 0, 2);
		world.setBlock(i - 17, j + 5, k - 32, AbyssalCraft.dreadbrick, 0, 2);
		world.setBlock(i - 17, j + 5, k - 31, AbyssalCraft.dreadbrick, 0, 2);
		world.setBlock(i - 17, j + 5, k - 30, AbyssalCraft.dreadbrick, 0, 2);
		world.setBlock(i - 17, j + 5, k - 22, AbyssalCraft.dreadbrick, 0, 2);
		world.setBlock(i - 17, j + 6, k - 41, AbyssalCraft.dreadbrick, 0, 2);
		world.setBlock(i - 17, j + 6, k - 36, AbyssalCraft.dreadbrick, 0, 2);
		world.setBlock(i - 17, j + 6, k - 35, AbyssalCraft.dreadbrick, 0, 2);
		world.setBlock(i - 17, j + 6, k - 34, AbyssalCraft.dreadbrick, 0, 2);
		world.setBlock(i - 17, j + 6, k - 33, AbyssalCraft.dreadbrick, 0, 2);
		world.setBlock(i - 17, j + 6, k - 32, AbyssalCraft.dreadbrick, 0, 2);
		world.setBlock(i - 17, j + 6, k - 31, AbyssalCraft.dreadbrick, 0, 2);
		world.setBlock(i - 17, j + 6, k - 30, AbyssalCraft.dreadbrick, 0, 2);
		world.setBlock(i - 17, j + 6, k - 22, AbyssalCraft.dreadbrick, 0, 2);
		world.setBlock(i - 17, j + 7, k - 41, AbyssalCraft.dreadbrick, 0, 2);
		world.setBlock(i - 17, j + 7, k - 36, AbyssalCraft.dreadbrick, 0, 2);
		world.setBlock(i - 17, j + 7, k - 35, AbyssalCraft.dreadbrick, 0, 2);
		world.setBlock(i - 17, j + 7, k - 34, AbyssalCraft.dreadbrick, 0, 2);
		world.setBlock(i - 17, j + 7, k - 33, AbyssalCraft.dreadbrick, 0, 2);
		world.setBlock(i - 17, j + 7, k - 32, AbyssalCraft.dreadbrick, 0, 2);
		world.setBlock(i - 17, j + 7, k - 31, AbyssalCraft.dreadbrick, 0, 2);
		world.setBlock(i - 17, j + 7, k - 30, AbyssalCraft.dreadbrick, 0, 2);
		world.setBlock(i - 17, j + 7, k - 22, AbyssalCraft.dreadbrick, 0, 2);
		world.setBlock(i - 17, j + 8, k - 41, AbyssalCraft.dreadbrick, 0, 2);
		world.setBlock(i - 17, j + 8, k - 36, AbyssalCraft.dreadbrick, 0, 2);
		world.setBlock(i - 17, j + 8, k - 35, AbyssalCraft.dreadbrick, 0, 2);
		world.setBlock(i - 17, j + 8, k - 34, AbyssalCraft.dreadbrick, 0, 2);
		world.setBlock(i - 17, j + 8, k - 33, AbyssalCraft.dreadbrick, 0, 2);
		world.setBlock(i - 17, j + 8, k - 32, AbyssalCraft.dreadbrick, 0, 2);
		world.setBlock(i - 17, j + 8, k - 31, AbyssalCraft.dreadbrick, 0, 2);
		world.setBlock(i - 17, j + 8, k - 30, AbyssalCraft.dreadbrick, 0, 2);
		world.setBlock(i - 17, j + 8, k - 29, AbyssalCraft.dreadbrick, 0, 2);
		world.setBlock(i - 17, j + 8, k - 28, AbyssalCraft.dreadbrick, 0, 2);
		world.setBlock(i - 17, j + 8, k - 27, AbyssalCraft.dreadbrick, 0, 2);
		world.setBlock(i - 17, j + 8, k - 26, AbyssalCraft.dreadbrick, 0, 2);
		world.setBlock(i - 17, j + 8, k - 25, AbyssalCraft.dreadbrick, 0, 2);
		world.setBlock(i - 17, j + 8, k - 24, AbyssalCraft.dreadbrick, 0, 2);
		world.setBlock(i - 17, j + 8, k - 23, AbyssalCraft.dreadbrick, 0, 2);
		world.setBlock(i - 17, j + 8, k - 22, AbyssalCraft.dreadbrick, 0, 2);
		world.setBlock(i - 17, j + 9, k - 41, AbyssalCraft.dreadbrick, 0, 2);
		world.setBlock(i - 17, j + 9, k - 36, AbyssalCraft.dreadbrick, 0, 2);
		world.setBlock(i - 17, j + 9, k - 35, AbyssalCraft.dreadbrick, 0, 2);
		world.setBlock(i - 17, j + 9, k - 34, AbyssalCraft.dreadbrick, 0, 2);
		world.setBlock(i - 17, j + 10, k - 41, AbyssalCraft.dreadbrick, 0, 2);
		world.setBlock(i - 17, j + 10, k - 40, AbyssalCraft.dreadbrick, 0, 2);
		world.setBlock(i - 17, j + 10, k - 39, AbyssalCraft.dreadbrick, 0, 2);
		world.setBlock(i - 17, j + 10, k - 38, AbyssalCraft.dreadbrick, 0, 2);
		world.setBlock(i - 17, j + 10, k - 37, AbyssalCraft.dreadbrick, 0, 2);
		world.setBlock(i - 17, j + 10, k - 36, AbyssalCraft.dreadbrick, 0, 2);
		world.setBlock(i - 17, j + 10, k - 35, AbyssalCraft.dreadbrick, 0, 2);
		world.setBlock(i - 17, j + 11, k - 41, AbyssalCraft.dreadbrick, 0, 2);
		world.setBlock(i - 17, j + 11, k - 40, AbyssalCraft.dreadbrickfence, 0, 2);
		world.setBlock(i - 17, j + 11, k - 39, AbyssalCraft.dreadbrickfence, 0, 2);
		world.setBlock(i - 17, j + 11, k - 38, AbyssalCraft.dreadbrickfence, 0, 2);
		world.setBlock(i - 17, j + 11, k - 37, AbyssalCraft.dreadbrickfence, 0, 2);
		world.setBlock(i - 17, j + 11, k - 36, AbyssalCraft.dreadbrick, 0, 2);
		world.setBlock(i - 17, j + 12, k - 41, AbyssalCraft.dreadbrick, 0, 2);
		world.setBlock(i - 17, j + 12, k - 40, AbyssalCraft.dreadbrick, 0, 2);
		world.setBlock(i - 17, j + 12, k - 39, AbyssalCraft.dreadbrick, 0, 2);
		world.setBlock(i - 17, j + 12, k - 38, AbyssalCraft.dreadbrick, 0, 2);
		world.setBlock(i - 17, j + 12, k - 37, AbyssalCraft.dreadbrick, 0, 2);
		world.setBlock(i - 17, j + 12, k - 36, AbyssalCraft.dreadbrick, 0, 2);
		world.setBlock(i - 17, j + 13, k - 41, AbyssalCraft.dreadbrick, 0, 2);
		world.setBlock(i - 17, j + 13, k - 40, AbyssalCraft.dreadbrickfence, 0, 2);
		world.setBlock(i - 17, j + 13, k - 39, AbyssalCraft.dreadbrickfence, 0, 2);
		world.setBlock(i - 17, j + 13, k - 38, AbyssalCraft.dreadbrickfence, 0, 2);
		world.setBlock(i - 17, j + 13, k - 37, AbyssalCraft.dreadbrickfence, 0, 2);
		world.setBlock(i - 17, j + 13, k - 36, AbyssalCraft.dreadbrick, 0, 2);
		world.setBlock(i - 17, j + 14, k - 41, AbyssalCraft.dreadbrick, 0, 2);
		world.setBlock(i - 17, j + 14, k - 40, AbyssalCraft.dreadbrick, 0, 2);
		world.setBlock(i - 17, j + 14, k - 39, AbyssalCraft.dreadbrick, 0, 2);
		world.setBlock(i - 17, j + 14, k - 38, AbyssalCraft.dreadbrick, 0, 2);
		world.setBlock(i - 17, j + 14, k - 37, AbyssalCraft.dreadbrick, 0, 2);
		world.setBlock(i - 17, j + 14, k - 36, AbyssalCraft.dreadbrick, 0, 2);
		world.setBlock(i - 16, j + 3, k - 40, AbyssalCraft.dreadbrick, 0, 2);
		world.setBlock(i - 16, j + 3, k - 39, AbyssalCraft.dreadbrick, 0, 2);
		world.setBlock(i - 16, j + 3, k - 38, AbyssalCraft.dreadbrick, 0, 2);
		world.setBlock(i - 16, j + 3, k - 37, AbyssalCraft.dreadbrick, 0, 2);
		world.setBlock(i - 16, j + 3, k - 29, AbyssalCraft.dreadbrick, 0, 2);
		world.setBlock(i - 16, j + 3, k - 28, AbyssalCraft.dreadbrick, 0, 2);
		world.setBlock(i - 16, j + 3, k - 27, AbyssalCraft.dreadbrick, 0, 2);
		world.setBlock(i - 16, j + 3, k - 26, AbyssalCraft.dreadbrick, 0, 2);
		world.setBlock(i - 16, j + 3, k - 25, AbyssalCraft.dreadbrick, 0, 2);
		world.setBlock(i - 16, j + 3, k - 24, AbyssalCraft.dreadbrick, 0, 2);
		world.setBlock(i - 16, j + 3, k - 23, AbyssalCraft.dreadbrick, 0, 2);
		world.setBlock(i - 16, j + 4, k - 41, AbyssalCraft.dreadbrick, 0, 2);
		world.setBlock(i - 16, j + 4, k - 36, AbyssalCraft.dreadbrick, 0, 2);
		world.setBlock(i - 16, j + 4, k - 30, AbyssalCraft.dreadbrick, 0, 2);
		world.setBlock(i - 16, j + 4, k - 22, AbyssalCraft.dreadbrick, 0, 2);
		world.setBlock(i - 16, j + 5, k - 41, AbyssalCraft.dreadbrick, 0, 2);
		world.setBlock(i - 16, j + 5, k - 36, AbyssalCraft.dreadbrick, 0, 2);
		world.setBlock(i - 16, j + 5, k - 30, AbyssalCraft.dreadbrick, 0, 2);
		world.setBlock(i - 16, j + 5, k - 22, AbyssalCraft.dreadbrick, 0, 2);
		world.setBlock(i - 16, j + 6, k - 41, AbyssalCraft.dreadbrick, 0, 2);
		world.setBlock(i - 16, j + 6, k - 36, AbyssalCraft.dreadbrick, 0, 2);
		world.setBlock(i - 16, j + 6, k - 30, AbyssalCraft.dreadbrick, 0, 2);
		world.setBlock(i - 16, j + 6, k - 22, AbyssalCraft.dreadbrick, 0, 2);
		world.setBlock(i - 16, j + 7, k - 41, AbyssalCraft.dreadbrick, 0, 2);
		world.setBlock(i - 16, j + 7, k - 36, AbyssalCraft.dreadbrick, 0, 2);
		world.setBlock(i - 16, j + 7, k - 30, AbyssalCraft.dreadbrick, 0, 2);
		world.setBlock(i - 16, j + 7, k - 22, AbyssalCraft.dreadbrick, 0, 2);
		world.setBlock(i - 16, j + 8, k - 41, AbyssalCraft.dreadbrick, 0, 2);
		world.setBlock(i - 16, j + 8, k - 36, AbyssalCraft.dreadbrick, 0, 2);
		world.setBlock(i - 16, j + 8, k - 30, AbyssalCraft.dreadbrick, 0, 2);
		world.setBlock(i - 16, j + 8, k - 29, AbyssalCraft.dreadbrick, 0, 2);
		world.setBlock(i - 16, j + 8, k - 28, AbyssalCraft.dreadbrick, 0, 2);
		world.setBlock(i - 16, j + 8, k - 27, AbyssalCraft.dreadbrick, 0, 2);
		world.setBlock(i - 16, j + 8, k - 26, AbyssalCraft.dreadbrick, 0, 2);
		world.setBlock(i - 16, j + 8, k - 25, AbyssalCraft.dreadbrick, 0, 2);
		world.setBlock(i - 16, j + 8, k - 24, AbyssalCraft.dreadbrick, 0, 2);
		world.setBlock(i - 16, j + 8, k - 23, AbyssalCraft.dreadbrick, 0, 2);
		world.setBlock(i - 16, j + 8, k - 22, AbyssalCraft.dreadbrick, 0, 2);
		world.setBlock(i - 16, j + 9, k - 41, AbyssalCraft.dreadbrick, 0, 2);
		world.setBlock(i - 16, j + 9, k - 36, AbyssalCraft.dreadbrick, 0, 2);
		world.setBlock(i - 16, j + 10, k - 41, AbyssalCraft.dreadbrick, 0, 2);
		world.setBlock(i - 16, j + 10, k - 36, AbyssalCraft.dreadbrick, 0, 2);
		world.setBlock(i - 16, j + 11, k - 41, AbyssalCraft.dreadbrick, 0, 2);
		world.setBlock(i - 16, j + 11, k - 36, AbyssalCraft.dreadbrick, 0, 2);
		world.setBlock(i - 16, j + 12, k - 41, AbyssalCraft.dreadbrick, 0, 2);
		world.setBlock(i - 16, j + 12, k - 36, AbyssalCraft.dreadbrick, 0, 2);
		world.setBlock(i - 16, j + 13, k - 41, AbyssalCraft.dreadbrick, 0, 2);
		world.setBlock(i - 16, j + 13, k - 36, AbyssalCraft.dreadbrick, 0, 2);
		world.setBlock(i - 16, j + 14, k - 41, AbyssalCraft.dreadbrick, 0, 2);
		world.setBlock(i - 16, j + 14, k - 40, AbyssalCraft.dreadbrick, 0, 2);
		world.setBlock(i - 16, j + 14, k - 39, AbyssalCraft.dreadbrick, 0, 2);
		world.setBlock(i - 16, j + 14, k - 38, AbyssalCraft.dreadbrick, 0, 2);
		world.setBlock(i - 16, j + 14, k - 37, AbyssalCraft.dreadbrick, 0, 2);
		world.setBlock(i - 16, j + 14, k - 36, AbyssalCraft.dreadbrick, 0, 2);
		world.setBlock(i - 15, j + 3, k - 40, AbyssalCraft.dreadbrick, 0, 2);
		world.setBlock(i - 15, j + 3, k - 39, AbyssalCraft.dreadbrick, 0, 2);
		world.setBlock(i - 15, j + 3, k - 38, AbyssalCraft.dreadbrick, 0, 2);
		world.setBlock(i - 15, j + 3, k - 37, AbyssalCraft.dreadbrick, 0, 2);
		world.setBlock(i - 15, j + 3, k - 29, AbyssalCraft.dreadbrick, 0, 2);
		world.setBlock(i - 15, j + 3, k - 28, AbyssalCraft.dreadbrick, 0, 2);
		world.setBlock(i - 15, j + 3, k - 27, AbyssalCraft.dreadbrick, 0, 2);
		world.setBlock(i - 15, j + 3, k - 26, AbyssalCraft.dreadbrick, 0, 2);
		world.setBlock(i - 15, j + 3, k - 25, AbyssalCraft.dreadbrick, 0, 2);
		world.setBlock(i - 15, j + 3, k - 24, AbyssalCraft.dreadbrick, 0, 2);
		world.setBlock(i - 15, j + 3, k - 23, AbyssalCraft.dreadbrick, 0, 2);
		world.setBlock(i - 15, j + 4, k - 41, AbyssalCraft.dreadbrick, 0, 2);
		world.setBlock(i - 15, j + 4, k - 36, AbyssalCraft.dreadbrick, 0, 2);
		world.setBlock(i - 15, j + 4, k - 30, AbyssalCraft.dreadbrick, 0, 2);
		world.setBlock(i - 15, j + 4, k - 22, AbyssalCraft.dreadbrick, 0, 2);
		world.setBlock(i - 15, j + 5, k - 41, AbyssalCraft.dreadbrick, 0, 2);
		world.setBlock(i - 15, j + 5, k - 36, AbyssalCraft.dreadbrick, 0, 2);
		world.setBlock(i - 15, j + 5, k - 30, AbyssalCraft.dreadbrick, 0, 2);
		world.setBlock(i - 15, j + 5, k - 22, AbyssalCraft.dreadbrick, 0, 2);
		world.setBlock(i - 15, j + 6, k - 41, AbyssalCraft.dreadbrick, 0, 2);
		world.setBlock(i - 15, j + 6, k - 36, AbyssalCraft.dreadbrick, 0, 2);
		world.setBlock(i - 15, j + 6, k - 30, AbyssalCraft.dreadbrick, 0, 2);
		world.setBlock(i - 15, j + 6, k - 22, AbyssalCraft.dreadbrick, 0, 2);
		world.setBlock(i - 15, j + 7, k - 41, AbyssalCraft.dreadbrick, 0, 2);
		world.setBlock(i - 15, j + 7, k - 36, AbyssalCraft.dreadbrick, 0, 2);
		world.setBlock(i - 15, j + 7, k - 30, AbyssalCraft.dreadbrick, 0, 2);
		world.setBlock(i - 15, j + 7, k - 22, AbyssalCraft.dreadbrick, 0, 2);
		world.setBlock(i - 15, j + 8, k - 41, AbyssalCraft.dreadbrick, 0, 2);
		world.setBlock(i - 15, j + 8, k - 36, AbyssalCraft.dreadbrick, 0, 2);
		world.setBlock(i - 15, j + 8, k - 30, AbyssalCraft.dreadbrick, 0, 2);
		world.setBlock(i - 15, j + 8, k - 29, AbyssalCraft.dreadbrick, 0, 2);
		world.setBlock(i - 15, j + 8, k - 28, AbyssalCraft.dreadbrick, 0, 2);
		world.setBlock(i - 15, j + 8, k - 27, AbyssalCraft.dreadbrick, 0, 2);
		world.setBlock(i - 15, j + 8, k - 26, AbyssalCraft.dreadbrick, 0, 2);
		world.setBlock(i - 15, j + 8, k - 25, AbyssalCraft.dreadbrick, 0, 2);
		world.setBlock(i - 15, j + 8, k - 24, AbyssalCraft.dreadbrick, 0, 2);
		world.setBlock(i - 15, j + 8, k - 23, AbyssalCraft.dreadbrick, 0, 2);
		world.setBlock(i - 15, j + 8, k - 22, AbyssalCraft.dreadbrick, 0, 2);
		world.setBlock(i - 15, j + 9, k - 41, AbyssalCraft.dreadbrick, 0, 2);
		world.setBlock(i - 15, j + 9, k - 36, AbyssalCraft.dreadbrick, 0, 2);
		world.setBlock(i - 15, j + 10, k - 41, AbyssalCraft.dreadbrick, 0, 2);
		world.setBlock(i - 15, j + 10, k - 36, AbyssalCraft.dreadbrick, 0, 2);
		world.setBlock(i - 15, j + 11, k - 41, AbyssalCraft.dreadbrick, 0, 2);
		world.setBlock(i - 15, j + 11, k - 36, AbyssalCraft.dreadbrick, 0, 2);
		world.setBlock(i - 15, j + 12, k - 41, AbyssalCraft.dreadbrick, 0, 2);
		world.setBlock(i - 15, j + 12, k - 36, AbyssalCraft.dreadbrick, 0, 2);
		world.setBlock(i - 15, j + 13, k - 41, AbyssalCraft.dreadbrick, 0, 2);
		world.setBlock(i - 15, j + 13, k - 36, AbyssalCraft.dreadbrick, 0, 2);
		world.setBlock(i - 15, j + 14, k - 41, AbyssalCraft.dreadbrick, 0, 2);
		world.setBlock(i - 15, j + 14, k - 40, AbyssalCraft.dreadbrick, 0, 2);
		world.setBlock(i - 15, j + 14, k - 39, AbyssalCraft.dreadbrick, 0, 2);
		world.setBlock(i - 15, j + 14, k - 38, AbyssalCraft.dreadbrick, 0, 2);
		world.setBlock(i - 15, j + 14, k - 37, AbyssalCraft.dreadbrick, 0, 2);
		world.setBlock(i - 15, j + 14, k - 36, AbyssalCraft.dreadbrick, 0, 2);
		world.setBlock(i - 14, j + 3, k - 40, AbyssalCraft.dreadbrick, 0, 2);
		world.setBlock(i - 14, j + 3, k - 39, AbyssalCraft.dreadbrick, 0, 2);
		world.setBlock(i - 14, j + 3, k - 38, AbyssalCraft.dreadbrick, 0, 2);
		world.setBlock(i - 14, j + 3, k - 37, AbyssalCraft.dreadbrick, 0, 2);
		world.setBlock(i - 14, j + 3, k - 29, AbyssalCraft.dreadbrick, 0, 2);
		world.setBlock(i - 14, j + 3, k - 28, AbyssalCraft.dreadbrick, 0, 2);
		world.setBlock(i - 14, j + 3, k - 27, AbyssalCraft.dreadbrick, 0, 2);
		world.setBlock(i - 14, j + 3, k - 26, AbyssalCraft.dreadbrick, 0, 2);
		world.setBlock(i - 14, j + 3, k - 25, AbyssalCraft.dreadbrick, 0, 2);
		world.setBlock(i - 14, j + 3, k - 24, AbyssalCraft.dreadbrick, 0, 2);
		world.setBlock(i - 14, j + 3, k - 23, AbyssalCraft.dreadbrick, 0, 2);
		world.setBlock(i - 14, j + 4, k - 41, AbyssalCraft.dreadbrick, 0, 2);
		world.setBlock(i - 14, j + 4, k - 39, AbyssalCraft.dreadguardspawner, 0, 2);
		world.setBlock(i - 14, j + 4, k - 36, AbyssalCraft.dreadbrick, 0, 2);
		world.setBlock(i - 14, j + 4, k - 30, AbyssalCraft.dreadbrick, 0, 2);
		world.setBlock(i - 14, j + 4, k - 29, AbyssalCraft.dreadbrick, 0, 2);
		world.setBlock(i - 14, j + 4, k - 28, AbyssalCraft.dreadbrick, 0, 2);
		world.setBlock(i - 14, j + 4, k - 27, AbyssalCraft.dreadbrick, 0, 2);
		world.setBlock(i - 14, j + 4, k - 26, AbyssalCraft.dreadbrickslab1, 5, 2);
		world.setBlock(i - 14, j + 4, k - 25, AbyssalCraft.dreadbrick, 0, 2);
		world.setBlock(i - 14, j + 4, k - 24, AbyssalCraft.dreadbrick, 0, 2);
		world.setBlock(i - 14, j + 4, k - 23, AbyssalCraft.dreadbrick, 0, 2);
		world.setBlock(i - 14, j + 4, k - 22, AbyssalCraft.dreadbrick, 0, 2);
		world.setBlock(i - 14, j + 5, k - 41, AbyssalCraft.dreadbrick, 0, 2);
		world.setBlock(i - 14, j + 5, k - 36, AbyssalCraft.dreadbrick, 0, 2);
		world.setBlock(i - 14, j + 5, k - 30, AbyssalCraft.dreadbrick, 0, 2);
		world.setBlock(i - 14, j + 5, k - 22, AbyssalCraft.dreadbrick, 0, 2);
		world.setBlock(i - 14, j + 6, k - 41, AbyssalCraft.dreadbrick, 0, 2);
		world.setBlock(i - 14, j + 6, k - 36, AbyssalCraft.dreadbrick, 0, 2);
		world.setBlock(i - 14, j + 6, k - 30, AbyssalCraft.dreadbrick, 0, 2);
		world.setBlock(i - 14, j + 6, k - 22, AbyssalCraft.dreadbrick, 0, 2);
		world.setBlock(i - 14, j + 7, k - 41, AbyssalCraft.dreadbrick, 0, 2);
		world.setBlock(i - 14, j + 7, k - 36, AbyssalCraft.dreadbrick, 0, 2);
		world.setBlock(i - 14, j + 7, k - 30, AbyssalCraft.dreadbrick, 0, 2);
		world.setBlock(i - 14, j + 7, k - 22, AbyssalCraft.dreadbrick, 0, 2);
		world.setBlock(i - 14, j + 8, k - 41, AbyssalCraft.dreadbrick, 0, 2);
		world.setBlock(i - 14, j + 8, k - 36, AbyssalCraft.dreadbrick, 0, 2);
		world.setBlock(i - 14, j + 8, k - 30, AbyssalCraft.dreadbrick, 0, 2);
		world.setBlock(i - 14, j + 8, k - 29, AbyssalCraft.dreadbrick, 0, 2);
		world.setBlock(i - 14, j + 8, k - 28, AbyssalCraft.dreadbrick, 0, 2);
		world.setBlock(i - 14, j + 8, k - 27, AbyssalCraft.dreadbrick, 0, 2);
		world.setBlock(i - 14, j + 8, k - 26, AbyssalCraft.dreadbrick, 0, 2);
		world.setBlock(i - 14, j + 8, k - 25, AbyssalCraft.dreadbrick, 0, 2);
		world.setBlock(i - 14, j + 8, k - 24, AbyssalCraft.dreadbrick, 0, 2);
		world.setBlock(i - 14, j + 8, k - 23, AbyssalCraft.dreadbrick, 0, 2);
		world.setBlock(i - 14, j + 8, k - 22, AbyssalCraft.dreadbrick, 0, 2);
		world.setBlock(i - 14, j + 9, k - 41, AbyssalCraft.dreadbrick, 0, 2);
		world.setBlock(i - 14, j + 9, k - 36, AbyssalCraft.dreadbrick, 0, 2);
		world.setBlock(i - 14, j + 10, k - 41, AbyssalCraft.dreadbrick, 0, 2);
		world.setBlock(i - 14, j + 10, k - 36, AbyssalCraft.dreadbrick, 0, 2);
		world.setBlock(i - 14, j + 11, k - 41, AbyssalCraft.dreadbrick, 0, 2);
		world.setBlock(i - 14, j + 11, k - 36, AbyssalCraft.dreadbrick, 0, 2);
		world.setBlock(i - 14, j + 12, k - 41, AbyssalCraft.dreadbrick, 0, 2);
		world.setBlock(i - 14, j + 12, k - 36, AbyssalCraft.dreadbrick, 0, 2);
		world.setBlock(i - 14, j + 13, k - 41, AbyssalCraft.dreadbrick, 0, 2);
		world.setBlock(i - 14, j + 13, k - 36, AbyssalCraft.dreadbrick, 0, 2);
		world.setBlock(i - 14, j + 14, k - 41, AbyssalCraft.dreadbrick, 0, 2);
		world.setBlock(i - 14, j + 14, k - 40, AbyssalCraft.dreadbrick, 0, 2);
		world.setBlock(i - 14, j + 14, k - 39, AbyssalCraft.dreadbrick, 0, 2);
		world.setBlock(i - 14, j + 14, k - 38, AbyssalCraft.dreadbrick, 0, 2);
		world.setBlock(i - 14, j + 14, k - 37, AbyssalCraft.dreadbrick, 0, 2);
		world.setBlock(i - 14, j + 14, k - 36, AbyssalCraft.dreadbrick, 0, 2);
		world.setBlock(i - 13, j + 3, k - 40, AbyssalCraft.dreadbrick, 0, 2);
		world.setBlock(i - 13, j + 3, k - 39, AbyssalCraft.dreadbrick, 0, 2);
		world.setBlock(i - 13, j + 3, k - 38, AbyssalCraft.dreadbrick, 0, 2);
		world.setBlock(i - 13, j + 3, k - 37, AbyssalCraft.dreadbrick, 0, 2);
		world.setBlock(i - 13, j + 3, k - 29, AbyssalCraft.dreadbrick, 0, 2);
		world.setBlock(i - 13, j + 3, k - 28, AbyssalCraft.dreadbrick, 0, 2);
		world.setBlock(i - 13, j + 3, k - 27, AbyssalCraft.dreadbrick, 0, 2);
		world.setBlock(i - 13, j + 3, k - 26, AbyssalCraft.dreadbrick, 0, 2);
		world.setBlock(i - 13, j + 3, k - 25, AbyssalCraft.dreadbrick, 0, 2);
		world.setBlock(i - 13, j + 3, k - 24, AbyssalCraft.dreadbrick, 0, 2);
		world.setBlock(i - 13, j + 3, k - 23, AbyssalCraft.dreadbrick, 0, 2);
		world.setBlock(i - 13, j + 4, k - 41, AbyssalCraft.dreadbrick, 0, 2);
		world.setBlock(i - 13, j + 4, k - 36, AbyssalCraft.dreadbrick, 0, 2);
		world.setBlock(i - 13, j + 4, k - 30, AbyssalCraft.dreadbrick, 0, 2);
		world.setBlock(i - 13, j + 4, k - 29, Blocks.lava, 0, 2);
		world.setBlock(i - 13, j + 4, k - 28, Blocks.lava, 0, 2);
		world.setBlock(i - 13, j + 4, k - 27, AbyssalCraft.dreadbrick, 0, 2);
		world.setBlock(i - 13, j + 4, k - 26, AbyssalCraft.dreadbrick, 0, 2);
		world.setBlock(i - 13, j + 4, k - 25, AbyssalCraft.dreadbrick, 0, 2);
		world.setBlock(i - 13, j + 4, k - 24, Blocks.lava, 0, 2);
		world.setBlock(i - 13, j + 4, k - 23, Blocks.lava, 0, 2);
		world.setBlock(i - 13, j + 4, k - 22, AbyssalCraft.dreadbrick, 0, 2);
		world.setBlock(i - 13, j + 5, k - 41, AbyssalCraft.dreadbrick, 0, 2);
		world.setBlock(i - 13, j + 5, k - 36, AbyssalCraft.dreadbrick, 0, 2);
		world.setBlock(i - 13, j + 5, k - 30, AbyssalCraft.dreadbrick, 0, 2);
		world.setBlock(i - 13, j + 5, k - 27, AbyssalCraft.dreadbrick, 0, 2);
		world.setBlock(i - 13, j + 5, k - 26, AbyssalCraft.crystallizer, 4, 2);
		world.setBlock(i - 13, j + 5, k - 25, AbyssalCraft.dreadbrick, 0, 2);
		world.setBlock(i - 13, j + 5, k - 22, AbyssalCraft.dreadbrick, 0, 2);
		world.setBlock(i - 13, j + 6, k - 41, AbyssalCraft.dreadbrick, 0, 2);
		world.setBlock(i - 13, j + 6, k - 36, AbyssalCraft.dreadbrick, 0, 2);
		world.setBlock(i - 13, j + 6, k - 30, AbyssalCraft.dreadbrick, 0, 2);
		world.setBlock(i - 13, j + 6, k - 27, AbyssalCraft.dreadbrick, 0, 2);
		world.setBlock(i - 13, j + 6, k - 26, AbyssalCraft.dreadbrick, 0, 2);
		world.setBlock(i - 13, j + 6, k - 25, AbyssalCraft.dreadbrick, 0, 2);
		world.setBlock(i - 13, j + 6, k - 22, AbyssalCraft.dreadbrick, 0, 2);
		world.setBlock(i - 13, j + 7, k - 41, AbyssalCraft.dreadbrick, 0, 2);
		world.setBlock(i - 13, j + 7, k - 36, AbyssalCraft.dreadbrick, 0, 2);
		world.setBlock(i - 13, j + 7, k - 30, AbyssalCraft.dreadbrick, 0, 2);
		world.setBlock(i - 13, j + 7, k - 22, AbyssalCraft.dreadbrick, 0, 2);
		world.setBlock(i - 13, j + 8, k - 41, AbyssalCraft.dreadbrick, 0, 2);
		world.setBlock(i - 13, j + 8, k - 36, AbyssalCraft.dreadbrick, 0, 2);
		world.setBlock(i - 13, j + 8, k - 30, AbyssalCraft.dreadbrick, 0, 2);
		world.setBlock(i - 13, j + 8, k - 29, AbyssalCraft.dreadbrick, 0, 2);
		world.setBlock(i - 13, j + 8, k - 28, AbyssalCraft.dreadbrick, 0, 2);
		world.setBlock(i - 13, j + 8, k - 27, AbyssalCraft.dreadbrick, 0, 2);
		world.setBlock(i - 13, j + 8, k - 26, AbyssalCraft.dreadbrick, 0, 2);
		world.setBlock(i - 13, j + 8, k - 25, AbyssalCraft.dreadbrick, 0, 2);
		world.setBlock(i - 13, j + 8, k - 24, AbyssalCraft.dreadbrick, 0, 2);
		world.setBlock(i - 13, j + 8, k - 23, AbyssalCraft.dreadbrick, 0, 2);
		world.setBlock(i - 13, j + 8, k - 22, AbyssalCraft.dreadbrick, 0, 2);
		world.setBlock(i - 13, j + 9, k - 41, AbyssalCraft.dreadbrick, 0, 2);
		world.setBlock(i - 13, j + 9, k - 36, AbyssalCraft.dreadbrick, 0, 2);
		world.setBlock(i - 13, j + 10, k - 41, AbyssalCraft.dreadbrick, 0, 2);
		world.setBlock(i - 13, j + 10, k - 36, AbyssalCraft.dreadbrick, 0, 2);
		world.setBlock(i - 13, j + 11, k - 41, AbyssalCraft.dreadbrick, 0, 2);
		world.setBlock(i - 13, j + 11, k - 36, AbyssalCraft.dreadbrick, 0, 2);
		world.setBlock(i - 13, j + 12, k - 41, AbyssalCraft.dreadbrick, 0, 2);
		world.setBlock(i - 13, j + 12, k - 36, AbyssalCraft.dreadbrick, 0, 2);
		world.setBlock(i - 13, j + 13, k - 41, AbyssalCraft.dreadbrick, 0, 2);
		world.setBlock(i - 13, j + 13, k - 36, AbyssalCraft.dreadbrick, 0, 2);
		world.setBlock(i - 13, j + 14, k - 41, AbyssalCraft.dreadbrick, 0, 2);
		world.setBlock(i - 13, j + 14, k - 40, AbyssalCraft.dreadbrick, 0, 2);
		world.setBlock(i - 13, j + 14, k - 39, AbyssalCraft.dreadbrick, 0, 2);
		world.setBlock(i - 13, j + 14, k - 38, AbyssalCraft.dreadbrick, 0, 2);
		world.setBlock(i - 13, j + 14, k - 37, AbyssalCraft.dreadbrick, 0, 2);
		world.setBlock(i - 13, j + 14, k - 36, AbyssalCraft.dreadbrick, 0, 2);
		world.setBlock(i - 12, j + 3, k - 40, AbyssalCraft.dreadbrick, 0, 2);
		world.setBlock(i - 12, j + 3, k - 39, AbyssalCraft.dreadbrick, 0, 2);
		world.setBlock(i - 12, j + 3, k - 38, AbyssalCraft.dreadbrick, 0, 2);
		world.setBlock(i - 12, j + 3, k - 37, AbyssalCraft.dreadbrick, 0, 2);
		world.setBlock(i - 12, j + 4, k - 41, AbyssalCraft.dreadbrick, 0, 2);
		world.setBlock(i - 12, j + 4, k - 36, AbyssalCraft.dreadbrick, 0, 2);
		world.setBlock(i - 12, j + 4, k - 30, AbyssalCraft.dreadbrick, 0, 2);
		world.setBlock(i - 12, j + 4, k - 29, AbyssalCraft.dreadbrick, 0, 2);
		world.setBlock(i - 12, j + 4, k - 28, AbyssalCraft.dreadbrick, 0, 2);
		world.setBlock(i - 12, j + 4, k - 27, AbyssalCraft.dreadbrick, 0, 2);
		world.setBlock(i - 12, j + 4, k - 26, AbyssalCraft.dreadbrick, 0, 2);
		world.setBlock(i - 12, j + 4, k - 25, AbyssalCraft.dreadbrick, 0, 2);
		world.setBlock(i - 12, j + 4, k - 24, AbyssalCraft.dreadbrick, 0, 2);
		world.setBlock(i - 12, j + 4, k - 23, AbyssalCraft.dreadbrick, 0, 2);
		world.setBlock(i - 12, j + 4, k - 22, AbyssalCraft.dreadbrick, 0, 2);
		world.setBlock(i - 12, j + 5, k - 41, AbyssalCraft.dreadbrick, 0, 2);
		world.setBlock(i - 12, j + 5, k - 36, AbyssalCraft.dreadbrick, 0, 2);
		world.setBlock(i - 12, j + 5, k - 30, AbyssalCraft.dreadbrick, 0, 2);
		world.setBlock(i - 12, j + 5, k - 29, AbyssalCraft.dreadbrick, 0, 2);
		world.setBlock(i - 12, j + 5, k - 28, AbyssalCraft.dreadbrick, 0, 2);
		world.setBlock(i - 12, j + 5, k - 27, AbyssalCraft.dreadbrick, 0, 2);
		world.setBlock(i - 12, j + 5, k - 26, AbyssalCraft.dreadbrick, 0, 2);
		world.setBlock(i - 12, j + 5, k - 25, AbyssalCraft.dreadbrick, 0, 2);
		world.setBlock(i - 12, j + 5, k - 24, AbyssalCraft.dreadbrick, 0, 2);
		world.setBlock(i - 12, j + 5, k - 23, AbyssalCraft.dreadbrick, 0, 2);
		world.setBlock(i - 12, j + 5, k - 22, AbyssalCraft.dreadbrick, 0, 2);
		world.setBlock(i - 12, j + 6, k - 41, AbyssalCraft.dreadbrick, 0, 2);
		world.setBlock(i - 12, j + 6, k - 36, AbyssalCraft.dreadbrick, 0, 2);
		world.setBlock(i - 12, j + 6, k - 30, AbyssalCraft.dreadbrick, 0, 2);
		world.setBlock(i - 12, j + 6, k - 29, AbyssalCraft.dreadbrick, 0, 2);
		world.setBlock(i - 12, j + 6, k - 28, AbyssalCraft.dreadbrick, 0, 2);
		world.setBlock(i - 12, j + 6, k - 27, AbyssalCraft.dreadbrick, 0, 2);
		world.setBlock(i - 12, j + 6, k - 26, AbyssalCraft.dreadbrick, 0, 2);
		world.setBlock(i - 12, j + 6, k - 25, AbyssalCraft.dreadbrick, 0, 2);
		world.setBlock(i - 12, j + 6, k - 24, AbyssalCraft.dreadbrick, 0, 2);
		world.setBlock(i - 12, j + 6, k - 23, AbyssalCraft.dreadbrick, 0, 2);
		world.setBlock(i - 12, j + 6, k - 22, AbyssalCraft.dreadbrick, 0, 2);
		world.setBlock(i - 12, j + 7, k - 41, AbyssalCraft.dreadbrick, 0, 2);
		world.setBlock(i - 12, j + 7, k - 36, AbyssalCraft.dreadbrick, 0, 2);
		world.setBlock(i - 12, j + 7, k - 30, AbyssalCraft.dreadbrick, 0, 2);
		world.setBlock(i - 12, j + 7, k - 29, AbyssalCraft.dreadbrick, 0, 2);
		world.setBlock(i - 12, j + 7, k - 28, AbyssalCraft.dreadbrick, 0, 2);
		world.setBlock(i - 12, j + 7, k - 27, AbyssalCraft.dreadbrick, 0, 2);
		world.setBlock(i - 12, j + 7, k - 26, AbyssalCraft.dreadbrick, 0, 2);
		world.setBlock(i - 12, j + 7, k - 25, AbyssalCraft.dreadbrick, 0, 2);
		world.setBlock(i - 12, j + 7, k - 24, AbyssalCraft.dreadbrick, 0, 2);
		world.setBlock(i - 12, j + 7, k - 23, AbyssalCraft.dreadbrick, 0, 2);
		world.setBlock(i - 12, j + 7, k - 22, AbyssalCraft.dreadbrick, 0, 2);
		world.setBlock(i - 12, j + 8, k - 41, AbyssalCraft.dreadbrick, 0, 2);
		world.setBlock(i - 12, j + 8, k - 36, AbyssalCraft.dreadbrick, 0, 2);
		world.setBlock(i - 12, j + 8, k - 30, AbyssalCraft.dreadbrick, 0, 2);
		world.setBlock(i - 12, j + 8, k - 29, AbyssalCraft.dreadbrick, 0, 2);
		world.setBlock(i - 12, j + 8, k - 28, AbyssalCraft.dreadbrick, 0, 2);
		world.setBlock(i - 12, j + 8, k - 27, AbyssalCraft.dreadbrick, 0, 2);
		world.setBlock(i - 12, j + 8, k - 26, AbyssalCraft.dreadbrick, 0, 2);
		world.setBlock(i - 12, j + 8, k - 25, AbyssalCraft.dreadbrick, 0, 2);
		world.setBlock(i - 12, j + 8, k - 24, AbyssalCraft.dreadbrick, 0, 2);
		world.setBlock(i - 12, j + 8, k - 23, AbyssalCraft.dreadbrick, 0, 2);
		world.setBlock(i - 12, j + 8, k - 22, AbyssalCraft.dreadbrick, 0, 2);
		world.setBlock(i - 12, j + 9, k - 41, AbyssalCraft.dreadbrick, 0, 2);
		world.setBlock(i - 12, j + 9, k - 36, AbyssalCraft.dreadbrick, 0, 2);
		world.setBlock(i - 12, j + 10, k - 41, AbyssalCraft.dreadbrick, 0, 2);
		world.setBlock(i - 12, j + 10, k - 36, AbyssalCraft.dreadbrick, 0, 2);
		world.setBlock(i - 12, j + 11, k - 41, AbyssalCraft.dreadbrick, 0, 2);
		world.setBlock(i - 12, j + 11, k - 36, AbyssalCraft.dreadbrick, 0, 2);
		world.setBlock(i - 12, j + 12, k - 41, AbyssalCraft.dreadbrick, 0, 2);
		world.setBlock(i - 12, j + 12, k - 36, AbyssalCraft.dreadbrick, 0, 2);
		world.setBlock(i - 12, j + 13, k - 41, AbyssalCraft.dreadbrick, 0, 2);
		world.setBlock(i - 12, j + 13, k - 36, AbyssalCraft.dreadbrick, 0, 2);
		world.setBlock(i - 12, j + 14, k - 41, AbyssalCraft.dreadbrick, 0, 2);
		world.setBlock(i - 12, j + 14, k - 40, AbyssalCraft.dreadbrick, 0, 2);
		world.setBlock(i - 12, j + 14, k - 39, AbyssalCraft.dreadbrick, 0, 2);
		world.setBlock(i - 12, j + 14, k - 38, AbyssalCraft.dreadbrick, 0, 2);
		world.setBlock(i - 12, j + 14, k - 37, AbyssalCraft.dreadbrick, 0, 2);
		world.setBlock(i - 12, j + 14, k - 36, AbyssalCraft.dreadbrick, 0, 2);
		world.setBlock(i - 11, j + 3, k - 40, AbyssalCraft.dreadbrick, 0, 2);
		world.setBlock(i - 11, j + 3, k - 39, AbyssalCraft.dreadbrick, 0, 2);
		world.setBlock(i - 11, j + 3, k - 38, AbyssalCraft.dreadbrick, 0, 2);
		world.setBlock(i - 11, j + 3, k - 37, AbyssalCraft.dreadbrick, 0, 2);
		world.setBlock(i - 11, j + 4, k - 41, AbyssalCraft.dreadbrick, 0, 2);
		world.setBlock(i - 11, j + 4, k - 36, AbyssalCraft.dreadbrick, 0, 2);
		world.setBlock(i - 11, j + 5, k - 41, AbyssalCraft.dreadbrick, 0, 2);
		world.setBlock(i - 11, j + 5, k - 36, AbyssalCraft.dreadbrick, 0, 2);
		world.setBlock(i - 11, j + 6, k - 41, AbyssalCraft.dreadbrick, 0, 2);
		world.setBlock(i - 11, j + 6, k - 36, AbyssalCraft.dreadbrick, 0, 2);
		world.setBlock(i - 11, j + 7, k - 41, AbyssalCraft.dreadbrick, 0, 2);
		world.setBlock(i - 11, j + 7, k - 36, AbyssalCraft.dreadbrick, 0, 2);
		world.setBlock(i - 11, j + 8, k - 41, AbyssalCraft.dreadbrick, 0, 2);
		world.setBlock(i - 11, j + 8, k - 36, AbyssalCraft.dreadbrick, 0, 2);
		world.setBlock(i - 11, j + 9, k - 41, AbyssalCraft.dreadbrick, 0, 2);
		world.setBlock(i - 11, j + 9, k - 36, AbyssalCraft.dreadbrick, 0, 2);
		world.setBlock(i - 11, j + 10, k - 41, AbyssalCraft.dreadbrick, 0, 2);
		world.setBlock(i - 11, j + 10, k - 36, AbyssalCraft.dreadbrick, 0, 2);
		world.setBlock(i - 11, j + 11, k - 41, AbyssalCraft.dreadbrick, 0, 2);
		world.setBlock(i - 11, j + 11, k - 36, AbyssalCraft.dreadbrick, 0, 2);
		world.setBlock(i - 11, j + 12, k - 41, AbyssalCraft.dreadbrick, 0, 2);
		world.setBlock(i - 11, j + 12, k - 36, AbyssalCraft.dreadbrick, 0, 2);
		world.setBlock(i - 11, j + 13, k - 41, AbyssalCraft.dreadbrick, 0, 2);
		world.setBlock(i - 11, j + 13, k - 36, AbyssalCraft.dreadbrick, 0, 2);
		world.setBlock(i - 11, j + 14, k - 41, AbyssalCraft.dreadbrick, 0, 2);
		world.setBlock(i - 11, j + 14, k - 40, AbyssalCraft.dreadbrick, 0, 2);
		world.setBlock(i - 11, j + 14, k - 39, AbyssalCraft.dreadbrick, 0, 2);
		world.setBlock(i - 11, j + 14, k - 38, AbyssalCraft.dreadbrick, 0, 2);
		world.setBlock(i - 11, j + 14, k - 37, AbyssalCraft.dreadbrick, 0, 2);
		world.setBlock(i - 11, j + 14, k - 36, AbyssalCraft.dreadbrick, 0, 2);
		world.setBlock(i - 10, j + 3, k - 40, AbyssalCraft.dreadbrick, 0, 2);
		world.setBlock(i - 10, j + 3, k - 39, AbyssalCraft.dreadbrick, 0, 2);
		world.setBlock(i - 10, j + 3, k - 38, AbyssalCraft.dreadbrick, 0, 2);
		world.setBlock(i - 10, j + 3, k - 37, AbyssalCraft.dreadbrick, 0, 2);
		world.setBlock(i - 10, j + 4, k - 41, AbyssalCraft.dreadbrick, 0, 2);
		world.setBlock(i - 10, j + 4, k - 36, AbyssalCraft.dreadbrick, 0, 2);
		world.setBlock(i - 10, j + 5, k - 41, AbyssalCraft.dreadbrick, 0, 2);
		world.setBlock(i - 10, j + 5, k - 36, AbyssalCraft.dreadbrick, 0, 2);
		world.setBlock(i - 10, j + 6, k - 41, AbyssalCraft.dreadbrick, 0, 2);
		world.setBlock(i - 10, j + 6, k - 36, AbyssalCraft.dreadbrick, 0, 2);
		world.setBlock(i - 10, j + 7, k - 41, AbyssalCraft.dreadbrick, 0, 2);
		world.setBlock(i - 10, j + 7, k - 36, AbyssalCraft.dreadbrick, 0, 2);
		world.setBlock(i - 10, j + 8, k - 41, AbyssalCraft.dreadbrick, 0, 2);
		world.setBlock(i - 10, j + 8, k - 36, AbyssalCraft.dreadbrick, 0, 2);
		world.setBlock(i - 10, j + 9, k - 41, AbyssalCraft.dreadbrick, 0, 2);
		world.setBlock(i - 10, j + 9, k - 36, AbyssalCraft.dreadbrick, 0, 2);
		world.setBlock(i - 10, j + 10, k - 41, AbyssalCraft.dreadbrick, 0, 2);
		world.setBlock(i - 10, j + 10, k - 36, AbyssalCraft.dreadbrick, 0, 2);
		world.setBlock(i - 10, j + 11, k - 41, AbyssalCraft.dreadbrick, 0, 2);
		world.setBlock(i - 10, j + 11, k - 36, AbyssalCraft.dreadbrick, 0, 2);
		world.setBlock(i - 10, j + 12, k - 41, AbyssalCraft.dreadbrick, 0, 2);
		world.setBlock(i - 10, j + 12, k - 36, AbyssalCraft.dreadbrick, 0, 2);
		world.setBlock(i - 10, j + 13, k - 41, AbyssalCraft.dreadbrick, 0, 2);
		world.setBlock(i - 10, j + 13, k - 36, AbyssalCraft.dreadbrick, 0, 2);
		world.setBlock(i - 10, j + 14, k - 41, AbyssalCraft.dreadbrick, 0, 2);
		world.setBlock(i - 10, j + 14, k - 40, AbyssalCraft.dreadbrick, 0, 2);
		world.setBlock(i - 10, j + 14, k - 39, AbyssalCraft.dreadbrick, 0, 2);
		world.setBlock(i - 10, j + 14, k - 38, AbyssalCraft.dreadbrick, 0, 2);
		world.setBlock(i - 10, j + 14, k - 37, AbyssalCraft.dreadbrick, 0, 2);
		world.setBlock(i - 10, j + 14, k - 36, AbyssalCraft.dreadbrick, 0, 2);
		world.setBlock(i - 9, j - 15, k - 63, AbyssalCraft.dreadstone, 0, 2);
		world.setBlock(i - 9, j - 14, k - 63, AbyssalCraft.dreadstone, 0, 2);
		world.setBlock(i - 9, j - 13, k - 63, AbyssalCraft.dreadstone, 0, 2);
		world.setBlock(i - 9, j - 12, k - 63, AbyssalCraft.dreadstone, 0, 2);
		world.setBlock(i - 9, j - 11, k - 63, AbyssalCraft.dreadstone, 0, 2);
		world.setBlock(i - 9, j - 10, k - 63, AbyssalCraft.dreadstone, 0, 2);
		world.setBlock(i - 9, j - 9, k - 63, AbyssalCraft.dreadstone, 0, 2);
		world.setBlock(i - 9, j - 8, k - 63, AbyssalCraft.dreadstone, 0, 2);
		world.setBlock(i - 9, j - 7, k - 63, AbyssalCraft.dreadstone, 0, 2);
		world.setBlock(i - 9, j + 3, k - 40, AbyssalCraft.dreadbrick, 0, 2);
		world.setBlock(i - 9, j + 3, k - 39, AbyssalCraft.dreadbrick, 0, 2);
		world.setBlock(i - 9, j + 3, k - 38, AbyssalCraft.dreadbrick, 0, 2);
		world.setBlock(i - 9, j + 3, k - 37, AbyssalCraft.dreadbrick, 0, 2);
		world.setBlock(i - 9, j + 4, k - 41, AbyssalCraft.dreadbrick, 0, 2);
		world.setBlock(i - 9, j + 4, k - 36, AbyssalCraft.dreadbrick, 0, 2);
		world.setBlock(i - 9, j + 5, k - 41, AbyssalCraft.dreadbrick, 0, 2);
		world.setBlock(i - 9, j + 5, k - 36, AbyssalCraft.dreadbrick, 0, 2);
		world.setBlock(i - 9, j + 6, k - 41, AbyssalCraft.dreadbrick, 0, 2);
		world.setBlock(i - 9, j + 6, k - 36, AbyssalCraft.dreadbrick, 0, 2);
		world.setBlock(i - 9, j + 7, k - 41, AbyssalCraft.dreadbrick, 0, 2);
		world.setBlock(i - 9, j + 7, k - 36, AbyssalCraft.dreadbrick, 0, 2);
		world.setBlock(i - 9, j + 8, k - 41, AbyssalCraft.dreadbrick, 0, 2);
		world.setBlock(i - 9, j + 8, k - 36, AbyssalCraft.dreadbrick, 0, 2);
		world.setBlock(i - 9, j + 9, k - 41, AbyssalCraft.dreadbrick, 0, 2);
		world.setBlock(i - 9, j + 9, k - 36, AbyssalCraft.dreadbrick, 0, 2);
		world.setBlock(i - 9, j + 10, k - 41, AbyssalCraft.dreadbrick, 0, 2);
		world.setBlock(i - 9, j + 10, k - 36, AbyssalCraft.dreadbrick, 0, 2);
		world.setBlock(i - 9, j + 11, k - 41, AbyssalCraft.dreadbrick, 0, 2);
		world.setBlock(i - 9, j + 11, k - 36, AbyssalCraft.dreadbrick, 0, 2);
		world.setBlock(i - 9, j + 12, k - 41, AbyssalCraft.dreadbrick, 0, 2);
		world.setBlock(i - 9, j + 12, k - 36, AbyssalCraft.dreadbrick, 0, 2);
		world.setBlock(i - 9, j + 13, k - 41, AbyssalCraft.dreadbrick, 0, 2);
		world.setBlock(i - 9, j + 13, k - 36, AbyssalCraft.dreadbrick, 0, 2);
		world.setBlock(i - 9, j + 14, k - 41, AbyssalCraft.dreadbrick, 0, 2);
		world.setBlock(i - 9, j + 14, k - 40, AbyssalCraft.dreadbrick, 0, 2);
		world.setBlock(i - 9, j + 14, k - 39, AbyssalCraft.dreadbrick, 0, 2);
		world.setBlock(i - 9, j + 14, k - 38, AbyssalCraft.dreadbrick, 0, 2);
		world.setBlock(i - 9, j + 14, k - 37, AbyssalCraft.dreadbrick, 0, 2);
		world.setBlock(i - 9, j + 14, k - 36, AbyssalCraft.dreadbrick, 0, 2);
		world.setBlock(i - 8, j - 15, k - 67, AbyssalCraft.dreadstone, 0, 2);
		world.setBlock(i - 8, j - 15, k - 65, AbyssalCraft.dreadstone, 0, 2);
		world.setBlock(i - 8, j - 15, k - 64, AbyssalCraft.dreadstone, 0, 2);
		world.setBlock(i - 8, j - 15, k - 63, AbyssalCraft.dreadstone, 0, 2);
		world.setBlock(i - 8, j - 15, k - 62, AbyssalCraft.dreadstone, 0, 2);
		world.setBlock(i - 8, j - 15, k - 61, AbyssalCraft.dreadstone, 0, 2);
		world.setBlock(i - 8, j - 14, k - 67, AbyssalCraft.dreadstone, 0, 2);
		world.setBlock(i - 8, j - 14, k - 65, AbyssalCraft.dreadstone, 0, 2);
		world.setBlock(i - 8, j - 14, k - 64, AbyssalCraft.dreadstone, 0, 2);
		world.setBlock(i - 8, j - 14, k - 63, AbyssalCraft.dreadstone, 0, 2);
		world.setBlock(i - 8, j - 14, k - 62, AbyssalCraft.dreadstone, 0, 2);
		world.setBlock(i - 8, j - 14, k - 61, AbyssalCraft.dreadstone, 0, 2);
		world.setBlock(i - 8, j - 13, k - 67, AbyssalCraft.dreadstone, 0, 2);
		world.setBlock(i - 8, j - 13, k - 65, AbyssalCraft.dreadstone, 0, 2);
		world.setBlock(i - 8, j - 13, k - 64, AbyssalCraft.dreadstone, 0, 2);
		world.setBlock(i - 8, j - 13, k - 63, AbyssalCraft.dreadstone, 0, 2);
		world.setBlock(i - 8, j - 13, k - 62, AbyssalCraft.dreadstone, 0, 2);
		world.setBlock(i - 8, j - 13, k - 61, AbyssalCraft.dreadstone, 0, 2);
		world.setBlock(i - 8, j - 12, k - 67, AbyssalCraft.dreadstone, 0, 2);
		world.setBlock(i - 8, j - 12, k - 65, AbyssalCraft.dreadstone, 0, 2);
		world.setBlock(i - 8, j - 12, k - 64, AbyssalCraft.dreadstone, 0, 2);
		world.setBlock(i - 8, j - 12, k - 62, AbyssalCraft.dreadstone, 0, 2);
		world.setBlock(i - 8, j - 12, k - 61, AbyssalCraft.dreadstone, 0, 2);
		world.setBlock(i - 8, j - 11, k - 67, AbyssalCraft.dreadstone, 0, 2);
		world.setBlock(i - 8, j - 11, k - 65, AbyssalCraft.dreadstone, 0, 2);
		world.setBlock(i - 8, j - 11, k - 64, AbyssalCraft.dreadstone, 0, 2);
		world.setBlock(i - 8, j - 11, k - 62, AbyssalCraft.dreadstone, 0, 2);
		world.setBlock(i - 8, j - 11, k - 61, AbyssalCraft.dreadstone, 0, 2);
		world.setBlock(i - 8, j - 10, k - 67, AbyssalCraft.dreadstone, 0, 2);
		world.setBlock(i - 8, j - 10, k - 65, AbyssalCraft.dreadstone, 0, 2);
		world.setBlock(i - 8, j - 10, k - 64, AbyssalCraft.dreadstone, 0, 2);
		world.setBlock(i - 8, j - 10, k - 62, AbyssalCraft.dreadstone, 0, 2);
		world.setBlock(i - 8, j - 10, k - 61, AbyssalCraft.dreadstone, 0, 2);
		world.setBlock(i - 8, j - 9, k - 67, AbyssalCraft.dreadstone, 0, 2);
		world.setBlock(i - 8, j - 9, k - 65, AbyssalCraft.dreadstone, 0, 2);
		world.setBlock(i - 8, j - 9, k - 64, AbyssalCraft.dreadstone, 0, 2);
		world.setBlock(i - 8, j - 9, k - 62, AbyssalCraft.dreadstone, 0, 2);
		world.setBlock(i - 8, j - 9, k - 61, AbyssalCraft.dreadstone, 0, 2);
		world.setBlock(i - 8, j - 8, k - 67, AbyssalCraft.dreadstone, 0, 2);
		world.setBlock(i - 8, j - 8, k - 65, AbyssalCraft.dreadstone, 0, 2);
		world.setBlock(i - 8, j - 8, k - 64, AbyssalCraft.dreadstone, 0, 2);
		world.setBlock(i - 8, j - 8, k - 63, AbyssalCraft.dreadstone, 0, 2);
		world.setBlock(i - 8, j - 8, k - 62, AbyssalCraft.dreadstone, 0, 2);
		world.setBlock(i - 8, j - 8, k - 61, AbyssalCraft.dreadstone, 0, 2);
		world.setBlock(i - 8, j - 7, k - 67, AbyssalCraft.dreadstone, 0, 2);
		world.setBlock(i - 8, j - 7, k - 65, AbyssalCraft.dreadstone, 0, 2);
		world.setBlock(i - 8, j - 7, k - 64, AbyssalCraft.dreadstone, 0, 2);
		world.setBlock(i - 8, j - 7, k - 63, AbyssalCraft.dreadstone, 0, 2);
		world.setBlock(i - 8, j - 7, k - 62, AbyssalCraft.dreadstone, 0, 2);
		world.setBlock(i - 8, j - 7, k - 61, AbyssalCraft.dreadstone, 0, 2);
		world.setBlock(i - 8, j + 0, k - 35, AbyssalCraft.dreadbrick, 0, 2);
		world.setBlock(i - 8, j + 0, k - 34, AbyssalCraft.dreadbrick, 0, 2);
		world.setBlock(i - 8, j + 0, k - 33, AbyssalCraft.dreadbrick, 0, 2);
		world.setBlock(i - 8, j + 0, k - 32, AbyssalCraft.dreadbrick, 0, 2);
		world.setBlock(i - 8, j + 0, k - 31, AbyssalCraft.dreadbrick, 0, 2);
		world.setBlock(i - 8, j + 0, k - 30, AbyssalCraft.dreadbrick, 0, 2);
		world.setBlock(i - 8, j + 0, k - 29, AbyssalCraft.dreadbrick, 0, 2);
		world.setBlock(i - 8, j + 0, k - 28, AbyssalCraft.dreadbrick, 0, 2);
		world.setBlock(i - 8, j + 0, k - 27, AbyssalCraft.dreadbrick, 0, 2);
		world.setBlock(i - 8, j + 0, k - 26, AbyssalCraft.dreadbrick, 0, 2);
		world.setBlock(i - 8, j + 0, k - 25, AbyssalCraft.dreadbrick, 0, 2);
		world.setBlock(i - 8, j + 0, k - 24, AbyssalCraft.dreadbrick, 0, 2);
		world.setBlock(i - 8, j + 0, k - 23, AbyssalCraft.dreadbrick, 0, 2);
		world.setBlock(i - 8, j + 0, k - 17, AbyssalCraft.dreadbrick, 0, 2);
		world.setBlock(i - 8, j + 0, k - 16, AbyssalCraft.dreadbrick, 0, 2);
		world.setBlock(i - 8, j + 0, k - 15, AbyssalCraft.dreadbrick, 0, 2);
		world.setBlock(i - 8, j + 0, k - 14, AbyssalCraft.dreadbrick, 0, 2);
		world.setBlock(i - 8, j + 0, k - 13, AbyssalCraft.dreadbrick, 0, 2);
		world.setBlock(i - 8, j + 0, k - 12, AbyssalCraft.dreadbrick, 0, 2);
		world.setBlock(i - 8, j + 0, k - 11, AbyssalCraft.dreadbrick, 0, 2);
		world.setBlock(i - 8, j + 0, k - 10, AbyssalCraft.dreadbrick, 0, 2);
		world.setBlock(i - 8, j + 0, k - 9, AbyssalCraft.dreadbrick, 0, 2);
		world.setBlock(i - 8, j + 0, k - 8, AbyssalCraft.dreadbrick, 0, 2);
		world.setBlock(i - 8, j + 0, k - 7, AbyssalCraft.dreadbrick, 0, 2);
		world.setBlock(i - 8, j + 0, k - 6, AbyssalCraft.dreadbrick, 0, 2);
		world.setBlock(i - 8, j + 0, k - 5, AbyssalCraft.dreadbrick, 0, 2);
		world.setBlock(i - 8, j + 0, k - 4, AbyssalCraft.dreadbrick, 0, 2);
		world.setBlock(i - 8, j + 0, k - 3, AbyssalCraft.dreadbrick, 0, 2);
		world.setBlock(i - 8, j + 1, k - 35, AbyssalCraft.dreadbrick, 0, 2);
		world.setBlock(i - 8, j + 1, k - 34, AbyssalCraft.dreadbrick, 0, 2);
		world.setBlock(i - 8, j + 1, k - 33, AbyssalCraft.dreadbrick, 0, 2);
		world.setBlock(i - 8, j + 1, k - 32, AbyssalCraft.dreadbrick, 0, 2);
		world.setBlock(i - 8, j + 1, k - 31, AbyssalCraft.dreadbrick, 0, 2);
		world.setBlock(i - 8, j + 1, k - 30, AbyssalCraft.dreadbrick, 0, 2);
		world.setBlock(i - 8, j + 1, k - 29, AbyssalCraft.dreadbrick, 0, 2);
		world.setBlock(i - 8, j + 1, k - 28, AbyssalCraft.dreadbrick, 0, 2);
		world.setBlock(i - 8, j + 1, k - 27, AbyssalCraft.dreadbrick, 0, 2);
		world.setBlock(i - 8, j + 1, k - 26, AbyssalCraft.dreadbrick, 0, 2);
		world.setBlock(i - 8, j + 1, k - 25, AbyssalCraft.dreadbrick, 0, 2);
		world.setBlock(i - 8, j + 1, k - 24, AbyssalCraft.dreadbrick, 0, 2);
		world.setBlock(i - 8, j + 1, k - 23, AbyssalCraft.dreadbrick, 0, 2);
		world.setBlock(i - 8, j + 1, k - 17, AbyssalCraft.dreadbrick, 0, 2);
		world.setBlock(i - 8, j + 1, k - 16, AbyssalCraft.dreadbrick, 0, 2);
		world.setBlock(i - 8, j + 1, k - 15, AbyssalCraft.dreadbrick, 0, 2);
		world.setBlock(i - 8, j + 1, k - 14, AbyssalCraft.dreadbrick, 0, 2);
		world.setBlock(i - 8, j + 1, k - 13, AbyssalCraft.dreadbrick, 0, 2);
		world.setBlock(i - 8, j + 1, k - 12, AbyssalCraft.dreadbrick, 0, 2);
		world.setBlock(i - 8, j + 1, k - 11, AbyssalCraft.dreadbrick, 0, 2);
		world.setBlock(i - 8, j + 1, k - 10, AbyssalCraft.dreadbrick, 0, 2);
		world.setBlock(i - 8, j + 1, k - 9, AbyssalCraft.dreadbrick, 0, 2);
		world.setBlock(i - 8, j + 1, k - 8, AbyssalCraft.dreadbrick, 0, 2);
		world.setBlock(i - 8, j + 1, k - 7, AbyssalCraft.dreadbrick, 0, 2);
		world.setBlock(i - 8, j + 1, k - 6, AbyssalCraft.dreadbrick, 0, 2);
		world.setBlock(i - 8, j + 1, k - 5, AbyssalCraft.dreadbrick, 0, 2);
		world.setBlock(i - 8, j + 1, k - 4, AbyssalCraft.dreadbrick, 0, 2);
		world.setBlock(i - 8, j + 1, k - 3, AbyssalCraft.dreadbrick, 0, 2);
		world.setBlock(i - 8, j + 2, k - 35, AbyssalCraft.dreadbrick, 0, 2);
		world.setBlock(i - 8, j + 2, k - 34, AbyssalCraft.dreadbrick, 0, 2);
		world.setBlock(i - 8, j + 2, k - 33, AbyssalCraft.dreadbrick, 0, 2);
		world.setBlock(i - 8, j + 2, k - 32, AbyssalCraft.dreadbrick, 0, 2);
		world.setBlock(i - 8, j + 2, k - 31, AbyssalCraft.dreadbrick, 0, 2);
		world.setBlock(i - 8, j + 2, k - 30, AbyssalCraft.dreadbrick, 0, 2);
		world.setBlock(i - 8, j + 2, k - 29, AbyssalCraft.dreadbrick, 0, 2);
		world.setBlock(i - 8, j + 2, k - 28, AbyssalCraft.dreadbrick, 0, 2);
		world.setBlock(i - 8, j + 2, k - 27, AbyssalCraft.dreadbrick, 0, 2);
		world.setBlock(i - 8, j + 2, k - 26, AbyssalCraft.dreadbrick, 0, 2);
		world.setBlock(i - 8, j + 2, k - 25, AbyssalCraft.dreadbrick, 0, 2);
		world.setBlock(i - 8, j + 2, k - 24, AbyssalCraft.dreadbrick, 0, 2);
		world.setBlock(i - 8, j + 2, k - 23, AbyssalCraft.dreadbrick, 0, 2);
		world.setBlock(i - 8, j + 2, k - 17, AbyssalCraft.dreadbrick, 0, 2);
		world.setBlock(i - 8, j + 2, k - 16, AbyssalCraft.dreadbrick, 0, 2);
		world.setBlock(i - 8, j + 2, k - 15, AbyssalCraft.dreadbrickfence, 0, 2);
		world.setBlock(i - 8, j + 2, k - 14, AbyssalCraft.dreadbrick, 0, 2);
		world.setBlock(i - 8, j + 2, k - 13, AbyssalCraft.dreadbrickfence, 0, 2);
		world.setBlock(i - 8, j + 2, k - 12, AbyssalCraft.dreadbrick, 0, 2);
		world.setBlock(i - 8, j + 2, k - 11, AbyssalCraft.dreadbrickfence, 0, 2);
		world.setBlock(i - 8, j + 2, k - 10, AbyssalCraft.dreadbrick, 0, 2);
		world.setBlock(i - 8, j + 2, k - 9, AbyssalCraft.dreadbrickfence, 0, 2);
		world.setBlock(i - 8, j + 2, k - 8, AbyssalCraft.dreadbrick, 0, 2);
		world.setBlock(i - 8, j + 2, k - 7, AbyssalCraft.dreadbrickfence, 0, 2);
		world.setBlock(i - 8, j + 2, k - 6, AbyssalCraft.dreadbrick, 0, 2);
		world.setBlock(i - 8, j + 2, k - 5, AbyssalCraft.dreadbrickfence, 0, 2);
		world.setBlock(i - 8, j + 2, k - 4, AbyssalCraft.dreadbrick, 0, 2);
		world.setBlock(i - 8, j + 2, k - 3, AbyssalCraft.dreadbrick, 0, 2);
		world.setBlock(i - 8, j + 3, k - 40, AbyssalCraft.dreadbrick, 0, 2);
		world.setBlock(i - 8, j + 3, k - 39, AbyssalCraft.dreadbrick, 0, 2);
		world.setBlock(i - 8, j + 3, k - 38, AbyssalCraft.dreadbrick, 0, 2);
		world.setBlock(i - 8, j + 3, k - 37, AbyssalCraft.dreadbrick, 0, 2);
		world.setBlock(i - 8, j + 3, k - 36, AbyssalCraft.dreadbrick, 0, 2);
		world.setBlock(i - 8, j + 3, k - 35, AbyssalCraft.dreadbrick, 0, 2);
		world.setBlock(i - 8, j + 3, k - 34, AbyssalCraft.dreadbrick, 0, 2);
		world.setBlock(i - 8, j + 3, k - 33, AbyssalCraft.dreadbrick, 0, 2);
		world.setBlock(i - 8, j + 3, k - 32, AbyssalCraft.dreadbrick, 0, 2);
		world.setBlock(i - 8, j + 3, k - 31, AbyssalCraft.dreadbrick, 0, 2);
		world.setBlock(i - 8, j + 3, k - 30, AbyssalCraft.dreadbrick, 0, 2);
		world.setBlock(i - 8, j + 3, k - 29, AbyssalCraft.dreadbrick, 0, 2);
		world.setBlock(i - 8, j + 3, k - 28, AbyssalCraft.dreadbrick, 0, 2);
		world.setBlock(i - 8, j + 3, k - 27, AbyssalCraft.dreadbrick, 0, 2);
		world.setBlock(i - 8, j + 3, k - 26, AbyssalCraft.dreadbrick, 0, 2);
		world.setBlock(i - 8, j + 3, k - 25, AbyssalCraft.dreadbrick, 0, 2);
		world.setBlock(i - 8, j + 3, k - 24, AbyssalCraft.dreadbrick, 0, 2);
		world.setBlock(i - 8, j + 3, k - 23, AbyssalCraft.dreadbrick, 0, 2);
		world.setBlock(i - 8, j + 3, k - 17, AbyssalCraft.dreadbrick, 0, 2);
		world.setBlock(i - 8, j + 3, k - 16, AbyssalCraft.dreadbrick, 0, 2);
		world.setBlock(i - 8, j + 3, k - 15, AbyssalCraft.dreadbrickfence, 0, 2);
		world.setBlock(i - 8, j + 3, k - 14, AbyssalCraft.dreadbrick, 0, 2);
		world.setBlock(i - 8, j + 3, k - 13, AbyssalCraft.dreadbrickfence, 0, 2);
		world.setBlock(i - 8, j + 3, k - 12, AbyssalCraft.dreadbrick, 0, 2);
		world.setBlock(i - 8, j + 3, k - 11, AbyssalCraft.dreadbrickfence, 0, 2);
		world.setBlock(i - 8, j + 3, k - 10, AbyssalCraft.dreadbrick, 0, 2);
		world.setBlock(i - 8, j + 3, k - 9, AbyssalCraft.dreadbrickfence, 0, 2);
		world.setBlock(i - 8, j + 3, k - 8, AbyssalCraft.dreadbrick, 0, 2);
		world.setBlock(i - 8, j + 3, k - 7, AbyssalCraft.dreadbrickfence, 0, 2);
		world.setBlock(i - 8, j + 3, k - 6, AbyssalCraft.dreadbrick, 0, 2);
		world.setBlock(i - 8, j + 3, k - 5, AbyssalCraft.dreadbrickfence, 0, 2);
		world.setBlock(i - 8, j + 3, k - 4, AbyssalCraft.dreadbrick, 0, 2);
		world.setBlock(i - 8, j + 3, k - 3, AbyssalCraft.dreadbrick, 0, 2);
		world.setBlock(i - 8, j + 4, k - 43, AbyssalCraft.dreadbrick, 0, 2);
		world.setBlock(i - 8, j + 4, k - 42, AbyssalCraft.dreadbrick, 0, 2);
		world.setBlock(i - 8, j + 4, k - 41, AbyssalCraft.dreadbrick, 0, 2);
		world.setBlock(i - 8, j + 4, k - 36, AbyssalCraft.dreadbrick, 0, 2);
		world.setBlock(i - 8, j + 4, k - 35, AbyssalCraft.dreadbrick, 0, 2);
		world.setBlock(i - 8, j + 4, k - 34, AbyssalCraft.dreadbrick, 0, 2);
		world.setBlock(i - 8, j + 4, k - 33, AbyssalCraft.dreadbrick, 0, 2);
		world.setBlock(i - 8, j + 4, k - 32, AbyssalCraft.dreadbrick, 0, 2);
		world.setBlock(i - 8, j + 4, k - 31, AbyssalCraft.dreadbrick, 0, 2);
		world.setBlock(i - 8, j + 4, k - 30, AbyssalCraft.dreadbrick, 0, 2);
		world.setBlock(i - 8, j + 4, k - 29, AbyssalCraft.dreadbrick, 0, 2);
		world.setBlock(i - 8, j + 4, k - 28, AbyssalCraft.dreadbrick, 0, 2);
		world.setBlock(i - 8, j + 4, k - 27, AbyssalCraft.dreadbrick, 0, 2);
		world.setBlock(i - 8, j + 4, k - 26, AbyssalCraft.dreadbrick, 0, 2);
		world.setBlock(i - 8, j + 4, k - 25, AbyssalCraft.dreadbrick, 0, 2);
		world.setBlock(i - 8, j + 4, k - 24, AbyssalCraft.dreadbrick, 0, 2);
		world.setBlock(i - 8, j + 4, k - 23, AbyssalCraft.dreadbrick, 0, 2);
		world.setBlock(i - 8, j + 4, k - 17, AbyssalCraft.dreadbrick, 0, 2);
		world.setBlock(i - 8, j + 4, k - 16, AbyssalCraft.dreadbrick, 0, 2);
		world.setBlock(i - 8, j + 4, k - 15, AbyssalCraft.dreadbrickfence, 0, 2);
		world.setBlock(i - 8, j + 4, k - 14, AbyssalCraft.dreadbrick, 0, 2);
		world.setBlock(i - 8, j + 4, k - 13, AbyssalCraft.dreadbrickfence, 0, 2);
		world.setBlock(i - 8, j + 4, k - 12, AbyssalCraft.dreadbrick, 0, 2);
		world.setBlock(i - 8, j + 4, k - 11, AbyssalCraft.dreadbrickfence, 0, 2);
		world.setBlock(i - 8, j + 4, k - 10, AbyssalCraft.dreadbrick, 0, 2);
		world.setBlock(i - 8, j + 4, k - 9, AbyssalCraft.dreadbrickfence, 0, 2);
		world.setBlock(i - 8, j + 4, k - 8, AbyssalCraft.dreadbrick, 0, 2);
		world.setBlock(i - 8, j + 4, k - 7, AbyssalCraft.dreadbrickfence, 0, 2);
		world.setBlock(i - 8, j + 4, k - 6, AbyssalCraft.dreadbrick, 0, 2);
		world.setBlock(i - 8, j + 4, k - 5, AbyssalCraft.dreadbrickfence, 0, 2);
		world.setBlock(i - 8, j + 4, k - 4, AbyssalCraft.dreadbrick, 0, 2);
		world.setBlock(i - 8, j + 4, k - 3, AbyssalCraft.dreadbrick, 0, 2);
		world.setBlock(i - 8, j + 5, k - 43, AbyssalCraft.dreadbrick, 0, 2);
		world.setBlock(i - 8, j + 5, k - 42, AbyssalCraft.dreadbrick, 0, 2);
		world.setBlock(i - 8, j + 5, k - 41, AbyssalCraft.dreadbrick, 0, 2);
		world.setBlock(i - 8, j + 5, k - 36, AbyssalCraft.dreadbrick, 0, 2);
		world.setBlock(i - 8, j + 5, k - 35, AbyssalCraft.dreadbrick, 0, 2);
		world.setBlock(i - 8, j + 5, k - 34, AbyssalCraft.dreadbrick, 0, 2);
		world.setBlock(i - 8, j + 5, k - 33, AbyssalCraft.dreadbrick, 0, 2);
		world.setBlock(i - 8, j + 5, k - 32, AbyssalCraft.dreadbrick, 0, 2);
		world.setBlock(i - 8, j + 5, k - 31, AbyssalCraft.dreadbrick, 0, 2);
		world.setBlock(i - 8, j + 5, k - 30, AbyssalCraft.dreadbrick, 0, 2);
		world.setBlock(i - 8, j + 5, k - 29, AbyssalCraft.dreadbrick, 0, 2);
		world.setBlock(i - 8, j + 5, k - 28, AbyssalCraft.dreadbrick, 0, 2);
		world.setBlock(i - 8, j + 5, k - 27, AbyssalCraft.dreadbrick, 0, 2);
		world.setBlock(i - 8, j + 5, k - 26, AbyssalCraft.dreadbrick, 0, 2);
		world.setBlock(i - 8, j + 5, k - 25, AbyssalCraft.dreadbrick, 0, 2);
		world.setBlock(i - 8, j + 5, k - 24, AbyssalCraft.dreadbrick, 0, 2);
		world.setBlock(i - 8, j + 5, k - 23, AbyssalCraft.dreadbrick, 0, 2);
		world.setBlock(i - 8, j + 5, k - 17, AbyssalCraft.dreadbrick, 0, 2);
		world.setBlock(i - 8, j + 5, k - 16, AbyssalCraft.dreadbrick, 0, 2);
		world.setBlock(i - 8, j + 5, k - 15, AbyssalCraft.dreadbrick, 0, 2);
		world.setBlock(i - 8, j + 5, k - 14, AbyssalCraft.dreadbrick, 0, 2);
		world.setBlock(i - 8, j + 5, k - 13, AbyssalCraft.dreadbrick, 0, 2);
		world.setBlock(i - 8, j + 5, k - 12, AbyssalCraft.dreadbrick, 0, 2);
		world.setBlock(i - 8, j + 5, k - 11, AbyssalCraft.dreadbrick, 0, 2);
		world.setBlock(i - 8, j + 5, k - 10, AbyssalCraft.dreadbrick, 0, 2);
		world.setBlock(i - 8, j + 5, k - 9, AbyssalCraft.dreadbrick, 0, 2);
		world.setBlock(i - 8, j + 5, k - 8, AbyssalCraft.dreadbrick, 0, 2);
		world.setBlock(i - 8, j + 5, k - 7, AbyssalCraft.dreadbrick, 0, 2);
		world.setBlock(i - 8, j + 5, k - 6, AbyssalCraft.dreadbrick, 0, 2);
		world.setBlock(i - 8, j + 5, k - 5, AbyssalCraft.dreadbrick, 0, 2);
		world.setBlock(i - 8, j + 5, k - 4, AbyssalCraft.dreadbrick, 0, 2);
		world.setBlock(i - 8, j + 5, k - 3, AbyssalCraft.dreadbrick, 0, 2);
		world.setBlock(i - 8, j + 6, k - 43, AbyssalCraft.dreadbrick, 0, 2);
		world.setBlock(i - 8, j + 6, k - 42, AbyssalCraft.dreadbrick, 0, 2);
		world.setBlock(i - 8, j + 6, k - 41, AbyssalCraft.dreadbrick, 0, 2);
		world.setBlock(i - 8, j + 6, k - 36, AbyssalCraft.dreadbrick, 0, 2);
		world.setBlock(i - 8, j + 6, k - 35, AbyssalCraft.dreadbrick, 0, 2);
		world.setBlock(i - 8, j + 6, k - 34, AbyssalCraft.dreadbrick, 0, 2);
		world.setBlock(i - 8, j + 6, k - 33, AbyssalCraft.dreadbrick, 0, 2);
		world.setBlock(i - 8, j + 6, k - 32, AbyssalCraft.dreadbrick, 0, 2);
		world.setBlock(i - 8, j + 6, k - 31, AbyssalCraft.dreadbrick, 0, 2);
		world.setBlock(i - 8, j + 6, k - 30, AbyssalCraft.dreadbrick, 0, 2);
		world.setBlock(i - 8, j + 6, k - 29, AbyssalCraft.dreadbrick, 0, 2);
		world.setBlock(i - 8, j + 6, k - 28, AbyssalCraft.dreadbrick, 0, 2);
		world.setBlock(i - 8, j + 6, k - 27, AbyssalCraft.dreadbrick, 0, 2);
		world.setBlock(i - 8, j + 6, k - 26, AbyssalCraft.dreadbrick, 0, 2);
		world.setBlock(i - 8, j + 6, k - 25, AbyssalCraft.dreadbrick, 0, 2);
		world.setBlock(i - 8, j + 6, k - 24, AbyssalCraft.dreadbrick, 0, 2);
		world.setBlock(i - 8, j + 6, k - 23, AbyssalCraft.dreadbrick, 0, 2);
		world.setBlock(i - 8, j + 7, k - 43, AbyssalCraft.dreadbrick, 0, 2);
		world.setBlock(i - 8, j + 7, k - 42, AbyssalCraft.dreadbrick, 0, 2);
		world.setBlock(i - 8, j + 7, k - 41, AbyssalCraft.dreadbrick, 0, 2);
		world.setBlock(i - 8, j + 7, k - 36, AbyssalCraft.dreadbrick, 0, 2);
		world.setBlock(i - 8, j + 7, k - 35, AbyssalCraft.dreadbrick, 0, 2);
		world.setBlock(i - 8, j + 7, k - 34, AbyssalCraft.dreadbrick, 0, 2);
		world.setBlock(i - 8, j + 7, k - 33, AbyssalCraft.dreadbrick, 0, 2);
		world.setBlock(i - 8, j + 7, k - 32, AbyssalCraft.dreadbrick, 0, 2);
		world.setBlock(i - 8, j + 7, k - 31, AbyssalCraft.dreadbrick, 0, 2);
		world.setBlock(i - 8, j + 7, k - 30, AbyssalCraft.dreadbrick, 0, 2);
		world.setBlock(i - 8, j + 7, k - 29, AbyssalCraft.dreadbrick, 0, 2);
		world.setBlock(i - 8, j + 7, k - 28, AbyssalCraft.dreadbrick, 0, 2);
		world.setBlock(i - 8, j + 7, k - 27, AbyssalCraft.dreadbrick, 0, 2);
		world.setBlock(i - 8, j + 7, k - 26, AbyssalCraft.dreadbrick, 0, 2);
		world.setBlock(i - 8, j + 7, k - 25, AbyssalCraft.dreadbrick, 0, 2);
		world.setBlock(i - 8, j + 7, k - 24, AbyssalCraft.dreadbrick, 0, 2);
		world.setBlock(i - 8, j + 8, k - 43, AbyssalCraft.dreadbrick, 0, 2);
		world.setBlock(i - 8, j + 8, k - 42, AbyssalCraft.dreadbrick, 0, 2);
		world.setBlock(i - 8, j + 8, k - 41, AbyssalCraft.dreadbrick, 0, 2);
		world.setBlock(i - 8, j + 8, k - 36, AbyssalCraft.dreadbrick, 0, 2);
		world.setBlock(i - 8, j + 8, k - 35, AbyssalCraft.dreadbrick, 0, 2);
		world.setBlock(i - 8, j + 8, k - 34, AbyssalCraft.dreadbrick, 0, 2);
		world.setBlock(i - 8, j + 8, k - 33, AbyssalCraft.dreadbrick, 0, 2);
		world.setBlock(i - 8, j + 8, k - 32, AbyssalCraft.dreadbrick, 0, 2);
		world.setBlock(i - 8, j + 8, k - 31, AbyssalCraft.dreadbrick, 0, 2);
		world.setBlock(i - 8, j + 8, k - 30, AbyssalCraft.dreadbrick, 0, 2);
		world.setBlock(i - 8, j + 8, k - 29, AbyssalCraft.dreadbrick, 0, 2);
		world.setBlock(i - 8, j + 8, k - 28, AbyssalCraft.dreadbrick, 0, 2);
		world.setBlock(i - 8, j + 8, k - 27, AbyssalCraft.dreadbrick, 0, 2);
		world.setBlock(i - 8, j + 8, k - 26, AbyssalCraft.dreadbrick, 0, 2);
		world.setBlock(i - 8, j + 9, k - 43, AbyssalCraft.dreadbrick, 0, 2);
		world.setBlock(i - 8, j + 9, k - 42, AbyssalCraft.dreadbrick, 0, 2);
		world.setBlock(i - 8, j + 9, k - 41, AbyssalCraft.dreadbrick, 0, 2);
		world.setBlock(i - 8, j + 9, k - 36, AbyssalCraft.dreadbrick, 0, 2);
		world.setBlock(i - 8, j + 9, k - 35, AbyssalCraft.dreadbrick, 0, 2);
		world.setBlock(i - 8, j + 9, k - 34, AbyssalCraft.dreadbrick, 0, 2);
		world.setBlock(i - 8, j + 9, k - 33, AbyssalCraft.dreadbrick, 0, 2);
		world.setBlock(i - 8, j + 9, k - 32, AbyssalCraft.dreadbrick, 0, 2);
		world.setBlock(i - 8, j + 9, k - 31, AbyssalCraft.dreadbrick, 0, 2);
		world.setBlock(i - 8, j + 9, k - 30, AbyssalCraft.dreadbrick, 0, 2);
		world.setBlock(i - 8, j + 9, k - 29, AbyssalCraft.dreadbrick, 0, 2);
		world.setBlock(i - 8, j + 9, k - 28, AbyssalCraft.dreadbrick, 0, 2);
		world.setBlock(i - 8, j + 10, k - 43, AbyssalCraft.dreadbrick, 0, 2);
		world.setBlock(i - 8, j + 10, k - 42, AbyssalCraft.dreadbrick, 0, 2);
		world.setBlock(i - 8, j + 10, k - 41, AbyssalCraft.dreadbrick, 0, 2);
		world.setBlock(i - 8, j + 10, k - 36, AbyssalCraft.dreadbrick, 0, 2);
		world.setBlock(i - 8, j + 10, k - 35, AbyssalCraft.dreadbrick, 0, 2);
		world.setBlock(i - 8, j + 11, k - 43, AbyssalCraft.dreadbrick, 0, 2);
		world.setBlock(i - 8, j + 11, k - 42, AbyssalCraft.dreadbrick, 0, 2);
		world.setBlock(i - 8, j + 11, k - 41, AbyssalCraft.dreadbrick, 0, 2);
		world.setBlock(i - 8, j + 11, k - 36, AbyssalCraft.dreadbrick, 0, 2);
		world.setBlock(i - 8, j + 11, k - 35, AbyssalCraft.dreadbrick, 0, 2);
		world.setBlock(i - 8, j + 12, k - 43, AbyssalCraft.dreadbrick, 0, 2);
		world.setBlock(i - 8, j + 12, k - 42, AbyssalCraft.dreadbrick, 0, 2);
		world.setBlock(i - 8, j + 12, k - 41, AbyssalCraft.dreadbrick, 0, 2);
		world.setBlock(i - 8, j + 12, k - 36, AbyssalCraft.dreadbrick, 0, 2);
		world.setBlock(i - 8, j + 13, k - 43, AbyssalCraft.dreadbrick, 0, 2);
		world.setBlock(i - 8, j + 13, k - 42, AbyssalCraft.dreadbrick, 0, 2);
		world.setBlock(i - 8, j + 13, k - 41, AbyssalCraft.dreadbrick, 0, 2);
		world.setBlock(i - 8, j + 13, k - 36, AbyssalCraft.dreadbrick, 0, 2);
		world.setBlock(i - 8, j + 14, k - 43, AbyssalCraft.dreadbrick, 0, 2);
		world.setBlock(i - 8, j + 14, k - 42, AbyssalCraft.dreadbrick, 0, 2);
		world.setBlock(i - 8, j + 14, k - 41, AbyssalCraft.dreadbrick, 0, 2);
		world.setBlock(i - 8, j + 14, k - 40, AbyssalCraft.dreadbrick, 0, 2);
		world.setBlock(i - 8, j + 14, k - 39, AbyssalCraft.dreadbrick, 0, 2);
		world.setBlock(i - 8, j + 14, k - 38, AbyssalCraft.dreadbrick, 0, 2);
		world.setBlock(i - 8, j + 14, k - 37, AbyssalCraft.dreadbrick, 0, 2);
		world.setBlock(i - 8, j + 14, k - 36, AbyssalCraft.dreadbrick, 0, 2);
		world.setBlock(i - 7, j - 15, k - 68, AbyssalCraft.dreadstone, 0, 2);
		world.setBlock(i - 7, j - 15, k - 67, AbyssalCraft.dreadstone, 0, 2);
		world.setBlock(i - 7, j - 15, k - 66, AbyssalCraft.dreadstone, 0, 2);
		world.setBlock(i - 7, j - 15, k - 65, AbyssalCraft.dreadstone, 0, 2);
		world.setBlock(i - 7, j - 15, k - 64, AbyssalCraft.dreadstone, 0, 2);
		world.setBlock(i - 7, j - 15, k - 63, AbyssalCraft.dreadstone, 0, 2);
		world.setBlock(i - 7, j - 15, k - 62, AbyssalCraft.dreadstone, 0, 2);
		world.setBlock(i - 7, j - 15, k - 61, AbyssalCraft.dreadstone, 0, 2);
		world.setBlock(i - 7, j - 15, k - 60, AbyssalCraft.dreadstone, 0, 2);
		world.setBlock(i - 7, j - 15, k - 59, AbyssalCraft.dreadstone, 0, 2);
		world.setBlock(i - 7, j - 14, k - 69, AbyssalCraft.dreadstone, 0, 2);
		world.setBlock(i - 7, j - 14, k - 68, AbyssalCraft.dreadstone, 0, 2);
		world.setBlock(i - 7, j - 14, k - 67, AbyssalCraft.dreadstone, 0, 2);
		world.setBlock(i - 7, j - 14, k - 66, AbyssalCraft.dreadstone, 0, 2);
		world.setBlock(i - 7, j - 14, k - 65, AbyssalCraft.dreadstone, 0, 2);
		world.setBlock(i - 7, j - 14, k - 64, AbyssalCraft.dreadstone, 0, 2);
		world.setBlock(i - 7, j - 14, k - 61, AbyssalCraft.dreadstone, 0, 2);
		world.setBlock(i - 7, j - 14, k - 60, AbyssalCraft.dreadstone, 0, 2);
		world.setBlock(i - 7, j - 14, k - 59, AbyssalCraft.dreadstone, 0, 2);
		world.setBlock(i - 7, j - 13, k - 68, AbyssalCraft.dreadstone, 0, 2);
		world.setBlock(i - 7, j - 13, k - 66, AbyssalCraft.dreadstone, 0, 2);
		world.setBlock(i - 7, j - 13, k - 60, AbyssalCraft.dreadstone, 0, 2);
		world.setBlock(i - 7, j - 13, k - 59, AbyssalCraft.dreadstone, 0, 2);
		world.setBlock(i - 7, j - 12, k - 68, AbyssalCraft.dreadstone, 0, 2);
		world.setBlock(i - 7, j - 12, k - 66, AbyssalCraft.dreadstone, 0, 2);
		world.setBlock(i - 7, j - 12, k - 60, AbyssalCraft.dreadstone, 0, 2);
		world.setBlock(i - 7, j - 12, k - 59, AbyssalCraft.dreadstone, 0, 2);
		world.setBlock(i - 7, j - 11, k - 68, AbyssalCraft.dreadstone, 0, 2);
		world.setBlock(i - 7, j - 11, k - 67, AbyssalCraft.dreadstone, 0, 2);
		world.setBlock(i - 7, j - 11, k - 66, AbyssalCraft.dreadstone, 0, 2);
		world.setBlock(i - 7, j - 11, k - 60, AbyssalCraft.dreadstone, 0, 2);
		world.setBlock(i - 7, j - 11, k - 59, AbyssalCraft.dreadstone, 0, 2);
		world.setBlock(i - 7, j - 10, k - 68, AbyssalCraft.dreadstone, 0, 2);
		world.setBlock(i - 7, j - 10, k - 67, AbyssalCraft.dreadstone, 0, 2);
		world.setBlock(i - 7, j - 10, k - 66, AbyssalCraft.dreadstone, 0, 2);
		world.setBlock(i - 7, j - 10, k - 60, AbyssalCraft.dreadstone, 0, 2);
		world.setBlock(i - 7, j - 10, k - 59, AbyssalCraft.dreadstone, 0, 2);
		world.setBlock(i - 7, j - 9, k - 68, AbyssalCraft.dreadstone, 0, 2);
		world.setBlock(i - 7, j - 9, k - 67, AbyssalCraft.dreadstone, 0, 2);
		world.setBlock(i - 7, j - 9, k - 66, AbyssalCraft.dreadstone, 0, 2);
		world.setBlock(i - 7, j - 9, k - 65, AbyssalCraft.dreadstone, 0, 2);
		world.setBlock(i - 7, j - 9, k - 64, AbyssalCraft.dreadstone, 0, 2);
		world.setBlock(i - 7, j - 9, k - 61, AbyssalCraft.dreadstone, 0, 2);
		world.setBlock(i - 7, j - 9, k - 60, AbyssalCraft.dreadstone, 0, 2);
		world.setBlock(i - 7, j - 9, k - 59, AbyssalCraft.dreadstone, 0, 2);
		world.setBlock(i - 7, j - 8, k - 68, AbyssalCraft.dreadstone, 0, 2);
		world.setBlock(i - 7, j - 8, k - 67, AbyssalCraft.dreadstone, 0, 2);
		world.setBlock(i - 7, j - 8, k - 66, AbyssalCraft.dreadstone, 0, 2);
		world.setBlock(i - 7, j - 8, k - 65, AbyssalCraft.dreadstone, 0, 2);
		world.setBlock(i - 7, j - 8, k - 64, AbyssalCraft.dreadstone, 0, 2);
		world.setBlock(i - 7, j - 8, k - 63, AbyssalCraft.dreadstone, 0, 2);
		world.setBlock(i - 7, j - 8, k - 61, AbyssalCraft.dreadstone, 0, 2);
		world.setBlock(i - 7, j - 8, k - 60, AbyssalCraft.dreadstone, 0, 2);
		world.setBlock(i - 7, j - 8, k - 59, AbyssalCraft.dreadstone, 0, 2);
		world.setBlock(i - 7, j - 7, k - 68, AbyssalCraft.dreadstone, 0, 2);
		world.setBlock(i - 7, j - 7, k - 67, AbyssalCraft.dreadstone, 0, 2);
		world.setBlock(i - 7, j - 7, k - 66, AbyssalCraft.dreadstone, 0, 2);
		world.setBlock(i - 7, j - 7, k - 65, AbyssalCraft.dreadstone, 0, 2);
		world.setBlock(i - 7, j - 7, k - 64, AbyssalCraft.dreadstone, 0, 2);
		world.setBlock(i - 7, j - 7, k - 63, AbyssalCraft.dreadstone, 0, 2);
		world.setBlock(i - 7, j - 7, k - 62, AbyssalCraft.dreadstone, 0, 2);
		world.setBlock(i - 7, j - 7, k - 61, AbyssalCraft.dreadstone, 0, 2);
		world.setBlock(i - 7, j - 7, k - 60, AbyssalCraft.dreadstone, 0, 2);
		world.setBlock(i - 7, j - 7, k - 59, AbyssalCraft.dreadstone, 0, 2);
		world.setBlock(i - 7, j + 0, k - 35, AbyssalCraft.dreadbrick, 0, 2);
		world.setBlock(i - 7, j + 0, k - 34, AbyssalCraft.dreadbrick, 0, 2);
		world.setBlock(i - 7, j + 0, k - 33, AbyssalCraft.dreadbrick, 0, 2);
		world.setBlock(i - 7, j + 0, k - 32, AbyssalCraft.dreadbrick, 0, 2);
		world.setBlock(i - 7, j + 0, k - 31, AbyssalCraft.dreadbrick, 0, 2);
		world.setBlock(i - 7, j + 0, k - 30, AbyssalCraft.dreadbrick, 0, 2);
		world.setBlock(i - 7, j + 0, k - 29, AbyssalCraft.dreadbrick, 0, 2);
		world.setBlock(i - 7, j + 0, k - 28, AbyssalCraft.dreadbrick, 0, 2);
		world.setBlock(i - 7, j + 0, k - 27, AbyssalCraft.dreadbrick, 0, 2);
		world.setBlock(i - 7, j + 0, k - 26, AbyssalCraft.dreadbrick, 0, 2);
		world.setBlock(i - 7, j + 0, k - 25, AbyssalCraft.dreadbrick, 0, 2);
		world.setBlock(i - 7, j + 0, k - 24, AbyssalCraft.dreadbrick, 0, 2);
		world.setBlock(i - 7, j + 0, k - 23, AbyssalCraft.dreadbrick, 0, 2);
		world.setBlock(i - 7, j + 0, k - 17, AbyssalCraft.dreadbrick, 0, 2);
		world.setBlock(i - 7, j + 0, k - 16, AbyssalCraft.dreadbrick, 0, 2);
		world.setBlock(i - 7, j + 0, k - 15, AbyssalCraft.dreadbrick, 0, 2);
		world.setBlock(i - 7, j + 0, k - 14, AbyssalCraft.dreadbrick, 0, 2);
		world.setBlock(i - 7, j + 0, k - 13, AbyssalCraft.dreadbrick, 0, 2);
		world.setBlock(i - 7, j + 0, k - 12, AbyssalCraft.dreadbrick, 0, 2);
		world.setBlock(i - 7, j + 0, k - 11, AbyssalCraft.dreadbrick, 0, 2);
		world.setBlock(i - 7, j + 0, k - 10, AbyssalCraft.dreadbrick, 0, 2);
		world.setBlock(i - 7, j + 0, k - 9, AbyssalCraft.dreadbrick, 0, 2);
		world.setBlock(i - 7, j + 0, k - 8, AbyssalCraft.dreadbrick, 0, 2);
		world.setBlock(i - 7, j + 0, k - 7, AbyssalCraft.dreadbrick, 0, 2);
		world.setBlock(i - 7, j + 0, k - 6, AbyssalCraft.dreadbrick, 0, 2);
		world.setBlock(i - 7, j + 0, k - 5, AbyssalCraft.dreadbrick, 0, 2);
		world.setBlock(i - 7, j + 0, k - 4, AbyssalCraft.dreadbrick, 0, 2);
		world.setBlock(i - 7, j + 0, k - 3, AbyssalCraft.dreadbrick, 0, 2);
		world.setBlock(i - 7, j + 1, k - 35, AbyssalCraft.dreadbrick, 0, 2);
		world.setBlock(i - 7, j + 1, k - 34, AbyssalCraft.dreadbrick, 0, 2);
		world.setBlock(i - 7, j + 1, k - 33, AbyssalCraft.dreadbrick, 0, 2);
		world.setBlock(i - 7, j + 1, k - 32, AbyssalCraft.dreadbrick, 0, 2);
		world.setBlock(i - 7, j + 1, k - 31, AbyssalCraft.dreadbrick, 0, 2);
		world.setBlock(i - 7, j + 1, k - 30, AbyssalCraft.dreadbrick, 0, 2);
		world.setBlock(i - 7, j + 1, k - 29, AbyssalCraft.dreadbrickslab1, 5, 2);
		world.setBlock(i - 7, j + 1, k - 23, AbyssalCraft.dreadbrick, 0, 2);
		world.setBlock(i - 7, j + 1, k - 17, AbyssalCraft.dreadbrick, 0, 2);
		world.setBlock(i - 7, j + 1, k - 3, AbyssalCraft.dreadbrick, 0, 2);
		world.setBlock(i - 7, j + 2, k - 35, AbyssalCraft.dreadbrick, 0, 2);
		world.setBlock(i - 7, j + 2, k - 34, AbyssalCraft.dreadbrick, 0, 2);
		world.setBlock(i - 7, j + 2, k - 33, AbyssalCraft.dreadbrick, 0, 2);
		world.setBlock(i - 7, j + 2, k - 32, AbyssalCraft.dreadbrick, 0, 2);
		world.setBlock(i - 7, j + 2, k - 31, AbyssalCraft.dreadbrickslab1, 5, 2);
		world.setBlock(i - 7, j + 2, k - 23, AbyssalCraft.dreadbrick, 0, 2);
		world.setBlock(i - 7, j + 2, k - 17, AbyssalCraft.dreadbrick, 0, 2);
		world.setBlock(i - 7, j + 2, k - 3, AbyssalCraft.dreadbrick, 0, 2);
		world.setBlock(i - 7, j + 3, k - 58, AbyssalCraft.dreadbrick, 0, 2);
		world.setBlock(i - 7, j + 3, k - 57, AbyssalCraft.dreadbrick, 0, 2);
		world.setBlock(i - 7, j + 3, k - 56, AbyssalCraft.dreadbrick, 0, 2);
		world.setBlock(i - 7, j + 3, k - 55, AbyssalCraft.dreadbrick, 0, 2);
		world.setBlock(i - 7, j + 3, k - 54, AbyssalCraft.dreadbrick, 0, 2);
		world.setBlock(i - 7, j + 3, k - 53, AbyssalCraft.dreadbrick, 0, 2);
		world.setBlock(i - 7, j + 3, k - 52, AbyssalCraft.dreadbrick, 0, 2);
		world.setBlock(i - 7, j + 3, k - 51, AbyssalCraft.dreadbrick, 0, 2);
		world.setBlock(i - 7, j + 3, k - 50, AbyssalCraft.dreadbrick, 0, 2);
		world.setBlock(i - 7, j + 3, k - 49, AbyssalCraft.dreadbrick, 0, 2);
		world.setBlock(i - 7, j + 3, k - 48, AbyssalCraft.dreadbrick, 0, 2);
		world.setBlock(i - 7, j + 3, k - 47, AbyssalCraft.dreadbrick, 0, 2);
		world.setBlock(i - 7, j + 3, k - 46, AbyssalCraft.dreadbrick, 0, 2);
		world.setBlock(i - 7, j + 3, k - 45, AbyssalCraft.dreadbrick, 0, 2);
		world.setBlock(i - 7, j + 3, k - 44, AbyssalCraft.dreadbrick, 0, 2);
		world.setBlock(i - 7, j + 3, k - 43, AbyssalCraft.dreadbrick, 0, 2);
		world.setBlock(i - 7, j + 3, k - 42, AbyssalCraft.dreadbrick, 0, 2);
		world.setBlock(i - 7, j + 3, k - 41, AbyssalCraft.dreadbrick, 0, 2);
		world.setBlock(i - 7, j + 3, k - 40, AbyssalCraft.dreadbrick, 0, 2);
		world.setBlock(i - 7, j + 3, k - 39, AbyssalCraft.dreadbrick, 0, 2);
		world.setBlock(i - 7, j + 3, k - 38, AbyssalCraft.dreadbrick, 0, 2);
		world.setBlock(i - 7, j + 3, k - 37, AbyssalCraft.dreadbrick, 0, 2);
		world.setBlock(i - 7, j + 3, k - 36, AbyssalCraft.dreadbrick, 0, 2);
		world.setBlock(i - 7, j + 3, k - 35, AbyssalCraft.dreadbrick, 0, 2);
		world.setBlock(i - 7, j + 3, k - 34, AbyssalCraft.dreadbrick, 0, 2);
		world.setBlock(i - 7, j + 3, k - 33, AbyssalCraft.dreadbrickslab1, 5, 2);
		world.setBlock(i - 7, j + 3, k - 23, AbyssalCraft.dreadbrick, 0, 2);
		world.setBlock(i - 7, j + 3, k - 17, AbyssalCraft.dreadbrick, 0, 2);
		world.setBlock(i - 7, j + 3, k - 3, AbyssalCraft.dreadbrick, 0, 2);
		world.setBlock(i - 7, j + 4, k - 58, AbyssalCraft.dreadbrick, 0, 2);
		world.setBlock(i - 7, j + 4, k - 57, AbyssalCraft.dreadbrick, 0, 2);
		world.setBlock(i - 7, j + 4, k - 56, AbyssalCraft.dreadbrick, 0, 2);
		world.setBlock(i - 7, j + 4, k - 55, AbyssalCraft.dreadbrick, 0, 2);
		world.setBlock(i - 7, j + 4, k - 54, AbyssalCraft.dreadbrick, 0, 2);
		world.setBlock(i - 7, j + 4, k - 53, AbyssalCraft.dreadbrick, 0, 2);
		world.setBlock(i - 7, j + 4, k - 52, AbyssalCraft.dreadbrick, 0, 2);
		world.setBlock(i - 7, j + 4, k - 51, AbyssalCraft.dreadbrick, 0, 2);
		world.setBlock(i - 7, j + 4, k - 50, AbyssalCraft.dreadbrick, 0, 2);
		world.setBlock(i - 7, j + 4, k - 49, AbyssalCraft.dreadbrick, 0, 2);
		world.setBlock(i - 7, j + 4, k - 48, AbyssalCraft.dreadbrick, 0, 2);
		world.setBlock(i - 7, j + 4, k - 47, AbyssalCraft.dreadbrick, 0, 2);
		world.setBlock(i - 7, j + 4, k - 46, AbyssalCraft.dreadbrick, 0, 2);
		world.setBlock(i - 7, j + 4, k - 45, AbyssalCraft.dreadbrick, 0, 2);
		world.setBlock(i - 7, j + 4, k - 44, AbyssalCraft.dreadbrick, 0, 2);
		world.setBlock(i - 7, j + 4, k - 43, AbyssalCraft.dreadbrick, 0, 2);
		world.setBlock(i - 7, j + 4, k - 23, AbyssalCraft.dreadbrick, 0, 2);
		world.setBlock(i - 7, j + 4, k - 17, AbyssalCraft.dreadbrick, 0, 2);
		world.setBlock(i - 7, j + 4, k - 3, AbyssalCraft.dreadbrick, 0, 2);
		world.setBlock(i - 7, j + 5, k - 58, AbyssalCraft.dreadbrick, 0, 2);
		world.setBlock(i - 7, j + 5, k - 57, AbyssalCraft.dreadbrick, 0, 2);
		world.setBlock(i - 7, j + 5, k - 56, AbyssalCraft.dreadbrick, 0, 2);
		world.setBlock(i - 7, j + 5, k - 55, AbyssalCraft.dreadbrick, 0, 2);
		world.setBlock(i - 7, j + 5, k - 54, AbyssalCraft.dreadbrick, 0, 2);
		world.setBlock(i - 7, j + 5, k - 53, AbyssalCraft.dreadbrick, 0, 2);
		world.setBlock(i - 7, j + 5, k - 52, AbyssalCraft.dreadbrick, 0, 2);
		world.setBlock(i - 7, j + 5, k - 51, AbyssalCraft.dreadbrick, 0, 2);
		world.setBlock(i - 7, j + 5, k - 50, AbyssalCraft.dreadbrick, 0, 2);
		world.setBlock(i - 7, j + 5, k - 49, AbyssalCraft.dreadbrick, 0, 2);
		world.setBlock(i - 7, j + 5, k - 48, AbyssalCraft.dreadbrick, 0, 2);
		world.setBlock(i - 7, j + 5, k - 47, AbyssalCraft.dreadbrick, 0, 2);
		world.setBlock(i - 7, j + 5, k - 46, AbyssalCraft.dreadbrick, 0, 2);
		world.setBlock(i - 7, j + 5, k - 45, AbyssalCraft.dreadbrick, 0, 2);
		world.setBlock(i - 7, j + 5, k - 44, AbyssalCraft.dreadbrick, 0, 2);
		world.setBlock(i - 7, j + 5, k - 43, AbyssalCraft.dreadbrick, 0, 2);
		world.setBlock(i - 7, j + 5, k - 23, AbyssalCraft.dreadbrick, 0, 2);
		world.setBlock(i - 7, j + 5, k - 17, AbyssalCraft.dreadbrick, 0, 2);
		world.setBlock(i - 7, j + 5, k - 16, AbyssalCraft.dreadbrick, 0, 2);
		world.setBlock(i - 7, j + 5, k - 15, AbyssalCraft.dreadbrick, 0, 2);
		world.setBlock(i - 7, j + 5, k - 14, AbyssalCraft.dreadbrick, 0, 2);
		world.setBlock(i - 7, j + 5, k - 13, AbyssalCraft.dreadbrick, 0, 2);
		world.setBlock(i - 7, j + 5, k - 12, AbyssalCraft.dreadbrick, 0, 2);
		world.setBlock(i - 7, j + 5, k - 11, AbyssalCraft.dreadbrick, 0, 2);
		world.setBlock(i - 7, j + 5, k - 10, AbyssalCraft.dreadbrick, 0, 2);
		world.setBlock(i - 7, j + 5, k - 9, AbyssalCraft.dreadbrick, 0, 2);
		world.setBlock(i - 7, j + 5, k - 8, AbyssalCraft.dreadbrick, 0, 2);
