package com.shinoow.abyssalcraft.common.structures;

import java.util.Random;

import com.shinoow.abyssalcraft.AbyssalCraft;

import net.minecraft.init.Blocks;
import net.minecraft.world.World;
import net.minecraft.world.gen.feature.WorldGenerator;

public class StructureHouse extends WorldGenerator
{

	public StructureHouse() { }

	@Override
	public boolean generate(World world, Random rand, int i, int j, int k) {

		world.setBlock(i - 9, j + 0, k - 23, AbyssalCraft.ethaxiumbrick, 0, 0);
		world.setBlock(i - 9, j + 0, k - 22, AbyssalCraft.ethaxiumbrick, 0, 0);
		world.setBlock(i - 9, j + 0, k - 21, AbyssalCraft.ethaxiumbrick, 0, 0);
		world.setBlock(i - 9, j + 0, k - 20, AbyssalCraft.ethaxiumbrick, 0, 0);
		world.setBlock(i - 9, j + 0, k - 19, AbyssalCraft.ethaxiumbrick, 0, 0);
		world.setBlock(i - 9, j + 0, k - 18, AbyssalCraft.ethaxiumbrick, 0, 0);
		world.setBlock(i - 9, j + 0, k - 17, AbyssalCraft.ethaxiumbrick, 0, 0);
		world.setBlock(i - 9, j + 0, k - 16, AbyssalCraft.ethaxiumbrick, 0, 0);
		world.setBlock(i - 9, j + 0, k - 15, AbyssalCraft.ethaxiumbrick, 0, 0);
		world.setBlock(i - 9, j + 0, k - 14, AbyssalCraft.ethaxiumbrick, 0, 0);
		world.setBlock(i - 9, j + 0, k - 13, AbyssalCraft.ethaxiumbrick, 0, 0);
		world.setBlock(i - 9, j + 0, k - 12, AbyssalCraft.ethaxiumbrick, 0, 0);
		world.setBlock(i - 9, j + 0, k - 11, AbyssalCraft.ethaxiumbrick, 0, 0);
		world.setBlock(i - 9, j + 0, k - 10, AbyssalCraft.ethaxiumbrick, 0, 0);
		world.setBlock(i - 9, j + 0, k - 9, AbyssalCraft.ethaxiumbrick, 0, 0);
		world.setBlock(i - 9, j + 0, k - 8, AbyssalCraft.ethaxiumbrick, 0, 0);
		world.setBlock(i - 9, j + 0, k - 7, AbyssalCraft.ethaxiumbrick, 0, 0);
		world.setBlock(i - 9, j + 0, k - 6, AbyssalCraft.ethaxiumbrick, 0, 0);
		world.setBlock(i - 9, j + 0, k - 5, AbyssalCraft.ethaxiumbrick, 0, 0);
		world.setBlock(i - 9, j + 0, k - 4, AbyssalCraft.ethaxiumbrick, 0, 0);
		world.setBlock(i - 9, j + 0, k - 3, AbyssalCraft.ethaxiumbrick, 0, 0);
		world.setBlock(i - 9, j + 0, k - 2, AbyssalCraft.ethaxiumbrick, 0, 0);
		world.setBlock(i - 9, j + 0, k - 1, AbyssalCraft.ethaxiumbrick, 0, 0);
		world.setBlock(i - 9, j + 1, k - 23, AbyssalCraft.ethaxiumpillar, 0, 0);
		world.setBlock(i - 9, j + 1, k - 22, AbyssalCraft.ethaxiumbrick, 0, 0);
		world.setBlock(i - 9, j + 1, k - 21, AbyssalCraft.ethaxiumbrick, 0, 0);
		world.setBlock(i - 9, j + 1, k - 20, AbyssalCraft.ethaxiumbrick, 0, 0);
		world.setBlock(i - 9, j + 1, k - 19, AbyssalCraft.ethaxiumbrick, 0, 0);
		world.setBlock(i - 9, j + 1, k - 18, AbyssalCraft.ethaxiumbrick, 0, 0);
		world.setBlock(i - 9, j + 1, k - 17, AbyssalCraft.ethaxiumbrick, 0, 0);
		world.setBlock(i - 9, j + 1, k - 16, AbyssalCraft.ethaxiumbrick, 0, 0);
		world.setBlock(i - 9, j + 1, k - 15, AbyssalCraft.ethaxiumbrick, 0, 0);
		world.setBlock(i - 9, j + 1, k - 14, AbyssalCraft.ethaxiumbrick, 0, 0);
		world.setBlock(i - 9, j + 1, k - 13, AbyssalCraft.ethaxiumbrick, 0, 0);
		world.setBlock(i - 9, j + 1, k - 12, AbyssalCraft.ethaxiumbrick, 0, 0);
		world.setBlock(i - 9, j + 1, k - 11, AbyssalCraft.ethaxiumbrick, 0, 0);
		world.setBlock(i - 9, j + 1, k - 10, AbyssalCraft.ethaxiumbrick, 0, 0);
		world.setBlock(i - 9, j + 1, k - 9, AbyssalCraft.ethaxiumbrick, 0, 0);
		world.setBlock(i - 9, j + 1, k - 8, AbyssalCraft.ethaxiumbrick, 0, 0);
		world.setBlock(i - 9, j + 1, k - 7, AbyssalCraft.ethaxiumbrick, 0, 0);
		world.setBlock(i - 9, j + 1, k - 6, AbyssalCraft.ethaxiumbrick, 0, 0);
		world.setBlock(i - 9, j + 1, k - 5, AbyssalCraft.ethaxiumbrick, 0, 0);
		world.setBlock(i - 9, j + 1, k - 4, AbyssalCraft.ethaxiumbrick, 0, 0);
		world.setBlock(i - 9, j + 1, k - 3, AbyssalCraft.ethaxiumbrick, 0, 0);
		world.setBlock(i - 9, j + 1, k - 2, AbyssalCraft.ethaxiumbrick, 0, 0);
		world.setBlock(i - 9, j + 1, k - 1, AbyssalCraft.ethaxiumpillar, 0, 0);
		world.setBlock(i - 9, j + 2, k - 23, AbyssalCraft.ethaxiumpillar, 0, 0);
		world.setBlock(i - 9, j + 2, k - 22, AbyssalCraft.ethaxiumbrick, 0, 0);
		world.setBlock(i - 9, j + 2, k - 21, AbyssalCraft.ethaxiumbrick, 0, 0);
		world.setBlock(i - 9, j + 2, k - 20, AbyssalCraft.ethaxiumbrick, 0, 0);
		world.setBlock(i - 9, j + 2, k - 19, AbyssalCraft.ethaxiumbrick, 0, 0);
		world.setBlock(i - 9, j + 2, k - 18, AbyssalCraft.ethaxiumbrick, 0, 0);
		world.setBlock(i - 9, j + 2, k - 17, AbyssalCraft.ethaxiumbrick, 0, 0);
		world.setBlock(i - 9, j + 2, k - 16, AbyssalCraft.ethaxiumbrick, 0, 0);
		world.setBlock(i - 9, j + 2, k - 15, AbyssalCraft.ethaxiumbrick, 0, 0);
		world.setBlock(i - 9, j + 2, k - 14, AbyssalCraft.ethaxiumbrick, 0, 0);
		world.setBlock(i - 9, j + 2, k - 13, AbyssalCraft.ethaxiumbrick, 0, 0);
		world.setBlock(i - 9, j + 2, k - 12, AbyssalCraft.ethaxiumbrick, 0, 0);
		world.setBlock(i - 9, j + 2, k - 11, AbyssalCraft.ethaxiumbrick, 0, 0);
		world.setBlock(i - 9, j + 2, k - 10, AbyssalCraft.ethaxiumbrick, 0, 0);
		world.setBlock(i - 9, j + 2, k - 9, AbyssalCraft.ethaxiumbrick, 0, 0);
		world.setBlock(i - 9, j + 2, k - 8, AbyssalCraft.ethaxiumbrick, 0, 0);
		world.setBlock(i - 9, j + 2, k - 7, AbyssalCraft.ethaxiumbrick, 0, 0);
		world.setBlock(i - 9, j + 2, k - 6, AbyssalCraft.ethaxiumbrick, 0, 0);
		world.setBlock(i - 9, j + 2, k - 5, AbyssalCraft.ethaxiumbrick, 0, 0);
		world.setBlock(i - 9, j + 2, k - 4, AbyssalCraft.ethaxiumbrick, 0, 0);
		world.setBlock(i - 9, j + 2, k - 3, AbyssalCraft.ethaxiumbrick, 0, 0);
		world.setBlock(i - 9, j + 2, k - 2, AbyssalCraft.ethaxiumbrick, 0, 0);
		world.setBlock(i - 9, j + 2, k - 1, AbyssalCraft.ethaxiumpillar, 0, 0);
		world.setBlock(i - 9, j + 3, k - 23, AbyssalCraft.ethaxiumpillar, 0, 0);
		world.setBlock(i - 9, j + 3, k - 22, AbyssalCraft.ethaxiumbrick, 0, 0);
		world.setBlock(i - 9, j + 3, k - 21, AbyssalCraft.ethaxiumbrick, 0, 0);
		world.setBlock(i - 9, j + 3, k - 20, AbyssalCraft.ethaxiumbrick, 0, 0);
		world.setBlock(i - 9, j + 3, k - 19, AbyssalCraft.ethaxiumbrick, 0, 0);
		world.setBlock(i - 9, j + 3, k - 18, AbyssalCraft.ethaxiumbrick, 0, 0);
		world.setBlock(i - 9, j + 3, k - 17, AbyssalCraft.ethaxiumbrick, 0, 0);
		world.setBlock(i - 9, j + 3, k - 16, AbyssalCraft.ethaxiumbrick, 0, 0);
		world.setBlock(i - 9, j + 3, k - 15, AbyssalCraft.ethaxiumbrick, 0, 0);
		world.setBlock(i - 9, j + 3, k - 14, AbyssalCraft.ethaxiumbrick, 0, 0);
		world.setBlock(i - 9, j + 3, k - 13, AbyssalCraft.ethaxiumbrick, 0, 0);
		world.setBlock(i - 9, j + 3, k - 12, AbyssalCraft.ethaxiumbrick, 0, 0);
		world.setBlock(i - 9, j + 3, k - 11, AbyssalCraft.ethaxiumbrick, 0, 0);
		world.setBlock(i - 9, j + 3, k - 10, AbyssalCraft.ethaxiumbrick, 0, 0);
		world.setBlock(i - 9, j + 3, k - 9, AbyssalCraft.ethaxiumbrick, 0, 0);
		world.setBlock(i - 9, j + 3, k - 8, AbyssalCraft.ethaxiumbrick, 0, 0);
		world.setBlock(i - 9, j + 3, k - 7, AbyssalCraft.ethaxiumbrick, 0, 0);
		world.setBlock(i - 9, j + 3, k - 6, AbyssalCraft.ethaxiumbrick, 0, 0);
		world.setBlock(i - 9, j + 3, k - 5, AbyssalCraft.ethaxiumbrick, 0, 0);
		world.setBlock(i - 9, j + 3, k - 4, AbyssalCraft.ethaxiumbrick, 0, 0);
		world.setBlock(i - 9, j + 3, k - 3, AbyssalCraft.ethaxiumbrick, 0, 0);
		world.setBlock(i - 9, j + 3, k - 2, AbyssalCraft.ethaxiumbrick, 0, 0);
		world.setBlock(i - 9, j + 3, k - 1, AbyssalCraft.ethaxiumpillar, 0, 0);
		world.setBlock(i - 9, j + 4, k - 23, AbyssalCraft.ethaxiumpillar, 0, 0);
		world.setBlock(i - 9, j + 4, k - 22, AbyssalCraft.ethaxiumbrick, 0, 0);
		world.setBlock(i - 9, j + 4, k - 21, AbyssalCraft.ethaxiumbrick, 0, 0);
		world.setBlock(i - 9, j + 4, k - 20, AbyssalCraft.ethaxiumbrick, 0, 0);
		world.setBlock(i - 9, j + 4, k - 19, AbyssalCraft.ethaxiumbrick, 0, 0);
		world.setBlock(i - 9, j + 4, k - 18, AbyssalCraft.ethaxiumbrick, 0, 0);
		world.setBlock(i - 9, j + 4, k - 17, AbyssalCraft.ethaxiumbrick, 0, 0);
		world.setBlock(i - 9, j + 4, k - 16, AbyssalCraft.ethaxiumbrick, 0, 0);
		world.setBlock(i - 9, j + 4, k - 15, AbyssalCraft.ethaxiumbrick, 0, 0);
		world.setBlock(i - 9, j + 4, k - 14, AbyssalCraft.ethaxiumbrick, 0, 0);
		world.setBlock(i - 9, j + 4, k - 13, AbyssalCraft.ethaxiumbrick, 0, 0);
		world.setBlock(i - 9, j + 4, k - 12, AbyssalCraft.ethaxiumbrick, 0, 0);
		world.setBlock(i - 9, j + 4, k - 11, AbyssalCraft.ethaxiumbrick, 0, 0);
		world.setBlock(i - 9, j + 4, k - 10, AbyssalCraft.ethaxiumbrick, 0, 0);
		world.setBlock(i - 9, j + 4, k - 9, AbyssalCraft.ethaxiumbrick, 0, 0);
		world.setBlock(i - 9, j + 4, k - 8, AbyssalCraft.ethaxiumbrick, 0, 0);
		world.setBlock(i - 9, j + 4, k - 7, AbyssalCraft.ethaxiumbrick, 0, 0);
		world.setBlock(i - 9, j + 4, k - 6, AbyssalCraft.ethaxiumbrick, 0, 0);
		world.setBlock(i - 9, j + 4, k - 5, AbyssalCraft.ethaxiumbrick, 0, 0);
		world.setBlock(i - 9, j + 4, k - 4, AbyssalCraft.ethaxiumbrick, 0, 0);
		world.setBlock(i - 9, j + 4, k - 3, AbyssalCraft.ethaxiumbrick, 0, 0);
		world.setBlock(i - 9, j + 4, k - 2, AbyssalCraft.ethaxiumbrick, 0, 0);
		world.setBlock(i - 9, j + 4, k - 1, AbyssalCraft.ethaxiumpillar, 0, 0);
		world.setBlock(i - 9, j + 5, k - 23, AbyssalCraft.ethaxiumpillar, 0, 0);
		world.setBlock(i - 9, j + 5, k - 22, AbyssalCraft.ethaxiumbrick, 0, 0);
		world.setBlock(i - 9, j + 5, k - 21, AbyssalCraft.ethaxiumbrick, 0, 0);
		world.setBlock(i - 9, j + 5, k - 20, AbyssalCraft.ethaxiumbrick, 0, 0);
		world.setBlock(i - 9, j + 5, k - 19, AbyssalCraft.ethaxiumbrick, 0, 0);
		world.setBlock(i - 9, j + 5, k - 18, AbyssalCraft.ethaxiumbrick, 0, 0);
		world.setBlock(i - 9, j + 5, k - 17, AbyssalCraft.ethaxiumbrick, 0, 0);
		world.setBlock(i - 9, j + 5, k - 16, AbyssalCraft.ethaxiumbrick, 0, 0);
		world.setBlock(i - 9, j + 5, k - 15, AbyssalCraft.ethaxiumbrick, 0, 0);
		world.setBlock(i - 9, j + 5, k - 14, AbyssalCraft.ethaxiumbrick, 0, 0);
		world.setBlock(i - 9, j + 5, k - 13, AbyssalCraft.ethaxiumbrick, 0, 0);
		world.setBlock(i - 9, j + 5, k - 12, AbyssalCraft.ethaxiumbrick, 0, 0);
		world.setBlock(i - 9, j + 5, k - 11, AbyssalCraft.ethaxiumbrick, 0, 0);
		world.setBlock(i - 9, j + 5, k - 10, AbyssalCraft.ethaxiumbrick, 0, 0);
		world.setBlock(i - 9, j + 5, k - 9, AbyssalCraft.ethaxiumbrick, 0, 0);
		world.setBlock(i - 9, j + 5, k - 8, AbyssalCraft.ethaxiumbrick, 0, 0);
		world.setBlock(i - 9, j + 5, k - 7, AbyssalCraft.ethaxiumbrick, 0, 0);
		world.setBlock(i - 9, j + 5, k - 6, AbyssalCraft.ethaxiumbrick, 0, 0);
		world.setBlock(i - 9, j + 5, k - 5, AbyssalCraft.ethaxiumbrick, 0, 0);
		world.setBlock(i - 9, j + 5, k - 4, AbyssalCraft.ethaxiumbrick, 0, 0);
		world.setBlock(i - 9, j + 5, k - 3, AbyssalCraft.ethaxiumbrick, 0, 0);
		world.setBlock(i - 9, j + 5, k - 2, AbyssalCraft.ethaxiumbrick, 0, 0);
		world.setBlock(i - 9, j + 5, k - 1, AbyssalCraft.ethaxiumpillar, 0, 0);
		world.setBlock(i - 9, j + 6, k - 23, AbyssalCraft.ethaxiumstairs, 0, 0);
		world.setBlock(i - 9, j + 6, k - 22, AbyssalCraft.ethaxiumstairs, 0, 0);
		world.setBlock(i - 9, j + 6, k - 21, AbyssalCraft.ethaxiumstairs, 0, 0);
		world.setBlock(i - 9, j + 6, k - 20, AbyssalCraft.ethaxiumstairs, 0, 0);
		world.setBlock(i - 9, j + 6, k - 19, AbyssalCraft.ethaxiumstairs, 0, 0);
		world.setBlock(i - 9, j + 6, k - 18, AbyssalCraft.ethaxiumstairs, 0, 0);
		world.setBlock(i - 9, j + 6, k - 17, AbyssalCraft.ethaxiumstairs, 0, 0);
		world.setBlock(i - 9, j + 6, k - 16, AbyssalCraft.ethaxiumstairs, 0, 0);
		world.setBlock(i - 9, j + 6, k - 15, AbyssalCraft.ethaxiumstairs, 0, 0);
		world.setBlock(i - 9, j + 6, k - 14, AbyssalCraft.ethaxiumstairs, 0, 0);
		world.setBlock(i - 9, j + 6, k - 13, AbyssalCraft.ethaxiumstairs, 0, 0);
		world.setBlock(i - 9, j + 6, k - 12, AbyssalCraft.ethaxiumstairs, 0, 0);
		world.setBlock(i - 9, j + 6, k - 11, AbyssalCraft.ethaxiumstairs, 0, 0);
		world.setBlock(i - 9, j + 6, k - 10, AbyssalCraft.ethaxiumstairs, 0, 0);
		world.setBlock(i - 9, j + 6, k - 9, AbyssalCraft.ethaxiumstairs, 0, 0);
		world.setBlock(i - 9, j + 6, k - 8, AbyssalCraft.ethaxiumstairs, 0, 0);
		world.setBlock(i - 9, j + 6, k - 7, AbyssalCraft.ethaxiumstairs, 0, 0);
		world.setBlock(i - 9, j + 6, k - 6, AbyssalCraft.ethaxiumstairs, 0, 0);
		world.setBlock(i - 9, j + 6, k - 5, AbyssalCraft.ethaxiumstairs, 0, 0);
		world.setBlock(i - 9, j + 6, k - 4, AbyssalCraft.ethaxiumstairs, 0, 0);
		world.setBlock(i - 9, j + 6, k - 3, AbyssalCraft.ethaxiumstairs, 0, 0);
		world.setBlock(i - 9, j + 6, k - 2, AbyssalCraft.ethaxiumstairs, 0, 0);
		world.setBlock(i - 9, j + 6, k - 1, AbyssalCraft.ethaxiumstairs, 3, 0);
		world.setBlock(i - 8, j + 0, k - 23, AbyssalCraft.ethaxiumbrick, 0, 0);
		world.setBlock(i - 8, j + 0, k - 22, AbyssalCraft.ethaxiumbrick, 0, 0);
		world.setBlock(i - 8, j + 0, k - 21, AbyssalCraft.ethaxiumbrick, 0, 0);
		world.setBlock(i - 8, j + 0, k - 20, AbyssalCraft.ethaxiumbrick, 0, 0);
		world.setBlock(i - 8, j + 0, k - 19, AbyssalCraft.ethaxiumbrick, 0, 0);
		world.setBlock(i - 8, j + 0, k - 18, AbyssalCraft.ethaxiumbrick, 0, 0);
		world.setBlock(i - 8, j + 0, k - 17, AbyssalCraft.ethaxiumbrick, 0, 0);
		world.setBlock(i - 8, j + 0, k - 16, AbyssalCraft.ethaxiumbrick, 0, 0);
		world.setBlock(i - 8, j + 0, k - 15, AbyssalCraft.ethaxiumbrick, 0, 0);
		world.setBlock(i - 8, j + 0, k - 14, AbyssalCraft.ethaxiumbrick, 0, 0);
		world.setBlock(i - 8, j + 0, k - 13, AbyssalCraft.ethaxiumbrick, 0, 0);
		world.setBlock(i - 8, j + 0, k - 12, AbyssalCraft.ethaxiumbrick, 0, 0);
		world.setBlock(i - 8, j + 0, k - 11, AbyssalCraft.ethaxiumbrick, 0, 0);
		world.setBlock(i - 8, j + 0, k - 10, AbyssalCraft.ethaxiumbrick, 0, 0);
		world.setBlock(i - 8, j + 0, k - 9, AbyssalCraft.ethaxiumbrick, 0, 0);
		world.setBlock(i - 8, j + 0, k - 8, AbyssalCraft.ethaxiumbrick, 0, 0);
		world.setBlock(i - 8, j + 0, k - 7, AbyssalCraft.ethaxiumbrick, 0, 0);
		world.setBlock(i - 8, j + 0, k - 6, AbyssalCraft.ethaxiumbrick, 0, 0);
		world.setBlock(i - 8, j + 0, k - 5, AbyssalCraft.ethaxiumbrick, 0, 0);
		world.setBlock(i - 8, j + 0, k - 4, AbyssalCraft.ethaxiumbrick, 0, 0);
		world.setBlock(i - 8, j + 0, k - 3, AbyssalCraft.ethaxiumbrick, 0, 0);
		world.setBlock(i - 8, j + 0, k - 2, AbyssalCraft.ethaxiumbrick, 0, 0);
		world.setBlock(i - 8, j + 1, k - 23, AbyssalCraft.ethaxiumbrick, 0, 0);
		world.setBlock(i - 8, j + 1, k - 22, AbyssalCraft.ethaxiumbrick, 0, 0);
		world.setBlock(i - 8, j + 1, k - 21, AbyssalCraft.ethaxiumbrick, 0, 0);
		world.setBlock(i - 8, j + 1, k - 20, AbyssalCraft.ethaxiumbrick, 0, 0);
		world.setBlock(i - 8, j + 1, k - 19, AbyssalCraft.ethaxiumbrick, 0, 0);
		world.setBlock(i - 8, j + 1, k - 18, AbyssalCraft.ethaxiumbrick, 0, 0);
		world.setBlock(i - 8, j + 1, k - 17, AbyssalCraft.ethaxiumbrick, 0, 0);
		world.setBlock(i - 8, j + 1, k - 16, AbyssalCraft.ethaxiumbrick, 0, 0);
		world.setBlock(i - 8, j + 1, k - 15, AbyssalCraft.ethaxiumbrick, 0, 0);
		world.setBlock(i - 8, j + 1, k - 14, AbyssalCraft.ethaxiumbrick, 0, 0);
		world.setBlock(i - 8, j + 1, k - 13, AbyssalCraft.ethaxiumbrick, 0, 0);
		world.setBlock(i - 8, j + 1, k - 12, AbyssalCraft.ethaxiumbrick, 0, 0);
		world.setBlock(i - 8, j + 1, k - 11, AbyssalCraft.ethaxiumbrick, 0, 0);
		world.setBlock(i - 8, j + 1, k - 10, AbyssalCraft.ethaxiumbrick, 0, 0);
		world.setBlock(i - 8, j + 1, k - 9, AbyssalCraft.ethaxiumbrick, 0, 0);
		world.setBlock(i - 8, j + 1, k - 8, AbyssalCraft.ethaxiumbrick, 0, 0);
		world.setBlock(i - 8, j + 1, k - 7, AbyssalCraft.ethaxiumbrick, 0, 0);
		world.setBlock(i - 8, j + 1, k - 6, AbyssalCraft.ethaxiumbrick, 0, 0);
		world.setBlock(i - 8, j + 1, k - 5, AbyssalCraft.ethaxiumbrick, 0, 0);
		world.setBlock(i - 8, j + 1, k - 4, AbyssalCraft.ethaxiumbrick, 0, 0);
		world.setBlock(i - 8, j + 1, k - 3, AbyssalCraft.ethaxiumbrick, 0, 0);
		world.setBlock(i - 8, j + 2, k - 23, AbyssalCraft.ethaxiumbrick, 0, 0);
		world.setBlock(i - 8, j + 2, k - 22, AbyssalCraft.ethaxiumbrick, 0, 0);
		world.setBlock(i - 8, j + 2, k - 21, AbyssalCraft.Darkstone_brick, 0, 0);
		world.setBlock(i - 8, j + 2, k - 20, AbyssalCraft.Darkstone_brick, 0, 0);
		world.setBlock(i - 8, j + 2, k - 19, AbyssalCraft.Darkstone_brick, 0, 0);
		world.setBlock(i - 8, j + 2, k - 18, AbyssalCraft.Darkstone_brick, 0, 0);
		world.setBlock(i - 8, j + 2, k - 17, AbyssalCraft.Darkstone_brick, 0, 0);
		world.setBlock(i - 8, j + 2, k - 16, AbyssalCraft.Darkstone_brick, 0, 0);
		world.setBlock(i - 8, j + 2, k - 15, AbyssalCraft.Darkstone_brick, 0, 0);
		world.setBlock(i - 8, j + 2, k - 14, AbyssalCraft.Darkstone_brick, 0, 0);
		world.setBlock(i - 8, j + 2, k - 13, AbyssalCraft.Darkstone_brick, 0, 0);
		world.setBlock(i - 8, j + 2, k - 12, AbyssalCraft.Darkstone_brick, 0, 0);
		world.setBlock(i - 8, j + 2, k - 11, AbyssalCraft.Darkstone_brick, 0, 0);
		world.setBlock(i - 8, j + 2, k - 10, AbyssalCraft.Darkstone_brick, 0, 0);
		world.setBlock(i - 8, j + 2, k - 9, AbyssalCraft.Darkstone_brick, 0, 0);
		world.setBlock(i - 8, j + 2, k - 8, AbyssalCraft.Darkstone_brick, 0, 0);
		world.setBlock(i - 8, j + 2, k - 7, AbyssalCraft.Darkstone_brick, 0, 0);
		world.setBlock(i - 8, j + 2, k - 6, AbyssalCraft.ethaxiumbrick, 0, 0);
		world.setBlock(i - 8, j + 2, k - 5, AbyssalCraft.ethaxiumbrick, 0, 0);
		world.setBlock(i - 8, j + 2, k - 4, AbyssalCraft.ethaxiumbrick, 0, 0);
		world.setBlock(i - 8, j + 2, k - 3, AbyssalCraft.ethaxiumbrick, 0, 0);
		world.setBlock(i - 8, j + 3, k - 23, AbyssalCraft.ethaxiumbrick, 0, 0);
		world.setBlock(i - 8, j + 3, k - 22, AbyssalCraft.ethaxiumbrick, 0, 0);
		world.setBlock(i - 8, j + 3, k - 21, AbyssalCraft.Darkstone_brick, 0, 0);
		world.setBlock(i - 8, j + 3, k - 20, AbyssalCraft.Darkstone_brick, 0, 0);
		world.setBlock(i - 8, j + 3, k - 19, AbyssalCraft.DSGlow, 0, 0);
		world.setBlock(i - 8, j + 3, k - 18, AbyssalCraft.Darkstone_brick, 0, 0);
		world.setBlock(i - 8, j + 3, k - 17, AbyssalCraft.Darkstone_brick, 0, 0);
		world.setBlock(i - 8, j + 3, k - 16, AbyssalCraft.Darkstone_brick, 0, 0);
		world.setBlock(i - 8, j + 3, k - 15, AbyssalCraft.Darkstone_brick, 0, 0);
		world.setBlock(i - 8, j + 3, k - 14, AbyssalCraft.DSGlow, 0, 0);
		world.setBlock(i - 8, j + 3, k - 13, AbyssalCraft.Darkstone_brick, 0, 0);
		world.setBlock(i - 8, j + 3, k - 12, AbyssalCraft.Darkstone_brick, 0, 0);
		world.setBlock(i - 8, j + 3, k - 11, AbyssalCraft.Darkstone_brick, 0, 0);
		world.setBlock(i - 8, j + 3, k - 10, AbyssalCraft.Darkstone_brick, 0, 0);
		world.setBlock(i - 8, j + 3, k - 9, AbyssalCraft.Darkstone_brick, 0, 0);
		world.setBlock(i - 8, j + 3, k - 8, AbyssalCraft.Darkstone_brick, 0, 0);
		world.setBlock(i - 8, j + 3, k - 7, AbyssalCraft.DSGlow, 0, 0);
		world.setBlock(i - 8, j + 3, k - 6, AbyssalCraft.ethaxiumbrick, 0, 0);
		world.setBlock(i - 8, j + 3, k - 5, AbyssalCraft.ethaxiumbrick, 0, 0);
		world.setBlock(i - 8, j + 3, k - 4, AbyssalCraft.ethaxiumbrick, 0, 0);
		world.setBlock(i - 8, j + 3, k - 3, AbyssalCraft.ethaxiumbrick, 0, 0);
		world.setBlock(i - 8, j + 4, k - 23, AbyssalCraft.ethaxiumbrick, 0, 0);
		world.setBlock(i - 8, j + 4, k - 22, AbyssalCraft.ethaxiumbrick, 0, 0);
		world.setBlock(i - 8, j + 4, k - 21, AbyssalCraft.Darkstone_brick, 0, 0);
		world.setBlock(i - 8, j + 4, k - 20, AbyssalCraft.Darkstone_brick, 0, 0);
		world.setBlock(i - 8, j + 4, k - 19, AbyssalCraft.Darkstone_brick, 0, 0);
		world.setBlock(i - 8, j + 4, k - 18, AbyssalCraft.Darkstone_brick, 0, 0);
		world.setBlock(i - 8, j + 4, k - 17, AbyssalCraft.Darkstone_brick, 0, 0);
		world.setBlock(i - 8, j + 4, k - 16, AbyssalCraft.Darkstone_brick, 0, 0);
		world.setBlock(i - 8, j + 4, k - 15, AbyssalCraft.Darkstone_brick, 0, 0);
		world.setBlock(i - 8, j + 4, k - 14, AbyssalCraft.Darkstone_brick, 0, 0);
		world.setBlock(i - 8, j + 4, k - 13, AbyssalCraft.Darkstone_brick, 0, 0);
		world.setBlock(i - 8, j + 4, k - 12, AbyssalCraft.Darkstone_brick, 0, 0);
		world.setBlock(i - 8, j + 4, k - 11, AbyssalCraft.Darkstone_brick, 0, 0);
		world.setBlock(i - 8, j + 4, k - 10, AbyssalCraft.Darkstone_brick, 0, 0);
		world.setBlock(i - 8, j + 4, k - 9, AbyssalCraft.Darkstone_brick, 0, 0);
		world.setBlock(i - 8, j + 4, k - 8, AbyssalCraft.Darkstone_brick, 0, 0);
		world.setBlock(i - 8, j + 4, k - 7, AbyssalCraft.Darkstone_brick, 0, 0);
		world.setBlock(i - 8, j + 4, k - 6, AbyssalCraft.ethaxiumbrick, 0, 0);
		world.setBlock(i - 8, j + 4, k - 5, AbyssalCraft.ethaxiumbrick, 0, 0);
		world.setBlock(i - 8, j + 4, k - 4, AbyssalCraft.ethaxiumbrick, 0, 0);
		world.setBlock(i - 8, j + 4, k - 3, AbyssalCraft.ethaxiumbrick, 0, 0);
		world.setBlock(i - 8, j + 5, k - 23, AbyssalCraft.ethaxiumbrick, 0, 0);
		world.setBlock(i - 8, j + 5, k - 22, AbyssalCraft.ethaxiumbrick, 0, 0);
		world.setBlock(i - 8, j + 5, k - 21, AbyssalCraft.ethaxiumbrick, 0, 0);
		world.setBlock(i - 8, j + 5, k - 20, AbyssalCraft.ethaxiumbrick, 0, 0);
		world.setBlock(i - 8, j + 5, k - 19, AbyssalCraft.ethaxiumbrick, 0, 0);
		world.setBlock(i - 8, j + 5, k - 18, AbyssalCraft.ethaxiumbrick, 0, 0);
		world.setBlock(i - 8, j + 5, k - 17, AbyssalCraft.ethaxiumbrick, 0, 0);
		world.setBlock(i - 8, j + 5, k - 16, AbyssalCraft.ethaxiumbrick, 0, 0);
		world.setBlock(i - 8, j + 5, k - 15, AbyssalCraft.ethaxiumbrick, 0, 0);
		world.setBlock(i - 8, j + 5, k - 14, AbyssalCraft.ethaxiumbrick, 0, 0);
		world.setBlock(i - 8, j + 5, k - 13, AbyssalCraft.ethaxiumbrick, 0, 0);
		world.setBlock(i - 8, j + 5, k - 12, AbyssalCraft.ethaxiumbrick, 0, 0);
		world.setBlock(i - 8, j + 5, k - 11, AbyssalCraft.ethaxiumbrick, 0, 0);
		world.setBlock(i - 8, j + 5, k - 10, AbyssalCraft.ethaxiumbrick, 0, 0);
		world.setBlock(i - 8, j + 5, k - 9, AbyssalCraft.ethaxiumbrick, 0, 0);
		world.setBlock(i - 8, j + 5, k - 8, AbyssalCraft.ethaxiumbrick, 0, 0);
		world.setBlock(i - 8, j + 5, k - 7, AbyssalCraft.ethaxiumbrick, 0, 0);
		world.setBlock(i - 8, j + 5, k - 6, AbyssalCraft.ethaxiumbrick, 0, 0);
		world.setBlock(i - 8, j + 5, k - 5, AbyssalCraft.ethaxiumbrick, 0, 0);
		world.setBlock(i - 8, j + 5, k - 4, AbyssalCraft.ethaxiumbrick, 0, 0);
		world.setBlock(i - 8, j + 5, k - 3, AbyssalCraft.ethaxiumbrick, 0, 0);
		world.setBlock(i - 8, j + 6, k - 23, AbyssalCraft.ethaxiumstairs, 2, 0);
		world.setBlock(i - 8, j + 6, k - 22, AbyssalCraft.ethaxiumbrick, 0, 0);
		world.setBlock(i - 8, j + 6, k - 21, AbyssalCraft.ethaxiumbrick, 0, 0);
		world.setBlock(i - 8, j + 6, k - 20, AbyssalCraft.ethaxiumbrick, 0, 0);
		world.setBlock(i - 8, j + 6, k - 19, AbyssalCraft.ethaxiumbrick, 0, 0);
		world.setBlock(i - 8, j + 6, k - 18, AbyssalCraft.ethaxiumbrick, 0, 0);
		world.setBlock(i - 8, j + 6, k - 17, AbyssalCraft.ethaxiumbrick, 0, 0);
		world.setBlock(i - 8, j + 6, k - 16, AbyssalCraft.ethaxiumbrick, 0, 0);
		world.setBlock(i - 8, j + 6, k - 15, AbyssalCraft.ethaxiumbrick, 0, 0);
		world.setBlock(i - 8, j + 6, k - 14, AbyssalCraft.ethaxiumbrick, 0, 0);
		world.setBlock(i - 8, j + 6, k - 13, AbyssalCraft.ethaxiumbrick, 0, 0);
		world.setBlock(i - 8, j + 6, k - 12, AbyssalCraft.ethaxiumbrick, 0, 0);
		world.setBlock(i - 8, j + 6, k - 11, AbyssalCraft.ethaxiumbrick, 0, 0);
		world.setBlock(i - 8, j + 6, k - 10, AbyssalCraft.ethaxiumbrick, 0, 0);
		world.setBlock(i - 8, j + 6, k - 9, AbyssalCraft.ethaxiumbrick, 0, 0);
		world.setBlock(i - 8, j + 6, k - 8, AbyssalCraft.ethaxiumbrick, 0, 0);
		world.setBlock(i - 8, j + 6, k - 7, AbyssalCraft.ethaxiumbrick, 0, 0);
		world.setBlock(i - 8, j + 6, k - 6, AbyssalCraft.ethaxiumbrick, 0, 0);
		world.setBlock(i - 8, j + 6, k - 5, AbyssalCraft.ethaxiumbrick, 0, 0);
		world.setBlock(i - 8, j + 6, k - 4, AbyssalCraft.ethaxiumbrick, 0, 0);
		world.setBlock(i - 8, j + 6, k - 3, AbyssalCraft.ethaxiumbrick, 0, 0);
		world.setBlock(i - 8, j + 6, k - 2, AbyssalCraft.ethaxiumbrick, 0, 0);
		world.setBlock(i - 8, j + 6, k - 1, AbyssalCraft.ethaxiumstairs, 3, 0);
		world.setBlock(i - 7, j + 0, k - 23, AbyssalCraft.ethaxiumbrick, 0, 0);
		world.setBlock(i - 7, j + 0, k - 22, AbyssalCraft.ethaxiumbrick, 0, 0);
		world.setBlock(i - 7, j + 0, k - 21, AbyssalCraft.ethaxiumbrick, 0, 0);
		world.setBlock(i - 7, j + 0, k - 20, AbyssalCraft.ethaxiumbrick, 0, 0);
		world.setBlock(i - 7, j + 0, k - 19, AbyssalCraft.ethaxiumbrick, 0, 0);
		world.setBlock(i - 7, j + 0, k - 18, AbyssalCraft.ethaxiumbrick, 0, 0);
		world.setBlock(i - 7, j + 0, k - 17, AbyssalCraft.ethaxiumbrick, 0, 0);
		world.setBlock(i - 7, j + 0, k - 16, AbyssalCraft.ethaxiumbrick, 0, 0);
		world.setBlock(i - 7, j + 0, k - 15, AbyssalCraft.ethaxiumbrick, 0, 0);
		world.setBlock(i - 7, j + 0, k - 14, AbyssalCraft.ethaxiumbrick, 0, 0);
		world.setBlock(i - 7, j + 0, k - 13, AbyssalCraft.ethaxiumbrick, 0, 0);
		world.setBlock(i - 7, j + 0, k - 12, AbyssalCraft.ethaxiumbrick, 0, 0);
		world.setBlock(i - 7, j + 0, k - 11, AbyssalCraft.ethaxiumbrick, 0, 0);
		world.setBlock(i - 7, j + 0, k - 10, AbyssalCraft.ethaxiumbrick, 0, 0);
		world.setBlock(i - 7, j + 0, k - 9, AbyssalCraft.ethaxiumbrick, 0, 0);
		world.setBlock(i - 7, j + 0, k - 8, AbyssalCraft.ethaxiumbrick, 0, 0);
		world.setBlock(i - 7, j + 0, k - 7, AbyssalCraft.ethaxiumbrick, 0, 0);
		world.setBlock(i - 7, j + 0, k - 6, AbyssalCraft.ethaxiumbrick, 0, 0);
		world.setBlock(i - 7, j + 0, k - 5, AbyssalCraft.ethaxiumbrick, 0, 0);
		world.setBlock(i - 7, j + 0, k - 4, AbyssalCraft.ethaxiumbrick, 0, 0);
		world.setBlock(i - 7, j + 0, k - 3, AbyssalCraft.ethaxiumbrick, 0, 0);
		world.setBlock(i - 7, j + 0, k - 2, AbyssalCraft.ethaxiumbrick, 0, 0);
		world.setBlock(i - 7, j + 1, k - 23, AbyssalCraft.ethaxiumbrick, 0, 0);
		world.setBlock(i - 7, j + 1, k - 22, AbyssalCraft.ethaxiumbrick, 0, 0);
		world.setBlock(i - 7, j + 1, k - 21, AbyssalCraft.Darkstone_cobble, 0, 0);
		world.setBlock(i - 7, j + 1, k - 20, AbyssalCraft.Darkstone_cobble, 0, 0);
		world.setBlock(i - 7, j + 1, k - 19, AbyssalCraft.Darkstone_cobble, 0, 0);
		world.setBlock(i - 7, j + 1, k - 18, AbyssalCraft.Darkstone_cobble, 0, 0);
		world.setBlock(i - 7, j + 1, k - 17, AbyssalCraft.Darkstone_cobble, 0, 0);
		world.setBlock(i - 7, j + 1, k - 16, AbyssalCraft.Darkstone_cobble, 0, 0);
		world.setBlock(i - 7, j + 1, k - 15, AbyssalCraft.Darkstone_cobble, 0, 0);
		world.setBlock(i - 7, j + 1, k - 14, AbyssalCraft.Darkstone_cobble, 0, 0);
		world.setBlock(i - 7, j + 1, k - 13, AbyssalCraft.Darkstone_cobble, 0, 0);
		world.setBlock(i - 7, j + 1, k - 12, AbyssalCraft.Darkstone_cobble, 0, 0);
		world.setBlock(i - 7, j + 1, k - 11, AbyssalCraft.Darkstone_cobble, 0, 0);
		world.setBlock(i - 7, j + 1, k - 10, AbyssalCraft.Darkstone_cobble, 0, 0);
		world.setBlock(i - 7, j + 1, k - 9, AbyssalCraft.Darkstone_cobble, 0, 0);
		world.setBlock(i - 7, j + 1, k - 8, AbyssalCraft.Darkstone_cobble, 0, 0);
		world.setBlock(i - 7, j + 1, k - 7, Blocks.water, 0, 0);
		world.setBlock(i - 7, j + 1, k - 6, AbyssalCraft.ethaxiumbrick, 0, 0);
		world.setBlock(i - 7, j + 1, k - 5, AbyssalCraft.ethaxiumbrick, 0, 0);
		world.setBlock(i - 7, j + 1, k - 4, AbyssalCraft.ethaxiumbrick, 0, 0);
		world.setBlock(i - 7, j + 1, k - 3, AbyssalCraft.ethaxiumbrick, 0, 0);
		world.setBlock(i - 7, j + 2, k - 23, AbyssalCraft.ethaxiumbrick, 0, 0);
		world.setBlock(i - 7, j + 2, k - 22, AbyssalCraft.Darkstone_brick, 0, 0);
		world.setBlock(i - 7, j + 2, k - 16, AbyssalCraft.Darkstone_brick, 0, 0);
		world.setBlock(i - 7, j + 2, k - 12, AbyssalCraft.Darkstone_brick, 0, 0);
		world.setBlock(i - 7, j + 2, k - 11, AbyssalCraft.Darkstone_brick, 0, 0);
		world.setBlock(i - 7, j + 2, k - 10, AbyssalCraft.Darkstone_brick, 0, 0);
		world.setBlock(i - 7, j + 2, k - 9, AbyssalCraft.Darkstone_brick, 0, 0);
		world.setBlock(i - 7, j + 2, k - 8, AbyssalCraft.Darkstone_brick, 0, 0);
		world.setBlock(i - 7, j + 2, k - 6, AbyssalCraft.Darkstone_brick, 0, 0);
		world.setBlock(i - 7, j + 2, k - 5, AbyssalCraft.ethaxiumbrick, 0, 0);
		world.setBlock(i - 7, j + 2, k - 3, AbyssalCraft.ethaxiumfence, 0, 0);
		world.setBlock(i - 7, j + 3, k - 23, AbyssalCraft.ethaxiumbrick, 0, 0);
		world.setBlock(i - 7, j + 3, k - 22, AbyssalCraft.Darkstone_brick, 0, 0);
		world.setBlock(i - 7, j + 3, k - 16, AbyssalCraft.Darkstone_brick, 0, 0);
		world.setBlock(i - 7, j + 3, k - 12, AbyssalCraft.Darkstone_brick, 0, 0);
		world.setBlock(i - 7, j + 3, k - 6, AbyssalCraft.Darkstone_brick, 0, 0);
		world.setBlock(i - 7, j + 3, k - 5, AbyssalCraft.ethaxiumbrick, 0, 0);
		world.setBlock(i - 7, j + 3, k - 3, AbyssalCraft.ethaxiumfence, 0, 0);
		world.setBlock(i - 7, j + 4, k - 23, AbyssalCraft.ethaxiumbrick, 0, 0);
		world.setBlock(i - 7, j + 4, k - 22, AbyssalCraft.Darkstone_brick, 0, 0);
		world.setBlock(i - 7, j + 4, k - 16, AbyssalCraft.Darkstone_brick, 0, 0);
		world.setBlock(i - 7, j + 4, k - 12, AbyssalCraft.Darkstone_brick, 0, 0);
		world.setBlock(i - 7, j + 4, k - 6, AbyssalCraft.Darkstone_brick, 0, 0);
		world.setBlock(i - 7, j + 4, k - 5, AbyssalCraft.ethaxiumbrick, 0, 0);
		world.setBlock(i - 7, j + 4, k - 3, AbyssalCraft.ethaxiumfence, 0, 0);
		world.setBlock(i - 7, j + 5, k - 23, AbyssalCraft.ethaxiumbrick, 0, 0);
		world.setBlock(i - 7, j + 5, k - 22, AbyssalCraft.ethaxiumbrick, 0, 0);
		world.setBlock(i - 7, j + 5, k - 21, AbyssalCraft.Darkstone_brick, 0, 0);
		world.setBlock(i - 7, j + 5, k - 20, AbyssalCraft.Darkstone_brick, 0, 0);
		world.setBlock(i - 7, j + 5, k - 19, AbyssalCraft.Darkstone_brick, 0, 0);
		world.setBlock(i - 7, j + 5, k - 18, AbyssalCraft.Darkstone_brick, 0, 0);
		world.setBlock(i - 7, j + 5, k - 17, AbyssalCraft.Darkstone_brick, 0, 0);
		world.setBlock(i - 7, j + 5, k - 16, AbyssalCraft.Darkstone_brick, 0, 0);
		world.setBlock(i - 7, j + 5, k - 15, AbyssalCraft.Darkstone_brick, 0, 0);
		world.setBlock(i - 7, j + 5, k - 14, AbyssalCraft.Darkstone_brick, 0, 0);
		world.setBlock(i - 7, j + 5, k - 13, AbyssalCraft.Darkstone_brick, 0, 0);
		world.setBlock(i - 7, j + 5, k - 12, AbyssalCraft.Darkstone_brick, 0, 0);
		world.setBlock(i - 7, j + 5, k - 11, AbyssalCraft.Darkstone_brick, 0, 0);
		world.setBlock(i - 7, j + 5, k - 10, AbyssalCraft.Darkstone_brick, 0, 0);
		world.setBlock(i - 7, j + 5, k - 9, AbyssalCraft.Darkstone_brick, 0, 0);
		world.setBlock(i - 7, j + 5, k - 8, AbyssalCraft.Darkstone_brick, 0, 0);
		world.setBlock(i - 7, j + 5, k - 7, AbyssalCraft.Darkstone_brick, 0, 0);
		world.setBlock(i - 7, j + 5, k - 6, AbyssalCraft.ethaxiumbrick, 0, 0);
		world.setBlock(i - 7, j + 5, k - 5, AbyssalCraft.ethaxiumbrick, 0, 0);
		world.setBlock(i - 7, j + 5, k - 3, AbyssalCraft.ethaxiumbrick, 0, 0);
		world.setBlock(i - 7, j + 6, k - 23, AbyssalCraft.ethaxiumstairs, 2, 0);
		world.setBlock(i - 7, j + 6, k - 22, AbyssalCraft.ethaxiumbrick, 0, 0);
		world.setBlock(i - 7, j + 6, k - 21, AbyssalCraft.ethaxiumbrick, 0, 0);
		world.setBlock(i - 7, j + 6, k - 20, AbyssalCraft.ethaxiumbrick, 0, 0);
		world.setBlock(i - 7, j + 6, k - 19, AbyssalCraft.ethaxiumbrick, 0, 0);
		world.setBlock(i - 7, j + 6, k - 18, AbyssalCraft.ethaxiumbrick, 0, 0);
		world.setBlock(i - 7, j + 6, k - 17, AbyssalCraft.ethaxiumbrick, 0, 0);
		world.setBlock(i - 7, j + 6, k - 16, AbyssalCraft.ethaxiumbrick, 0, 0);
		world.setBlock(i - 7, j + 6, k - 15, AbyssalCraft.ethaxiumbrick, 0, 0);
		world.setBlock(i - 7, j + 6, k - 14, AbyssalCraft.ethaxiumbrick, 0, 0);
		world.setBlock(i - 7, j + 6, k - 13, AbyssalCraft.ethaxiumbrick, 0, 0);
		world.setBlock(i - 7, j + 6, k - 12, AbyssalCraft.ethaxiumbrick, 0, 0);
		world.setBlock(i - 7, j + 6, k - 11, AbyssalCraft.ethaxiumbrick, 0, 0);
		world.setBlock(i - 7, j + 6, k - 10, AbyssalCraft.ethaxiumbrick, 0, 0);
		world.setBlock(i - 7, j + 6, k - 9, AbyssalCraft.ethaxiumbrick, 0, 0);
		world.setBlock(i - 7, j + 6, k - 8, AbyssalCraft.ethaxiumbrick, 0, 0);
		world.setBlock(i - 7, j + 6, k - 7, AbyssalCraft.ethaxiumbrick, 0, 0);
		world.setBlock(i - 7, j + 6, k - 6, AbyssalCraft.ethaxiumbrick, 0, 0);
		world.setBlock(i - 7, j + 6, k - 5, AbyssalCraft.ethaxiumbrick, 0, 0);
		world.setBlock(i - 7, j + 6, k - 4, AbyssalCraft.ethaxiumbrick, 0, 0);
		world.setBlock(i - 7, j + 6, k - 3, AbyssalCraft.ethaxiumbrick, 0, 0);
		world.setBlock(i - 7, j + 6, k - 2, AbyssalCraft.ethaxiumbrick, 0, 0);
		world.setBlock(i - 7, j + 6, k - 1, AbyssalCraft.ethaxiumstairs, 3, 0);
		world.setBlock(i - 6, j + 0, k - 23, AbyssalCraft.ethaxiumbrick, 0, 0);
		world.setBlock(i - 6, j + 0, k - 22, AbyssalCraft.ethaxiumbrick, 0, 0);
		world.setBlock(i - 6, j + 0, k - 21, AbyssalCraft.ethaxiumbrick, 0, 0);
		world.setBlock(i - 6, j + 0, k - 20, AbyssalCraft.ethaxiumbrick, 0, 0);
		world.setBlock(i - 6, j + 0, k - 19, AbyssalCraft.ethaxiumbrick, 0, 0);
		world.setBlock(i - 6, j + 0, k - 18, AbyssalCraft.ethaxiumbrick, 0, 0);
		world.setBlock(i - 6, j + 0, k - 17, AbyssalCraft.ethaxiumbrick, 0, 0);
		world.setBlock(i - 6, j + 0, k - 16, AbyssalCraft.ethaxiumbrick, 0, 0);
		world.setBlock(i - 6, j + 0, k - 15, AbyssalCraft.ethaxiumbrick, 0, 0);
		world.setBlock(i - 6, j + 0, k - 14, AbyssalCraft.ethaxiumbrick, 0, 0);
		world.setBlock(i - 6, j + 0, k - 13, AbyssalCraft.ethaxiumbrick, 0, 0);
		world.setBlock(i - 6, j + 0, k - 12, AbyssalCraft.ethaxiumbrick, 0, 0);
		world.setBlock(i - 6, j + 0, k - 11, AbyssalCraft.ethaxiumbrick, 0, 0);
		world.setBlock(i - 6, j + 0, k - 10, AbyssalCraft.ethaxiumbrick, 0, 0);
		world.setBlock(i - 6, j + 0, k - 9, AbyssalCraft.ethaxiumbrick, 0, 0);
		world.setBlock(i - 6, j + 0, k - 8, AbyssalCraft.ethaxiumbrick, 0, 0);
		world.setBlock(i - 6, j + 0, k - 7, AbyssalCraft.ethaxiumbrick, 0, 0);
		world.setBlock(i - 6, j + 0, k - 6, AbyssalCraft.ethaxiumbrick, 0, 0);
		world.setBlock(i - 6, j + 0, k - 5, AbyssalCraft.ethaxiumbrick, 0, 0);
		world.setBlock(i - 6, j + 0, k - 4, AbyssalCraft.ethaxiumbrick, 0, 0);
		world.setBlock(i - 6, j + 0, k - 3, AbyssalCraft.ethaxiumbrick, 0, 0);
		world.setBlock(i - 6, j + 0, k - 2, AbyssalCraft.ethaxiumbrick, 0, 0);
		world.setBlock(i - 6, j + 1, k - 23, AbyssalCraft.ethaxiumbrick, 0, 0);
		world.setBlock(i - 6, j + 1, k - 22, AbyssalCraft.ethaxiumbrick, 0, 0);
		world.setBlock(i - 6, j + 1, k - 21, AbyssalCraft.Darkstone_cobble, 0, 0);
		world.setBlock(i - 6, j + 1, k - 20, AbyssalCraft.Darkstone_cobble, 0, 0);
		world.setBlock(i - 6, j + 1, k - 19, AbyssalCraft.Darkstone_cobble, 0, 0);
		world.setBlock(i - 6, j + 1, k - 18, AbyssalCraft.Darkstone_cobble, 0, 0);
		world.setBlock(i - 6, j + 1, k - 17, AbyssalCraft.Darkstone_cobble, 0, 0);
		world.setBlock(i - 6, j + 1, k - 16, AbyssalCraft.Darkstone_cobble, 0, 0);
		world.setBlock(i - 6, j + 1, k - 15, AbyssalCraft.Darkstone_cobble, 0, 0);
		world.setBlock(i - 6, j + 1, k - 14, AbyssalCraft.Darkstone_cobble, 0, 0);
		world.setBlock(i - 6, j + 1, k - 13, AbyssalCraft.Darkstone_cobble, 0, 0);
		world.setBlock(i - 6, j + 1, k - 12, AbyssalCraft.Darkstone_cobble, 0, 0);
		world.setBlock(i - 6, j + 1, k - 11, AbyssalCraft.Darkstone_cobble, 0, 0);
		world.setBlock(i - 6, j + 1, k - 10, AbyssalCraft.Darkstone_cobble, 0, 0);
		world.setBlock(i - 6, j + 1, k - 9, AbyssalCraft.Darkstone_cobble, 0, 0);
		world.setBlock(i - 6, j + 1, k - 8, AbyssalCraft.Darkstone_cobble, 0, 0);
		world.setBlock(i - 6, j + 1, k - 7, AbyssalCraft.Darkstone_cobble, 0, 0);
		world.setBlock(i - 6, j + 1, k - 6, AbyssalCraft.ethaxiumbrick, 0, 0);
		world.setBlock(i - 6, j + 1, k - 5, AbyssalCraft.ethaxiumbrick, 0, 0);
		world.setBlock(i - 6, j + 1, k - 4, AbyssalCraft.ethaxiumbrick, 0, 0);
		world.setBlock(i - 6, j + 1, k - 3, AbyssalCraft.ethaxiumbrick, 0, 0);
		world.setBlock(i - 6, j + 2, k - 23, AbyssalCraft.ethaxiumbrick, 0, 0);
		world.setBlock(i - 6, j + 2, k - 22, AbyssalCraft.Darkstone_brick, 0, 0);
		world.setBlock(i - 6, j + 2, k - 16, AbyssalCraft.Darkstone_brick, 0, 0);
		world.setBlock(i - 6, j + 2, k - 6, AbyssalCraft.Darkstone_brick, 0, 0);
		world.setBlock(i - 6, j + 2, k - 5, AbyssalCraft.ethaxiumbrick, 0, 0);
		world.setBlock(i - 6, j + 2, k - 4, AbyssalCraft.ethaxiumbrick, 0, 0);
		world.setBlock(i - 6, j + 2, k - 3, AbyssalCraft.ethaxiumbrick, 0, 0);
		world.setBlock(i - 6, j + 3, k - 23, AbyssalCraft.ethaxiumbrick, 0, 0);
		world.setBlock(i - 6, j + 3, k - 22, AbyssalCraft.Darkstone_brick, 0, 0);
		world.setBlock(i - 6, j + 3, k - 16, AbyssalCraft.Darkstone_brick, 0, 0);
		world.setBlock(i - 6, j + 3, k - 6, AbyssalCraft.Darkstone_brick, 0, 0);
		world.setBlock(i - 6, j + 3, k - 5, AbyssalCraft.ethaxiumbrick, 0, 0);
		world.setBlock(i - 6, j + 3, k - 4, AbyssalCraft.ethaxiumbrick, 0, 0);
		world.setBlock(i - 6, j + 3, k - 3, AbyssalCraft.ethaxiumbrick, 1, 0);
		world.setBlock(i - 6, j + 4, k - 23, AbyssalCraft.ethaxiumbrick, 0, 0);
		world.setBlock(i - 6, j + 4, k - 22, AbyssalCraft.Darkstone_brick, 0, 0);
		world.setBlock(i - 6, j + 4, k - 16, AbyssalCraft.Darkstone_brick, 0, 0);
		world.setBlock(i - 6, j + 4, k - 12, AbyssalCraft.Darkstone_brick, 0, 0);
		world.setBlock(i - 6, j + 4, k - 6, AbyssalCraft.Darkstone_brick, 0, 0);
		world.setBlock(i - 6, j + 4, k - 5, AbyssalCraft.ethaxiumbrick, 0, 0);
		world.setBlock(i - 6, j + 4, k - 4, AbyssalCraft.ethaxiumbrick, 0, 0);
		world.setBlock(i - 6, j + 4, k - 3, AbyssalCraft.ethaxiumbrick, 0, 0);
		world.setBlock(i - 6, j + 5, k - 23, AbyssalCraft.ethaxiumbrick, 0, 0);
		world.setBlock(i - 6, j + 5, k - 22, AbyssalCraft.ethaxiumbrick, 0, 0);
		world.setBlock(i - 6, j + 5, k - 21, AbyssalCraft.Darkstone_brick, 0, 0);
		world.setBlock(i - 6, j + 5, k - 20, AbyssalCraft.Darkstone_brick, 0, 0);
		world.setBlock(i - 6, j + 5, k - 19, AbyssalCraft.Darkstone_brick, 0, 0);
		world.setBlock(i - 6, j + 5, k - 18, AbyssalCraft.Darkstone_brick, 0, 0);
		world.setBlock(i - 6, j + 5, k - 17, AbyssalCraft.Darkstone_brick, 0, 0);
		world.setBlock(i - 6, j + 5, k - 16, AbyssalCraft.Darkstone_brick, 0, 0);
		world.setBlock(i - 6, j + 5, k - 15, AbyssalCraft.Darkstone_brick, 0, 0);
		world.setBlock(i - 6, j + 5, k - 14, AbyssalCraft.Darkstone_brick, 0, 0);
		world.setBlock(i - 6, j + 5, k - 13, AbyssalCraft.Darkstone_brick, 0, 0);
		world.setBlock(i - 6, j + 5, k - 12, AbyssalCraft.Darkstone_brick, 0, 0);
		world.setBlock(i - 6, j + 5, k - 11, AbyssalCraft.Darkstone_brick, 0, 0);
		world.setBlock(i - 6, j + 5, k - 10, AbyssalCraft.Darkstone_brick, 0, 0);
		world.setBlock(i - 6, j + 5, k - 9, AbyssalCraft.Darkstone_brick, 0, 0);
		world.setBlock(i - 6, j + 5, k - 8, AbyssalCraft.Darkstone_brick, 0, 0);
		world.setBlock(i - 6, j + 5, k - 7, AbyssalCraft.Darkstone_brick, 0, 0);
		world.setBlock(i - 6, j + 5, k - 6, AbyssalCraft.ethaxiumbrick, 0, 0);
		world.setBlock(i - 6, j + 5, k - 5, AbyssalCraft.ethaxiumbrick, 0, 0);
		world.setBlock(i - 6, j + 5, k - 4, AbyssalCraft.ethaxiumbrick, 0, 0);
		world.setBlock(i - 6, j + 5, k - 3, AbyssalCraft.ethaxiumbrick, 0, 0);
		world.setBlock(i - 6, j + 6, k - 23, AbyssalCraft.ethaxiumstairs, 2, 0);
		world.setBlock(i - 6, j + 6, k - 22, AbyssalCraft.ethaxiumbrick, 0, 0);
		world.setBlock(i - 6, j + 6, k - 21, AbyssalCraft.ethaxiumbrick, 0, 0);
		world.setBlock(i - 6, j + 6, k - 20, AbyssalCraft.ethaxiumbrick, 0, 0);
		world.setBlock(i - 6, j + 6, k - 19, AbyssalCraft.ethaxiumbrick, 0, 0);
		world.setBlock(i - 6, j + 6, k - 18, AbyssalCraft.ethaxiumbrick, 0, 0);
		world.setBlock(i - 6, j + 6, k - 17, AbyssalCraft.ethaxiumbrick, 0, 0);
		world.setBlock(i - 6, j + 6, k - 16, AbyssalCraft.ethaxiumbrick, 0, 0);
		world.setBlock(i - 6, j + 6, k - 15, AbyssalCraft.ethaxiumbrick, 0, 0);
		world.setBlock(i - 6, j + 6, k - 14, AbyssalCraft.ethaxiumbrick, 0, 0);
		world.setBlock(i - 6, j + 6, k - 13, AbyssalCraft.ethaxiumbrick, 0, 0);
		world.setBlock(i - 6, j + 6, k - 12, AbyssalCraft.ethaxiumbrick, 0, 0);
		world.setBlock(i - 6, j + 6, k - 11, AbyssalCraft.ethaxiumbrick, 0, 0);
		world.setBlock(i - 6, j + 6, k - 10, AbyssalCraft.ethaxiumbrick, 0, 0);
		world.setBlock(i - 6, j + 6, k - 9, AbyssalCraft.ethaxiumbrick, 0, 0);
		world.setBlock(i - 6, j + 6, k - 8, AbyssalCraft.ethaxiumbrick, 0, 0);
		world.setBlock(i - 6, j + 6, k - 7, AbyssalCraft.ethaxiumbrick, 0, 0);
		world.setBlock(i - 6, j + 6, k - 6, AbyssalCraft.ethaxiumbrick, 0, 0);
		world.setBlock(i - 6, j + 6, k - 5, AbyssalCraft.ethaxiumbrick, 0, 0);
		world.setBlock(i - 6, j + 6, k - 4, AbyssalCraft.ethaxiumbrick, 0, 0);
		world.setBlock(i - 6, j + 6, k - 3, AbyssalCraft.ethaxiumbrick, 0, 0);
		world.setBlock(i - 6, j + 6, k - 2, AbyssalCraft.ethaxiumbrick, 0, 0);
		world.setBlock(i - 6, j + 6, k - 1, AbyssalCraft.ethaxiumstairs, 3, 0);
		world.setBlock(i - 5, j + 0, k - 23, AbyssalCraft.ethaxiumbrick, 0, 0);
		world.setBlock(i - 5, j + 0, k - 22, AbyssalCraft.ethaxiumbrick, 0, 0);
		world.setBlock(i - 5, j + 0, k - 21, AbyssalCraft.ethaxiumbrick, 0, 0);
		world.setBlock(i - 5, j + 0, k - 20, AbyssalCraft.ethaxiumbrick, 0, 0);
		world.setBlock(i - 5, j + 0, k - 19, AbyssalCraft.ethaxiumbrick, 0, 0);
		world.setBlock(i - 5, j + 0, k - 18, AbyssalCraft.ethaxiumbrick, 0, 0);
		world.setBlock(i - 5, j + 0, k - 17, AbyssalCraft.ethaxiumbrick, 0, 0);
		world.setBlock(i - 5, j + 0, k - 16, AbyssalCraft.ethaxiumbrick, 0, 0);
		world.setBlock(i - 5, j + 0, k - 15, AbyssalCraft.ethaxiumbrick, 0, 0);
		world.setBlock(i - 5, j + 0, k - 14, AbyssalCraft.ethaxiumbrick, 0, 0);
		world.setBlock(i - 5, j + 0, k - 13, AbyssalCraft.ethaxiumbrick, 0, 0);
		world.setBlock(i - 5, j + 0, k - 12, AbyssalCraft.ethaxiumbrick, 0, 0);
		world.setBlock(i - 5, j + 0, k - 11, AbyssalCraft.ethaxiumbrick, 0, 0);
		world.setBlock(i - 5, j + 0, k - 10, AbyssalCraft.ethaxiumbrick, 0, 0);
		world.setBlock(i - 5, j + 0, k - 9, AbyssalCraft.ethaxiumbrick, 0, 0);
		world.setBlock(i - 5, j + 0, k - 8, AbyssalCraft.ethaxiumbrick, 0, 0);
		world.setBlock(i - 5, j + 0, k - 7, AbyssalCraft.ethaxiumbrick, 0, 0);
		world.setBlock(i - 5, j + 0, k - 6, AbyssalCraft.ethaxiumbrick, 0, 0);
		world.setBlock(i - 5, j + 0, k - 5, AbyssalCraft.ethaxiumbrick, 0, 0);
		world.setBlock(i - 5, j + 0, k - 4, AbyssalCraft.ethaxiumbrick, 0, 0);
		world.setBlock(i - 5, j + 0, k - 3, AbyssalCraft.ethaxiumbrick, 0, 0);
		world.setBlock(i - 5, j + 0, k - 2, AbyssalCraft.ethaxiumbrick, 0, 0);
		world.setBlock(i - 5, j + 1, k - 23, AbyssalCraft.ethaxiumbrick, 0, 0);
		world.setBlock(i - 5, j + 1, k - 22, AbyssalCraft.ethaxiumbrick, 0, 0);
		world.setBlock(i - 5, j + 1, k - 21, AbyssalCraft.Darkstone_cobble, 0, 0);
		world.setBlock(i - 5, j + 1, k - 20, AbyssalCraft.Darkstone_cobble, 0, 0);
		world.setBlock(i - 5, j + 1, k - 19, AbyssalCraft.Darkstone_cobble, 0, 0);
		world.setBlock(i - 5, j + 1, k - 18, AbyssalCraft.Darkstone_cobble, 0, 0);
		world.setBlock(i - 5, j + 1, k - 17, AbyssalCraft.Darkstone_cobble, 0, 0);
		world.setBlock(i - 5, j + 1, k - 16, AbyssalCraft.Darkstone_cobble, 0, 0);
		world.setBlock(i - 5, j + 1, k - 15, AbyssalCraft.Darkstone_cobble, 0, 0);
		world.setBlock(i - 5, j + 1, k - 14, AbyssalCraft.Darkstone_cobble, 0, 0);
		world.setBlock(i - 5, j + 1, k - 13, AbyssalCraft.Darkstone_cobble, 0, 0);
		world.setBlock(i - 5, j + 1, k - 12, AbyssalCraft.Darkstone_cobble, 0, 0);
		world.setBlock(i - 5, j + 1, k - 11, AbyssalCraft.Darkstone_cobble, 0, 0);
		world.setBlock(i - 5, j + 1, k - 10, AbyssalCraft.Darkstone_cobble, 0, 0);
		world.setBlock(i - 5, j + 1, k - 9, AbyssalCraft.Darkstone_cobble, 0, 0);
		world.setBlock(i - 5, j + 1, k - 8, AbyssalCraft.Darkstone_cobble, 0, 0);
		world.setBlock(i - 5, j + 1, k - 7, AbyssalCraft.Darkstone_cobble, 0, 0);
		world.setBlock(i - 5, j + 1, k - 6, AbyssalCraft.ethaxiumbrick, 0, 0);
		world.setBlock(i - 5, j + 1, k - 5, AbyssalCraft.ethaxiumbrick, 0, 0);
		world.setBlock(i - 5, j + 1, k - 4, AbyssalCraft.ethaxiumbrick, 0, 0);
		world.setBlock(i - 5, j + 1, k - 3, AbyssalCraft.ethaxiumbrick, 0, 0);
		world.setBlock(i - 5, j + 2, k - 23, AbyssalCraft.ethaxiumbrick, 0, 0);
		world.setBlock(i - 5, j + 2, k - 22, AbyssalCraft.Darkstone_brick, 0, 0);
		world.setBlock(i - 5, j + 2, k - 12, AbyssalCraft.Darkstone_brick, 0, 0);
		world.setBlock(i - 5, j + 2, k - 11, AbyssalCraft.Darkstone_brick, 0, 0);
		world.setBlock(i - 5, j + 2, k - 10, AbyssalCraft.Darkstone_brick, 0, 0);
		world.setBlock(i - 5, j + 2, k - 9, AbyssalCraft.Darkstone_brick, 0, 0);
		world.setBlock(i - 5, j + 2, k - 8, AbyssalCraft.Darkstone_brick, 0, 0);
		world.setBlock(i - 5, j + 2, k - 7, AbyssalCraft.Darkstone_brick, 0, 0);
		world.setBlock(i - 5, j + 2, k - 6, AbyssalCraft.Darkstone_brick, 0, 0);
		world.setBlock(i - 5, j + 2, k - 5, AbyssalCraft.ethaxiumbrick, 0, 0);
		world.setBlock(i - 5, j + 2, k - 3, AbyssalCraft.ethaxiumfence, 0, 0);
		world.setBlock(i - 5, j + 3, k - 23, AbyssalCraft.ethaxiumbrick, 0, 0);
		world.setBlock(i - 5, j + 3, k - 22, AbyssalCraft.Darkstone_brick, 0, 0);
		world.setBlock(i - 5, j + 3, k - 12, AbyssalCraft.Darkstone_brick, 0, 0);
		world.setBlock(i - 5, j + 3, k - 11, AbyssalCraft.Darkstone_brick, 0, 0);
		world.setBlock(i - 5, j + 3, k - 10, AbyssalCraft.Darkstone_brick, 0, 0);
		world.setBlock(i - 5, j + 3, k - 9, AbyssalCraft.Darkstone_brick, 0, 0);
		world.setBlock(i - 5, j + 3, k - 8, AbyssalCraft.Darkstone_brick, 0, 0);
		world.setBlock(i - 5, j + 3, k - 7, AbyssalCraft.Darkstone_brick, 0, 0);
		world.setBlock(i - 5, j + 3, k - 6, AbyssalCraft.Darkstone_brick, 0, 0);
		world.setBlock(i - 5, j + 3, k - 5, AbyssalCraft.ethaxiumbrick, 0, 0);
		world.setBlock(i - 5, j + 3, k - 3, AbyssalCraft.ethaxiumfence, 0, 0);
		world.setBlock(i - 5, j + 4, k - 23, AbyssalCraft.ethaxiumbrick, 0, 0);
		world.setBlock(i - 5, j + 4, k - 22, AbyssalCraft.Darkstone_brick, 0, 0);
		world.setBlock(i - 5, j + 4, k - 16, AbyssalCraft.Darkstone_brick, 0, 0);
		world.setBlock(i - 5, j + 4, k - 12, AbyssalCraft.Darkstone_brick, 0, 0);
		world.setBlock(i - 5, j + 4, k - 11, AbyssalCraft.Darkstone_brick, 0, 0);
		world.setBlock(i - 5, j + 4, k - 10, AbyssalCraft.Darkstone_brick, 0, 0);
		world.setBlock(i - 5, j + 4, k - 9, AbyssalCraft.Darkstone_brick, 0, 0);
		world.setBlock(i - 5, j + 4, k - 8, AbyssalCraft.Darkstone_brick, 0, 0);
		world.setBlock(i - 5, j + 4, k - 7, AbyssalCraft.Darkstone_brick, 0, 0);
		world.setBlock(i - 5, j + 4, k - 6, AbyssalCraft.Darkstone_brick, 0, 0);
		world.setBlock(i - 5, j + 4, k - 5, AbyssalCraft.ethaxiumbrick, 0, 0);
		world.setBlock(i - 5, j + 4, k - 3, AbyssalCraft.ethaxiumfence, 0, 0);
		world.setBlock(i - 5, j + 5, k - 23, AbyssalCraft.ethaxiumbrick, 0, 0);
		world.setBlock(i - 5, j + 5, k - 22, AbyssalCraft.ethaxiumbrick, 0, 0);
		world.setBlock(i - 5, j + 5, k - 21, AbyssalCraft.Darkstone_brick, 0, 0);
		world.setBlock(i - 5, j + 5, k - 20, AbyssalCraft.Darkstone_brick, 0, 0);
		world.setBlock(i - 5, j + 5, k - 19, AbyssalCraft.Darkstone_brick, 0, 0);
		world.setBlock(i - 5, j + 5, k - 18, AbyssalCraft.Darkstone_brick, 0, 0);
		world.setBlock(i - 5, j + 5, k - 17, AbyssalCraft.Darkstone_brick, 0, 0);
		world.setBlock(i - 5, j + 5, k - 16, AbyssalCraft.Darkstone_brick, 0, 0);
		world.setBlock(i - 5, j + 5, k - 15, AbyssalCraft.Darkstone_brick, 0, 0);
		world.setBlock(i - 5, j + 5, k - 14, AbyssalCraft.Darkstone_brick, 0, 0);
		world.setBlock(i - 5, j + 5, k - 13, AbyssalCraft.Darkstone_brick, 0, 0);
		world.setBlock(i - 5, j + 5, k - 12, AbyssalCraft.Darkstone_brick, 0, 0);
		world.setBlock(i - 5, j + 5, k - 11, AbyssalCraft.Darkstone_brick, 0, 0);
		world.setBlock(i - 5, j + 5, k - 10, AbyssalCraft.Darkstone_brick, 0, 0);
		world.setBlock(i - 5, j + 5, k - 9, AbyssalCraft.Darkstone_brick, 0, 0);
		world.setBlock(i - 5, j + 5, k - 8, AbyssalCraft.Darkstone_brick, 0, 0);
		world.setBlock(i - 5, j + 5, k - 7, AbyssalCraft.Darkstone_brick, 0, 0);
		world.setBlock(i - 5, j + 5, k - 6, AbyssalCraft.ethaxiumbrick, 0, 0);
		world.setBlock(i - 5, j + 5, k - 5, AbyssalCraft.ethaxiumbrick, 0, 0);
		world.setBlock(i - 5, j + 5, k - 3, AbyssalCraft.ethaxiumbrick, 0, 0);
		world.setBlock(i - 5, j + 6, k - 23, AbyssalCraft.ethaxiumstairs, 2, 0);
		world.setBlock(i - 5, j + 6, k - 22, AbyssalCraft.ethaxiumbrick, 0, 0);
		world.setBlock(i - 5, j + 6, k - 21, AbyssalCraft.ethaxiumbrick, 0, 0);
		world.setBlock(i - 5, j + 6, k - 20, AbyssalCraft.ethaxiumbrick, 0, 0);
		world.setBlock(i - 5, j + 6, k - 19, AbyssalCraft.ethaxiumbrick, 0, 0);
		world.setBlock(i - 5, j + 6, k - 18, AbyssalCraft.ethaxiumbrick, 0, 0);
		world.setBlock(i - 5, j + 6, k - 17, AbyssalCraft.ethaxiumbrick, 0, 0);
		world.setBlock(i - 5, j + 6, k - 16, AbyssalCraft.ethaxiumbrick, 0, 0);
		world.setBlock(i - 5, j + 6, k - 15, AbyssalCraft.ethaxiumbrick, 0, 0);
		world.setBlock(i - 5, j + 6, k - 14, AbyssalCraft.ethaxiumbrick, 0, 0);
		world.setBlock(i - 5, j + 6, k - 13, AbyssalCraft.ethaxiumbrick, 0, 0);
		world.setBlock(i - 5, j + 6, k - 12, AbyssalCraft.ethaxiumbrick, 0, 0);
		world.setBlock(i - 5, j + 6, k - 11, AbyssalCraft.ethaxiumbrick, 0, 0);
		world.setBlock(i - 5, j + 6, k - 10, AbyssalCraft.ethaxiumbrick, 0, 0);
		world.setBlock(i - 5, j + 6, k - 9, AbyssalCraft.ethaxiumbrick, 0, 0);
		world.setBlock(i - 5, j + 6, k - 8, AbyssalCraft.ethaxiumbrick, 0, 0);
		world.setBlock(i - 5, j + 6, k - 7, AbyssalCraft.ethaxiumbrick, 0, 0);
		world.setBlock(i - 5, j + 6, k - 6, AbyssalCraft.ethaxiumbrick, 0, 0);
		world.setBlock(i - 5, j + 6, k - 5, AbyssalCraft.ethaxiumbrick, 0, 0);
		world.setBlock(i - 5, j + 6, k - 4, AbyssalCraft.ethaxiumbrick, 0, 0);
		world.setBlock(i - 5, j + 6, k - 3, AbyssalCraft.ethaxiumbrick, 0, 0);
		world.setBlock(i - 5, j + 6, k - 2, AbyssalCraft.ethaxiumbrick, 0, 0);
		world.setBlock(i - 5, j + 6, k - 1, AbyssalCraft.ethaxiumstairs, 3, 0);
		world.setBlock(i - 4, j + 0, k - 23, AbyssalCraft.ethaxiumbrick, 0, 0);
		world.setBlock(i - 4, j + 0, k - 22, AbyssalCraft.ethaxiumbrick, 0, 0);
		world.setBlock(i - 4, j + 0, k - 21, AbyssalCraft.ethaxiumbrick, 0, 0);
		world.setBlock(i - 4, j + 0, k - 20, AbyssalCraft.ethaxiumbrick, 0, 0);
		world.setBlock(i - 4, j + 0, k - 19, AbyssalCraft.ethaxiumbrick, 0, 0);
		world.setBlock(i - 4, j + 0, k - 18, AbyssalCraft.ethaxiumbrick, 0, 0);
		world.setBlock(i - 4, j + 0, k - 17, AbyssalCraft.ethaxiumbrick, 0, 0);
		world.setBlock(i - 4, j + 0, k - 16, AbyssalCraft.ethaxiumbrick, 0, 0);
		world.setBlock(i - 4, j + 0, k - 15, AbyssalCraft.ethaxiumbrick, 0, 0);
		world.setBlock(i - 4, j + 0, k - 14, AbyssalCraft.ethaxiumbrick, 0, 0);
		world.setBlock(i - 4, j + 0, k - 13, AbyssalCraft.ethaxiumbrick, 0, 0);
		world.setBlock(i - 4, j + 0, k - 12, AbyssalCraft.ethaxiumbrick, 0, 0);
		world.setBlock(i - 4, j + 0, k - 11, AbyssalCraft.ethaxiumbrick, 0, 0);
		world.setBlock(i - 4, j + 0, k - 10, AbyssalCraft.ethaxiumbrick, 0, 0);
		world.setBlock(i - 4, j + 0, k - 9, AbyssalCraft.ethaxiumbrick, 0, 0);
		world.setBlock(i - 4, j + 0, k - 8, AbyssalCraft.ethaxiumbrick, 0, 0);
		world.setBlock(i - 4, j + 0, k - 7, AbyssalCraft.ethaxiumbrick, 0, 0);
		world.setBlock(i - 4, j + 0, k - 6, AbyssalCraft.ethaxiumbrick, 0, 0);
		world.setBlock(i - 4, j + 0, k - 5, AbyssalCraft.ethaxiumbrick, 0, 0);
		world.setBlock(i - 4, j + 0, k - 4, AbyssalCraft.ethaxiumbrick, 0, 0);
		world.setBlock(i - 4, j + 0, k - 3, AbyssalCraft.ethaxiumbrick, 0, 0);
		world.setBlock(i - 4, j + 0, k - 2, AbyssalCraft.ethaxiumbrick, 0, 0);
		world.setBlock(i - 4, j + 1, k - 23, AbyssalCraft.ethaxiumbrick, 0, 0);
		world.setBlock(i - 4, j + 1, k - 22, AbyssalCraft.ethaxiumbrick, 0, 0);
		world.setBlock(i - 4, j + 1, k - 21, AbyssalCraft.Darkstone_cobble, 0, 0);
		world.setBlock(i - 4, j + 1, k - 20, AbyssalCraft.Darkstone_cobble, 0, 0);
		world.setBlock(i - 4, j + 1, k - 19, AbyssalCraft.Darkstone_cobble, 0, 0);
		world.setBlock(i - 4, j + 1, k - 18, AbyssalCraft.Darkstone_cobble, 0, 0);
		world.setBlock(i - 4, j + 1, k - 17, AbyssalCraft.Darkstone_cobble, 0, 0);
		world.setBlock(i - 4, j + 1, k - 16, AbyssalCraft.Darkstone_cobble, 0, 0);
		world.setBlock(i - 4, j + 1, k - 15, AbyssalCraft.Darkstone_cobble, 0, 0);
		world.setBlock(i - 4, j + 1, k - 14, AbyssalCraft.Darkstone_cobble, 0, 0);
		world.setBlock(i - 4, j + 1, k - 13, AbyssalCraft.Darkstone_cobble, 0, 0);
		world.setBlock(i - 4, j + 1, k - 12, AbyssalCraft.Darkstone_cobble, 0, 0);
		world.setBlock(i - 4, j + 1, k - 11, AbyssalCraft.Darkstone_cobble, 0, 0);
		world.setBlock(i - 4, j + 1, k - 10, AbyssalCraft.Darkstone_cobble, 0, 0);
		world.setBlock(i - 4, j + 1, k - 9, AbyssalCraft.Darkstone_cobble, 0, 0);
		world.setBlock(i - 4, j + 1, k - 8, AbyssalCraft.Darkstone_cobble, 0, 0);
		world.setBlock(i - 4, j + 1, k - 7, AbyssalCraft.Darkstone_cobble, 0, 0);
		world.setBlock(i - 4, j + 1, k - 6, AbyssalCraft.ethaxiumbrick, 0, 0);
		world.setBlock(i - 4, j + 1, k - 5, AbyssalCraft.ethaxiumbrick, 0, 0);
		world.setBlock(i - 4, j + 1, k - 4, AbyssalCraft.ethaxiumbrick, 0, 0);
		world.setBlock(i - 4, j + 1, k - 3, AbyssalCraft.ethaxiumbrick, 0, 0);
		world.setBlock(i - 4, j + 2, k - 23, AbyssalCraft.ethaxiumbrick, 0, 0);
		world.setBlock(i - 4, j + 2, k - 22, AbyssalCraft.Darkstone_brick, 0, 0);
		world.setBlock(i - 4, j + 2, k - 16, AbyssalCraft.Darkstone_brick, 0, 0);
		world.setBlock(i - 4, j + 2, k - 6, AbyssalCraft.Darkstone_brick, 0, 0);
		world.setBlock(i - 4, j + 2, k - 5, AbyssalCraft.ethaxiumbrick, 0, 0);
		world.setBlock(i - 4, j + 2, k - 4, AbyssalCraft.ethaxiumbrick, 0, 0);
		world.setBlock(i - 4, j + 2, k - 3, AbyssalCraft.ethaxiumbrick, 0, 0);
		world.setBlock(i - 4, j + 3, k - 23, AbyssalCraft.ethaxiumbrick, 0, 0);
		world.setBlock(i - 4, j + 3, k - 22, AbyssalCraft.Darkstone_brick, 0, 0);
		world.setBlock(i - 4, j + 3, k - 16, AbyssalCraft.Darkstone_brick, 0, 0);
		world.setBlock(i - 4, j + 3, k - 6, AbyssalCraft.Darkstone_brick, 0, 0);
		world.setBlock(i - 4, j + 3, k - 5, AbyssalCraft.ethaxiumbrick, 0, 0);
		world.setBlock(i - 4, j + 3, k - 4, AbyssalCraft.ethaxiumbrick, 0, 0);
		world.setBlock(i - 4, j + 3, k - 3, AbyssalCraft.ethaxiumbrick, 0, 0);
		world.setBlock(i - 4, j + 4, k - 23, AbyssalCraft.ethaxiumbrick, 0, 0);
		world.setBlock(i - 4, j + 4, k - 22, AbyssalCraft.Darkstone_brick, 0, 0);
		world.setBlock(i - 4, j + 4, k - 16, AbyssalCraft.Darkstone_brick, 0, 0);
		world.setBlock(i - 4, j + 4, k - 6, AbyssalCraft.Darkstone_brick, 0, 0);
		world.setBlock(i - 4, j + 4, k - 5, AbyssalCraft.ethaxiumbrick, 0, 0);
		world.setBlock(i - 4, j + 4, k - 4, AbyssalCraft.ethaxiumbrick, 0, 0);
		world.setBlock(i - 4, j + 4, k - 3, AbyssalCraft.ethaxiumbrick, 0, 0);
		world.setBlock(i - 4, j + 5, k - 23, AbyssalCraft.ethaxiumbrick, 0, 0);
		world.setBlock(i - 4, j + 5, k - 22, AbyssalCraft.ethaxiumbrick, 0, 0);
		world.setBlock(i - 4, j + 5, k - 21, AbyssalCraft.Darkstone_brick, 0, 0);
		world.setBlock(i - 4, j + 5, k - 20, AbyssalCraft.Darkstone_brick, 0, 0);
		world.setBlock(i - 4, j + 5, k - 19, AbyssalCraft.Darkstone_brick, 0, 0);
		world.setBlock(i - 4, j + 5, k - 18, AbyssalCraft.Darkstone_brick, 0, 0);
		world.setBlock(i - 4, j + 5, k - 17, AbyssalCraft.Darkstone_brick, 0, 0);
		world.setBlock(i - 4, j + 5, k - 16, AbyssalCraft.Darkstone_brick, 0, 0);
		world.setBlock(i - 4, j + 5, k - 15, AbyssalCraft.Darkstone_brick, 0, 0);
		world.setBlock(i - 4, j + 5, k - 14, AbyssalCraft.Darkstone_brick, 0, 0);
		world.setBlock(i - 4, j + 5, k - 13, AbyssalCraft.Darkstone_brick, 0, 0);
		world.setBlock(i - 4, j + 5, k - 12, AbyssalCraft.Darkstone_brick, 0, 0);
		world.setBlock(i - 4, j + 5, k - 11, AbyssalCraft.Darkstone_brick, 0, 0);
		world.setBlock(i - 4, j + 5, k - 10, AbyssalCraft.Darkstone_brick, 0, 0);
		world.setBlock(i - 4, j + 5, k - 9, AbyssalCraft.Darkstone_brick, 0, 0);
		world.setBlock(i - 4, j + 5, k - 8, AbyssalCraft.Darkstone_brick, 0, 0);
		world.setBlock(i - 4, j + 5, k - 7, AbyssalCraft.Darkstone_brick, 0, 0);
		world.setBlock(i - 4, j + 5, k - 6, AbyssalCraft.ethaxiumbrick, 0, 0);
		world.setBlock(i - 4, j + 5, k - 5, AbyssalCraft.ethaxiumbrick, 0, 0);
		world.setBlock(i - 4, j + 5, k - 4, AbyssalCraft.ethaxiumbrick, 0, 0);
		world.setBlock(i - 4, j + 5, k - 3, AbyssalCraft.ethaxiumbrick, 0, 0);
		world.setBlock(i - 4, j + 6, k - 23, AbyssalCraft.ethaxiumstairs, 2, 0);
		world.setBlock(i - 4, j + 6, k - 22, AbyssalCraft.ethaxiumbrick, 0, 0);
		world.setBlock(i - 4, j + 6, k - 21, AbyssalCraft.ethaxiumbrick, 0, 0);
		world.setBlock(i - 4, j + 6, k - 20, AbyssalCraft.ethaxiumbrick, 0, 0);
		world.setBlock(i - 4, j + 6, k - 19, AbyssalCraft.ethaxiumbrick, 0, 0);
		world.setBlock(i - 4, j + 6, k - 18, AbyssalCraft.ethaxiumbrick, 0, 0);
		world.setBlock(i - 4, j + 6, k - 17, AbyssalCraft.ethaxiumbrick, 0, 0);
		world.setBlock(i - 4, j + 6, k - 16, AbyssalCraft.ethaxiumbrick, 0, 0);
		world.setBlock(i - 4, j + 6, k - 15, AbyssalCraft.ethaxiumbrick, 0, 0);
		world.setBlock(i - 4, j + 6, k - 14, AbyssalCraft.ethaxiumbrick, 0, 0);
		world.setBlock(i - 4, j + 6, k - 13, AbyssalCraft.ethaxiumbrick, 0, 0);
		world.setBlock(i - 4, j + 6, k - 12, AbyssalCraft.ethaxiumbrick, 0, 0);
		world.setBlock(i - 4, j + 6, k - 11, AbyssalCraft.ethaxiumbrick, 0, 0);
		world.setBlock(i - 4, j + 6, k - 10, AbyssalCraft.ethaxiumbrick, 0, 0);
		world.setBlock(i - 4, j + 6, k - 9, AbyssalCraft.ethaxiumbrick, 0, 0);
		world.setBlock(i - 4, j + 6, k - 8, AbyssalCraft.ethaxiumbrick, 0, 0);
		world.setBlock(i - 4, j + 6, k - 7, AbyssalCraft.ethaxiumbrick, 0, 0);
		world.setBlock(i - 4, j + 6, k - 6, AbyssalCraft.ethaxiumbrick, 0, 0);
		world.setBlock(i - 4, j + 6, k - 5, AbyssalCraft.ethaxiumbrick, 0, 0);
		world.setBlock(i - 4, j + 6, k - 4, AbyssalCraft.ethaxiumbrick, 0, 0);
		world.setBlock(i - 4, j + 6, k - 3, AbyssalCraft.ethaxiumbrick, 0, 0);
		world.setBlock(i - 4, j + 6, k - 2, AbyssalCraft.ethaxiumbrick, 0, 0);
		world.setBlock(i - 4, j + 6, k - 1, AbyssalCraft.ethaxiumstairs, 3, 0);
		world.setBlock(i - 3, j + 0, k - 23, AbyssalCraft.ethaxiumbrick, 0, 0);
		world.setBlock(i - 3, j + 0, k - 22, AbyssalCraft.ethaxiumbrick, 0, 0);
		world.setBlock(i - 3, j + 0, k - 21, AbyssalCraft.ethaxiumbrick, 0, 0);
		world.setBlock(i - 3, j + 0, k - 20, AbyssalCraft.ethaxiumbrick, 0, 0);
		world.setBlock(i - 3, j + 0, k - 19, AbyssalCraft.ethaxiumbrick, 0, 0);
		world.setBlock(i - 3, j + 0, k - 18, AbyssalCraft.ethaxiumbrick, 0, 0);
		world.setBlock(i - 3, j + 0, k - 17, AbyssalCraft.ethaxiumbrick, 0, 0);
		world.setBlock(i - 3, j + 0, k - 16, AbyssalCraft.ethaxiumbrick, 0, 0);
		world.setBlock(i - 3, j + 0, k - 15, AbyssalCraft.ethaxiumbrick, 0, 0);
		world.setBlock(i - 3, j + 0, k - 14, AbyssalCraft.ethaxiumbrick, 0, 0);
		world.setBlock(i - 3, j + 0, k - 13, AbyssalCraft.ethaxiumbrick, 0, 0);
		world.setBlock(i - 3, j + 0, k - 12, AbyssalCraft.ethaxiumbrick, 0, 0);
		world.setBlock(i - 3, j + 0, k - 11, AbyssalCraft.ethaxiumbrick, 0, 0);
		world.setBlock(i - 3, j + 0, k - 10, AbyssalCraft.ethaxiumbrick, 0, 0);
		world.setBlock(i - 3, j + 0, k - 9, AbyssalCraft.ethaxiumbrick, 0, 0);
		world.setBlock(i - 3, j + 0, k - 8, AbyssalCraft.ethaxiumbrick, 0, 0);
		world.setBlock(i - 3, j + 0, k - 7, AbyssalCraft.ethaxiumbrick, 0, 0);
		world.setBlock(i - 3, j + 0, k - 6, AbyssalCraft.ethaxiumbrick, 0, 0);
		world.setBlock(i - 3, j + 0, k - 5, AbyssalCraft.ethaxiumbrick, 0, 0);
		world.setBlock(i - 3, j + 0, k - 4, AbyssalCraft.ethaxiumbrick, 0, 0);
		world.setBlock(i - 3, j + 0, k - 3, AbyssalCraft.ethaxiumbrick, 0, 0);
		world.setBlock(i - 3, j + 0, k - 2, AbyssalCraft.ethaxiumbrick, 0, 0);
		world.setBlock(i - 3, j + 0, k - 1, AbyssalCraft.ethaxiumbrick, 0, 0);
		world.setBlock(i - 3, j + 1, k - 23, AbyssalCraft.ethaxiumbrick, 0, 0);
		world.setBlock(i - 3, j + 1, k - 22, AbyssalCraft.ethaxiumbrick, 0, 0);
		world.setBlock(i - 3, j + 1, k - 21, AbyssalCraft.Darkstone_cobble, 0, 0);
		world.setBlock(i - 3, j + 1, k - 20, AbyssalCraft.Darkstone_cobble, 0, 0);
		world.setBlock(i - 3, j + 1, k - 19, AbyssalCraft.Darkstone_cobble, 0, 0);
		world.setBlock(i - 3, j + 1, k - 18, AbyssalCraft.Darkstone_cobble, 0, 0);
		world.setBlock(i - 3, j + 1, k - 17, AbyssalCraft.Darkstone_cobble, 0, 0);
		world.setBlock(i - 3, j + 1, k - 16, AbyssalCraft.Darkstone_cobble, 0, 0);
		world.setBlock(i - 3, j + 1, k - 15, AbyssalCraft.Darkstone_cobble, 0, 0);
		world.setBlock(i - 3, j + 1, k - 14, AbyssalCraft.Darkstone_cobble, 0, 0);
		world.setBlock(i - 3, j + 1, k - 13, AbyssalCraft.Darkstone_cobble, 0, 0);
		world.setBlock(i - 3, j + 1, k - 12, AbyssalCraft.Darkstone_cobble, 0, 0);
		world.setBlock(i - 3, j + 1, k - 11, AbyssalCraft.Darkstone_cobble, 0, 0);
		world.setBlock(i - 3, j + 1, k - 10, AbyssalCraft.Darkstone_cobble, 0, 0);
		world.setBlock(i - 3, j + 1, k - 9, AbyssalCraft.Darkstone_cobble, 0, 0);
		world.setBlock(i - 3, j + 1, k - 8, AbyssalCraft.Darkstone_cobble, 0, 0);
		world.setBlock(i - 3, j + 1, k - 7, AbyssalCraft.Darkstone_cobble, 0, 0);
		world.setBlock(i - 3, j + 1, k - 6, AbyssalCraft.ethaxiumbrick, 0, 0);
		world.setBlock(i - 3, j + 1, k - 5, AbyssalCraft.ethaxiumbrick, 0, 0);
		world.setBlock(i - 3, j + 1, k - 4, AbyssalCraft.ethaxiumbrick, 0, 0);
		world.setBlock(i - 3, j + 1, k - 3, AbyssalCraft.ethaxiumbrick, 0, 0);
		world.setBlock(i - 3, j + 1, k - 2, AbyssalCraft.ethaxiumbrick, 0, 0);
		world.setBlock(i - 3, j + 1, k - 1, AbyssalCraft.ethaxiumpillar, 0, 0);
		world.setBlock(i - 3, j + 2, k - 23, AbyssalCraft.ethaxiumbrick, 0, 0);
		world.setBlock(i - 3, j + 2, k - 22, AbyssalCraft.Darkstone_brick, 0, 0);
		world.setBlock(i - 3, j + 2, k - 21, AbyssalCraft.Darkstone_brick, 0, 0);
		world.setBlock(i - 3, j + 2, k - 20, AbyssalCraft.Darkstone_brick, 0, 0);
		world.setBlock(i - 3, j + 2, k - 19, AbyssalCraft.Darkstone_brick, 0, 0);
		world.setBlock(i - 3, j + 2, k - 18, AbyssalCraft.Darkstone_brick, 0, 0);
		world.setBlock(i - 3, j + 2, k - 17, AbyssalCraft.Darkstone_brick, 0, 0);
		world.setBlock(i - 3, j + 2, k - 16, AbyssalCraft.Darkstone_brick, 0, 0);
		world.setBlock(i - 3, j + 2, k - 6, AbyssalCraft.Darkstone_brick, 0, 0);
		world.setBlock(i - 3, j + 2, k - 5, AbyssalCraft.ethaxiumbrick, 0, 0);
		world.setBlock(i - 3, j + 2, k - 4, AbyssalCraft.ethaxiumbrick, 0, 0);
		world.setBlock(i - 3, j + 2, k - 3, AbyssalCraft.ethaxiumbrick, 0, 0);
		world.setBlock(i - 3, j + 2, k - 2, AbyssalCraft.ethaxiumbrick, 0, 0);
		world.setBlock(i - 3, j + 2, k - 1, AbyssalCraft.ethaxiumpillar, 0, 0);
		world.setBlock(i - 3, j + 3, k - 23, AbyssalCraft.ethaxiumbrick, 0, 0);
		world.setBlock(i - 3, j + 3, k - 22, AbyssalCraft.Darkstone_brick, 0, 0);
		world.setBlock(i - 3, j + 3, k - 21, AbyssalCraft.Darkstone_brick, 0, 0);
		world.setBlock(i - 3, j + 3, k - 20, AbyssalCraft.Darkstone_brick, 0, 0);
		world.setBlock(i - 3, j + 3, k - 19, AbyssalCraft.Darkstone_brick, 0, 0);
		world.setBlock(i - 3, j + 3, k - 18, AbyssalCraft.Darkstone_brick, 0, 0);
		world.setBlock(i - 3, j + 3, k - 17, AbyssalCraft.Darkstone_brick, 0, 0);
		world.setBlock(i - 3, j + 3, k - 16, AbyssalCraft.Darkstone_brick, 0, 0);
		world.setBlock(i - 3, j + 3, k - 6, AbyssalCraft.Darkstone_brick, 0, 0);
		world.setBlock(i - 3, j + 3, k - 5, AbyssalCraft.ethaxiumbrick, 0, 0);
		world.setBlock(i - 3, j + 3, k - 4, AbyssalCraft.ethaxiumbrick, 0, 0);
		world.setBlock(i - 3, j + 3, k - 3, AbyssalCraft.ethaxiumbrick, 0, 0);
		world.setBlock(i - 3, j + 3, k - 2, AbyssalCraft.ethaxiumbrick, 0, 0);
		world.setBlock(i - 3, j + 3, k - 1, AbyssalCraft.ethaxiumpillar, 0, 0);
		world.setBlock(i - 3, j + 4, k - 23, AbyssalCraft.ethaxiumbrick, 0, 0);
		world.setBlock(i - 3, j + 4, k - 22, AbyssalCraft.Darkstone_brick, 0, 0);
		world.setBlock(i - 3, j + 4, k - 21, AbyssalCraft.Darkstone_brick, 0, 0);
		world.setBlock(i - 3, j + 4, k - 20, AbyssalCraft.Darkstone_brick, 0, 0);
		world.setBlock(i - 3, j + 4, k - 19, AbyssalCraft.Darkstone_brick, 0, 0);
		world.setBlock(i - 3, j + 4, k - 18, AbyssalCraft.Darkstone_brick, 0, 0);
		world.setBlock(i - 3, j + 4, k - 17, AbyssalCraft.Darkstone_brick, 0, 0);
		world.setBlock(i - 3, j + 4, k - 16, AbyssalCraft.Darkstone_brick, 0, 0);
		world.setBlock(i - 3, j + 4, k - 6, AbyssalCraft.Darkstone_brick, 0, 0);
		world.setBlock(i - 3, j + 4, k - 5, AbyssalCraft.ethaxiumbrick, 0, 0);
		world.setBlock(i - 3, j + 4, k - 4, AbyssalCraft.ethaxiumbrick, 0, 0);
		world.setBlock(i - 3, j + 4, k - 3, AbyssalCraft.ethaxiumbrick, 0, 0);
		world.setBlock(i - 3, j + 4, k - 2, AbyssalCraft.ethaxiumbrick, 0, 0);
		world.setBlock(i - 3, j + 4, k - 1, AbyssalCraft.ethaxiumpillar, 0, 0);
		world.setBlock(i - 3, j + 5, k - 23, AbyssalCraft.ethaxiumbrick, 0, 0);
		world.setBlock(i - 3, j + 5, k - 22, AbyssalCraft.ethaxiumbrick, 0, 0);
		world.setBlock(i - 3, j + 5, k - 21, AbyssalCraft.Darkstone_brick, 0, 0);
		world.setBlock(i - 3, j + 5, k - 20, AbyssalCraft.Darkstone_brick, 0, 0);
		world.setBlock(i - 3, j + 5, k - 19, AbyssalCraft.Darkstone_brick, 0, 0);
		world.setBlock(i - 3, j + 5, k - 18, AbyssalCraft.Darkstone_brick, 0, 0);
		world.setBlock(i - 3, j + 5, k - 17, AbyssalCraft.Darkstone_brick, 0, 0);
		world.setBlock(i - 3, j + 5, k - 16, AbyssalCraft.Darkstone_brick, 0, 0);
		world.setBlock(i - 3, j + 5, k - 15, AbyssalCraft.Darkstone_brick, 0, 0);
		world.setBlock(i - 3, j + 5, k - 14, AbyssalCraft.Darkstone_brick, 0, 0);
		world.setBlock(i - 3, j + 5, k - 13, AbyssalCraft.Darkstone_brick, 0, 0);
		world.setBlock(i - 3, j + 5, k - 12, AbyssalCraft.Darkstone_brick, 0, 0);
		world.setBlock(i - 3, j + 5, k - 11, AbyssalCraft.Darkstone_brick, 0, 0);
		world.setBlock(i - 3, j + 5, k - 10, AbyssalCraft.Darkstone_brick, 0, 0);
		world.setBlock(i - 3, j + 5, k - 9, AbyssalCraft.Darkstone_brick, 0, 0);
		world.setBlock(i - 3, j + 5, k - 8, AbyssalCraft.Darkstone_brick, 0, 0);
		world.setBlock(i - 3, j + 5, k - 7, AbyssalCraft.Darkstone_brick, 0, 0);
		world.setBlock(i - 3, j + 5, k - 6, AbyssalCraft.ethaxiumbrick, 0, 0);
		world.setBlock(i - 3, j + 5, k - 5, AbyssalCraft.ethaxiumbrick, 0, 0);
		world.setBlock(i - 3, j + 5, k - 4, AbyssalCraft.ethaxiumbrick, 0, 0);
		world.setBlock(i - 3, j + 5, k - 3, AbyssalCraft.ethaxiumbrick, 0, 0);
		world.setBlock(i - 3, j + 5, k - 2, AbyssalCraft.ethaxiumbrick, 0, 0);
		world.setBlock(i - 3, j + 5, k - 1, AbyssalCraft.ethaxiumpillar, 0, 0);
		world.setBlock(i - 3, j + 6, k - 23, AbyssalCraft.ethaxiumstairs, 2, 0);
		world.setBlock(i - 3, j + 6, k - 22, AbyssalCraft.ethaxiumbrick, 0, 0);
		world.setBlock(i - 3, j + 6, k - 21, AbyssalCraft.ethaxiumbrick, 0, 0);
		world.setBlock(i - 3, j + 6, k - 20, AbyssalCraft.ethaxiumbrick, 0, 0);
		world.setBlock(i - 3, j + 6, k - 19, AbyssalCraft.ethaxiumbrick, 0, 0);
		world.setBlock(i - 3, j + 6, k - 18, AbyssalCraft.ethaxiumbrick, 0, 0);
		world.setBlock(i - 3, j + 6, k - 17, AbyssalCraft.ethaxiumbrick, 0, 0);
		world.setBlock(i - 3, j + 6, k - 16, AbyssalCraft.ethaxiumbrick, 0, 0);
		world.setBlock(i - 3, j + 6, k - 15, AbyssalCraft.ethaxiumbrick, 0, 0);
		world.setBlock(i - 3, j + 6, k - 14, AbyssalCraft.ethaxiumbrick, 0, 0);
		world.setBlock(i - 3, j + 6, k - 13, AbyssalCraft.ethaxiumbrick, 0, 0);
		world.setBlock(i - 3, j + 6, k - 12, AbyssalCraft.ethaxiumbrick, 0, 0);
		world.setBlock(i - 3, j + 6, k - 11, AbyssalCraft.ethaxiumbrick, 0, 0);
		world.setBlock(i - 3, j + 6, k - 10, AbyssalCraft.ethaxiumbrick, 0, 0);
		world.setBlock(i - 3, j + 6, k - 9, AbyssalCraft.ethaxiumbrick, 0, 0);
		world.setBlock(i - 3, j + 6, k - 8, AbyssalCraft.ethaxiumbrick, 0, 0);
		world.setBlock(i - 3, j + 6, k - 7, AbyssalCraft.ethaxiumbrick, 0, 0);
		world.setBlock(i - 3, j + 6, k - 6, AbyssalCraft.ethaxiumbrick, 0, 0);
		world.setBlock(i - 3, j + 6, k - 5, AbyssalCraft.ethaxiumbrick, 0, 0);
		world.setBlock(i - 3, j + 6, k - 4, AbyssalCraft.ethaxiumbrick, 0, 0);
		world.setBlock(i - 3, j + 6, k - 3, AbyssalCraft.ethaxiumbrick, 0, 0);
		world.setBlock(i - 3, j + 6, k - 2, AbyssalCraft.ethaxiumbrick, 0, 0);
		world.setBlock(i - 3, j + 6, k - 1, AbyssalCraft.ethaxiumstairs, 3, 0);
		world.setBlock(i - 2, j + 0, k - 23, AbyssalCraft.ethaxiumbrick, 0, 0);
		world.setBlock(i - 2, j + 0, k - 22, AbyssalCraft.ethaxiumbrick, 0, 0);
		world.setBlock(i - 2, j + 0, k - 21, AbyssalCraft.ethaxiumbrick, 0, 0);
		world.setBlock(i - 2, j + 0, k - 20, AbyssalCraft.ethaxiumbrick, 0, 0);
		world.setBlock(i - 2, j + 0, k - 19, AbyssalCraft.ethaxiumbrick, 0, 0);
		world.setBlock(i - 2, j + 0, k - 18, AbyssalCraft.ethaxiumbrick, 0, 0);
		world.setBlock(i - 2, j + 0, k - 17, AbyssalCraft.ethaxiumbrick, 0, 0);
		world.setBlock(i - 2, j + 0, k - 16, AbyssalCraft.ethaxiumbrick, 0, 0);
		world.setBlock(i - 2, j + 0, k - 15, AbyssalCraft.ethaxiumbrick, 0, 0);
		world.setBlock(i - 2, j + 0, k - 14, AbyssalCraft.ethaxiumbrick, 0, 0);
		world.setBlock(i - 2, j + 0, k - 13, AbyssalCraft.ethaxiumbrick, 0, 0);
		world.setBlock(i - 2, j + 0, k - 12, AbyssalCraft.ethaxiumbrick, 0, 0);
		world.setBlock(i - 2, j + 0, k - 11, AbyssalCraft.ethaxiumbrick, 0, 0);
		world.setBlock(i - 2, j + 0, k - 10, AbyssalCraft.ethaxiumbrick, 0, 0);
		world.setBlock(i - 2, j + 0, k - 9, AbyssalCraft.ethaxiumbrick, 0, 0);
		world.setBlock(i - 2, j + 0, k - 8, AbyssalCraft.ethaxiumbrick, 0, 0);
		world.setBlock(i - 2, j + 0, k - 7, AbyssalCraft.ethaxiumbrick, 0, 0);
		world.setBlock(i - 2, j + 0, k - 6, AbyssalCraft.ethaxiumbrick, 0, 0);
		world.setBlock(i - 2, j + 0, k - 5, AbyssalCraft.ethaxiumbrick, 0, 0);
		world.setBlock(i - 2, j + 0, k - 4, AbyssalCraft.ethaxiumbrick, 0, 0);
		world.setBlock(i - 2, j + 0, k - 3, AbyssalCraft.ethaxiumbrick, 0, 0);
		world.setBlock(i - 2, j + 0, k - 2, AbyssalCraft.ethaxiumbrick, 0, 0);
		world.setBlock(i - 2, j + 0, k - 1, AbyssalCraft.ethaxiumstairs, 3, 0);
		world.setBlock(i - 2, j + 1, k - 23, AbyssalCraft.ethaxiumbrick, 0, 0);
		world.setBlock(i - 2, j + 1, k - 22, AbyssalCraft.ethaxiumbrick, 0, 0);
		world.setBlock(i - 2, j + 1, k - 21, AbyssalCraft.Darkstone, 0, 0);
		world.setBlock(i - 2, j + 1, k - 20, AbyssalCraft.Darkstone, 0, 0);
		world.setBlock(i - 2, j + 1, k - 19, AbyssalCraft.Darkstone, 0, 0);
		world.setBlock(i - 2, j + 1, k - 18, AbyssalCraft.Darkstone, 0, 0);
		world.setBlock(i - 2, j + 1, k - 17, AbyssalCraft.Darkstone, 0, 0);
		world.setBlock(i - 2, j + 1, k - 16, AbyssalCraft.Darkstone_cobble, 0, 0);
		world.setBlock(i - 2, j + 1, k - 15, AbyssalCraft.Darkstone_cobble, 0, 0);
		world.setBlock(i - 2, j + 1, k - 14, AbyssalCraft.Darkstone_cobble, 0, 0);
		world.setBlock(i - 2, j + 1, k - 13, AbyssalCraft.Darkstone_cobble, 0, 0);
		world.setBlock(i - 2, j + 1, k - 12, AbyssalCraft.Darkstone_cobble, 0, 0);
		world.setBlock(i - 2, j + 1, k - 11, AbyssalCraft.Darkstone_cobble, 0, 0);
		world.setBlock(i - 2, j + 1, k - 10, AbyssalCraft.Darkstone_cobble, 0, 0);
		world.setBlock(i - 2, j + 1, k - 9, AbyssalCraft.Darkstone_cobble, 0, 0);
		world.setBlock(i - 2, j + 1, k - 8, AbyssalCraft.Darkstone_cobble, 0, 0);
		world.setBlock(i - 2, j + 1, k - 7, AbyssalCraft.Darkstone_cobble, 0, 0);
		world.setBlock(i - 2, j + 1, k - 6, AbyssalCraft.ethaxiumbrick, 0, 0);
		world.setBlock(i - 2, j + 1, k - 5, AbyssalCraft.ethaxiumbrick, 0, 0);
		world.setBlock(i - 2, j + 2, k - 23, AbyssalCraft.ethaxiumbrick, 0, 0);
		world.setBlock(i - 2, j + 2, k - 22, AbyssalCraft.Darkstone_brick, 0, 0);
		world.setBlock(i - 2, j + 2, k - 16, AbyssalCraft.Darkstone_brick, 0, 0);
		world.setBlock(i - 2, j + 2, k - 13, AbyssalCraft.Darkstone_brick, 0, 0);
		world.setBlock(i - 2, j + 2, k - 12, AbyssalCraft.Darkstone_brick, 0, 0);
		world.setBlock(i - 2, j + 2, k - 11, AbyssalCraft.Darkstone_brick, 0, 0);
		world.setBlock(i - 2, j + 2, k - 10, AbyssalCraft.Darkstone_brick, 0, 0);
		world.setBlock(i - 2, j + 2, k - 6, AbyssalCraft.Darkstone_brick, 0, 0);
		world.setBlock(i - 2, j + 2, k - 5, AbyssalCraft.ethaxiumbrick, 0, 0);
		world.setBlock(i - 2, j + 3, k - 23, AbyssalCraft.ethaxiumbrick, 0, 0);
		world.setBlock(i - 2, j + 3, k - 22, AbyssalCraft.Darkstone_brick, 0, 0);
		world.setBlock(i - 2, j + 3, k - 16, AbyssalCraft.Darkstone_brick, 0, 0);
		world.setBlock(i - 2, j + 3, k - 13, AbyssalCraft.Darkstone_brick, 0, 0);
		world.setBlock(i - 2, j + 3, k - 12, AbyssalCraft.Darkstone_brick, 0, 0);
		world.setBlock(i - 2, j + 3, k - 11, AbyssalCraft.Darkstone_brick, 0, 0);
		world.setBlock(i - 2, j + 3, k - 10, AbyssalCraft.Darkstone_brick, 0, 0);
		world.setBlock(i - 2, j + 3, k - 6, AbyssalCraft.Darkstone_brick, 0, 0);
		world.setBlock(i - 2, j + 3, k - 5, AbyssalCraft.ethaxiumbrick, 0, 0);
		world.setBlock(i - 2, j + 4, k - 23, AbyssalCraft.ethaxiumbrick, 0, 0);
		world.setBlock(i - 2, j + 4, k - 22, AbyssalCraft.Darkstone_brick, 0, 0);
		world.setBlock(i - 2, j + 4, k - 16, AbyssalCraft.Darkstone_brick, 0, 0);
		world.setBlock(i - 2, j + 4, k - 13, AbyssalCraft.Darkstone_brick, 0, 0);
		world.setBlock(i - 2, j + 4, k - 12, AbyssalCraft.Darkstone_brick, 0, 0);
		world.setBlock(i - 2, j + 4, k - 11, AbyssalCraft.Darkstone_brick, 0, 0);
		world.setBlock(i - 2, j + 4, k - 10, AbyssalCraft.Darkstone_brick, 0, 0);
		world.setBlock(i - 2, j + 4, k - 6, AbyssalCraft.Darkstone_brick, 0, 0);
		world.setBlock(i - 2, j + 4, k - 5, AbyssalCraft.ethaxiumbrick, 0, 0);
		world.setBlock(i - 2, j + 5, k - 23, AbyssalCraft.ethaxiumbrick, 0, 0);
		world.setBlock(i - 2, j + 5, k - 22, AbyssalCraft.ethaxiumbrick, 0, 0);
		world.setBlock(i - 2, j + 5, k - 21, AbyssalCraft.Darkstone_brick, 0, 0);
		world.setBlock(i - 2, j + 5, k - 20, AbyssalCraft.Darkstone_brick, 0, 0);
		world.setBlock(i - 2, j + 5, k - 19, AbyssalCraft.Darkstone_brick, 0, 0);
		world.setBlock(i - 2, j + 5, k - 18, AbyssalCraft.Darkstone_brick, 0, 0);
		world.setBlock(i - 2, j + 5, k - 17, AbyssalCraft.Darkstone_brick, 0, 0);
		world.setBlock(i - 2, j + 5, k - 16, AbyssalCraft.Darkstone_brick, 0, 0);
		world.setBlock(i - 2, j + 5, k - 15, AbyssalCraft.Darkstone_brick, 0, 0);
		world.setBlock(i - 2, j + 5, k - 14, AbyssalCraft.Darkstone_brick, 0, 0);
		world.setBlock(i - 2, j + 5, k - 13, AbyssalCraft.Darkstone_brick, 0, 0);
		world.setBlock(i - 2, j + 5, k - 12, AbyssalCraft.Darkstone_brick, 0, 0);
		world.setBlock(i - 2, j + 5, k - 11, AbyssalCraft.Darkstone_brick, 0, 0);
		world.setBlock(i - 2, j + 5, k - 10, AbyssalCraft.Darkstone_brick, 0, 0);
		world.setBlock(i - 2, j + 5, k - 9, AbyssalCraft.Darkstone_brick, 0, 0);
		world.setBlock(i - 2, j + 5, k - 8, AbyssalCraft.Darkstone_brick, 0, 0);
		world.setBlock(i - 2, j + 5, k - 7, AbyssalCraft.Darkstone_brick, 0, 0);
		world.setBlock(i - 2, j + 5, k - 6, AbyssalCraft.ethaxiumbrick, 0, 0);
		world.setBlock(i - 2, j + 5, k - 5, AbyssalCraft.ethaxiumbrick, 0, 0);
		world.setBlock(i - 2, j + 5, k - 4, AbyssalCraft.ethaxiumbrick, 0, 0);
		world.setBlock(i - 2, j + 5, k - 3, AbyssalCraft.ethaxiumbrick, 0, 0);
		world.setBlock(i - 2, j + 5, k - 2, AbyssalCraft.ethaxiumstairs, 3, 0);
		world.setBlock(i - 2, j + 6, k - 23, AbyssalCraft.ethaxiumstairs, 2, 0);
		world.setBlock(i - 2, j + 6, k - 22, AbyssalCraft.ethaxiumbrick, 0, 0);
		world.setBlock(i - 2, j + 6, k - 21, AbyssalCraft.ethaxiumbrick, 0, 0);
		world.setBlock(i - 2, j + 6, k - 20, AbyssalCraft.ethaxiumbrick, 0, 0);
		world.setBlock(i - 2, j + 6, k - 19, AbyssalCraft.ethaxiumbrick, 0, 0);
		world.setBlock(i - 2, j + 6, k - 18, AbyssalCraft.ethaxiumbrick, 0, 0);
		world.setBlock(i - 2, j + 6, k - 17, AbyssalCraft.ethaxiumbrick, 0, 0);
		world.setBlock(i - 2, j + 6, k - 16, AbyssalCraft.ethaxiumbrick, 0, 0);
		world.setBlock(i - 2, j + 6, k - 15, AbyssalCraft.ethaxiumbrick, 0, 0);
		world.setBlock(i - 2, j + 6, k - 14, AbyssalCraft.ethaxiumbrick, 0, 0);
		world.setBlock(i - 2, j + 6, k - 13, AbyssalCraft.ethaxiumbrick, 0, 0);
		world.setBlock(i - 2, j + 6, k - 12, AbyssalCraft.ethaxiumbrick, 0, 0);
		world.setBlock(i - 2, j + 6, k - 11, AbyssalCraft.ethaxiumbrick, 0, 0);
		world.setBlock(i - 2, j + 6, k - 10, AbyssalCraft.ethaxiumbrick, 0, 0);
		world.setBlock(i - 2, j + 6, k - 9, AbyssalCraft.ethaxiumbrick, 0, 0);
		world.setBlock(i - 2, j + 6, k - 8, AbyssalCraft.ethaxiumbrick, 0, 0);
		world.setBlock(i - 2, j + 6, k - 7, AbyssalCraft.ethaxiumbrick, 0, 0);
		world.setBlock(i - 2, j + 6, k - 6, AbyssalCraft.ethaxiumbrick, 0, 0);
		world.setBlock(i - 2, j + 6, k - 5, AbyssalCraft.ethaxiumbrick, 0, 0);
		world.setBlock(i - 2, j + 6, k - 4, AbyssalCraft.ethaxiumstairs, 3, 0);
		world.setBlock(i - 1, j + 0, k - 23, AbyssalCraft.ethaxiumbrick, 0, 0);
		world.setBlock(i - 1, j + 0, k - 22, AbyssalCraft.ethaxiumbrick, 0, 0);
		world.setBlock(i - 1, j + 0, k - 21, AbyssalCraft.ethaxiumbrick, 0, 0);
		world.setBlock(i - 1, j + 0, k - 20, AbyssalCraft.ethaxiumbrick, 0, 0);
		world.setBlock(i - 1, j + 0, k - 19, AbyssalCraft.ethaxiumbrick, 0, 0);
		world.setBlock(i - 1, j + 0, k - 18, AbyssalCraft.ethaxiumbrick, 0, 0);
		world.setBlock(i - 1, j + 0, k - 17, AbyssalCraft.ethaxiumbrick, 0, 0);
		world.setBlock(i - 1, j + 0, k - 16, AbyssalCraft.ethaxiumbrick, 0, 0);
		world.setBlock(i - 1, j + 0, k - 15, AbyssalCraft.ethaxiumbrick, 0, 0);
		world.setBlock(i - 1, j + 0, k - 14, AbyssalCraft.ethaxiumbrick, 0, 0);
		world.setBlock(i - 1, j + 0, k - 13, AbyssalCraft.ethaxiumbrick, 0, 0);
		world.setBlock(i - 1, j + 0, k - 12, AbyssalCraft.ethaxiumbrick, 0, 0);
		world.setBlock(i - 1, j + 0, k - 11, AbyssalCraft.ethaxiumbrick, 0, 0);
		world.setBlock(i - 1, j + 0, k - 10, AbyssalCraft.ethaxiumbrick, 0, 0);
		world.setBlock(i - 1, j + 0, k - 9, AbyssalCraft.ethaxiumbrick, 0, 0);
		world.setBlock(i - 1, j + 0, k - 8, AbyssalCraft.ethaxiumbrick, 0, 0);
		world.setBlock(i - 1, j + 0, k - 7, AbyssalCraft.ethaxiumbrick, 0, 0);
		world.setBlock(i - 1, j + 0, k - 6, AbyssalCraft.ethaxiumbrick, 0, 0);
		world.setBlock(i - 1, j + 0, k - 5, AbyssalCraft.ethaxiumbrick, 0, 0);
		world.setBlock(i - 1, j + 0, k - 4, AbyssalCraft.ethaxiumbrick, 0, 0);
		world.setBlock(i - 1, j + 0, k - 3, AbyssalCraft.ethaxiumbrick, 0, 0);
		world.setBlock(i - 1, j + 0, k - 2, AbyssalCraft.ethaxiumbrick, 0, 0);
		world.setBlock(i - 1, j + 0, k - 1, AbyssalCraft.ethaxiumstairs, 3, 0);
		world.setBlock(i - 1, j + 1, k - 23, AbyssalCraft.ethaxiumbrick, 0, 0);
		world.setBlock(i - 1, j + 1, k - 22, AbyssalCraft.ethaxiumbrick, 0, 0);
		world.setBlock(i - 1, j + 1, k - 21, AbyssalCraft.Darkstone, 0, 0);
		world.setBlock(i - 1, j + 1, k - 20, AbyssalCraft.Darkstone_cobble, 0, 0);
		world.setBlock(i - 1, j + 1, k - 19, AbyssalCraft.Darkstone_cobble, 0, 0);
		world.setBlock(i - 1, j + 1, k - 18, AbyssalCraft.Darkstone_cobble, 0, 0);
		world.setBlock(i - 1, j + 1, k - 17, AbyssalCraft.Darkstone, 0, 0);
		world.setBlock(i - 1, j + 1, k - 16, AbyssalCraft.Darkstone_cobble, 0, 0);
		world.setBlock(i - 1, j + 1, k - 15, AbyssalCraft.Darkstone_cobble, 0, 0);
		world.setBlock(i - 1, j + 1, k - 14, AbyssalCraft.Darkstone_cobble, 0, 0);
		world.setBlock(i - 1, j + 1, k - 13, AbyssalCraft.Darkstone_cobble, 0, 0);
		world.setBlock(i - 1, j + 1, k - 12, AbyssalCraft.Darkstone_cobble, 0, 0);
		world.setBlock(i - 1, j + 1, k - 11, AbyssalCraft.Darkstone_cobble, 0, 0);
		world.setBlock(i - 1, j + 1, k - 10, AbyssalCraft.Darkstone_cobble, 0, 0);
		world.setBlock(i - 1, j + 1, k - 9, AbyssalCraft.Darkstone_cobble, 0, 0);
		world.setBlock(i - 1, j + 1, k - 8, AbyssalCraft.Darkstone_cobble, 0, 0);
		world.setBlock(i - 1, j + 1, k - 7, AbyssalCraft.Darkstone_cobble, 0, 0);
		world.setBlock(i - 1, j + 1, k - 6, AbyssalCraft.ethaxiumbrick, 0, 0);
		world.setBlock(i - 1, j + 1, k - 5, AbyssalCraft.ethaxiumbrick, 0, 0);
		world.setBlock(i - 1, j + 1, k - 4, AbyssalCraft.ethaxiumpillar, 0, 0);
		world.setBlock(i - 1, j + 2, k - 23, AbyssalCraft.ethaxiumbrick, 0, 0);
		world.setBlock(i - 1, j + 2, k - 22, AbyssalCraft.Darkstone_brick, 0, 0);
		world.setBlock(i - 1, j + 2, k - 16, AbyssalCraft.Darkstone_brick, 0, 0);
		world.setBlock(i - 1, j + 2, k - 11, AbyssalCraft.Darkstone_brick, 0, 0);
		world.setBlock(i - 1, j + 2, k - 6, AbyssalCraft.Darkstone_brick, 0, 0);
		world.setBlock(i - 1, j + 2, k - 5, AbyssalCraft.ethaxiumbrick, 0, 0);
		world.setBlock(i - 1, j + 2, k - 4, AbyssalCraft.ethaxiumpillar, 0, 0);
		world.setBlock(i - 1, j + 3, k - 23, AbyssalCraft.ethaxiumbrick, 0, 0);
		world.setBlock(i - 1, j + 3, k - 22, AbyssalCraft.Darkstone_brick, 0, 0);
		world.setBlock(i - 1, j + 3, k - 16, AbyssalCraft.Darkstone_brick, 0, 0);
		world.setBlock(i - 1, j + 3, k - 11, AbyssalCraft.Darkstone_brick, 0, 0);
		world.setBlock(i - 1, j + 3, k - 6, AbyssalCraft.Darkstone_brick, 0, 0);
		world.setBlock(i - 1, j + 3, k - 5, AbyssalCraft.ethaxiumbrick, 0, 0);
		world.setBlock(i - 1, j + 3, k - 4, AbyssalCraft.ethaxiumpillar, 0, 0);
		world.setBlock(i - 1, j + 4, k - 23, AbyssalCraft.ethaxiumbrick, 0, 0);
		world.setBlock(i - 1, j + 4, k - 22, AbyssalCraft.Darkstone_brick, 0, 0);
		world.setBlock(i - 1, j + 4, k - 16, AbyssalCraft.Darkstone_brick, 0, 0);
		world.setBlock(i - 1, j + 4, k - 11, AbyssalCraft.Darkstone_brick, 0, 0);
		world.setBlock(i - 1, j + 4, k - 6, AbyssalCraft.Darkstone_brick, 0, 0);
		world.setBlock(i - 1, j + 4, k - 5, AbyssalCraft.ethaxiumbrick, 0, 0);
		world.setBlock(i - 1, j + 4, k - 4, AbyssalCraft.ethaxiumpillar, 0, 0);
		world.setBlock(i - 1, j + 5, k - 23, AbyssalCraft.ethaxiumbrick, 0, 0);
		world.setBlock(i - 1, j + 5, k - 22, AbyssalCraft.ethaxiumbrick, 0, 0);
		world.setBlock(i - 1, j + 5, k - 21, AbyssalCraft.Darkstone_brick, 0, 0);
		world.setBlock(i - 1, j + 5, k - 20, AbyssalCraft.Darkstone_brick, 0, 0);
		world.setBlock(i - 1, j + 5, k - 19, AbyssalCraft.Darkstone_brick, 0, 0);
		world.setBlock(i - 1, j + 5, k - 18, AbyssalCraft.Darkstone_brick, 0, 0);
		world.setBlock(i - 1, j + 5, k - 17, AbyssalCraft.Darkstone_brick, 0, 0);
		world.setBlock(i - 1, j + 5, k - 16, AbyssalCraft.Darkstone_brick, 0, 0);
		world.setBlock(i - 1, j + 5, k - 15, AbyssalCraft.Darkstone_brick, 0, 0);
		world.setBlock(i - 1, j + 5, k - 14, AbyssalCraft.Darkstone_brick, 0, 0);
		world.setBlock(i - 1, j + 5, k - 13, AbyssalCraft.Darkstone_brick, 0, 0);
		world.setBlock(i - 1, j + 5, k - 12, AbyssalCraft.Darkstone_brick, 0, 0);
		world.setBlock(i - 1, j + 5, k - 11, AbyssalCraft.Darkstone_brick, 0, 0);
		world.setBlock(i - 1, j + 5, k - 10, AbyssalCraft.Darkstone_brick, 0, 0);
		world.setBlock(i - 1, j + 5, k - 9, AbyssalCraft.Darkstone_brick, 0, 0);
		world.setBlock(i - 1, j + 5, k - 8, AbyssalCraft.Darkstone_brick, 0, 0);
		world.setBlock(i - 1, j + 5, k - 7, AbyssalCraft.Darkstone_brick, 0, 0);
		world.setBlock(i - 1, j + 5, k - 6, AbyssalCraft.ethaxiumbrick, 0, 0);
		world.setBlock(i - 1, j + 5, k - 5, AbyssalCraft.ethaxiumbrick, 0, 0);
		world.setBlock(i - 1, j + 5, k - 4, AbyssalCraft.ethaxiumbrick, 0, 0);
		world.setBlock(i - 1, j + 5, k - 3, AbyssalCraft.ethaxiumbrick, 0, 0);
		world.setBlock(i - 1, j + 5, k - 2, AbyssalCraft.ethaxiumstairs, 3, 0);
		world.setBlock(i - 1, j + 6, k - 23, AbyssalCraft.ethaxiumstairs, 2, 0);
		world.setBlock(i - 1, j + 6, k - 22, AbyssalCraft.ethaxiumbrick, 0, 0);
		world.setBlock(i - 1, j + 6, k - 21, AbyssalCraft.ethaxiumbrick, 0, 0);
		world.setBlock(i - 1, j + 6, k - 20, AbyssalCraft.ethaxiumbrick, 0, 0);
		world.setBlock(i - 1, j + 6, k - 19, AbyssalCraft.ethaxiumbrick, 0, 0);
		world.setBlock(i - 1, j + 6, k - 18, AbyssalCraft.ethaxiumbrick, 0, 0);
		world.setBlock(i - 1, j + 6, k - 17, AbyssalCraft.ethaxiumbrick, 0, 0);
		world.setBlock(i - 1, j + 6, k - 16, AbyssalCraft.ethaxiumbrick, 0, 0);
		world.setBlock(i - 1, j + 6, k - 15, AbyssalCraft.ethaxiumbrick, 0, 0);
		world.setBlock(i - 1, j + 6, k - 14, AbyssalCraft.ethaxiumbrick, 0, 0);
		world.setBlock(i - 1, j + 6, k - 13, AbyssalCraft.ethaxiumbrick, 0, 0);
		world.setBlock(i - 1, j + 6, k - 12, AbyssalCraft.ethaxiumbrick, 0, 0);
		world.setBlock(i - 1, j + 6, k - 11, AbyssalCraft.ethaxiumbrick, 0, 0);
		world.setBlock(i - 1, j + 6, k - 10, AbyssalCraft.ethaxiumbrick, 0, 0);
		world.setBlock(i - 1, j + 6, k - 9, AbyssalCraft.ethaxiumbrick, 0, 0);
		world.setBlock(i - 1, j + 6, k - 8, AbyssalCraft.ethaxiumbrick, 0, 0);
		world.setBlock(i - 1, j + 6, k - 7, AbyssalCraft.ethaxiumbrick, 0, 0);
		world.setBlock(i - 1, j + 6, k - 6, AbyssalCraft.ethaxiumbrick, 0, 0);
		world.setBlock(i - 1, j + 6, k - 5, AbyssalCraft.ethaxiumbrick, 0, 0);
		world.setBlock(i - 1, j + 6, k - 4, AbyssalCraft.ethaxiumstairs, 3, 0);
		world.setBlock(i + 0, j + 0, k - 23, AbyssalCraft.ethaxiumbrick, 0, 0);
		world.setBlock(i + 0, j + 0, k - 22, AbyssalCraft.ethaxiumbrick, 0, 0);
		world.setBlock(i + 0, j + 0, k - 21, AbyssalCraft.ethaxiumbrick, 0, 0);
		world.setBlock(i + 0, j + 0, k - 20, AbyssalCraft.ethaxiumbrick, 0, 0);
		world.setBlock(i + 0, j + 0, k - 19, AbyssalCraft.ethaxiumbrick, 0, 0);
		world.setBlock(i + 0, j + 0, k - 18, AbyssalCraft.ethaxiumbrick, 0, 0);
		world.setBlock(i + 0, j + 0, k - 17, AbyssalCraft.ethaxiumbrick, 0, 0);
		world.setBlock(i + 0, j + 0, k - 16, AbyssalCraft.ethaxiumbrick, 0, 0);
		world.setBlock(i + 0, j + 0, k - 15, AbyssalCraft.ethaxiumbrick, 0, 0);
		world.setBlock(i + 0, j + 0, k - 14, AbyssalCraft.ethaxiumbrick, 0, 0);
		world.setBlock(i + 0, j + 0, k - 13, AbyssalCraft.ethaxiumbrick, 0, 0);
		world.setBlock(i + 0, j + 0, k - 12, AbyssalCraft.ethaxiumbrick, 0, 0);
		world.setBlock(i + 0, j + 0, k - 11, AbyssalCraft.ethaxiumbrick, 0, 0);
		world.setBlock(i + 0, j + 0, k - 10, AbyssalCraft.ethaxiumbrick, 0, 0);
		world.setBlock(i + 0, j + 0, k - 9, AbyssalCraft.ethaxiumbrick, 0, 0);
		world.setBlock(i + 0, j + 0, k - 8, AbyssalCraft.ethaxiumbrick, 0, 0);
		world.setBlock(i + 0, j + 0, k - 7, AbyssalCraft.ethaxiumbrick, 0, 0);
		world.setBlock(i + 0, j + 0, k - 6, AbyssalCraft.ethaxiumbrick, 0, 0);
		world.setBlock(i + 0, j + 0, k - 5, AbyssalCraft.ethaxiumbrick, 0, 0);
		world.setBlock(i + 0, j + 0, k - 4, AbyssalCraft.ethaxiumbrick, 0, 0);
		world.setBlock(i + 0, j + 0, k - 3, AbyssalCraft.ethaxiumbrick, 0, 0);
		world.setBlock(i + 0, j + 0, k - 2, AbyssalCraft.ethaxiumbrick, 0, 0);
		world.setBlock(i + 0, j + 0, k - 1, AbyssalCraft.ethaxiumstairs, 3, 0);
		world.setBlock(i + 0, j + 0, k + 0, Blocks.air, 0, 0);
		world.setBlock(i + 0, j + 1, k - 23, AbyssalCraft.ethaxiumbrick, 0, 0);
		world.setBlock(i + 0, j + 1, k - 22, AbyssalCraft.ethaxiumbrick, 0, 0);
		world.setBlock(i + 0, j + 1, k - 21, AbyssalCraft.Darkstone, 0, 0);
		world.setBlock(i + 0, j + 1, k - 20, AbyssalCraft.Darkstone_cobble, 0, 0);
		world.setBlock(i + 0, j + 1, k - 19, AbyssalCraft.Darkstone, 0, 0);
		world.setBlock(i + 0, j + 1, k - 18, AbyssalCraft.Darkstone_cobble, 0, 0);
		world.setBlock(i + 0, j + 1, k - 17, AbyssalCraft.Darkstone_cobble, 0, 0);
		world.setBlock(i + 0, j + 1, k - 16, AbyssalCraft.Darkstone_cobble, 0, 0);
		world.setBlock(i + 0, j + 1, k - 15, AbyssalCraft.Darkstone_cobble, 0, 0);
		world.setBlock(i + 0, j + 1, k - 14, AbyssalCraft.Darkstone_cobble, 0, 0);
		world.setBlock(i + 0, j + 1, k - 13, AbyssalCraft.Darkstone, 0, 0);
		world.setBlock(i + 0, j + 1, k - 12, AbyssalCraft.Darkstone, 0, 0);
		world.setBlock(i + 0, j + 1, k - 11, AbyssalCraft.Darkstone_cobble, 0, 0);
		world.setBlock(i + 0, j + 1, k - 10, AbyssalCraft.Darkstone_cobble, 0, 0);
		world.setBlock(i + 0, j + 1, k - 9, AbyssalCraft.Darkstone_cobble, 0, 0);
		world.setBlock(i + 0, j + 1, k - 8, AbyssalCraft.Darkstone_cobble, 0, 0);
		world.setBlock(i + 0, j + 1, k - 7, AbyssalCraft.Darkstone_cobble, 0, 0);
		world.setBlock(i + 0, j + 1, k - 6, AbyssalCraft.Darkstone_cobble, 0, 0);
		world.setBlock(i + 0, j + 1, k - 5, AbyssalCraft.ethaxiumstairs, 3, 0);
		world.setBlock(i + 0, j + 2, k - 23, AbyssalCraft.ethaxiumbrick, 0, 0);
		world.setBlock(i + 0, j + 2, k - 22, AbyssalCraft.Darkstone_brick, 0, 0);
		world.setBlock(i + 0, j + 2, k - 11, AbyssalCraft.Darkstone_brick, 0, 0);
		world.setBlock(i + 0, j + 3, k - 23, AbyssalCraft.ethaxiumbrick, 0, 0);
		world.setBlock(i + 0, j + 3, k - 22, AbyssalCraft.DSGlow, 0, 0);
		world.setBlock(i + 0, j + 3, k - 11, AbyssalCraft.DSGlow, 0, 0);
		world.setBlock(i + 0, j + 4, k - 23, AbyssalCraft.ethaxiumbrick, 0, 0);
		world.setBlock(i + 0, j + 4, k - 22, AbyssalCraft.Darkstone_brick, 0, 0);
		world.setBlock(i + 0, j + 4, k - 16, AbyssalCraft.Darkstone_brick, 0, 0);
		world.setBlock(i + 0, j + 4, k - 11, AbyssalCraft.Darkstone_brick, 0, 0);
		world.setBlock(i + 0, j + 4, k - 6, AbyssalCraft.Darkstone_brick, 0, 0);
		world.setBlock(i + 0, j + 4, k - 5, AbyssalCraft.ethaxiumbrick, 0, 0);
		world.setBlock(i + 0, j + 4, k - 4, AbyssalCraft.ethaxiumbrick, 1, 0);
		world.setBlock(i + 0, j + 5, k - 23, AbyssalCraft.ethaxiumbrick, 0, 0);
		world.setBlock(i + 0, j + 5, k - 22, AbyssalCraft.ethaxiumbrick, 0, 0);
		world.setBlock(i + 0, j + 5, k - 21, AbyssalCraft.Darkstone_brick, 0, 0);
		world.setBlock(i + 0, j + 5, k - 20, AbyssalCraft.Darkstone_brick, 0, 0);
		world.setBlock(i + 0, j + 5, k - 19, AbyssalCraft.Darkstone_brick, 0, 0);
		world.setBlock(i + 0, j + 5, k - 18, AbyssalCraft.Darkstone_brick, 0, 0);
		world.setBlock(i + 0, j + 5, k - 17, AbyssalCraft.Darkstone_brick, 0, 0);
		world.setBlock(i + 0, j + 5, k - 16, AbyssalCraft.Darkstone_brick, 0, 0);
		world.setBlock(i + 0, j + 5, k - 15, AbyssalCraft.Darkstone_brick, 0, 0);
		world.setBlock(i + 0, j + 5, k - 14, AbyssalCraft.Darkstone_brick, 0, 0);
		world.setBlock(i + 0, j + 5, k - 13, AbyssalCraft.Darkstone_brick, 0, 0);
		world.setBlock(i + 0, j + 5, k - 12, AbyssalCraft.Darkstone_brick, 0, 0);
		world.setBlock(i + 0, j + 5, k - 11, AbyssalCraft.Darkstone_brick, 0, 0);
		world.setBlock(i + 0, j + 5, k - 10, AbyssalCraft.Darkstone_brick, 0, 0);
		world.setBlock(i + 0, j + 5, k - 9, AbyssalCraft.Darkstone_brick, 0, 0);
		world.setBlock(i + 0, j + 5, k - 8, AbyssalCraft.Darkstone_brick, 0, 0);
		world.setBlock(i + 0, j + 5, k - 7, AbyssalCraft.Darkstone_brick, 0, 0);
		world.setBlock(i + 0, j + 5, k - 6, AbyssalCraft.ethaxiumbrick, 0, 0);
		world.setBlock(i + 0, j + 5, k - 5, AbyssalCraft.ethaxiumbrick, 0, 0);
		world.setBlock(i + 0, j + 5, k - 4, AbyssalCraft.ethaxiumbrick, 0, 0);
		world.setBlock(i + 0, j + 5, k - 3, AbyssalCraft.ethaxiumbrick, 0, 0);
		world.setBlock(i + 0, j + 5, k - 2, AbyssalCraft.ethaxiumstairs, 3, 0);
		world.setBlock(i + 0, j + 6, k - 23, AbyssalCraft.ethaxiumstairs, 2, 0);
		world.setBlock(i + 0, j + 6, k - 22, AbyssalCraft.ethaxiumbrick, 0, 0);
		world.setBlock(i + 0, j + 6, k - 21, AbyssalCraft.ethaxiumbrick, 0, 0);
		world.setBlock(i + 0, j + 6, k - 20, AbyssalCraft.ethaxiumbrick, 0, 0);
		world.setBlock(i + 0, j + 6, k - 19, AbyssalCraft.ethaxiumbrick, 0, 0);
		world.setBlock(i + 0, j + 6, k - 18, AbyssalCraft.ethaxiumbrick, 0, 0);
		world.setBlock(i + 0, j + 6, k - 17, AbyssalCraft.ethaxiumbrick, 0, 0);
		world.setBlock(i + 0, j + 6, k - 16, AbyssalCraft.ethaxiumbrick, 0, 0);
		world.setBlock(i + 0, j + 6, k - 15, AbyssalCraft.ethaxiumbrick, 0, 0);
		world.setBlock(i + 0, j + 6, k - 14, AbyssalCraft.ethaxiumbrick, 0, 0);
		world.setBlock(i + 0, j + 6, k - 13, AbyssalCraft.ethaxiumbrick, 0, 0);
		world.setBlock(i + 0, j + 6, k - 12, AbyssalCraft.ethaxiumbrick, 0, 0);
		world.setBlock(i + 0, j + 6, k - 11, AbyssalCraft.ethaxiumbrick, 0, 0);
		world.setBlock(i + 0, j + 6, k - 10, AbyssalCraft.ethaxiumbrick, 0, 0);
		world.setBlock(i + 0, j + 6, k - 9, AbyssalCraft.ethaxiumbrick, 0, 0);
		world.setBlock(i + 0, j + 6, k - 8, AbyssalCraft.ethaxiumbrick, 0, 0);
		world.setBlock(i + 0, j + 6, k - 7, AbyssalCraft.ethaxiumbrick, 0, 0);
		world.setBlock(i + 0, j + 6, k - 6, AbyssalCraft.ethaxiumbrick, 0, 0);
		world.setBlock(i + 0, j + 6, k - 5, AbyssalCraft.ethaxiumbrick, 0, 0);
		world.setBlock(i + 0, j + 6, k - 4, AbyssalCraft.ethaxiumstairs, 3, 0);
		world.setBlock(i + 1, j + 0, k - 23, AbyssalCraft.ethaxiumbrick, 0, 0);
		world.setBlock(i + 1, j + 0, k - 22, AbyssalCraft.ethaxiumbrick, 0, 0);
		world.setBlock(i + 1, j + 0, k - 21, AbyssalCraft.ethaxiumbrick, 0, 0);
		world.setBlock(i + 1, j + 0, k - 20, AbyssalCraft.ethaxiumbrick, 0, 0);
		world.setBlock(i + 1, j + 0, k - 19, AbyssalCraft.ethaxiumbrick, 0, 0);
		world.setBlock(i + 1, j + 0, k - 18, AbyssalCraft.ethaxiumbrick, 0, 0);
		world.setBlock(i + 1, j + 0, k - 17, AbyssalCraft.ethaxiumbrick, 0, 0);
		world.setBlock(i + 1, j + 0, k - 16, AbyssalCraft.ethaxiumbrick, 0, 0);
		world.setBlock(i + 1, j + 0, k - 15, AbyssalCraft.ethaxiumbrick, 0, 0);
		world.setBlock(i + 1, j + 0, k - 14, AbyssalCraft.ethaxiumbrick, 0, 0);
		world.setBlock(i + 1, j + 0, k - 13, AbyssalCraft.ethaxiumbrick, 0, 0);
		world.setBlock(i + 1, j + 0, k - 12, AbyssalCraft.ethaxiumbrick, 0, 0);
		world.setBlock(i + 1, j + 0, k - 11, AbyssalCraft.ethaxiumbrick, 0, 0);
		world.setBlock(i + 1, j + 0, k - 10, AbyssalCraft.ethaxiumbrick, 0, 0);
		world.setBlock(i + 1, j + 0, k - 9, AbyssalCraft.ethaxiumbrick, 0, 0);
		world.setBlock(i + 1, j + 0, k - 8, AbyssalCraft.ethaxiumbrick, 0, 0);
		world.setBlock(i + 1, j + 0, k - 7, AbyssalCraft.ethaxiumbrick, 0, 0);
		world.setBlock(i + 1, j + 0, k - 6, AbyssalCraft.ethaxiumbrick, 0, 0);
		world.setBlock(i + 1, j + 0, k - 5, AbyssalCraft.ethaxiumbrick, 0, 0);
		world.setBlock(i + 1, j + 0, k - 4, AbyssalCraft.ethaxiumbrick, 0, 0);
		world.setBlock(i + 1, j + 0, k - 3, AbyssalCraft.ethaxiumbrick, 0, 0);
		world.setBlock(i + 1, j + 0, k - 2, AbyssalCraft.ethaxiumbrick, 0, 0);
		world.setBlock(i + 1, j + 0, k - 1, AbyssalCraft.ethaxiumstairs, 3, 0);
		world.setBlock(i + 1, j + 1, k - 23, AbyssalCraft.ethaxiumbrick, 0, 0);
		world.setBlock(i + 1, j + 1, k - 22, AbyssalCraft.ethaxiumbrick, 0, 0);
		world.setBlock(i + 1, j + 1, k - 21, AbyssalCraft.Darkstone, 0, 0);
		world.setBlock(i + 1, j + 1, k - 20, AbyssalCraft.Darkstone_cobble, 0, 0);
		world.setBlock(i + 1, j + 1, k - 19, AbyssalCraft.Darkstone_cobble, 0, 0);
		world.setBlock(i + 1, j + 1, k - 18, AbyssalCraft.Darkstone_cobble, 0, 0);
		world.setBlock(i + 1, j + 1, k - 17, AbyssalCraft.Darkstone, 0, 0);
		world.setBlock(i + 1, j + 1, k - 16, AbyssalCraft.Darkstone_cobble, 0, 0);
		world.setBlock(i + 1, j + 1, k - 15, AbyssalCraft.Darkstone_cobble, 0, 0);
		world.setBlock(i + 1, j + 1, k - 14, AbyssalCraft.Darkstone_cobble, 0, 0);
		world.setBlock(i + 1, j + 1, k - 13, AbyssalCraft.Darkstone_cobble, 0, 0);
		world.setBlock(i + 1, j + 1, k - 12, AbyssalCraft.Darkstone_cobble, 0, 0);
		world.setBlock(i + 1, j + 1, k - 11, AbyssalCraft.Darkstone_cobble, 0, 0);
		world.setBlock(i + 1, j + 1, k - 10, AbyssalCraft.Darkstone_cobble, 0, 0);
		world.setBlock(i + 1, j + 1, k - 9, AbyssalCraft.Darkstone_cobble, 0, 0);
		world.setBlock(i + 1, j + 1, k - 8, AbyssalCraft.Darkstone_cobble, 0, 0);
		world.setBlock(i + 1, j + 1, k - 7, AbyssalCraft.Darkstone_cobble, 0, 0);
		world.setBlock(i + 1, j + 1, k - 6, AbyssalCraft.ethaxiumbrick, 0, 0);
		world.setBlock(i + 1, j + 1, k - 5, AbyssalCraft.ethaxiumbrick, 0, 0);
		world.setBlock(i + 1, j + 1, k - 4, AbyssalCraft.ethaxiumpillar, 0, 0);
		world.setBlock(i + 1, j + 2, k - 23, AbyssalCraft.ethaxiumbrick, 0, 0);
		world.setBlock(i + 1, j + 2, k - 22, AbyssalCraft.Darkstone_brick, 0, 0);
		world.setBlock(i + 1, j + 2, k - 16, AbyssalCraft.Darkstone_brick, 0, 0);
		world.setBlock(i + 1, j + 2, k - 11, AbyssalCraft.Darkstone_brick, 0, 0);
		world.setBlock(i + 1, j + 2, k - 6, AbyssalCraft.Darkstone_brick, 0, 0);
		world.setBlock(i + 1, j + 2, k - 5, AbyssalCraft.ethaxiumbrick, 0, 0);
		world.setBlock(i + 1, j + 2, k - 4, AbyssalCraft.ethaxiumpillar, 0, 0);
		world.setBlock(i + 1, j + 3, k - 23, AbyssalCraft.ethaxiumbrick, 0, 0);
		world.setBlock(i + 1, j + 3, k - 22, AbyssalCraft.Darkstone_brick, 0, 0);
		world.setBlock(i + 1, j + 3, k - 16, AbyssalCraft.Darkstone_brick, 0, 0);
		world.setBlock(i + 1, j + 3, k - 11, AbyssalCraft.Darkstone_brick, 0, 0);
		world.setBlock(i + 1, j + 3, k - 6, AbyssalCraft.Darkstone_brick, 0, 0);
		world.setBlock(i + 1, j + 3, k - 5, AbyssalCraft.ethaxiumbrick, 0, 0);
		world.setBlock(i + 1, j + 3, k - 4, AbyssalCraft.ethaxiumpillar, 0, 0);
		world.setBlock(i + 1, j + 4, k - 23, AbyssalCraft.ethaxiumbrick, 0, 0);
		world.setBlock(i + 1, j + 4, k - 22, AbyssalCraft.Darkstone_brick, 0, 0);
		world.setBlock(i + 1, j + 4, k - 16, AbyssalCraft.Darkstone_brick, 0, 0);
		world.setBlock(i + 1, j + 4, k - 11, AbyssalCraft.Darkstone_brick, 0, 0);
		world.setBlock(i + 1, j + 4, k - 6, AbyssalCraft.Darkstone_brick, 0, 0);
		world.setBlock(i + 1, j + 4, k - 5, AbyssalCraft.ethaxiumbrick, 0, 0);
		world.setBlock(i + 1, j + 4, k - 4, AbyssalCraft.ethaxiumpillar, 0, 0);
		world.setBlock(i + 1, j + 5, k - 23, AbyssalCraft.ethaxiumbrick, 0, 0);
		world.setBlock(i + 1, j + 5, k - 22, AbyssalCraft.ethaxiumbrick, 0, 0);
		world.setBlock(i + 1, j + 5, k - 21, AbyssalCraft.Darkstone_brick, 0, 0);
		world.setBlock(i + 1, j + 5, k - 20, AbyssalCraft.Darkstone_brick, 0, 0);
		world.setBlock(i + 1, j + 5, k - 19, AbyssalCraft.Darkstone_brick, 0, 0);
		world.setBlock(i + 1, j + 5, k - 18, AbyssalCraft.Darkstone_brick, 0, 0);
		world.setBlock(i + 1, j + 5, k - 17, AbyssalCraft.Darkstone_brick, 0, 0);
		world.setBlock(i + 1, j + 5, k - 16, AbyssalCraft.Darkstone_brick, 0, 0);
		world.setBlock(i + 1, j + 5, k - 15, AbyssalCraft.Darkstone_brick, 0, 0);
		world.setBlock(i + 1, j + 5, k - 14, AbyssalCraft.Darkstone_brick, 0, 0);
		world.setBlock(i + 1, j + 5, k - 13, AbyssalCraft.Darkstone_brick, 0, 0);
		world.setBlock(i + 1, j + 5, k - 12, AbyssalCraft.Darkstone_brick, 0, 0);
		world.setBlock(i + 1, j + 5, k - 11, AbyssalCraft.Darkstone_brick, 0, 0);
		world.setBlock(i + 1, j + 5, k - 10, AbyssalCraft.Darkstone_brick, 0, 0);
		world.setBlock(i + 1, j + 5, k - 9, AbyssalCraft.Darkstone_brick, 0, 0);
		world.setBlock(i + 1, j + 5, k - 8, AbyssalCraft.Darkstone_brick, 0, 0);
		world.setBlock(i + 1, j + 5, k - 7, AbyssalCraft.Darkstone_brick, 0, 0);
		world.setBlock(i + 1, j + 5, k - 6, AbyssalCraft.ethaxiumbrick, 0, 0);
		world.setBlock(i + 1, j + 5, k - 5, AbyssalCraft.ethaxiumbrick, 0, 0);
		world.setBlock(i + 1, j + 5, k - 4, AbyssalCraft.ethaxiumbrick, 0, 0);
		world.setBlock(i + 1, j + 5, k - 3, AbyssalCraft.ethaxiumbrick, 0, 0);
		world.setBlock(i + 1, j + 5, k - 2, AbyssalCraft.ethaxiumstairs, 3, 0);
		world.setBlock(i + 1, j + 6, k - 23, AbyssalCraft.ethaxiumstairs, 2, 0);
		world.setBlock(i + 1, j + 6, k - 22, AbyssalCraft.ethaxiumbrick, 0, 0);
		world.setBlock(i + 1, j + 6, k - 21, AbyssalCraft.ethaxiumbrick, 0, 0);
		world.setBlock(i + 1, j + 6, k - 20, AbyssalCraft.ethaxiumbrick, 0, 0);
		world.setBlock(i + 1, j + 6, k - 19, AbyssalCraft.ethaxiumbrick, 0, 0);
		world.setBlock(i + 1, j + 6, k - 18, AbyssalCraft.ethaxiumbrick, 0, 0);
		world.setBlock(i + 1, j + 6, k - 17, AbyssalCraft.ethaxiumbrick, 0, 0);
		world.setBlock(i + 1, j + 6, k - 16, AbyssalCraft.ethaxiumbrick, 0, 0);
		world.setBlock(i + 1, j + 6, k - 15, AbyssalCraft.ethaxiumbrick, 0, 0);
		world.setBlock(i + 1, j + 6, k - 14, AbyssalCraft.ethaxiumbrick, 0, 0);
		world.setBlock(i + 1, j + 6, k - 13, AbyssalCraft.ethaxiumbrick, 0, 0);
		world.setBlock(i + 1, j + 6, k - 12, AbyssalCraft.ethaxiumbrick, 0, 0);
		world.setBlock(i + 1, j + 6, k - 11, AbyssalCraft.ethaxiumbrick, 0, 0);
		world.setBlock(i + 1, j + 6, k - 10, AbyssalCraft.ethaxiumbrick, 0, 0);
		world.setBlock(i + 1, j + 6, k - 9, AbyssalCraft.ethaxiumbrick, 0, 0);
		world.setBlock(i + 1, j + 6, k - 8, AbyssalCraft.ethaxiumbrick, 0, 0);
		world.setBlock(i + 1, j + 6, k - 7, AbyssalCraft.ethaxiumbrick, 0, 0);
		world.setBlock(i + 1, j + 6, k - 6, AbyssalCraft.ethaxiumbrick, 0, 0);
		world.setBlock(i + 1, j + 6, k - 5, AbyssalCraft.ethaxiumbrick, 0, 0);
		world.setBlock(i + 1, j + 6, k - 4, AbyssalCraft.ethaxiumstairs, 3, 0);
		world.setBlock(i + 2, j + 0, k - 23, AbyssalCraft.ethaxiumbrick, 0, 0);
		world.setBlock(i + 2, j + 0, k - 22, AbyssalCraft.ethaxiumbrick, 0, 0);
		world.setBlock(i + 2, j + 0, k - 21, AbyssalCraft.ethaxiumbrick, 0, 0);
		world.setBlock(i + 2, j + 0, k - 20, AbyssalCraft.ethaxiumbrick, 0, 0);
		world.setBlock(i + 2, j + 0, k - 19, AbyssalCraft.ethaxiumbrick, 0, 0);
		world.setBlock(i + 2, j + 0, k - 18, AbyssalCraft.ethaxiumbrick, 0, 0);
		world.setBlock(i + 2, j + 0, k - 17, AbyssalCraft.ethaxiumbrick, 0, 0);
		world.setBlock(i + 2, j + 0, k - 16, AbyssalCraft.ethaxiumbrick, 0, 0);
		world.setBlock(i + 2, j + 0, k - 15, AbyssalCraft.ethaxiumbrick, 0, 0);
		world.setBlock(i + 2, j + 0, k - 14, AbyssalCraft.ethaxiumbrick, 0, 0);
		world.setBlock(i + 2, j + 0, k - 13, AbyssalCraft.ethaxiumbrick, 0, 0);
		world.setBlock(i + 2, j + 0, k - 12, AbyssalCraft.ethaxiumbrick, 0, 0);
		world.setBlock(i + 2, j + 0, k - 11, AbyssalCraft.ethaxiumbrick, 0, 0);
		world.setBlock(i + 2, j + 0, k - 10, AbyssalCraft.ethaxiumbrick, 0, 0);
		world.setBlock(i + 2, j + 0, k - 9, AbyssalCraft.ethaxiumbrick, 0, 0);
		world.setBlock(i + 2, j + 0, k - 8, AbyssalCraft.ethaxiumbrick, 0, 0);
		world.setBlock(i + 2, j + 0, k - 7, AbyssalCraft.ethaxiumbrick, 0, 0);
		world.setBlock(i + 2, j + 0, k - 6, AbyssalCraft.ethaxiumbrick, 0, 0);
		world.setBlock(i + 2, j + 0, k - 5, AbyssalCraft.ethaxiumbrick, 0, 0);
		world.setBlock(i + 2, j + 0, k - 4, AbyssalCraft.ethaxiumbrick, 0, 0);
		world.setBlock(i + 2, j + 0, k - 3, AbyssalCraft.ethaxiumbrick, 0, 0);
		world.setBlock(i + 2, j + 0, k - 2, AbyssalCraft.ethaxiumbrick, 0, 0);
		world.setBlock(i + 2, j + 0, k - 1, AbyssalCraft.ethaxiumstairs, 3, 0);
		world.setBlock(i + 2, j + 1, k - 23, AbyssalCraft.ethaxiumbrick, 0, 0);
		world.setBlock(i + 2, j + 1, k - 22, AbyssalCraft.ethaxiumbrick, 0, 0);
