/*******************************************************************************
 * AbyssalCraft
 * Copyright (c) 2012 - 2016 Shinoow.
 * All rights reserved. This program and the accompanying materials
 * are made available under the terms of the GNU Lesser Public License v3
 * which accompanies this distribution, and is available at
 * http://www.gnu.org/licenses/lgpl-3.0.txt
 * 
 * Contributors:
 *     Shinoow -  implementation
 ******************************************************************************/
package com.shinoow.abyssalcraft.common.structures;

import java.util.Random;

import net.minecraft.init.Blocks;
import net.minecraft.util.math.BlockPos;
import net.minecraft.world.World;
import net.minecraft.world.gen.feature.WorldGenerator;

import com.shinoow.abyssalcraft.AbyssalCraft;

public class StructureHouse extends WorldGenerator
{

	public StructureHouse() { }

	@Override
	public boolean generate(World world, Random rand, BlockPos pos) {

		int i = pos.getX();
		int j = pos.getY();
		int k = pos.getZ();

		world.setBlockState(new BlockPos(i - 9, j + 0, k - 23), AbyssalCraft.ethaxiumbrick.getDefaultState(), 2);
		world.setBlockState(new BlockPos(i - 9, j + 0, k - 22), AbyssalCraft.ethaxiumbrick.getDefaultState(), 2);
		world.setBlockState(new BlockPos(i - 9, j + 0, k - 21), AbyssalCraft.ethaxiumbrick.getDefaultState(), 2);
		world.setBlockState(new BlockPos(i - 9, j + 0, k - 20), AbyssalCraft.ethaxiumbrick.getDefaultState(), 2);
		world.setBlockState(new BlockPos(i - 9, j + 0, k - 19), AbyssalCraft.ethaxiumbrick.getDefaultState(), 2);
		world.setBlockState(new BlockPos(i - 9, j + 0, k - 18), AbyssalCraft.ethaxiumbrick.getDefaultState(), 2);
		world.setBlockState(new BlockPos(i - 9, j + 0, k - 17), AbyssalCraft.ethaxiumbrick.getDefaultState(), 2);
		world.setBlockState(new BlockPos(i - 9, j + 0, k - 16), AbyssalCraft.ethaxiumbrick.getDefaultState(), 2);
		world.setBlockState(new BlockPos(i - 9, j + 0, k - 15), AbyssalCraft.ethaxiumbrick.getDefaultState(), 2);
		world.setBlockState(new BlockPos(i - 9, j + 0, k - 14), AbyssalCraft.ethaxiumbrick.getDefaultState(), 2);
		world.setBlockState(new BlockPos(i - 9, j + 0, k - 13), AbyssalCraft.ethaxiumbrick.getDefaultState(), 2);
		world.setBlockState(new BlockPos(i - 9, j + 0, k - 12), AbyssalCraft.ethaxiumbrick.getDefaultState(), 2);
		world.setBlockState(new BlockPos(i - 9, j + 0, k - 11), AbyssalCraft.ethaxiumbrick.getDefaultState(), 2);
		world.setBlockState(new BlockPos(i - 9, j + 0, k - 10), AbyssalCraft.ethaxiumbrick.getDefaultState(), 2);
		world.setBlockState(new BlockPos(i - 9, j + 0, k - 9), AbyssalCraft.ethaxiumbrick.getDefaultState(), 2);
		world.setBlockState(new BlockPos(i - 9, j + 0, k - 8), AbyssalCraft.ethaxiumbrick.getDefaultState(), 2);
		world.setBlockState(new BlockPos(i - 9, j + 0, k - 7), AbyssalCraft.ethaxiumbrick.getDefaultState(), 2);
		world.setBlockState(new BlockPos(i - 9, j + 0, k - 6), AbyssalCraft.ethaxiumbrick.getDefaultState(), 2);
		world.setBlockState(new BlockPos(i - 9, j + 0, k - 5), AbyssalCraft.ethaxiumbrick.getDefaultState(), 2);
		world.setBlockState(new BlockPos(i - 9, j + 0, k - 4), AbyssalCraft.ethaxiumbrick.getDefaultState(), 2);
		world.setBlockState(new BlockPos(i - 9, j + 0, k - 3), AbyssalCraft.ethaxiumbrick.getDefaultState(), 2);
		world.setBlockState(new BlockPos(i - 9, j + 0, k - 2), AbyssalCraft.ethaxiumbrick.getDefaultState(), 2);
		world.setBlockState(new BlockPos(i - 9, j + 0, k - 1), AbyssalCraft.ethaxiumbrick.getDefaultState(), 2);
		world.setBlockState(new BlockPos(i - 9, j + 1, k - 23), AbyssalCraft.ethaxiumpillar.getDefaultState(), 2);
		world.setBlockState(new BlockPos(i - 9, j + 1, k - 22), AbyssalCraft.ethaxiumbrick.getDefaultState(), 2);
		world.setBlockState(new BlockPos(i - 9, j + 1, k - 21), AbyssalCraft.ethaxiumbrick.getDefaultState(), 2);
		world.setBlockState(new BlockPos(i - 9, j + 1, k - 20), AbyssalCraft.ethaxiumbrick.getDefaultState(), 2);
		world.setBlockState(new BlockPos(i - 9, j + 1, k - 19), AbyssalCraft.ethaxiumbrick.getDefaultState(), 2);
		world.setBlockState(new BlockPos(i - 9, j + 1, k - 18), AbyssalCraft.ethaxiumbrick.getDefaultState(), 2);
		world.setBlockState(new BlockPos(i - 9, j + 1, k - 17), AbyssalCraft.ethaxiumbrick.getDefaultState(), 2);
		world.setBlockState(new BlockPos(i - 9, j + 1, k - 16), AbyssalCraft.ethaxiumbrick.getDefaultState(), 2);
		world.setBlockState(new BlockPos(i - 9, j + 1, k - 15), AbyssalCraft.ethaxiumbrick.getDefaultState(), 2);
		world.setBlockState(new BlockPos(i - 9, j + 1, k - 14), AbyssalCraft.ethaxiumbrick.getDefaultState(), 2);
		world.setBlockState(new BlockPos(i - 9, j + 1, k - 13), AbyssalCraft.ethaxiumbrick.getDefaultState(), 2);
		world.setBlockState(new BlockPos(i - 9, j + 1, k - 12), AbyssalCraft.ethaxiumbrick.getDefaultState(), 2);
		world.setBlockState(new BlockPos(i - 9, j + 1, k - 11), AbyssalCraft.ethaxiumbrick.getDefaultState(), 2);
		world.setBlockState(new BlockPos(i - 9, j + 1, k - 10), AbyssalCraft.ethaxiumbrick.getDefaultState(), 2);
		world.setBlockState(new BlockPos(i - 9, j + 1, k - 9), AbyssalCraft.ethaxiumbrick.getDefaultState(), 2);
		world.setBlockState(new BlockPos(i - 9, j + 1, k - 8), AbyssalCraft.ethaxiumbrick.getDefaultState(), 2);
		world.setBlockState(new BlockPos(i - 9, j + 1, k - 7), AbyssalCraft.ethaxiumbrick.getDefaultState(), 2);
		world.setBlockState(new BlockPos(i - 9, j + 1, k - 6), AbyssalCraft.ethaxiumbrick.getDefaultState(), 2);
		world.setBlockState(new BlockPos(i - 9, j + 1, k - 5), AbyssalCraft.ethaxiumbrick.getDefaultState(), 2);
		world.setBlockState(new BlockPos(i - 9, j + 1, k - 4), AbyssalCraft.ethaxiumbrick.getDefaultState(), 2);
		world.setBlockState(new BlockPos(i - 9, j + 1, k - 3), AbyssalCraft.ethaxiumbrick.getDefaultState(), 2);
		world.setBlockState(new BlockPos(i - 9, j + 1, k - 2), AbyssalCraft.ethaxiumbrick.getDefaultState(), 2);
		world.setBlockState(new BlockPos(i - 9, j + 1, k - 1), AbyssalCraft.ethaxiumpillar.getDefaultState(), 2);
		world.setBlockState(new BlockPos(i - 9, j + 2, k - 23), AbyssalCraft.ethaxiumpillar.getDefaultState(), 2);
		world.setBlockState(new BlockPos(i - 9, j + 2, k - 22), AbyssalCraft.ethaxiumbrick.getDefaultState(), 2);
		world.setBlockState(new BlockPos(i - 9, j + 2, k - 21), AbyssalCraft.ethaxiumbrick.getDefaultState(), 2);
		world.setBlockState(new BlockPos(i - 9, j + 2, k - 20), AbyssalCraft.ethaxiumbrick.getDefaultState(), 2);
		world.setBlockState(new BlockPos(i - 9, j + 2, k - 19), AbyssalCraft.ethaxiumbrick.getDefaultState(), 2);
		world.setBlockState(new BlockPos(i - 9, j + 2, k - 18), AbyssalCraft.ethaxiumbrick.getDefaultState(), 2);
		world.setBlockState(new BlockPos(i - 9, j + 2, k - 17), AbyssalCraft.ethaxiumbrick.getDefaultState(), 2);
		world.setBlockState(new BlockPos(i - 9, j + 2, k - 16), AbyssalCraft.ethaxiumbrick.getDefaultState(), 2);
		world.setBlockState(new BlockPos(i - 9, j + 2, k - 15), AbyssalCraft.ethaxiumbrick.getDefaultState(), 2);
		world.setBlockState(new BlockPos(i - 9, j + 2, k - 14), AbyssalCraft.ethaxiumbrick.getDefaultState(), 2);
		world.setBlockState(new BlockPos(i - 9, j + 2, k - 13), AbyssalCraft.ethaxiumbrick.getDefaultState(), 2);
		world.setBlockState(new BlockPos(i - 9, j + 2, k - 12), AbyssalCraft.ethaxiumbrick.getDefaultState(), 2);
		world.setBlockState(new BlockPos(i - 9, j + 2, k - 11), AbyssalCraft.ethaxiumbrick.getDefaultState(), 2);
		world.setBlockState(new BlockPos(i - 9, j + 2, k - 10), AbyssalCraft.ethaxiumbrick.getDefaultState(), 2);
		world.setBlockState(new BlockPos(i - 9, j + 2, k - 9), AbyssalCraft.ethaxiumbrick.getDefaultState(), 2);
		world.setBlockState(new BlockPos(i - 9, j + 2, k - 8), AbyssalCraft.ethaxiumbrick.getDefaultState(), 2);
		world.setBlockState(new BlockPos(i - 9, j + 2, k - 7), AbyssalCraft.ethaxiumbrick.getDefaultState(), 2);
		world.setBlockState(new BlockPos(i - 9, j + 2, k - 6), AbyssalCraft.ethaxiumbrick.getDefaultState(), 2);
		world.setBlockState(new BlockPos(i - 9, j + 2, k - 5), AbyssalCraft.ethaxiumbrick.getDefaultState(), 2);
		world.setBlockState(new BlockPos(i - 9, j + 2, k - 4), AbyssalCraft.ethaxiumbrick.getDefaultState(), 2);
		world.setBlockState(new BlockPos(i - 9, j + 2, k - 3), AbyssalCraft.ethaxiumbrick.getDefaultState(), 2);
		world.setBlockState(new BlockPos(i - 9, j + 2, k - 2), AbyssalCraft.ethaxiumbrick.getDefaultState(), 2);
		world.setBlockState(new BlockPos(i - 9, j + 2, k - 1), AbyssalCraft.ethaxiumpillar.getDefaultState(), 2);
		world.setBlockState(new BlockPos(i - 9, j + 3, k - 23), AbyssalCraft.ethaxiumpillar.getDefaultState(), 2);
		world.setBlockState(new BlockPos(i - 9, j + 3, k - 22), AbyssalCraft.ethaxiumbrick.getDefaultState(), 2);
		world.setBlockState(new BlockPos(i - 9, j + 3, k - 21), AbyssalCraft.ethaxiumbrick.getDefaultState(), 2);
		world.setBlockState(new BlockPos(i - 9, j + 3, k - 20), AbyssalCraft.ethaxiumbrick.getDefaultState(), 2);
		world.setBlockState(new BlockPos(i - 9, j + 3, k - 19), AbyssalCraft.ethaxiumbrick.getDefaultState(), 2);
		world.setBlockState(new BlockPos(i - 9, j + 3, k - 18), AbyssalCraft.ethaxiumbrick.getDefaultState(), 2);
		world.setBlockState(new BlockPos(i - 9, j + 3, k - 17), AbyssalCraft.ethaxiumbrick.getDefaultState(), 2);
		world.setBlockState(new BlockPos(i - 9, j + 3, k - 16), AbyssalCraft.ethaxiumbrick.getDefaultState(), 2);
		world.setBlockState(new BlockPos(i - 9, j + 3, k - 15), AbyssalCraft.ethaxiumbrick.getDefaultState(), 2);
		world.setBlockState(new BlockPos(i - 9, j + 3, k - 14), AbyssalCraft.ethaxiumbrick.getDefaultState(), 2);
		world.setBlockState(new BlockPos(i - 9, j + 3, k - 13), AbyssalCraft.ethaxiumbrick.getDefaultState(), 2);
		world.setBlockState(new BlockPos(i - 9, j + 3, k - 12), AbyssalCraft.ethaxiumbrick.getDefaultState(), 2);
		world.setBlockState(new BlockPos(i - 9, j + 3, k - 11), AbyssalCraft.ethaxiumbrick.getDefaultState(), 2);
		world.setBlockState(new BlockPos(i - 9, j + 3, k - 10), AbyssalCraft.ethaxiumbrick.getDefaultState(), 2);
		world.setBlockState(new BlockPos(i - 9, j + 3, k - 9), AbyssalCraft.ethaxiumbrick.getDefaultState(), 2);
		world.setBlockState(new BlockPos(i - 9, j + 3, k - 8), AbyssalCraft.ethaxiumbrick.getDefaultState(), 2);
		world.setBlockState(new BlockPos(i - 9, j + 3, k - 7), AbyssalCraft.ethaxiumbrick.getDefaultState(), 2);
		world.setBlockState(new BlockPos(i - 9, j + 3, k - 6), AbyssalCraft.ethaxiumbrick.getDefaultState(), 2);
		world.setBlockState(new BlockPos(i - 9, j + 3, k - 5), AbyssalCraft.ethaxiumbrick.getDefaultState(), 2);
		world.setBlockState(new BlockPos(i - 9, j + 3, k - 4), AbyssalCraft.ethaxiumbrick.getDefaultState(), 2);
		world.setBlockState(new BlockPos(i - 9, j + 3, k - 3), AbyssalCraft.ethaxiumbrick.getDefaultState(), 2);
		world.setBlockState(new BlockPos(i - 9, j + 3, k - 2), AbyssalCraft.ethaxiumbrick.getDefaultState(), 2);
		world.setBlockState(new BlockPos(i - 9, j + 3, k - 1), AbyssalCraft.ethaxiumpillar.getDefaultState(), 2);
		world.setBlockState(new BlockPos(i - 9, j + 4, k - 23), AbyssalCraft.ethaxiumpillar.getDefaultState(), 2);
		world.setBlockState(new BlockPos(i - 9, j + 4, k - 22), AbyssalCraft.ethaxiumbrick.getDefaultState(), 2);
		world.setBlockState(new BlockPos(i - 9, j + 4, k - 21), AbyssalCraft.ethaxiumbrick.getDefaultState(), 2);
		world.setBlockState(new BlockPos(i - 9, j + 4, k - 20), AbyssalCraft.ethaxiumbrick.getDefaultState(), 2);
		world.setBlockState(new BlockPos(i - 9, j + 4, k - 19), AbyssalCraft.ethaxiumbrick.getDefaultState(), 2);
		world.setBlockState(new BlockPos(i - 9, j + 4, k - 18), AbyssalCraft.ethaxiumbrick.getDefaultState(), 2);
		world.setBlockState(new BlockPos(i - 9, j + 4, k - 17), AbyssalCraft.ethaxiumbrick.getDefaultState(), 2);
		world.setBlockState(new BlockPos(i - 9, j + 4, k - 16), AbyssalCraft.ethaxiumbrick.getDefaultState(), 2);
		world.setBlockState(new BlockPos(i - 9, j + 4, k - 15), AbyssalCraft.ethaxiumbrick.getDefaultState(), 2);
		world.setBlockState(new BlockPos(i - 9, j + 4, k - 14), AbyssalCraft.ethaxiumbrick.getDefaultState(), 2);
		world.setBlockState(new BlockPos(i - 9, j + 4, k - 13), AbyssalCraft.ethaxiumbrick.getDefaultState(), 2);
		world.setBlockState(new BlockPos(i - 9, j + 4, k - 12), AbyssalCraft.ethaxiumbrick.getDefaultState(), 2);
		world.setBlockState(new BlockPos(i - 9, j + 4, k - 11), AbyssalCraft.ethaxiumbrick.getDefaultState(), 2);
		world.setBlockState(new BlockPos(i - 9, j + 4, k - 10), AbyssalCraft.ethaxiumbrick.getDefaultState(), 2);
		world.setBlockState(new BlockPos(i - 9, j + 4, k - 9), AbyssalCraft.ethaxiumbrick.getDefaultState(), 2);
		world.setBlockState(new BlockPos(i - 9, j + 4, k - 8), AbyssalCraft.ethaxiumbrick.getDefaultState(), 2);
		world.setBlockState(new BlockPos(i - 9, j + 4, k - 7), AbyssalCraft.ethaxiumbrick.getDefaultState(), 2);
		world.setBlockState(new BlockPos(i - 9, j + 4, k - 6), AbyssalCraft.ethaxiumbrick.getDefaultState(), 2);
		world.setBlockState(new BlockPos(i - 9, j + 4, k - 5), AbyssalCraft.ethaxiumbrick.getDefaultState(), 2);
		world.setBlockState(new BlockPos(i - 9, j + 4, k - 4), AbyssalCraft.ethaxiumbrick.getDefaultState(), 2);
		world.setBlockState(new BlockPos(i - 9, j + 4, k - 3), AbyssalCraft.ethaxiumbrick.getDefaultState(), 2);
		world.setBlockState(new BlockPos(i - 9, j + 4, k - 2), AbyssalCraft.ethaxiumbrick.getDefaultState(), 2);
		world.setBlockState(new BlockPos(i - 9, j + 4, k - 1), AbyssalCraft.ethaxiumpillar.getDefaultState(), 2);
		world.setBlockState(new BlockPos(i - 9, j + 5, k - 23), AbyssalCraft.ethaxiumpillar.getDefaultState(), 2);
		world.setBlockState(new BlockPos(i - 9, j + 5, k - 22), AbyssalCraft.ethaxiumbrick.getDefaultState(), 2);
		world.setBlockState(new BlockPos(i - 9, j + 5, k - 21), AbyssalCraft.ethaxiumbrick.getDefaultState(), 2);
		world.setBlockState(new BlockPos(i - 9, j + 5, k - 20), AbyssalCraft.ethaxiumbrick.getDefaultState(), 2);
		world.setBlockState(new BlockPos(i - 9, j + 5, k - 19), AbyssalCraft.ethaxiumbrick.getDefaultState(), 2);
		world.setBlockState(new BlockPos(i - 9, j + 5, k - 18), AbyssalCraft.ethaxiumbrick.getDefaultState(), 2);
		world.setBlockState(new BlockPos(i - 9, j + 5, k - 17), AbyssalCraft.ethaxiumbrick.getDefaultState(), 2);
		world.setBlockState(new BlockPos(i - 9, j + 5, k - 16), AbyssalCraft.ethaxiumbrick.getDefaultState(), 2);
		world.setBlockState(new BlockPos(i - 9, j + 5, k - 15), AbyssalCraft.ethaxiumbrick.getDefaultState(), 2);
		world.setBlockState(new BlockPos(i - 9, j + 5, k - 14), AbyssalCraft.ethaxiumbrick.getDefaultState(), 2);
		world.setBlockState(new BlockPos(i - 9, j + 5, k - 13), AbyssalCraft.ethaxiumbrick.getDefaultState(), 2);
		world.setBlockState(new BlockPos(i - 9, j + 5, k - 12), AbyssalCraft.ethaxiumbrick.getDefaultState(), 2);
		world.setBlockState(new BlockPos(i - 9, j + 5, k - 11), AbyssalCraft.ethaxiumbrick.getDefaultState(), 2);
		world.setBlockState(new BlockPos(i - 9, j + 5, k - 10), AbyssalCraft.ethaxiumbrick.getDefaultState(), 2);
		world.setBlockState(new BlockPos(i - 9, j + 5, k - 9), AbyssalCraft.ethaxiumbrick.getDefaultState(), 2);
		world.setBlockState(new BlockPos(i - 9, j + 5, k - 8), AbyssalCraft.ethaxiumbrick.getDefaultState(), 2);
		world.setBlockState(new BlockPos(i - 9, j + 5, k - 7), AbyssalCraft.ethaxiumbrick.getDefaultState(), 2);
		world.setBlockState(new BlockPos(i - 9, j + 5, k - 6), AbyssalCraft.ethaxiumbrick.getDefaultState(), 2);
		world.setBlockState(new BlockPos(i - 9, j + 5, k - 5), AbyssalCraft.ethaxiumbrick.getDefaultState(), 2);
		world.setBlockState(new BlockPos(i - 9, j + 5, k - 4), AbyssalCraft.ethaxiumbrick.getDefaultState(), 2);
		world.setBlockState(new BlockPos(i - 9, j + 5, k - 3), AbyssalCraft.ethaxiumbrick.getDefaultState(), 2);
		world.setBlockState(new BlockPos(i - 9, j + 5, k - 2), AbyssalCraft.ethaxiumbrick.getDefaultState(), 2);
		world.setBlockState(new BlockPos(i - 9, j + 5, k - 1), AbyssalCraft.ethaxiumpillar.getDefaultState(), 2);
		world.setBlockState(new BlockPos(i - 9, j + 6, k - 23), AbyssalCraft.ethaxiumstairs.getStateFromMeta(0), 2);
		world.setBlockState(new BlockPos(i - 9, j + 6, k - 22), AbyssalCraft.ethaxiumstairs.getStateFromMeta(0), 2);
		world.setBlockState(new BlockPos(i - 9, j + 6, k - 21), AbyssalCraft.ethaxiumstairs.getStateFromMeta(0), 2);
		world.setBlockState(new BlockPos(i - 9, j + 6, k - 20), AbyssalCraft.ethaxiumstairs.getStateFromMeta(0), 2);
		world.setBlockState(new BlockPos(i - 9, j + 6, k - 19), AbyssalCraft.ethaxiumstairs.getStateFromMeta(0), 2);
		world.setBlockState(new BlockPos(i - 9, j + 6, k - 18), AbyssalCraft.ethaxiumstairs.getStateFromMeta(0), 2);
		world.setBlockState(new BlockPos(i - 9, j + 6, k - 17), AbyssalCraft.ethaxiumstairs.getStateFromMeta(0), 2);
		world.setBlockState(new BlockPos(i - 9, j + 6, k - 16), AbyssalCraft.ethaxiumstairs.getStateFromMeta(0), 2);
		world.setBlockState(new BlockPos(i - 9, j + 6, k - 15), AbyssalCraft.ethaxiumstairs.getStateFromMeta(0), 2);
		world.setBlockState(new BlockPos(i - 9, j + 6, k - 14), AbyssalCraft.ethaxiumstairs.getStateFromMeta(0), 2);
		world.setBlockState(new BlockPos(i - 9, j + 6, k - 13), AbyssalCraft.ethaxiumstairs.getStateFromMeta(0), 2);
		world.setBlockState(new BlockPos(i - 9, j + 6, k - 12), AbyssalCraft.ethaxiumstairs.getStateFromMeta(0), 2);
		world.setBlockState(new BlockPos(i - 9, j + 6, k - 11), AbyssalCraft.ethaxiumstairs.getStateFromMeta(0), 2);
		world.setBlockState(new BlockPos(i - 9, j + 6, k - 10), AbyssalCraft.ethaxiumstairs.getStateFromMeta(0), 2);
		world.setBlockState(new BlockPos(i - 9, j + 6, k - 9), AbyssalCraft.ethaxiumstairs.getStateFromMeta(0), 2);
		world.setBlockState(new BlockPos(i - 9, j + 6, k - 8), AbyssalCraft.ethaxiumstairs.getStateFromMeta(0), 2);
		world.setBlockState(new BlockPos(i - 9, j + 6, k - 7), AbyssalCraft.ethaxiumstairs.getStateFromMeta(0), 2);
		world.setBlockState(new BlockPos(i - 9, j + 6, k - 6), AbyssalCraft.ethaxiumstairs.getStateFromMeta(0), 2);
		world.setBlockState(new BlockPos(i - 9, j + 6, k - 5), AbyssalCraft.ethaxiumstairs.getStateFromMeta(0), 2);
		world.setBlockState(new BlockPos(i - 9, j + 6, k - 4), AbyssalCraft.ethaxiumstairs.getStateFromMeta(0), 2);
		world.setBlockState(new BlockPos(i - 9, j + 6, k - 3), AbyssalCraft.ethaxiumstairs.getStateFromMeta(0), 2);
		world.setBlockState(new BlockPos(i - 9, j + 6, k - 2), AbyssalCraft.ethaxiumstairs.getStateFromMeta(0), 2);
		world.setBlockState(new BlockPos(i - 9, j + 6, k - 1), AbyssalCraft.ethaxiumstairs.getStateFromMeta(3), 2); //TODO: 3
		world.setBlockState(new BlockPos(i - 8, j + 0, k - 23), AbyssalCraft.ethaxiumbrick.getDefaultState(), 2);
		world.setBlockState(new BlockPos(i - 8, j + 0, k - 22), AbyssalCraft.ethaxiumbrick.getDefaultState(), 2);
		world.setBlockState(new BlockPos(i - 8, j + 0, k - 21), AbyssalCraft.ethaxiumbrick.getDefaultState(), 2);
		world.setBlockState(new BlockPos(i - 8, j + 0, k - 20), AbyssalCraft.ethaxiumbrick.getDefaultState(), 2);
		world.setBlockState(new BlockPos(i - 8, j + 0, k - 19), AbyssalCraft.ethaxiumbrick.getDefaultState(), 2);
		world.setBlockState(new BlockPos(i - 8, j + 0, k - 18), AbyssalCraft.ethaxiumbrick.getDefaultState(), 2);
		world.setBlockState(new BlockPos(i - 8, j + 0, k - 17), AbyssalCraft.ethaxiumbrick.getDefaultState(), 2);
		world.setBlockState(new BlockPos(i - 8, j + 0, k - 16), AbyssalCraft.ethaxiumbrick.getDefaultState(), 2);
		world.setBlockState(new BlockPos(i - 8, j + 0, k - 15), AbyssalCraft.ethaxiumbrick.getDefaultState(), 2);
		world.setBlockState(new BlockPos(i - 8, j + 0, k - 14), AbyssalCraft.ethaxiumbrick.getDefaultState(), 2);
		world.setBlockState(new BlockPos(i - 8, j + 0, k - 13), AbyssalCraft.ethaxiumbrick.getDefaultState(), 2);
		world.setBlockState(new BlockPos(i - 8, j + 0, k - 12), AbyssalCraft.ethaxiumbrick.getDefaultState(), 2);
		world.setBlockState(new BlockPos(i - 8, j + 0, k - 11), AbyssalCraft.ethaxiumbrick.getDefaultState(), 2);
		world.setBlockState(new BlockPos(i - 8, j + 0, k - 10), AbyssalCraft.ethaxiumbrick.getDefaultState(), 2);
		world.setBlockState(new BlockPos(i - 8, j + 0, k - 9), AbyssalCraft.ethaxiumbrick.getDefaultState(), 2);
		world.setBlockState(new BlockPos(i - 8, j + 0, k - 8), AbyssalCraft.ethaxiumbrick.getDefaultState(), 2);
		world.setBlockState(new BlockPos(i - 8, j + 0, k - 7), AbyssalCraft.ethaxiumbrick.getDefaultState(), 2);
		world.setBlockState(new BlockPos(i - 8, j + 0, k - 6), AbyssalCraft.ethaxiumbrick.getDefaultState(), 2);
		world.setBlockState(new BlockPos(i - 8, j + 0, k - 5), AbyssalCraft.ethaxiumbrick.getDefaultState(), 2);
		world.setBlockState(new BlockPos(i - 8, j + 0, k - 4), AbyssalCraft.ethaxiumbrick.getDefaultState(), 2);
		world.setBlockState(new BlockPos(i - 8, j + 0, k - 3), AbyssalCraft.ethaxiumbrick.getDefaultState(), 2);
		world.setBlockState(new BlockPos(i - 8, j + 0, k - 2), AbyssalCraft.ethaxiumbrick.getDefaultState(), 2);
		world.setBlockState(new BlockPos(i - 8, j + 1, k - 23), AbyssalCraft.ethaxiumbrick.getDefaultState(), 2);
		world.setBlockState(new BlockPos(i - 8, j + 1, k - 22), AbyssalCraft.ethaxiumbrick.getDefaultState(), 2);
		world.setBlockState(new BlockPos(i - 8, j + 1, k - 21), AbyssalCraft.ethaxiumbrick.getDefaultState(), 2);
		world.setBlockState(new BlockPos(i - 8, j + 1, k - 20), AbyssalCraft.ethaxiumbrick.getDefaultState(), 2);
		world.setBlockState(new BlockPos(i - 8, j + 1, k - 19), AbyssalCraft.ethaxiumbrick.getDefaultState(), 2);
		world.setBlockState(new BlockPos(i - 8, j + 1, k - 18), AbyssalCraft.ethaxiumbrick.getDefaultState(), 2);
		world.setBlockState(new BlockPos(i - 8, j + 1, k - 17), AbyssalCraft.ethaxiumbrick.getDefaultState(), 2);
		world.setBlockState(new BlockPos(i - 8, j + 1, k - 16), AbyssalCraft.ethaxiumbrick.getDefaultState(), 2);
		world.setBlockState(new BlockPos(i - 8, j + 1, k - 15), AbyssalCraft.ethaxiumbrick.getDefaultState(), 2);
		world.setBlockState(new BlockPos(i - 8, j + 1, k - 14), AbyssalCraft.ethaxiumbrick.getDefaultState(), 2);
		world.setBlockState(new BlockPos(i - 8, j + 1, k - 13), AbyssalCraft.ethaxiumbrick.getDefaultState(), 2);
		world.setBlockState(new BlockPos(i - 8, j + 1, k - 12), AbyssalCraft.ethaxiumbrick.getDefaultState(), 2);
		world.setBlockState(new BlockPos(i - 8, j + 1, k - 11), AbyssalCraft.ethaxiumbrick.getDefaultState(), 2);
		world.setBlockState(new BlockPos(i - 8, j + 1, k - 10), AbyssalCraft.ethaxiumbrick.getDefaultState(), 2);
		world.setBlockState(new BlockPos(i - 8, j + 1, k - 9), AbyssalCraft.ethaxiumbrick.getDefaultState(), 2);
		world.setBlockState(new BlockPos(i - 8, j + 1, k - 8), AbyssalCraft.ethaxiumbrick.getDefaultState(), 2);
		world.setBlockState(new BlockPos(i - 8, j + 1, k - 7), AbyssalCraft.ethaxiumbrick.getDefaultState(), 2);
		world.setBlockState(new BlockPos(i - 8, j + 1, k - 6), AbyssalCraft.ethaxiumbrick.getDefaultState(), 2);
		world.setBlockState(new BlockPos(i - 8, j + 1, k - 5), AbyssalCraft.ethaxiumbrick.getDefaultState(), 2);
		world.setBlockState(new BlockPos(i - 8, j + 1, k - 4), AbyssalCraft.ethaxiumbrick.getDefaultState(), 2);
		world.setBlockState(new BlockPos(i - 8, j + 1, k - 3), AbyssalCraft.ethaxiumbrick.getDefaultState(), 2);
		world.setBlockState(new BlockPos(i - 8, j + 2, k - 23), AbyssalCraft.ethaxiumbrick.getDefaultState(), 2);
		world.setBlockState(new BlockPos(i - 8, j + 2, k - 22), AbyssalCraft.ethaxiumbrick.getDefaultState(), 2);
		world.setBlockState(new BlockPos(i - 8, j + 2, k - 21), AbyssalCraft.Darkstone_brick.getDefaultState(), 2);
		world.setBlockState(new BlockPos(i - 8, j + 2, k - 20), AbyssalCraft.Darkstone_brick.getDefaultState(), 2);
		world.setBlockState(new BlockPos(i - 8, j + 2, k - 19), AbyssalCraft.Darkstone_brick.getDefaultState(), 2);
		world.setBlockState(new BlockPos(i - 8, j + 2, k - 18), AbyssalCraft.Darkstone_brick.getDefaultState(), 2);
		world.setBlockState(new BlockPos(i - 8, j + 2, k - 17), AbyssalCraft.Darkstone_brick.getDefaultState(), 2);
		world.setBlockState(new BlockPos(i - 8, j + 2, k - 16), AbyssalCraft.Darkstone_brick.getDefaultState(), 2);
		world.setBlockState(new BlockPos(i - 8, j + 2, k - 15), AbyssalCraft.Darkstone_brick.getDefaultState(), 2);
		world.setBlockState(new BlockPos(i - 8, j + 2, k - 14), AbyssalCraft.Darkstone_brick.getDefaultState(), 2);
		world.setBlockState(new BlockPos(i - 8, j + 2, k - 13), AbyssalCraft.Darkstone_brick.getDefaultState(), 2);
		world.setBlockState(new BlockPos(i - 8, j + 2, k - 12), AbyssalCraft.Darkstone_brick.getDefaultState(), 2);
		world.setBlockState(new BlockPos(i - 8, j + 2, k - 11), AbyssalCraft.Darkstone_brick.getDefaultState(), 2);
		world.setBlockState(new BlockPos(i - 8, j + 2, k - 10), AbyssalCraft.Darkstone_brick.getDefaultState(), 2);
		world.setBlockState(new BlockPos(i - 8, j + 2, k - 9), AbyssalCraft.Darkstone_brick.getDefaultState(), 2);
		world.setBlockState(new BlockPos(i - 8, j + 2, k - 8), AbyssalCraft.Darkstone_brick.getDefaultState(), 2);
		world.setBlockState(new BlockPos(i - 8, j + 2, k - 7), AbyssalCraft.Darkstone_brick.getDefaultState(), 2);
		world.setBlockState(new BlockPos(i - 8, j + 2, k - 6), AbyssalCraft.ethaxiumbrick.getDefaultState(), 2);
		world.setBlockState(new BlockPos(i - 8, j + 2, k - 5), AbyssalCraft.ethaxiumbrick.getDefaultState(), 2);
		world.setBlockState(new BlockPos(i - 8, j + 2, k - 4), AbyssalCraft.ethaxiumbrick.getDefaultState(), 2);
		world.setBlockState(new BlockPos(i - 8, j + 2, k - 3), AbyssalCraft.ethaxiumbrick.getDefaultState(), 2);
		world.setBlockState(new BlockPos(i - 8, j + 3, k - 23), AbyssalCraft.ethaxiumbrick.getDefaultState(), 2);
		world.setBlockState(new BlockPos(i - 8, j + 3, k - 22), AbyssalCraft.ethaxiumbrick.getDefaultState(), 2);
		world.setBlockState(new BlockPos(i - 8, j + 3, k - 21), AbyssalCraft.Darkstone_brick.getDefaultState(), 2);
		world.setBlockState(new BlockPos(i - 8, j + 3, k - 20), AbyssalCraft.Darkstone_brick.getDefaultState(), 2);
		world.setBlockState(new BlockPos(i - 8, j + 3, k - 19), AbyssalCraft.DSGlow.getDefaultState(), 2);
		world.setBlockState(new BlockPos(i - 8, j + 3, k - 18), AbyssalCraft.Darkstone_brick.getDefaultState(), 2);
		world.setBlockState(new BlockPos(i - 8, j + 3, k - 17), AbyssalCraft.Darkstone_brick.getDefaultState(), 2);
		world.setBlockState(new BlockPos(i - 8, j + 3, k - 16), AbyssalCraft.Darkstone_brick.getDefaultState(), 2);
		world.setBlockState(new BlockPos(i - 8, j + 3, k - 15), AbyssalCraft.Darkstone_brick.getDefaultState(), 2);
		world.setBlockState(new BlockPos(i - 8, j + 3, k - 14), AbyssalCraft.DSGlow.getDefaultState(), 2);
		world.setBlockState(new BlockPos(i - 8, j + 3, k - 13), AbyssalCraft.Darkstone_brick.getDefaultState(), 2);
		world.setBlockState(new BlockPos(i - 8, j + 3, k - 12), AbyssalCraft.Darkstone_brick.getDefaultState(), 2);
		world.setBlockState(new BlockPos(i - 8, j + 3, k - 11), AbyssalCraft.Darkstone_brick.getDefaultState(), 2);
		world.setBlockState(new BlockPos(i - 8, j + 3, k - 10), AbyssalCraft.Darkstone_brick.getDefaultState(), 2);
		world.setBlockState(new BlockPos(i - 8, j + 3, k - 9), AbyssalCraft.Darkstone_brick.getDefaultState(), 2);
		world.setBlockState(new BlockPos(i - 8, j + 3, k - 8), AbyssalCraft.Darkstone_brick.getDefaultState(), 2);
		world.setBlockState(new BlockPos(i - 8, j + 3, k - 7), AbyssalCraft.DSGlow.getDefaultState(), 2);
		world.setBlockState(new BlockPos(i - 8, j + 3, k - 6), AbyssalCraft.ethaxiumbrick.getDefaultState(), 2);
		world.setBlockState(new BlockPos(i - 8, j + 3, k - 5), AbyssalCraft.ethaxiumbrick.getDefaultState(), 2);
		world.setBlockState(new BlockPos(i - 8, j + 3, k - 4), AbyssalCraft.ethaxiumbrick.getDefaultState(), 2);
		world.setBlockState(new BlockPos(i - 8, j + 3, k - 3), AbyssalCraft.ethaxiumbrick.getDefaultState(), 2);
		world.setBlockState(new BlockPos(i - 8, j + 4, k - 23), AbyssalCraft.ethaxiumbrick.getDefaultState(), 2);
		world.setBlockState(new BlockPos(i - 8, j + 4, k - 22), AbyssalCraft.ethaxiumbrick.getDefaultState(), 2);
		world.setBlockState(new BlockPos(i - 8, j + 4, k - 21), AbyssalCraft.Darkstone_brick.getDefaultState(), 2);
		world.setBlockState(new BlockPos(i - 8, j + 4, k - 20), AbyssalCraft.Darkstone_brick.getDefaultState(), 2);
		world.setBlockState(new BlockPos(i - 8, j + 4, k - 19), AbyssalCraft.Darkstone_brick.getDefaultState(), 2);
		world.setBlockState(new BlockPos(i - 8, j + 4, k - 18), AbyssalCraft.Darkstone_brick.getDefaultState(), 2);
		world.setBlockState(new BlockPos(i - 8, j + 4, k - 17), AbyssalCraft.Darkstone_brick.getDefaultState(), 2);
		world.setBlockState(new BlockPos(i - 8, j + 4, k - 16), AbyssalCraft.Darkstone_brick.getDefaultState(), 2);
		world.setBlockState(new BlockPos(i - 8, j + 4, k - 15), AbyssalCraft.Darkstone_brick.getDefaultState(), 2);
		world.setBlockState(new BlockPos(i - 8, j + 4, k - 14), AbyssalCraft.Darkstone_brick.getDefaultState(), 2);
		world.setBlockState(new BlockPos(i - 8, j + 4, k - 13), AbyssalCraft.Darkstone_brick.getDefaultState(), 2);
		world.setBlockState(new BlockPos(i - 8, j + 4, k - 12), AbyssalCraft.Darkstone_brick.getDefaultState(), 2);
		world.setBlockState(new BlockPos(i - 8, j + 4, k - 11), AbyssalCraft.Darkstone_brick.getDefaultState(), 2);
		world.setBlockState(new BlockPos(i - 8, j + 4, k - 10), AbyssalCraft.Darkstone_brick.getDefaultState(), 2);
		world.setBlockState(new BlockPos(i - 8, j + 4, k - 9), AbyssalCraft.Darkstone_brick.getDefaultState(), 2);
		world.setBlockState(new BlockPos(i - 8, j + 4, k - 8), AbyssalCraft.Darkstone_brick.getDefaultState(), 2);
		world.setBlockState(new BlockPos(i - 8, j + 4, k - 7), AbyssalCraft.Darkstone_brick.getDefaultState(), 2);
		world.setBlockState(new BlockPos(i - 8, j + 4, k - 6), AbyssalCraft.ethaxiumbrick.getDefaultState(), 2);
		world.setBlockState(new BlockPos(i - 8, j + 4, k - 5), AbyssalCraft.ethaxiumbrick.getDefaultState(), 2);
		world.setBlockState(new BlockPos(i - 8, j + 4, k - 4), AbyssalCraft.ethaxiumbrick.getDefaultState(), 2);
		world.setBlockState(new BlockPos(i - 8, j + 4, k - 3), AbyssalCraft.ethaxiumbrick.getDefaultState(), 2);
		world.setBlockState(new BlockPos(i - 8, j + 5, k - 23), AbyssalCraft.ethaxiumbrick.getDefaultState(), 2);
		world.setBlockState(new BlockPos(i - 8, j + 5, k - 22), AbyssalCraft.ethaxiumbrick.getDefaultState(), 2);
		world.setBlockState(new BlockPos(i - 8, j + 5, k - 21), AbyssalCraft.ethaxiumbrick.getDefaultState(), 2);
		world.setBlockState(new BlockPos(i - 8, j + 5, k - 20), AbyssalCraft.ethaxiumbrick.getDefaultState(), 2);
		world.setBlockState(new BlockPos(i - 8, j + 5, k - 19), AbyssalCraft.ethaxiumbrick.getDefaultState(), 2);
		world.setBlockState(new BlockPos(i - 8, j + 5, k - 18), AbyssalCraft.ethaxiumbrick.getDefaultState(), 2);
		world.setBlockState(new BlockPos(i - 8, j + 5, k - 17), AbyssalCraft.ethaxiumbrick.getDefaultState(), 2);
		world.setBlockState(new BlockPos(i - 8, j + 5, k - 16), AbyssalCraft.ethaxiumbrick.getDefaultState(), 2);
		world.setBlockState(new BlockPos(i - 8, j + 5, k - 15), AbyssalCraft.ethaxiumbrick.getDefaultState(), 2);
		world.setBlockState(new BlockPos(i - 8, j + 5, k - 14), AbyssalCraft.ethaxiumbrick.getDefaultState(), 2);
		world.setBlockState(new BlockPos(i - 8, j + 5, k - 13), AbyssalCraft.ethaxiumbrick.getDefaultState(), 2);
		world.setBlockState(new BlockPos(i - 8, j + 5, k - 12), AbyssalCraft.ethaxiumbrick.getDefaultState(), 2);
		world.setBlockState(new BlockPos(i - 8, j + 5, k - 11), AbyssalCraft.ethaxiumbrick.getDefaultState(), 2);
		world.setBlockState(new BlockPos(i - 8, j + 5, k - 10), AbyssalCraft.ethaxiumbrick.getDefaultState(), 2);
		world.setBlockState(new BlockPos(i - 8, j + 5, k - 9), AbyssalCraft.ethaxiumbrick.getDefaultState(), 2);
		world.setBlockState(new BlockPos(i - 8, j + 5, k - 8), AbyssalCraft.ethaxiumbrick.getDefaultState(), 2);
		world.setBlockState(new BlockPos(i - 8, j + 5, k - 7), AbyssalCraft.ethaxiumbrick.getDefaultState(), 2);
		world.setBlockState(new BlockPos(i - 8, j + 5, k - 6), AbyssalCraft.ethaxiumbrick.getDefaultState(), 2);
		world.setBlockState(new BlockPos(i - 8, j + 5, k - 5), AbyssalCraft.ethaxiumbrick.getDefaultState(), 2);
		world.setBlockState(new BlockPos(i - 8, j + 5, k - 4), AbyssalCraft.ethaxiumbrick.getDefaultState(), 2);
		world.setBlockState(new BlockPos(i - 8, j + 5, k - 3), AbyssalCraft.ethaxiumbrick.getDefaultState(), 2);
		world.setBlockState(new BlockPos(i - 8, j + 6, k - 23), AbyssalCraft.ethaxiumstairs.getStateFromMeta(2), 2); //TODO: 2
		world.setBlockState(new BlockPos(i - 8, j + 6, k - 22), AbyssalCraft.ethaxiumbrick.getDefaultState(), 2);
		world.setBlockState(new BlockPos(i - 8, j + 6, k - 21), AbyssalCraft.ethaxiumbrick.getDefaultState(), 2);
		world.setBlockState(new BlockPos(i - 8, j + 6, k - 20), AbyssalCraft.ethaxiumbrick.getDefaultState(), 2);
		world.setBlockState(new BlockPos(i - 8, j + 6, k - 19), AbyssalCraft.ethaxiumbrick.getDefaultState(), 2);
		world.setBlockState(new BlockPos(i - 8, j + 6, k - 18), AbyssalCraft.ethaxiumbrick.getDefaultState(), 2);
		world.setBlockState(new BlockPos(i - 8, j + 6, k - 17), AbyssalCraft.ethaxiumbrick.getDefaultState(), 2);
		world.setBlockState(new BlockPos(i - 8, j + 6, k - 16), AbyssalCraft.ethaxiumbrick.getDefaultState(), 2);
		world.setBlockState(new BlockPos(i - 8, j + 6, k - 15), AbyssalCraft.ethaxiumbrick.getDefaultState(), 2);
		world.setBlockState(new BlockPos(i - 8, j + 6, k - 14), AbyssalCraft.ethaxiumbrick.getDefaultState(), 2);
		world.setBlockState(new BlockPos(i - 8, j + 6, k - 13), AbyssalCraft.ethaxiumbrick.getDefaultState(), 2);
		world.setBlockState(new BlockPos(i - 8, j + 6, k - 12), AbyssalCraft.ethaxiumbrick.getDefaultState(), 2);
		world.setBlockState(new BlockPos(i - 8, j + 6, k - 11), AbyssalCraft.ethaxiumbrick.getDefaultState(), 2);
		world.setBlockState(new BlockPos(i - 8, j + 6, k - 10), AbyssalCraft.ethaxiumbrick.getDefaultState(), 2);
		world.setBlockState(new BlockPos(i - 8, j + 6, k - 9), AbyssalCraft.ethaxiumbrick.getDefaultState(), 2);
		world.setBlockState(new BlockPos(i - 8, j + 6, k - 8), AbyssalCraft.ethaxiumbrick.getDefaultState(), 2);
		world.setBlockState(new BlockPos(i - 8, j + 6, k - 7), AbyssalCraft.ethaxiumbrick.getDefaultState(), 2);
		world.setBlockState(new BlockPos(i - 8, j + 6, k - 6), AbyssalCraft.ethaxiumbrick.getDefaultState(), 2);
		world.setBlockState(new BlockPos(i - 8, j + 6, k - 5), AbyssalCraft.ethaxiumbrick.getDefaultState(), 2);
		world.setBlockState(new BlockPos(i - 8, j + 6, k - 4), AbyssalCraft.ethaxiumbrick.getDefaultState(), 2);
		world.setBlockState(new BlockPos(i - 8, j + 6, k - 3), AbyssalCraft.ethaxiumbrick.getDefaultState(), 2);
		world.setBlockState(new BlockPos(i - 8, j + 6, k - 2), AbyssalCraft.ethaxiumbrick.getDefaultState(), 2);
		world.setBlockState(new BlockPos(i - 8, j + 6, k - 1), AbyssalCraft.ethaxiumstairs.getStateFromMeta(3), 2); //TODO: 3
		world.setBlockState(new BlockPos(i - 7, j + 0, k - 23), AbyssalCraft.ethaxiumbrick.getDefaultState(), 2);
		world.setBlockState(new BlockPos(i - 7, j + 0, k - 22), AbyssalCraft.ethaxiumbrick.getDefaultState(), 2);
		world.setBlockState(new BlockPos(i - 7, j + 0, k - 21), AbyssalCraft.ethaxiumbrick.getDefaultState(), 2);
		world.setBlockState(new BlockPos(i - 7, j + 0, k - 20), AbyssalCraft.ethaxiumbrick.getDefaultState(), 2);
		world.setBlockState(new BlockPos(i - 7, j + 0, k - 19), AbyssalCraft.ethaxiumbrick.getDefaultState(), 2);
		world.setBlockState(new BlockPos(i - 7, j + 0, k - 18), AbyssalCraft.ethaxiumbrick.getDefaultState(), 2);
		world.setBlockState(new BlockPos(i - 7, j + 0, k - 17), AbyssalCraft.ethaxiumbrick.getDefaultState(), 2);
		world.setBlockState(new BlockPos(i - 7, j + 0, k - 16), AbyssalCraft.ethaxiumbrick.getDefaultState(), 2);
		world.setBlockState(new BlockPos(i - 7, j + 0, k - 15), AbyssalCraft.ethaxiumbrick.getDefaultState(), 2);
		world.setBlockState(new BlockPos(i - 7, j + 0, k - 14), AbyssalCraft.ethaxiumbrick.getDefaultState(), 2);
		world.setBlockState(new BlockPos(i - 7, j + 0, k - 13), AbyssalCraft.ethaxiumbrick.getDefaultState(), 2);
		world.setBlockState(new BlockPos(i - 7, j + 0, k - 12), AbyssalCraft.ethaxiumbrick.getDefaultState(), 2);
		world.setBlockState(new BlockPos(i - 7, j + 0, k - 11), AbyssalCraft.ethaxiumbrick.getDefaultState(), 2);
		world.setBlockState(new BlockPos(i - 7, j + 0, k - 10), AbyssalCraft.ethaxiumbrick.getDefaultState(), 2);
		world.setBlockState(new BlockPos(i - 7, j + 0, k - 9), AbyssalCraft.ethaxiumbrick.getDefaultState(), 2);
		world.setBlockState(new BlockPos(i - 7, j + 0, k - 8), AbyssalCraft.ethaxiumbrick.getDefaultState(), 2);
		world.setBlockState(new BlockPos(i - 7, j + 0, k - 7), AbyssalCraft.ethaxiumbrick.getDefaultState(), 2);
		world.setBlockState(new BlockPos(i - 7, j + 0, k - 6), AbyssalCraft.ethaxiumbrick.getDefaultState(), 2);
		world.setBlockState(new BlockPos(i - 7, j + 0, k - 5), AbyssalCraft.ethaxiumbrick.getDefaultState(), 2);
		world.setBlockState(new BlockPos(i - 7, j + 0, k - 4), AbyssalCraft.ethaxiumbrick.getDefaultState(), 2);
		world.setBlockState(new BlockPos(i - 7, j + 0, k - 3), AbyssalCraft.ethaxiumbrick.getDefaultState(), 2);
		world.setBlockState(new BlockPos(i - 7, j + 0, k - 2), AbyssalCraft.ethaxiumbrick.getDefaultState(), 2);
		world.setBlockState(new BlockPos(i - 7, j + 1, k - 23), AbyssalCraft.ethaxiumbrick.getDefaultState(), 2);
		world.setBlockState(new BlockPos(i - 7, j + 1, k - 22), AbyssalCraft.ethaxiumbrick.getDefaultState(), 2);
		world.setBlockState(new BlockPos(i - 7, j + 1, k - 21), AbyssalCraft.Darkstone_cobble.getDefaultState(), 2);
		world.setBlockState(new BlockPos(i - 7, j + 1, k - 20), AbyssalCraft.Darkstone_cobble.getDefaultState(), 2);
		world.setBlockState(new BlockPos(i - 7, j + 1, k - 19), AbyssalCraft.Darkstone_cobble.getDefaultState(), 2);
		world.setBlockState(new BlockPos(i - 7, j + 1, k - 18), AbyssalCraft.Darkstone_cobble.getDefaultState(), 2);
		world.setBlockState(new BlockPos(i - 7, j + 1, k - 17), AbyssalCraft.Darkstone_cobble.getDefaultState(), 2);
		world.setBlockState(new BlockPos(i - 7, j + 1, k - 16), AbyssalCraft.Darkstone_cobble.getDefaultState(), 2);
		world.setBlockState(new BlockPos(i - 7, j + 1, k - 15), AbyssalCraft.Darkstone_cobble.getDefaultState(), 2);
		world.setBlockState(new BlockPos(i - 7, j + 1, k - 14), AbyssalCraft.Darkstone_cobble.getDefaultState(), 2);
		world.setBlockState(new BlockPos(i - 7, j + 1, k - 13), AbyssalCraft.Darkstone_cobble.getDefaultState(), 2);
		world.setBlockState(new BlockPos(i - 7, j + 1, k - 12), AbyssalCraft.Darkstone_cobble.getDefaultState(), 2);
		world.setBlockState(new BlockPos(i - 7, j + 1, k - 11), AbyssalCraft.Darkstone_cobble.getDefaultState(), 2);
		world.setBlockState(new BlockPos(i - 7, j + 1, k - 10), AbyssalCraft.Darkstone_cobble.getDefaultState(), 2);
		world.setBlockState(new BlockPos(i - 7, j + 1, k - 9), AbyssalCraft.Darkstone_cobble.getDefaultState(), 2);
		world.setBlockState(new BlockPos(i - 7, j + 1, k - 8), AbyssalCraft.Darkstone_cobble.getDefaultState(), 2);
		world.setBlockState(new BlockPos(i - 7, j + 1, k - 7), Blocks.water.getDefaultState(), 2);
		world.setBlockState(new BlockPos(i - 7, j + 1, k - 6), AbyssalCraft.ethaxiumbrick.getDefaultState(), 2);
		world.setBlockState(new BlockPos(i - 7, j + 1, k - 5), AbyssalCraft.ethaxiumbrick.getDefaultState(), 2);
		world.setBlockState(new BlockPos(i - 7, j + 1, k - 4), AbyssalCraft.ethaxiumbrick.getDefaultState(), 2);
		world.setBlockState(new BlockPos(i - 7, j + 1, k - 3), AbyssalCraft.ethaxiumbrick.getDefaultState(), 2);
		world.setBlockState(new BlockPos(i - 7, j + 2, k - 23), AbyssalCraft.ethaxiumbrick.getDefaultState(), 2);
		world.setBlockState(new BlockPos(i - 7, j + 2, k - 22), AbyssalCraft.Darkstone_brick.getDefaultState(), 2);
		world.setBlockState(new BlockPos(i - 7, j + 2, k - 16), AbyssalCraft.Darkstone_brick.getDefaultState(), 2);
		world.setBlockState(new BlockPos(i - 7, j + 2, k - 12), AbyssalCraft.Darkstone_brick.getDefaultState(), 2);
		world.setBlockState(new BlockPos(i - 7, j + 2, k - 11), AbyssalCraft.Darkstone_brick.getDefaultState(), 2);
		world.setBlockState(new BlockPos(i - 7, j + 2, k - 10), AbyssalCraft.Darkstone_brick.getDefaultState(), 2);
		world.setBlockState(new BlockPos(i - 7, j + 2, k - 9), AbyssalCraft.Darkstone_brick.getDefaultState(), 2);
		world.setBlockState(new BlockPos(i - 7, j + 2, k - 8), AbyssalCraft.Darkstone_brick.getDefaultState(), 2);
		world.setBlockState(new BlockPos(i - 7, j + 2, k - 6), AbyssalCraft.Darkstone_brick.getDefaultState(), 2);
		world.setBlockState(new BlockPos(i - 7, j + 2, k - 5), AbyssalCraft.ethaxiumbrick.getDefaultState(), 2);
		world.setBlockState(new BlockPos(i - 7, j + 2, k - 3), AbyssalCraft.ethaxiumfence.getDefaultState(), 2);
		world.setBlockState(new BlockPos(i - 7, j + 3, k - 23), AbyssalCraft.ethaxiumbrick.getDefaultState(), 2);
		world.setBlockState(new BlockPos(i - 7, j + 3, k - 22), AbyssalCraft.Darkstone_brick.getDefaultState(), 2);
		world.setBlockState(new BlockPos(i - 7, j + 3, k - 16), AbyssalCraft.Darkstone_brick.getDefaultState(), 2);
		world.setBlockState(new BlockPos(i - 7, j + 3, k - 12), AbyssalCraft.Darkstone_brick.getDefaultState(), 2);
		world.setBlockState(new BlockPos(i - 7, j + 3, k - 6), AbyssalCraft.Darkstone_brick.getDefaultState(), 2);
		world.setBlockState(new BlockPos(i - 7, j + 3, k - 5), AbyssalCraft.ethaxiumbrick.getDefaultState(), 2);
		world.setBlockState(new BlockPos(i - 7, j + 3, k - 3), AbyssalCraft.ethaxiumfence.getDefaultState(), 2);
		world.setBlockState(new BlockPos(i - 7, j + 4, k - 23), AbyssalCraft.ethaxiumbrick.getDefaultState(), 2);
		world.setBlockState(new BlockPos(i - 7, j + 4, k - 22), AbyssalCraft.Darkstone_brick.getDefaultState(), 2);
		world.setBlockState(new BlockPos(i - 7, j + 4, k - 16), AbyssalCraft.Darkstone_brick.getDefaultState(), 2);
		world.setBlockState(new BlockPos(i - 7, j + 4, k - 12), AbyssalCraft.Darkstone_brick.getDefaultState(), 2);
		world.setBlockState(new BlockPos(i - 7, j + 4, k - 6), AbyssalCraft.Darkstone_brick.getDefaultState(), 2);
		world.setBlockState(new BlockPos(i - 7, j + 4, k - 5), AbyssalCraft.ethaxiumbrick.getDefaultState(), 2);
		world.setBlockState(new BlockPos(i - 7, j + 4, k - 3), AbyssalCraft.ethaxiumfence.getDefaultState(), 2);
		world.setBlockState(new BlockPos(i - 7, j + 5, k - 23), AbyssalCraft.ethaxiumbrick.getDefaultState(), 2);
		world.setBlockState(new BlockPos(i - 7, j + 5, k - 22), AbyssalCraft.ethaxiumbrick.getDefaultState(), 2);
		world.setBlockState(new BlockPos(i - 7, j + 5, k - 21), AbyssalCraft.Darkstone_brick.getDefaultState(), 2);
		world.setBlockState(new BlockPos(i - 7, j + 5, k - 20), AbyssalCraft.Darkstone_brick.getDefaultState(), 2);
		world.setBlockState(new BlockPos(i - 7, j + 5, k - 19), AbyssalCraft.Darkstone_brick.getDefaultState(), 2);
		world.setBlockState(new BlockPos(i - 7, j + 5, k - 18), AbyssalCraft.Darkstone_brick.getDefaultState(), 2);
		world.setBlockState(new BlockPos(i - 7, j + 5, k - 17), AbyssalCraft.Darkstone_brick.getDefaultState(), 2);
		world.setBlockState(new BlockPos(i - 7, j + 5, k - 16), AbyssalCraft.Darkstone_brick.getDefaultState(), 2);
		world.setBlockState(new BlockPos(i - 7, j + 5, k - 15), AbyssalCraft.Darkstone_brick.getDefaultState(), 2);
		world.setBlockState(new BlockPos(i - 7, j + 5, k - 14), AbyssalCraft.Darkstone_brick.getDefaultState(), 2);
		world.setBlockState(new BlockPos(i - 7, j + 5, k - 13), AbyssalCraft.Darkstone_brick.getDefaultState(), 2);
		world.setBlockState(new BlockPos(i - 7, j + 5, k - 12), AbyssalCraft.Darkstone_brick.getDefaultState(), 2);
		world.setBlockState(new BlockPos(i - 7, j + 5, k - 11), AbyssalCraft.Darkstone_brick.getDefaultState(), 2);
		world.setBlockState(new BlockPos(i - 7, j + 5, k - 10), AbyssalCraft.Darkstone_brick.getDefaultState(), 2);
		world.setBlockState(new BlockPos(i - 7, j + 5, k - 9), AbyssalCraft.Darkstone_brick.getDefaultState(), 2);
		world.setBlockState(new BlockPos(i - 7, j + 5, k - 8), AbyssalCraft.Darkstone_brick.getDefaultState(), 2);
		world.setBlockState(new BlockPos(i - 7, j + 5, k - 7), AbyssalCraft.Darkstone_brick.getDefaultState(), 2);
		world.setBlockState(new BlockPos(i - 7, j + 5, k - 6), AbyssalCraft.ethaxiumbrick.getDefaultState(), 2);
		world.setBlockState(new BlockPos(i - 7, j + 5, k - 5), AbyssalCraft.ethaxiumbrick.getDefaultState(), 2);
		world.setBlockState(new BlockPos(i - 7, j + 5, k - 3), AbyssalCraft.ethaxiumbrick.getDefaultState(), 2);
		world.setBlockState(new BlockPos(i - 7, j + 6, k - 23), AbyssalCraft.ethaxiumstairs.getStateFromMeta(2), 2); //TODO: 2
		world.setBlockState(new BlockPos(i - 7, j + 6, k - 22), AbyssalCraft.ethaxiumbrick.getDefaultState(), 2);
		world.setBlockState(new BlockPos(i - 7, j + 6, k - 21), AbyssalCraft.ethaxiumbrick.getDefaultState(), 2);
		world.setBlockState(new BlockPos(i - 7, j + 6, k - 20), AbyssalCraft.ethaxiumbrick.getDefaultState(), 2);
		world.setBlockState(new BlockPos(i - 7, j + 6, k - 19), AbyssalCraft.ethaxiumbrick.getDefaultState(), 2);
		world.setBlockState(new BlockPos(i - 7, j + 6, k - 18), AbyssalCraft.ethaxiumbrick.getDefaultState(), 2);
		world.setBlockState(new BlockPos(i - 7, j + 6, k - 17), AbyssalCraft.ethaxiumbrick.getDefaultState(), 2);
		world.setBlockState(new BlockPos(i - 7, j + 6, k - 16), AbyssalCraft.ethaxiumbrick.getDefaultState(), 2);
		world.setBlockState(new BlockPos(i - 7, j + 6, k - 15), AbyssalCraft.ethaxiumbrick.getDefaultState(), 2);
		world.setBlockState(new BlockPos(i - 7, j + 6, k - 14), AbyssalCraft.ethaxiumbrick.getDefaultState(), 2);
		world.setBlockState(new BlockPos(i - 7, j + 6, k - 13), AbyssalCraft.ethaxiumbrick.getDefaultState(), 2);
		world.setBlockState(new BlockPos(i - 7, j + 6, k - 12), AbyssalCraft.ethaxiumbrick.getDefaultState(), 2);
		world.setBlockState(new BlockPos(i - 7, j + 6, k - 11), AbyssalCraft.ethaxiumbrick.getDefaultState(), 2);
		world.setBlockState(new BlockPos(i - 7, j + 6, k - 10), AbyssalCraft.ethaxiumbrick.getDefaultState(), 2);
		world.setBlockState(new BlockPos(i - 7, j + 6, k - 9), AbyssalCraft.ethaxiumbrick.getDefaultState(), 2);
		world.setBlockState(new BlockPos(i - 7, j + 6, k - 8), AbyssalCraft.ethaxiumbrick.getDefaultState(), 2);
		world.setBlockState(new BlockPos(i - 7, j + 6, k - 7), AbyssalCraft.ethaxiumbrick.getDefaultState(), 2);
		world.setBlockState(new BlockPos(i - 7, j + 6, k - 6), AbyssalCraft.ethaxiumbrick.getDefaultState(), 2);
		world.setBlockState(new BlockPos(i - 7, j + 6, k - 5), AbyssalCraft.ethaxiumbrick.getDefaultState(), 2);
		world.setBlockState(new BlockPos(i - 7, j + 6, k - 4), AbyssalCraft.ethaxiumbrick.getDefaultState(), 2);
		world.setBlockState(new BlockPos(i - 7, j + 6, k - 3), AbyssalCraft.ethaxiumbrick.getDefaultState(), 2);
		world.setBlockState(new BlockPos(i - 7, j + 6, k - 2), AbyssalCraft.ethaxiumbrick.getDefaultState(), 2);
		world.setBlockState(new BlockPos(i - 7, j + 6, k - 1), AbyssalCraft.ethaxiumstairs.getStateFromMeta(3), 2); //TODO: 3
		world.setBlockState(new BlockPos(i - 6, j + 0, k - 23), AbyssalCraft.ethaxiumbrick.getDefaultState(), 2);
		world.setBlockState(new BlockPos(i - 6, j + 0, k - 22), AbyssalCraft.ethaxiumbrick.getDefaultState(), 2);
		world.setBlockState(new BlockPos(i - 6, j + 0, k - 21), AbyssalCraft.ethaxiumbrick.getDefaultState(), 2);
		world.setBlockState(new BlockPos(i - 6, j + 0, k - 20), AbyssalCraft.ethaxiumbrick.getDefaultState(), 2);
		world.setBlockState(new BlockPos(i - 6, j + 0, k - 19), AbyssalCraft.ethaxiumbrick.getDefaultState(), 2);
		world.setBlockState(new BlockPos(i - 6, j + 0, k - 18), AbyssalCraft.ethaxiumbrick.getDefaultState(), 2);
		world.setBlockState(new BlockPos(i - 6, j + 0, k - 17), AbyssalCraft.ethaxiumbrick.getDefaultState(), 2);
		world.setBlockState(new BlockPos(i - 6, j + 0, k - 16), AbyssalCraft.ethaxiumbrick.getDefaultState(), 2);
		world.setBlockState(new BlockPos(i - 6, j + 0, k - 15), AbyssalCraft.ethaxiumbrick.getDefaultState(), 2);
		world.setBlockState(new BlockPos(i - 6, j + 0, k - 14), AbyssalCraft.ethaxiumbrick.getDefaultState(), 2);
		world.setBlockState(new BlockPos(i - 6, j + 0, k - 13), AbyssalCraft.ethaxiumbrick.getDefaultState(), 2);
		world.setBlockState(new BlockPos(i - 6, j + 0, k - 12), AbyssalCraft.ethaxiumbrick.getDefaultState(), 2);
		world.setBlockState(new BlockPos(i - 6, j + 0, k - 11), AbyssalCraft.ethaxiumbrick.getDefaultState(), 2);
		world.setBlockState(new BlockPos(i - 6, j + 0, k - 10), AbyssalCraft.ethaxiumbrick.getDefaultState(), 2);
		world.setBlockState(new BlockPos(i - 6, j + 0, k - 9), AbyssalCraft.ethaxiumbrick.getDefaultState(), 2);
		world.setBlockState(new BlockPos(i - 6, j + 0, k - 8), AbyssalCraft.ethaxiumbrick.getDefaultState(), 2);
		world.setBlockState(new BlockPos(i - 6, j + 0, k - 7), AbyssalCraft.ethaxiumbrick.getDefaultState(), 2);
		world.setBlockState(new BlockPos(i - 6, j + 0, k - 6), AbyssalCraft.ethaxiumbrick.getDefaultState(), 2);
		world.setBlockState(new BlockPos(i - 6, j + 0, k - 5), AbyssalCraft.ethaxiumbrick.getDefaultState(), 2);
		world.setBlockState(new BlockPos(i - 6, j + 0, k - 4), AbyssalCraft.ethaxiumbrick.getDefaultState(), 2);
		world.setBlockState(new BlockPos(i - 6, j + 0, k - 3), AbyssalCraft.ethaxiumbrick.getDefaultState(), 2);
		world.setBlockState(new BlockPos(i - 6, j + 0, k - 2), AbyssalCraft.ethaxiumbrick.getDefaultState(), 2);
		world.setBlockState(new BlockPos(i - 6, j + 1, k - 23), AbyssalCraft.ethaxiumbrick.getDefaultState(), 2);
		world.setBlockState(new BlockPos(i - 6, j + 1, k - 22), AbyssalCraft.ethaxiumbrick.getDefaultState(), 2);
		world.setBlockState(new BlockPos(i - 6, j + 1, k - 21), AbyssalCraft.Darkstone_cobble.getDefaultState(), 2);
		world.setBlockState(new BlockPos(i - 6, j + 1, k - 20), AbyssalCraft.Darkstone_cobble.getDefaultState(), 2);
		world.setBlockState(new BlockPos(i - 6, j + 1, k - 19), AbyssalCraft.Darkstone_cobble.getDefaultState(), 2);
		world.setBlockState(new BlockPos(i - 6, j + 1, k - 18), AbyssalCraft.Darkstone_cobble.getDefaultState(), 2);
		world.setBlockState(new BlockPos(i - 6, j + 1, k - 17), AbyssalCraft.Darkstone_cobble.getDefaultState(), 2);
		world.setBlockState(new BlockPos(i - 6, j + 1, k - 16), AbyssalCraft.Darkstone_cobble.getDefaultState(), 2);
		world.setBlockState(new BlockPos(i - 6, j + 1, k - 15), AbyssalCraft.Darkstone_cobble.getDefaultState(), 2);
		world.setBlockState(new BlockPos(i - 6, j + 1, k - 14), AbyssalCraft.Darkstone_cobble.getDefaultState(), 2);
		world.setBlockState(new BlockPos(i - 6, j + 1, k - 13), AbyssalCraft.Darkstone_cobble.getDefaultState(), 2);
		world.setBlockState(new BlockPos(i - 6, j + 1, k - 12), AbyssalCraft.Darkstone_cobble.getDefaultState(), 2);
		world.setBlockState(new BlockPos(i - 6, j + 1, k - 11), AbyssalCraft.Darkstone_cobble.getDefaultState(), 2);
		world.setBlockState(new BlockPos(i - 6, j + 1, k - 10), AbyssalCraft.Darkstone_cobble.getDefaultState(), 2);
		world.setBlockState(new BlockPos(i - 6, j + 1, k - 9), AbyssalCraft.Darkstone_cobble.getDefaultState(), 2);
		world.setBlockState(new BlockPos(i - 6, j + 1, k - 8), AbyssalCraft.Darkstone_cobble.getDefaultState(), 2);
		world.setBlockState(new BlockPos(i - 6, j + 1, k - 7), AbyssalCraft.Darkstone_cobble.getDefaultState(), 2);
		world.setBlockState(new BlockPos(i - 6, j + 1, k - 6), AbyssalCraft.ethaxiumbrick.getDefaultState(), 2);
		world.setBlockState(new BlockPos(i - 6, j + 1, k - 5), AbyssalCraft.ethaxiumbrick.getDefaultState(), 2);
		world.setBlockState(new BlockPos(i - 6, j + 1, k - 4), AbyssalCraft.ethaxiumbrick.getDefaultState(), 2);
		world.setBlockState(new BlockPos(i - 6, j + 1, k - 3), AbyssalCraft.ethaxiumbrick.getDefaultState(), 2);
		world.setBlockState(new BlockPos(i - 6, j + 2, k - 23), AbyssalCraft.ethaxiumbrick.getDefaultState(), 2);
		world.setBlockState(new BlockPos(i - 6, j + 2, k - 22), AbyssalCraft.Darkstone_brick.getDefaultState(), 2);
		world.setBlockState(new BlockPos(i - 6, j + 2, k - 16), AbyssalCraft.Darkstone_brick.getDefaultState(), 2);
		world.setBlockState(new BlockPos(i - 6, j + 2, k - 6), AbyssalCraft.Darkstone_brick.getDefaultState(), 2);
		world.setBlockState(new BlockPos(i - 6, j + 2, k - 5), AbyssalCraft.ethaxiumbrick.getDefaultState(), 2);
		world.setBlockState(new BlockPos(i - 6, j + 2, k - 4), AbyssalCraft.ethaxiumbrick.getDefaultState(), 2);
		world.setBlockState(new BlockPos(i - 6, j + 2, k - 3), AbyssalCraft.ethaxiumbrick.getDefaultState(), 2);
		world.setBlockState(new BlockPos(i - 6, j + 3, k - 23), AbyssalCraft.ethaxiumbrick.getDefaultState(), 2);
		world.setBlockState(new BlockPos(i - 6, j + 3, k - 22), AbyssalCraft.Darkstone_brick.getDefaultState(), 2);
		world.setBlockState(new BlockPos(i - 6, j + 3, k - 16), AbyssalCraft.Darkstone_brick.getDefaultState(), 2);
		world.setBlockState(new BlockPos(i - 6, j + 3, k - 6), AbyssalCraft.Darkstone_brick.getDefaultState(), 2);
		world.setBlockState(new BlockPos(i - 6, j + 3, k - 5), AbyssalCraft.ethaxiumbrick.getDefaultState(), 2);
		world.setBlockState(new BlockPos(i - 6, j + 3, k - 4), AbyssalCraft.ethaxiumbrick.getDefaultState(), 2);
		world.setBlockState(new BlockPos(i - 6, j + 3, k - 3), AbyssalCraft.ethaxiumbrick.getStateFromMeta(1), 2); //TODO: 1
		world.setBlockState(new BlockPos(i - 6, j + 4, k - 23), AbyssalCraft.ethaxiumbrick.getDefaultState(), 2);
		world.setBlockState(new BlockPos(i - 6, j + 4, k - 22), AbyssalCraft.Darkstone_brick.getDefaultState(), 2);
		world.setBlockState(new BlockPos(i - 6, j + 4, k - 16), AbyssalCraft.Darkstone_brick.getDefaultState(), 2);
		world.setBlockState(new BlockPos(i - 6, j + 4, k - 12), AbyssalCraft.Darkstone_brick.getDefaultState(), 2);
		world.setBlockState(new BlockPos(i - 6, j + 4, k - 6), AbyssalCraft.Darkstone_brick.getDefaultState(), 2);
		world.setBlockState(new BlockPos(i - 6, j + 4, k - 5), AbyssalCraft.ethaxiumbrick.getDefaultState(), 2);
		world.setBlockState(new BlockPos(i - 6, j + 4, k - 4), AbyssalCraft.ethaxiumbrick.getDefaultState(), 2);
		world.setBlockState(new BlockPos(i - 6, j + 4, k - 3), AbyssalCraft.ethaxiumbrick.getDefaultState(), 2);
		world.setBlockState(new BlockPos(i - 6, j + 5, k - 23), AbyssalCraft.ethaxiumbrick.getDefaultState(), 2);
		world.setBlockState(new BlockPos(i - 6, j + 5, k - 22), AbyssalCraft.ethaxiumbrick.getDefaultState(), 2);
		world.setBlockState(new BlockPos(i - 6, j + 5, k - 21), AbyssalCraft.Darkstone_brick.getDefaultState(), 2);
		world.setBlockState(new BlockPos(i - 6, j + 5, k - 20), AbyssalCraft.Darkstone_brick.getDefaultState(), 2);
		world.setBlockState(new BlockPos(i - 6, j + 5, k - 19), AbyssalCraft.Darkstone_brick.getDefaultState(), 2);
		world.setBlockState(new BlockPos(i - 6, j + 5, k - 18), AbyssalCraft.Darkstone_brick.getDefaultState(), 2);
		world.setBlockState(new BlockPos(i - 6, j + 5, k - 17), AbyssalCraft.Darkstone_brick.getDefaultState(), 2);
		world.setBlockState(new BlockPos(i - 6, j + 5, k - 16), AbyssalCraft.Darkstone_brick.getDefaultState(), 2);
		world.setBlockState(new BlockPos(i - 6, j + 5, k - 15), AbyssalCraft.Darkstone_brick.getDefaultState(), 2);
		world.setBlockState(new BlockPos(i - 6, j + 5, k - 14), AbyssalCraft.Darkstone_brick.getDefaultState(), 2);
		world.setBlockState(new BlockPos(i - 6, j + 5, k - 13), AbyssalCraft.Darkstone_brick.getDefaultState(), 2);
		world.setBlockState(new BlockPos(i - 6, j + 5, k - 12), AbyssalCraft.Darkstone_brick.getDefaultState(), 2);
		world.setBlockState(new BlockPos(i - 6, j + 5, k - 11), AbyssalCraft.Darkstone_brick.getDefaultState(), 2);
		world.setBlockState(new BlockPos(i - 6, j + 5, k - 10), AbyssalCraft.Darkstone_brick.getDefaultState(), 2);
		world.setBlockState(new BlockPos(i - 6, j + 5, k - 9), AbyssalCraft.Darkstone_brick.getDefaultState(), 2);
		world.setBlockState(new BlockPos(i - 6, j + 5, k - 8), AbyssalCraft.Darkstone_brick.getDefaultState(), 2);
		world.setBlockState(new BlockPos(i - 6, j + 5, k - 7), AbyssalCraft.Darkstone_brick.getDefaultState(), 2);
		world.setBlockState(new BlockPos(i - 6, j + 5, k - 6), AbyssalCraft.ethaxiumbrick.getDefaultState(), 2);
		world.setBlockState(new BlockPos(i - 6, j + 5, k - 5), AbyssalCraft.ethaxiumbrick.getDefaultState(), 2);
		world.setBlockState(new BlockPos(i - 6, j + 5, k - 4), AbyssalCraft.ethaxiumbrick.getDefaultState(), 2);
		world.setBlockState(new BlockPos(i - 6, j + 5, k - 3), AbyssalCraft.ethaxiumbrick.getDefaultState(), 2);
		world.setBlockState(new BlockPos(i - 6, j + 6, k - 23), AbyssalCraft.ethaxiumstairs.getStateFromMeta(2), 2); //TODO: 2
		world.setBlockState(new BlockPos(i - 6, j + 6, k - 22), AbyssalCraft.ethaxiumbrick.getDefaultState(), 2);
		world.setBlockState(new BlockPos(i - 6, j + 6, k - 21), AbyssalCraft.ethaxiumbrick.getDefaultState(), 2);
		world.setBlockState(new BlockPos(i - 6, j + 6, k - 20), AbyssalCraft.ethaxiumbrick.getDefaultState(), 2);
		world.setBlockState(new BlockPos(i - 6, j + 6, k - 19), AbyssalCraft.ethaxiumbrick.getDefaultState(), 2);
		world.setBlockState(new BlockPos(i - 6, j + 6, k - 18), AbyssalCraft.ethaxiumbrick.getDefaultState(), 2);
		world.setBlockState(new BlockPos(i - 6, j + 6, k - 17), AbyssalCraft.ethaxiumbrick.getDefaultState(), 2);
		world.setBlockState(new BlockPos(i - 6, j + 6, k - 16), AbyssalCraft.ethaxiumbrick.getDefaultState(), 2);
		world.setBlockState(new BlockPos(i - 6, j + 6, k - 15), AbyssalCraft.ethaxiumbrick.getDefaultState(), 2);
		world.setBlockState(new BlockPos(i - 6, j + 6, k - 14), AbyssalCraft.ethaxiumbrick.getDefaultState(), 2);
		world.setBlockState(new BlockPos(i - 6, j + 6, k - 13), AbyssalCraft.ethaxiumbrick.getDefaultState(), 2);
		world.setBlockState(new BlockPos(i - 6, j + 6, k - 12), AbyssalCraft.ethaxiumbrick.getDefaultState(), 2);
		world.setBlockState(new BlockPos(i - 6, j + 6, k - 11), AbyssalCraft.ethaxiumbrick.getDefaultState(), 2);
		world.setBlockState(new BlockPos(i - 6, j + 6, k - 10), AbyssalCraft.ethaxiumbrick.getDefaultState(), 2);
		world.setBlockState(new BlockPos(i - 6, j + 6, k - 9), AbyssalCraft.ethaxiumbrick.getDefaultState(), 2);
		world.setBlockState(new BlockPos(i - 6, j + 6, k - 8), AbyssalCraft.ethaxiumbrick.getDefaultState(), 2);
		world.setBlockState(new BlockPos(i - 6, j + 6, k - 7), AbyssalCraft.ethaxiumbrick.getDefaultState(), 2);
		world.setBlockState(new BlockPos(i - 6, j + 6, k - 6), AbyssalCraft.ethaxiumbrick.getDefaultState(), 2);
		world.setBlockState(new BlockPos(i - 6, j + 6, k - 5), AbyssalCraft.ethaxiumbrick.getDefaultState(), 2);
		world.setBlockState(new BlockPos(i - 6, j + 6, k - 4), AbyssalCraft.ethaxiumbrick.getDefaultState(), 2);
		world.setBlockState(new BlockPos(i - 6, j + 6, k - 3), AbyssalCraft.ethaxiumbrick.getDefaultState(), 2);
		world.setBlockState(new BlockPos(i - 6, j + 6, k - 2), AbyssalCraft.ethaxiumbrick.getDefaultState(), 2);
		world.setBlockState(new BlockPos(i - 6, j + 6, k - 1), AbyssalCraft.ethaxiumstairs.getStateFromMeta(3), 2); //TODO: 3
		world.setBlockState(new BlockPos(i - 5, j + 0, k - 23), AbyssalCraft.ethaxiumbrick.getDefaultState(), 2);
		world.setBlockState(new BlockPos(i - 5, j + 0, k - 22), AbyssalCraft.ethaxiumbrick.getDefaultState(), 2);
		world.setBlockState(new BlockPos(i - 5, j + 0, k - 21), AbyssalCraft.ethaxiumbrick.getDefaultState(), 2);
		world.setBlockState(new BlockPos(i - 5, j + 0, k - 20), AbyssalCraft.ethaxiumbrick.getDefaultState(), 2);
		world.setBlockState(new BlockPos(i - 5, j + 0, k - 19), AbyssalCraft.ethaxiumbrick.getDefaultState(), 2);
		world.setBlockState(new BlockPos(i - 5, j + 0, k - 18), AbyssalCraft.ethaxiumbrick.getDefaultState(), 2);
		world.setBlockState(new BlockPos(i - 5, j + 0, k - 17), AbyssalCraft.ethaxiumbrick.getDefaultState(), 2);
		world.setBlockState(new BlockPos(i - 5, j + 0, k - 16), AbyssalCraft.ethaxiumbrick.getDefaultState(), 2);
		world.setBlockState(new BlockPos(i - 5, j + 0, k - 15), AbyssalCraft.ethaxiumbrick.getDefaultState(), 2);
		world.setBlockState(new BlockPos(i - 5, j + 0, k - 14), AbyssalCraft.ethaxiumbrick.getDefaultState(), 2);
		world.setBlockState(new BlockPos(i - 5, j + 0, k - 13), AbyssalCraft.ethaxiumbrick.getDefaultState(), 2);
		world.setBlockState(new BlockPos(i - 5, j + 0, k - 12), AbyssalCraft.ethaxiumbrick.getDefaultState(), 2);
		world.setBlockState(new BlockPos(i - 5, j + 0, k - 11), AbyssalCraft.ethaxiumbrick.getDefaultState(), 2);
		world.setBlockState(new BlockPos(i - 5, j + 0, k - 10), AbyssalCraft.ethaxiumbrick.getDefaultState(), 2);
		world.setBlockState(new BlockPos(i - 5, j + 0, k - 9), AbyssalCraft.ethaxiumbrick.getDefaultState(), 2);
		world.setBlockState(new BlockPos(i - 5, j + 0, k - 8), AbyssalCraft.ethaxiumbrick.getDefaultState(), 2);
		world.setBlockState(new BlockPos(i - 5, j + 0, k - 7), AbyssalCraft.ethaxiumbrick.getDefaultState(), 2);
		world.setBlockState(new BlockPos(i - 5, j + 0, k - 6), AbyssalCraft.ethaxiumbrick.getDefaultState(), 2);
		world.setBlockState(new BlockPos(i - 5, j + 0, k - 5), AbyssalCraft.ethaxiumbrick.getDefaultState(), 2);
		world.setBlockState(new BlockPos(i - 5, j + 0, k - 4), AbyssalCraft.ethaxiumbrick.getDefaultState(), 2);
		world.setBlockState(new BlockPos(i - 5, j + 0, k - 3), AbyssalCraft.ethaxiumbrick.getDefaultState(), 2);
		world.setBlockState(new BlockPos(i - 5, j + 0, k - 2), AbyssalCraft.ethaxiumbrick.getDefaultState(), 2);
		world.setBlockState(new BlockPos(i - 5, j + 1, k - 23), AbyssalCraft.ethaxiumbrick.getDefaultState(), 2);
		world.setBlockState(new BlockPos(i - 5, j + 1, k - 22), AbyssalCraft.ethaxiumbrick.getDefaultState(), 2);
		world.setBlockState(new BlockPos(i - 5, j + 1, k - 21), AbyssalCraft.Darkstone_cobble.getDefaultState(), 2);
		world.setBlockState(new BlockPos(i - 5, j + 1, k - 20), AbyssalCraft.Darkstone_cobble.getDefaultState(), 2);
		world.setBlockState(new BlockPos(i - 5, j + 1, k - 19), AbyssalCraft.Darkstone_cobble.getDefaultState(), 2);
		world.setBlockState(new BlockPos(i - 5, j + 1, k - 18), AbyssalCraft.Darkstone_cobble.getDefaultState(), 2);
		world.setBlockState(new BlockPos(i - 5, j + 1, k - 17), AbyssalCraft.Darkstone_cobble.getDefaultState(), 2);
		world.setBlockState(new BlockPos(i - 5, j + 1, k - 16), AbyssalCraft.Darkstone_cobble.getDefaultState(), 2);
		world.setBlockState(new BlockPos(i - 5, j + 1, k - 15), AbyssalCraft.Darkstone_cobble.getDefaultState(), 2);
		world.setBlockState(new BlockPos(i - 5, j + 1, k - 14), AbyssalCraft.Darkstone_cobble.getDefaultState(), 2);
		world.setBlockState(new BlockPos(i - 5, j + 1, k - 13), AbyssalCraft.Darkstone_cobble.getDefaultState(), 2);
		world.setBlockState(new BlockPos(i - 5, j + 1, k - 12), AbyssalCraft.Darkstone_cobble.getDefaultState(), 2);
		world.setBlockState(new BlockPos(i - 5, j + 1, k - 11), AbyssalCraft.Darkstone_cobble.getDefaultState(), 2);
		world.setBlockState(new BlockPos(i - 5, j + 1, k - 10), AbyssalCraft.Darkstone_cobble.getDefaultState(), 2);
		world.setBlockState(new BlockPos(i - 5, j + 1, k - 9), AbyssalCraft.Darkstone_cobble.getDefaultState(), 2);
		world.setBlockState(new BlockPos(i - 5, j + 1, k - 8), AbyssalCraft.Darkstone_cobble.getDefaultState(), 2);
		world.setBlockState(new BlockPos(i - 5, j + 1, k - 7), AbyssalCraft.Darkstone_cobble.getDefaultState(), 2);
		world.setBlockState(new BlockPos(i - 5, j + 1, k - 6), AbyssalCraft.ethaxiumbrick.getDefaultState(), 2);
		world.setBlockState(new BlockPos(i - 5, j + 1, k - 5), AbyssalCraft.ethaxiumbrick.getDefaultState(), 2);
		world.setBlockState(new BlockPos(i - 5, j + 1, k - 4), AbyssalCraft.ethaxiumbrick.getDefaultState(), 2);
		world.setBlockState(new BlockPos(i - 5, j + 1, k - 3), AbyssalCraft.ethaxiumbrick.getDefaultState(), 2);
		world.setBlockState(new BlockPos(i - 5, j + 2, k - 23), AbyssalCraft.ethaxiumbrick.getDefaultState(), 2);
		world.setBlockState(new BlockPos(i - 5, j + 2, k - 22), AbyssalCraft.Darkstone_brick.getDefaultState(), 2);
		world.setBlockState(new BlockPos(i - 5, j + 2, k - 12), AbyssalCraft.Darkstone_brick.getDefaultState(), 2);
		world.setBlockState(new BlockPos(i - 5, j + 2, k - 11), AbyssalCraft.Darkstone_brick.getDefaultState(), 2);
		world.setBlockState(new BlockPos(i - 5, j + 2, k - 10), AbyssalCraft.Darkstone_brick.getDefaultState(), 2);
		world.setBlockState(new BlockPos(i - 5, j + 2, k - 9), AbyssalCraft.Darkstone_brick.getDefaultState(), 2);
		world.setBlockState(new BlockPos(i - 5, j + 2, k - 8), AbyssalCraft.Darkstone_brick.getDefaultState(), 2);
		world.setBlockState(new BlockPos(i - 5, j + 2, k - 7), AbyssalCraft.Darkstone_brick.getDefaultState(), 2);
		world.setBlockState(new BlockPos(i - 5, j + 2, k - 6), AbyssalCraft.Darkstone_brick.getDefaultState(), 2);
		world.setBlockState(new BlockPos(i - 5, j + 2, k - 5), AbyssalCraft.ethaxiumbrick.getDefaultState(), 2);
		world.setBlockState(new BlockPos(i - 5, j + 2, k - 3), AbyssalCraft.ethaxiumfence.getDefaultState(), 2);
		world.setBlockState(new BlockPos(i - 5, j + 3, k - 23), AbyssalCraft.ethaxiumbrick.getDefaultState(), 2);
		world.setBlockState(new BlockPos(i - 5, j + 3, k - 22), AbyssalCraft.Darkstone_brick.getDefaultState(), 2);
		world.setBlockState(new BlockPos(i - 5, j + 3, k - 12), AbyssalCraft.Darkstone_brick.getDefaultState(), 2);
		world.setBlockState(new BlockPos(i - 5, j + 3, k - 11), AbyssalCraft.Darkstone_brick.getDefaultState(), 2);
		world.setBlockState(new BlockPos(i - 5, j + 3, k - 10), AbyssalCraft.Darkstone_brick.getDefaultState(), 2);
		world.setBlockState(new BlockPos(i - 5, j + 3, k - 9), AbyssalCraft.Darkstone_brick.getDefaultState(), 2);
		world.setBlockState(new BlockPos(i - 5, j + 3, k - 8), AbyssalCraft.Darkstone_brick.getDefaultState(), 2);
		world.setBlockState(new BlockPos(i - 5, j + 3, k - 7), AbyssalCraft.Darkstone_brick.getDefaultState(), 2);
		world.setBlockState(new BlockPos(i - 5, j + 3, k - 6), AbyssalCraft.Darkstone_brick.getDefaultState(), 2);
		world.setBlockState(new BlockPos(i - 5, j + 3, k - 5), AbyssalCraft.ethaxiumbrick.getDefaultState(), 2);
		world.setBlockState(new BlockPos(i - 5, j + 3, k - 3), AbyssalCraft.ethaxiumfence.getDefaultState(), 2);
		world.setBlockState(new BlockPos(i - 5, j + 4, k - 23), AbyssalCraft.ethaxiumbrick.getDefaultState(), 2);
		world.setBlockState(new BlockPos(i - 5, j + 4, k - 22), AbyssalCraft.Darkstone_brick.getDefaultState(), 2);
		world.setBlockState(new BlockPos(i - 5, j + 4, k - 16), AbyssalCraft.Darkstone_brick.getDefaultState(), 2);
		world.setBlockState(new BlockPos(i - 5, j + 4, k - 12), AbyssalCraft.Darkstone_brick.getDefaultState(), 2);
		world.setBlockState(new BlockPos(i - 5, j + 4, k - 11), AbyssalCraft.Darkstone_brick.getDefaultState(), 2);
		world.setBlockState(new BlockPos(i - 5, j + 4, k - 10), AbyssalCraft.Darkstone_brick.getDefaultState(), 2);
		world.setBlockState(new BlockPos(i - 5, j + 4, k - 9), AbyssalCraft.Darkstone_brick.getDefaultState(), 2);
		world.setBlockState(new BlockPos(i - 5, j + 4, k - 8), AbyssalCraft.Darkstone_brick.getDefaultState(), 2);
		world.setBlockState(new BlockPos(i - 5, j + 4, k - 7), AbyssalCraft.Darkstone_brick.getDefaultState(), 2);
		world.setBlockState(new BlockPos(i - 5, j + 4, k - 6), AbyssalCraft.Darkstone_brick.getDefaultState(), 2);
		world.setBlockState(new BlockPos(i - 5, j + 4, k - 5), AbyssalCraft.ethaxiumbrick.getDefaultState(), 2);
		world.setBlockState(new BlockPos(i - 5, j + 4, k - 3), AbyssalCraft.ethaxiumfence.getDefaultState(), 2);
		world.setBlockState(new BlockPos(i - 5, j + 5, k - 23), AbyssalCraft.ethaxiumbrick.getDefaultState(), 2);
		world.setBlockState(new BlockPos(i - 5, j + 5, k - 22), AbyssalCraft.ethaxiumbrick.getDefaultState(), 2);
		world.setBlockState(new BlockPos(i - 5, j + 5, k - 21), AbyssalCraft.Darkstone_brick.getDefaultState(), 2);
		world.setBlockState(new BlockPos(i - 5, j + 5, k - 20), AbyssalCraft.Darkstone_brick.getDefaultState(), 2);
		world.setBlockState(new BlockPos(i - 5, j + 5, k - 19), AbyssalCraft.Darkstone_brick.getDefaultState(), 2);
		world.setBlockState(new BlockPos(i - 5, j + 5, k - 18), AbyssalCraft.Darkstone_brick.getDefaultState(), 2);
		world.setBlockState(new BlockPos(i - 5, j + 5, k - 17), AbyssalCraft.Darkstone_brick.getDefaultState(), 2);
		world.setBlockState(new BlockPos(i - 5, j + 5, k - 16), AbyssalCraft.Darkstone_brick.getDefaultState(), 2);
		world.setBlockState(new BlockPos(i - 5, j + 5, k - 15), AbyssalCraft.Darkstone_brick.getDefaultState(), 2);
		world.setBlockState(new BlockPos(i - 5, j + 5, k - 14), AbyssalCraft.Darkstone_brick.getDefaultState(), 2);
		world.setBlockState(new BlockPos(i - 5, j + 5, k - 13), AbyssalCraft.Darkstone_brick.getDefaultState(), 2);
		world.setBlockState(new BlockPos(i - 5, j + 5, k - 12), AbyssalCraft.Darkstone_brick.getDefaultState(), 2);
		world.setBlockState(new BlockPos(i - 5, j + 5, k - 11), AbyssalCraft.Darkstone_brick.getDefaultState(), 2);
		world.setBlockState(new BlockPos(i - 5, j + 5, k - 10), AbyssalCraft.Darkstone_brick.getDefaultState(), 2);
		world.setBlockState(new BlockPos(i - 5, j + 5, k - 9), AbyssalCraft.Darkstone_brick.getDefaultState(), 2);
		world.setBlockState(new BlockPos(i - 5, j + 5, k - 8), AbyssalCraft.Darkstone_brick.getDefaultState(), 2);
		world.setBlockState(new BlockPos(i - 5, j + 5, k - 7), AbyssalCraft.Darkstone_brick.getDefaultState(), 2);
		world.setBlockState(new BlockPos(i - 5, j + 5, k - 6), AbyssalCraft.ethaxiumbrick.getDefaultState(), 2);
		world.setBlockState(new BlockPos(i - 5, j + 5, k - 5), AbyssalCraft.ethaxiumbrick.getDefaultState(), 2);
		world.setBlockState(new BlockPos(i - 5, j + 5, k - 3), AbyssalCraft.ethaxiumbrick.getDefaultState(), 2);
		world.setBlockState(new BlockPos(i - 5, j + 6, k - 23), AbyssalCraft.ethaxiumstairs.getStateFromMeta(2), 2); //TODO: 2
		world.setBlockState(new BlockPos(i - 5, j + 6, k - 22), AbyssalCraft.ethaxiumbrick.getDefaultState(), 2);
		world.setBlockState(new BlockPos(i - 5, j + 6, k - 21), AbyssalCraft.ethaxiumbrick.getDefaultState(), 2);
		world.setBlockState(new BlockPos(i - 5, j + 6, k - 20), AbyssalCraft.ethaxiumbrick.getDefaultState(), 2);
		world.setBlockState(new BlockPos(i - 5, j + 6, k - 19), AbyssalCraft.ethaxiumbrick.getDefaultState(), 2);
		world.setBlockState(new BlockPos(i - 5, j + 6, k - 18), AbyssalCraft.ethaxiumbrick.getDefaultState(), 2);
		world.setBlockState(new BlockPos(i - 5, j + 6, k - 17), AbyssalCraft.ethaxiumbrick.getDefaultState(), 2);
		world.setBlockState(new BlockPos(i - 5, j + 6, k - 16), AbyssalCraft.ethaxiumbrick.getDefaultState(), 2);
		world.setBlockState(new BlockPos(i - 5, j + 6, k - 15), AbyssalCraft.ethaxiumbrick.getDefaultState(), 2);
		world.setBlockState(new BlockPos(i - 5, j + 6, k - 14), AbyssalCraft.ethaxiumbrick.getDefaultState(), 2);
		world.setBlockState(new BlockPos(i - 5, j + 6, k - 13), AbyssalCraft.ethaxiumbrick.getDefaultState(), 2);
		world.setBlockState(new BlockPos(i - 5, j + 6, k - 12), AbyssalCraft.ethaxiumbrick.getDefaultState(), 2);
		world.setBlockState(new BlockPos(i - 5, j + 6, k - 11), AbyssalCraft.ethaxiumbrick.getDefaultState(), 2);
		world.setBlockState(new BlockPos(i - 5, j + 6, k - 10), AbyssalCraft.ethaxiumbrick.getDefaultState(), 2);
		world.setBlockState(new BlockPos(i - 5, j + 6, k - 9), AbyssalCraft.ethaxiumbrick.getDefaultState(), 2);
		world.setBlockState(new BlockPos(i - 5, j + 6, k - 8), AbyssalCraft.ethaxiumbrick.getDefaultState(), 2);
		world.setBlockState(new BlockPos(i - 5, j + 6, k - 7), AbyssalCraft.ethaxiumbrick.getDefaultState(), 2);
		world.setBlockState(new BlockPos(i - 5, j + 6, k - 6), AbyssalCraft.ethaxiumbrick.getDefaultState(), 2);
		world.setBlockState(new BlockPos(i - 5, j + 6, k - 5), AbyssalCraft.ethaxiumbrick.getDefaultState(), 2);
		world.setBlockState(new BlockPos(i - 5, j + 6, k - 4), AbyssalCraft.ethaxiumbrick.getDefaultState(), 2);
		world.setBlockState(new BlockPos(i - 5, j + 6, k - 3), AbyssalCraft.ethaxiumbrick.getDefaultState(), 2);
		world.setBlockState(new BlockPos(i - 5, j + 6, k - 2), AbyssalCraft.ethaxiumbrick.getDefaultState(), 2);
		world.setBlockState(new BlockPos(i - 5, j + 6, k - 1), AbyssalCraft.ethaxiumstairs.getStateFromMeta(3), 2); //TODO: 3
		world.setBlockState(new BlockPos(i - 4, j + 0, k - 23), AbyssalCraft.ethaxiumbrick.getDefaultState(), 2);
		world.setBlockState(new BlockPos(i - 4, j + 0, k - 22), AbyssalCraft.ethaxiumbrick.getDefaultState(), 2);
		world.setBlockState(new BlockPos(i - 4, j + 0, k - 21), AbyssalCraft.ethaxiumbrick.getDefaultState(), 2);
		world.setBlockState(new BlockPos(i - 4, j + 0, k - 20), AbyssalCraft.ethaxiumbrick.getDefaultState(), 2);
		world.setBlockState(new BlockPos(i - 4, j + 0, k - 19), AbyssalCraft.ethaxiumbrick.getDefaultState(), 2);
		world.setBlockState(new BlockPos(i - 4, j + 0, k - 18), AbyssalCraft.ethaxiumbrick.getDefaultState(), 2);
		world.setBlockState(new BlockPos(i - 4, j + 0, k - 17), AbyssalCraft.ethaxiumbrick.getDefaultState(), 2);
		world.setBlockState(new BlockPos(i - 4, j + 0, k - 16), AbyssalCraft.ethaxiumbrick.getDefaultState(), 2);
		world.setBlockState(new BlockPos(i - 4, j + 0, k - 15), AbyssalCraft.ethaxiumbrick.getDefaultState(), 2);
		world.setBlockState(new BlockPos(i - 4, j + 0, k - 14), AbyssalCraft.ethaxiumbrick.getDefaultState(), 2);
		world.setBlockState(new BlockPos(i - 4, j + 0, k - 13), AbyssalCraft.ethaxiumbrick.getDefaultState(), 2);
		world.setBlockState(new BlockPos(i - 4, j + 0, k - 12), AbyssalCraft.ethaxiumbrick.getDefaultState(), 2);
		world.setBlockState(new BlockPos(i - 4, j + 0, k - 11), AbyssalCraft.ethaxiumbrick.getDefaultState(), 2);
		world.setBlockState(new BlockPos(i - 4, j + 0, k - 10), AbyssalCraft.ethaxiumbrick.getDefaultState(), 2);
		world.setBlockState(new BlockPos(i - 4, j + 0, k - 9), AbyssalCraft.ethaxiumbrick.getDefaultState(), 2);
		world.setBlockState(new BlockPos(i - 4, j + 0, k - 8), AbyssalCraft.ethaxiumbrick.getDefaultState(), 2);
		world.setBlockState(new BlockPos(i - 4, j + 0, k - 7), AbyssalCraft.ethaxiumbrick.getDefaultState(), 2);
		world.setBlockState(new BlockPos(i - 4, j + 0, k - 6), AbyssalCraft.ethaxiumbrick.getDefaultState(), 2);
		world.setBlockState(new BlockPos(i - 4, j + 0, k - 5), AbyssalCraft.ethaxiumbrick.getDefaultState(), 2);
		world.setBlockState(new BlockPos(i - 4, j + 0, k - 4), AbyssalCraft.ethaxiumbrick.getDefaultState(), 2);
		world.setBlockState(new BlockPos(i - 4, j + 0, k - 3), AbyssalCraft.ethaxiumbrick.getDefaultState(), 2);
		world.setBlockState(new BlockPos(i - 4, j + 0, k - 2), AbyssalCraft.ethaxiumbrick.getDefaultState(), 2);
		world.setBlockState(new BlockPos(i - 4, j + 1, k - 23), AbyssalCraft.ethaxiumbrick.getDefaultState(), 2);
		world.setBlockState(new BlockPos(i - 4, j + 1, k - 22), AbyssalCraft.ethaxiumbrick.getDefaultState(), 2);
		world.setBlockState(new BlockPos(i - 4, j + 1, k - 21), AbyssalCraft.Darkstone_cobble.getDefaultState(), 2);
		world.setBlockState(new BlockPos(i - 4, j + 1, k - 20), AbyssalCraft.Darkstone_cobble.getDefaultState(), 2);
		world.setBlockState(new BlockPos(i - 4, j + 1, k - 19), AbyssalCraft.Darkstone_cobble.getDefaultState(), 2);
		world.setBlockState(new BlockPos(i - 4, j + 1, k - 18), AbyssalCraft.Darkstone_cobble.getDefaultState(), 2);
		world.setBlockState(new BlockPos(i - 4, j + 1, k - 17), AbyssalCraft.Darkstone_cobble.getDefaultState(), 2);
		world.setBlockState(new BlockPos(i - 4, j + 1, k - 16), AbyssalCraft.Darkstone_cobble.getDefaultState(), 2);
		world.setBlockState(new BlockPos(i - 4, j + 1, k - 15), AbyssalCraft.Darkstone_cobble.getDefaultState(), 2);
		world.setBlockState(new BlockPos(i - 4, j + 1, k - 14), AbyssalCraft.Darkstone_cobble.getDefaultState(), 2);
		world.setBlockState(new BlockPos(i - 4, j + 1, k - 13), AbyssalCraft.Darkstone_cobble.getDefaultState(), 2);
		world.setBlockState(new BlockPos(i - 4, j + 1, k - 12), AbyssalCraft.Darkstone_cobble.getDefaultState(), 2);
		world.setBlockState(new BlockPos(i - 4, j + 1, k - 11), AbyssalCraft.Darkstone_cobble.getDefaultState(), 2);
		world.setBlockState(new BlockPos(i - 4, j + 1, k - 10), AbyssalCraft.Darkstone_cobble.getDefaultState(), 2);
		world.setBlockState(new BlockPos(i - 4, j + 1, k - 9), AbyssalCraft.Darkstone_cobble.getDefaultState(), 2);
		world.setBlockState(new BlockPos(i - 4, j + 1, k - 8), AbyssalCraft.Darkstone_cobble.getDefaultState(), 2);
		world.setBlockState(new BlockPos(i - 4, j + 1, k - 7), AbyssalCraft.Darkstone_cobble.getDefaultState(), 2);
		world.setBlockState(new BlockPos(i - 4, j + 1, k - 6), AbyssalCraft.ethaxiumbrick.getDefaultState(), 2);
		world.setBlockState(new BlockPos(i - 4, j + 1, k - 5), AbyssalCraft.ethaxiumbrick.getDefaultState(), 2);
		world.setBlockState(new BlockPos(i - 4, j + 1, k - 4), AbyssalCraft.ethaxiumbrick.getDefaultState(), 2);
		world.setBlockState(new BlockPos(i - 4, j + 1, k - 3), AbyssalCraft.ethaxiumbrick.getDefaultState(), 2);
		world.setBlockState(new BlockPos(i - 4, j + 2, k - 23), AbyssalCraft.ethaxiumbrick.getDefaultState(), 2);
		world.setBlockState(new BlockPos(i - 4, j + 2, k - 22), AbyssalCraft.Darkstone_brick.getDefaultState(), 2);
		world.setBlockState(new BlockPos(i - 4, j + 2, k - 16), AbyssalCraft.Darkstone_brick.getDefaultState(), 2);
		world.setBlockState(new BlockPos(i - 4, j + 2, k - 6), AbyssalCraft.Darkstone_brick.getDefaultState(), 2);
		world.setBlockState(new BlockPos(i - 4, j + 2, k - 5), AbyssalCraft.ethaxiumbrick.getDefaultState(), 2);
		world.setBlockState(new BlockPos(i - 4, j + 2, k - 4), AbyssalCraft.ethaxiumbrick.getDefaultState(), 2);
		world.setBlockState(new BlockPos(i - 4, j + 2, k - 3), AbyssalCraft.ethaxiumbrick.getDefaultState(), 2);
		world.setBlockState(new BlockPos(i - 4, j + 3, k - 23), AbyssalCraft.ethaxiumbrick.getDefaultState(), 2);
		world.setBlockState(new BlockPos(i - 4, j + 3, k - 22), AbyssalCraft.Darkstone_brick.getDefaultState(), 2);
		world.setBlockState(new BlockPos(i - 4, j + 3, k - 16), AbyssalCraft.Darkstone_brick.getDefaultState(), 2);
		world.setBlockState(new BlockPos(i - 4, j + 3, k - 6), AbyssalCraft.Darkstone_brick.getDefaultState(), 2);
		world.setBlockState(new BlockPos(i - 4, j + 3, k - 5), AbyssalCraft.ethaxiumbrick.getDefaultState(), 2);
		world.setBlockState(new BlockPos(i - 4, j + 3, k - 4), AbyssalCraft.ethaxiumbrick.getDefaultState(), 2);
		world.setBlockState(new BlockPos(i - 4, j + 3, k - 3), AbyssalCraft.ethaxiumbrick.getDefaultState(), 2);
		world.setBlockState(new BlockPos(i - 4, j + 4, k - 23), AbyssalCraft.ethaxiumbrick.getDefaultState(), 2);
		world.setBlockState(new BlockPos(i - 4, j + 4, k - 22), AbyssalCraft.Darkstone_brick.getDefaultState(), 2);
		world.setBlockState(new BlockPos(i - 4, j + 4, k - 16), AbyssalCraft.Darkstone_brick.getDefaultState(), 2);
		world.setBlockState(new BlockPos(i - 4, j + 4, k - 6), AbyssalCraft.Darkstone_brick.getDefaultState(), 2);
		world.setBlockState(new BlockPos(i - 4, j + 4, k - 5), AbyssalCraft.ethaxiumbrick.getDefaultState(), 2);
		world.setBlockState(new BlockPos(i - 4, j + 4, k - 4), AbyssalCraft.ethaxiumbrick.getDefaultState(), 2);
		world.setBlockState(new BlockPos(i - 4, j + 4, k - 3), AbyssalCraft.ethaxiumbrick.getDefaultState(), 2);
		world.setBlockState(new BlockPos(i - 4, j + 5, k - 23), AbyssalCraft.ethaxiumbrick.getDefaultState(), 2);
		world.setBlockState(new BlockPos(i - 4, j + 5, k - 22), AbyssalCraft.ethaxiumbrick.getDefaultState(), 2);
		world.setBlockState(new BlockPos(i - 4, j + 5, k - 21), AbyssalCraft.Darkstone_brick.getDefaultState(), 2);
		world.setBlockState(new BlockPos(i - 4, j + 5, k - 20), AbyssalCraft.Darkstone_brick.getDefaultState(), 2);
		world.setBlockState(new BlockPos(i - 4, j + 5, k - 19), AbyssalCraft.Darkstone_brick.getDefaultState(), 2);
		world.setBlockState(new BlockPos(i - 4, j + 5, k - 18), AbyssalCraft.Darkstone_brick.getDefaultState(), 2);
		world.setBlockState(new BlockPos(i - 4, j + 5, k - 17), AbyssalCraft.Darkstone_brick.getDefaultState(), 2);
		world.setBlockState(new BlockPos(i - 4, j + 5, k - 16), AbyssalCraft.Darkstone_brick.getDefaultState(), 2);
		world.setBlockState(new BlockPos(i - 4, j + 5, k - 15), AbyssalCraft.Darkstone_brick.getDefaultState(), 2);
		world.setBlockState(new BlockPos(i - 4, j + 5, k - 14), AbyssalCraft.Darkstone_brick.getDefaultState(), 2);
		world.setBlockState(new BlockPos(i - 4, j + 5, k - 13), AbyssalCraft.Darkstone_brick.getDefaultState(), 2);
		world.setBlockState(new BlockPos(i - 4, j + 5, k - 12), AbyssalCraft.Darkstone_brick.getDefaultState(), 2);
		world.setBlockState(new BlockPos(i - 4, j + 5, k - 11), AbyssalCraft.Darkstone_brick.getDefaultState(), 2);
		world.setBlockState(new BlockPos(i - 4, j + 5, k - 10), AbyssalCraft.Darkstone_brick.getDefaultState(), 2);
		world.setBlockState(new BlockPos(i - 4, j + 5, k - 9), AbyssalCraft.Darkstone_brick.getDefaultState(), 2);
		world.setBlockState(new BlockPos(i - 4, j + 5, k - 8), AbyssalCraft.Darkstone_brick.getDefaultState(), 2);
		world.setBlockState(new BlockPos(i - 4, j + 5, k - 7), AbyssalCraft.Darkstone_brick.getDefaultState(), 2);
		world.setBlockState(new BlockPos(i - 4, j + 5, k - 6), AbyssalCraft.ethaxiumbrick.getDefaultState(), 2);
		world.setBlockState(new BlockPos(i - 4, j + 5, k - 5), AbyssalCraft.ethaxiumbrick.getDefaultState(), 2);
		world.setBlockState(new BlockPos(i - 4, j + 5, k - 4), AbyssalCraft.ethaxiumbrick.getDefaultState(), 2);
		world.setBlockState(new BlockPos(i - 4, j + 5, k - 3), AbyssalCraft.ethaxiumbrick.getDefaultState(), 2);
		world.setBlockState(new BlockPos(i - 4, j + 6, k - 23), AbyssalCraft.ethaxiumstairs.getStateFromMeta(2), 2); //TODO: 2
		world.setBlockState(new BlockPos(i - 4, j + 6, k - 22), AbyssalCraft.ethaxiumbrick.getDefaultState(), 2);
		world.setBlockState(new BlockPos(i - 4, j + 6, k - 21), AbyssalCraft.ethaxiumbrick.getDefaultState(), 2);
		world.setBlockState(new BlockPos(i - 4, j + 6, k - 20), AbyssalCraft.ethaxiumbrick.getDefaultState(), 2);
		world.setBlockState(new BlockPos(i - 4, j + 6, k - 19), AbyssalCraft.ethaxiumbrick.getDefaultState(), 2);
		world.setBlockState(new BlockPos(i - 4, j + 6, k - 18), AbyssalCraft.ethaxiumbrick.getDefaultState(), 2);
		world.setBlockState(new BlockPos(i - 4, j + 6, k - 17), AbyssalCraft.ethaxiumbrick.getDefaultState(), 2);
		world.setBlockState(new BlockPos(i - 4, j + 6, k - 16), AbyssalCraft.ethaxiumbrick.getDefaultState(), 2);
		world.setBlockState(new BlockPos(i - 4, j + 6, k - 15), AbyssalCraft.ethaxiumbrick.getDefaultState(), 2);
		world.setBlockState(new BlockPos(i - 4, j + 6, k - 14), AbyssalCraft.ethaxiumbrick.getDefaultState(), 2);
		world.setBlockState(new BlockPos(i - 4, j + 6, k - 13), AbyssalCraft.ethaxiumbrick.getDefaultState(), 2);
		world.setBlockState(new BlockPos(i - 4, j + 6, k - 12), AbyssalCraft.ethaxiumbrick.getDefaultState(), 2);
		world.setBlockState(new BlockPos(i - 4, j + 6, k - 11), AbyssalCraft.ethaxiumbrick.getDefaultState(), 2);
		world.setBlockState(new BlockPos(i - 4, j + 6, k - 10), AbyssalCraft.ethaxiumbrick.getDefaultState(), 2);
		world.setBlockState(new BlockPos(i - 4, j + 6, k - 9), AbyssalCraft.ethaxiumbrick.getDefaultState(), 2);
		world.setBlockState(new BlockPos(i - 4, j + 6, k - 8), AbyssalCraft.ethaxiumbrick.getDefaultState(), 2);
		world.setBlockState(new BlockPos(i - 4, j + 6, k - 7), AbyssalCraft.ethaxiumbrick.getDefaultState(), 2);
		world.setBlockState(new BlockPos(i - 4, j + 6, k - 6), AbyssalCraft.ethaxiumbrick.getDefaultState(), 2);
		world.setBlockState(new BlockPos(i - 4, j + 6, k - 5), AbyssalCraft.ethaxiumbrick.getDefaultState(), 2);
		world.setBlockState(new BlockPos(i - 4, j + 6, k - 4), AbyssalCraft.ethaxiumbrick.getDefaultState(), 2);
		world.setBlockState(new BlockPos(i - 4, j + 6, k - 3), AbyssalCraft.ethaxiumbrick.getDefaultState(), 2);
		world.setBlockState(new BlockPos(i - 4, j + 6, k - 2), AbyssalCraft.ethaxiumbrick.getDefaultState(), 2);
		world.setBlockState(new BlockPos(i - 4, j + 6, k - 1), AbyssalCraft.ethaxiumstairs.getStateFromMeta(3), 2); //TODO: 3
		world.setBlockState(new BlockPos(i - 3, j + 0, k - 23), AbyssalCraft.ethaxiumbrick.getDefaultState(), 2);
		world.setBlockState(new BlockPos(i - 3, j + 0, k - 22), AbyssalCraft.ethaxiumbrick.getDefaultState(), 2);
		world.setBlockState(new BlockPos(i - 3, j + 0, k - 21), AbyssalCraft.ethaxiumbrick.getDefaultState(), 2);
		world.setBlockState(new BlockPos(i - 3, j + 0, k - 20), AbyssalCraft.ethaxiumbrick.getDefaultState(), 2);
		world.setBlockState(new BlockPos(i - 3, j + 0, k - 19), AbyssalCraft.ethaxiumbrick.getDefaultState(), 2);
		world.setBlockState(new BlockPos(i - 3, j + 0, k - 18), AbyssalCraft.ethaxiumbrick.getDefaultState(), 2);
		world.setBlockState(new BlockPos(i - 3, j + 0, k - 17), AbyssalCraft.ethaxiumbrick.getDefaultState(), 2);
		world.setBlockState(new BlockPos(i - 3, j + 0, k - 16), AbyssalCraft.ethaxiumbrick.getDefaultState(), 2);
		world.setBlockState(new BlockPos(i - 3, j + 0, k - 15), AbyssalCraft.ethaxiumbrick.getDefaultState(), 2);
		world.setBlockState(new BlockPos(i - 3, j + 0, k - 14), AbyssalCraft.ethaxiumbrick.getDefaultState(), 2);
		world.setBlockState(new BlockPos(i - 3, j + 0, k - 13), AbyssalCraft.ethaxiumbrick.getDefaultState(), 2);
		world.setBlockState(new BlockPos(i - 3, j + 0, k - 12), AbyssalCraft.ethaxiumbrick.getDefaultState(), 2);
		world.setBlockState(new BlockPos(i - 3, j + 0, k - 11), AbyssalCraft.ethaxiumbrick.getDefaultState(), 2);
		world.setBlockState(new BlockPos(i - 3, j + 0, k - 10), AbyssalCraft.ethaxiumbrick.getDefaultState(), 2);
		world.setBlockState(new BlockPos(i - 3, j + 0, k - 9), AbyssalCraft.ethaxiumbrick.getDefaultState(), 2);
		world.setBlockState(new BlockPos(i - 3, j + 0, k - 8), AbyssalCraft.ethaxiumbrick.getDefaultState(), 2);
		world.setBlockState(new BlockPos(i - 3, j + 0, k - 7), AbyssalCraft.ethaxiumbrick.getDefaultState(), 2);
		world.setBlockState(new BlockPos(i - 3, j + 0, k - 6), AbyssalCraft.ethaxiumbrick.getDefaultState(), 2);
		world.setBlockState(new BlockPos(i - 3, j + 0, k - 5), AbyssalCraft.ethaxiumbrick.getDefaultState(), 2);
		world.setBlockState(new BlockPos(i - 3, j + 0, k - 4), AbyssalCraft.ethaxiumbrick.getDefaultState(), 2);
		world.setBlockState(new BlockPos(i - 3, j + 0, k - 3), AbyssalCraft.ethaxiumbrick.getDefaultState(), 2);
		world.setBlockState(new BlockPos(i - 3, j + 0, k - 2), AbyssalCraft.ethaxiumbrick.getDefaultState(), 2);
		world.setBlockState(new BlockPos(i - 3, j + 0, k - 1), AbyssalCraft.ethaxiumbrick.getDefaultState(), 2);
		world.setBlockState(new BlockPos(i - 3, j + 1, k - 23), AbyssalCraft.ethaxiumbrick.getDefaultState(), 2);
		world.setBlockState(new BlockPos(i - 3, j + 1, k - 22), AbyssalCraft.ethaxiumbrick.getDefaultState(), 2);
		world.setBlockState(new BlockPos(i - 3, j + 1, k - 21), AbyssalCraft.Darkstone_cobble.getDefaultState(), 2);
		world.setBlockState(new BlockPos(i - 3, j + 1, k - 20), AbyssalCraft.Darkstone_cobble.getDefaultState(), 2);
		world.setBlockState(new BlockPos(i - 3, j + 1, k - 19), AbyssalCraft.Darkstone_cobble.getDefaultState(), 2);
		world.setBlockState(new BlockPos(i - 3, j + 1, k - 18), AbyssalCraft.Darkstone_cobble.getDefaultState(), 2);
		world.setBlockState(new BlockPos(i - 3, j + 1, k - 17), AbyssalCraft.Darkstone_cobble.getDefaultState(), 2);
		world.setBlockState(new BlockPos(i - 3, j + 1, k - 16), AbyssalCraft.Darkstone_cobble.getDefaultState(), 2);
		world.setBlockState(new BlockPos(i - 3, j + 1, k - 15), AbyssalCraft.Darkstone_cobble.getDefaultState(), 2);
		world.setBlockState(new BlockPos(i - 3, j + 1, k - 14), AbyssalCraft.Darkstone_cobble.getDefaultState(), 2);
		world.setBlockState(new BlockPos(i - 3, j + 1, k - 13), AbyssalCraft.Darkstone_cobble.getDefaultState(), 2);
		world.setBlockState(new BlockPos(i - 3, j + 1, k - 12), AbyssalCraft.Darkstone_cobble.getDefaultState(), 2);
		world.setBlockState(new BlockPos(i - 3, j + 1, k - 11), AbyssalCraft.Darkstone_cobble.getDefaultState(), 2);
		world.setBlockState(new BlockPos(i - 3, j + 1, k - 10), AbyssalCraft.Darkstone_cobble.getDefaultState(), 2);
		world.setBlockState(new BlockPos(i - 3, j + 1, k - 9), AbyssalCraft.Darkstone_cobble.getDefaultState(), 2);
		world.setBlockState(new BlockPos(i - 3, j + 1, k - 8), AbyssalCraft.Darkstone_cobble.getDefaultState(), 2);
		world.setBlockState(new BlockPos(i - 3, j + 1, k - 7), AbyssalCraft.Darkstone_cobble.getDefaultState(), 2);
		world.setBlockState(new BlockPos(i - 3, j + 1, k - 6), AbyssalCraft.ethaxiumbrick.getDefaultState(), 2);
		world.setBlockState(new BlockPos(i - 3, j + 1, k - 5), AbyssalCraft.ethaxiumbrick.getDefaultState(), 2);
		world.setBlockState(new BlockPos(i - 3, j + 1, k - 4), AbyssalCraft.ethaxiumbrick.getDefaultState(), 2);
		world.setBlockState(new BlockPos(i - 3, j + 1, k - 3), AbyssalCraft.ethaxiumbrick.getDefaultState(), 2);
		world.setBlockState(new BlockPos(i - 3, j + 1, k - 2), AbyssalCraft.ethaxiumbrick.getDefaultState(), 2);
		world.setBlockState(new BlockPos(i - 3, j + 1, k - 1), AbyssalCraft.ethaxiumpillar.getDefaultState(), 2);
		world.setBlockState(new BlockPos(i - 3, j + 2, k - 23), AbyssalCraft.ethaxiumbrick.getDefaultState(), 2);
		world.setBlockState(new BlockPos(i - 3, j + 2, k - 22), AbyssalCraft.Darkstone_brick.getDefaultState(), 2);
		world.setBlockState(new BlockPos(i - 3, j + 2, k - 21), AbyssalCraft.Darkstone_brick.getDefaultState(), 2);
		world.setBlockState(new BlockPos(i - 3, j + 2, k - 20), AbyssalCraft.Darkstone_brick.getDefaultState(), 2);
		world.setBlockState(new BlockPos(i - 3, j + 2, k - 19), AbyssalCraft.Darkstone_brick.getDefaultState(), 2);
		world.setBlockState(new BlockPos(i - 3, j + 2, k - 18), AbyssalCraft.Darkstone_brick.getDefaultState(), 2);
		world.setBlockState(new BlockPos(i - 3, j + 2, k - 17), AbyssalCraft.Darkstone_brick.getDefaultState(), 2);
		world.setBlockState(new BlockPos(i - 3, j + 2, k - 16), AbyssalCraft.Darkstone_brick.getDefaultState(), 2);
		world.setBlockState(new BlockPos(i - 3, j + 2, k - 6), AbyssalCraft.Darkstone_brick.getDefaultState(), 2);
		world.setBlockState(new BlockPos(i - 3, j + 2, k - 5), AbyssalCraft.ethaxiumbrick.getDefaultState(), 2);
		world.setBlockState(new BlockPos(i - 3, j + 2, k - 4), AbyssalCraft.ethaxiumbrick.getDefaultState(), 2);
		world.setBlockState(new BlockPos(i - 3, j + 2, k - 3), AbyssalCraft.ethaxiumbrick.getDefaultState(), 2);
		world.setBlockState(new BlockPos(i - 3, j + 2, k - 2), AbyssalCraft.ethaxiumbrick.getDefaultState(), 2);
		world.setBlockState(new BlockPos(i - 3, j + 2, k - 1), AbyssalCraft.ethaxiumpillar.getDefaultState(), 2);
		world.setBlockState(new BlockPos(i - 3, j + 3, k - 23), AbyssalCraft.ethaxiumbrick.getDefaultState(), 2);
		world.setBlockState(new BlockPos(i - 3, j + 3, k - 22), AbyssalCraft.Darkstone_brick.getDefaultState(), 2);
		world.setBlockState(new BlockPos(i - 3, j + 3, k - 21), AbyssalCraft.Darkstone_brick.getDefaultState(), 2);
		world.setBlockState(new BlockPos(i - 3, j + 3, k - 20), AbyssalCraft.Darkstone_brick.getDefaultState(), 2);
		world.setBlockState(new BlockPos(i - 3, j + 3, k - 19), AbyssalCraft.Darkstone_brick.getDefaultState(), 2);
		world.setBlockState(new BlockPos(i - 3, j + 3, k - 18), AbyssalCraft.Darkstone_brick.getDefaultState(), 2);
		world.setBlockState(new BlockPos(i - 3, j + 3, k - 17), AbyssalCraft.Darkstone_brick.getDefaultState(), 2);
		world.setBlockState(new BlockPos(i - 3, j + 3, k - 16), AbyssalCraft.Darkstone_brick.getDefaultState(), 2);
		world.setBlockState(new BlockPos(i - 3, j + 3, k - 6), AbyssalCraft.Darkstone_brick.getDefaultState(), 2);
		world.setBlockState(new BlockPos(i - 3, j + 3, k - 5), AbyssalCraft.ethaxiumbrick.getDefaultState(), 2);
		world.setBlockState(new BlockPos(i - 3, j + 3, k - 4), AbyssalCraft.ethaxiumbrick.getDefaultState(), 2);
		world.setBlockState(new BlockPos(i - 3, j + 3, k - 3), AbyssalCraft.ethaxiumbrick.getDefaultState(), 2);
		world.setBlockState(new BlockPos(i - 3, j + 3, k - 2), AbyssalCraft.ethaxiumbrick.getDefaultState(), 2);
		world.setBlockState(new BlockPos(i - 3, j + 3, k - 1), AbyssalCraft.ethaxiumpillar.getDefaultState(), 2);
		world.setBlockState(new BlockPos(i - 3, j + 4, k - 23), AbyssalCraft.ethaxiumbrick.getDefaultState(), 2);
		world.setBlockState(new BlockPos(i - 3, j + 4, k - 22), AbyssalCraft.Darkstone_brick.getDefaultState(), 2);
		world.setBlockState(new BlockPos(i - 3, j + 4, k - 21), AbyssalCraft.Darkstone_brick.getDefaultState(), 2);
		world.setBlockState(new BlockPos(i - 3, j + 4, k - 20), AbyssalCraft.Darkstone_brick.getDefaultState(), 2);
		world.setBlockState(new BlockPos(i - 3, j + 4, k - 19), AbyssalCraft.Darkstone_brick.getDefaultState(), 2);
		world.setBlockState(new BlockPos(i - 3, j + 4, k - 18), AbyssalCraft.Darkstone_brick.getDefaultState(), 2);
		world.setBlockState(new BlockPos(i - 3, j + 4, k - 17), AbyssalCraft.Darkstone_brick.getDefaultState(), 2);
		world.setBlockState(new BlockPos(i - 3, j + 4, k - 16), AbyssalCraft.Darkstone_brick.getDefaultState(), 2);
		world.setBlockState(new BlockPos(i - 3, j + 4, k - 6), AbyssalCraft.Darkstone_brick.getDefaultState(), 2);
		world.setBlockState(new BlockPos(i - 3, j + 4, k - 5), AbyssalCraft.ethaxiumbrick.getDefaultState(), 2);
		world.setBlockState(new BlockPos(i - 3, j + 4, k - 4), AbyssalCraft.ethaxiumbrick.getDefaultState(), 2);
		world.setBlockState(new BlockPos(i - 3, j + 4, k - 3), AbyssalCraft.ethaxiumbrick.getDefaultState(), 2);
		world.setBlockState(new BlockPos(i - 3, j + 4, k - 2), AbyssalCraft.ethaxiumbrick.getDefaultState(), 2);
		world.setBlockState(new BlockPos(i - 3, j + 4, k - 1), AbyssalCraft.ethaxiumpillar.getDefaultState(), 2);
		world.setBlockState(new BlockPos(i - 3, j + 5, k - 23), AbyssalCraft.ethaxiumbrick.getDefaultState(), 2);
		world.setBlockState(new BlockPos(i - 3, j + 5, k - 22), AbyssalCraft.ethaxiumbrick.getDefaultState(), 2);
		world.setBlockState(new BlockPos(i - 3, j + 5, k - 21), AbyssalCraft.Darkstone_brick.getDefaultState(), 2);
		world.setBlockState(new BlockPos(i - 3, j + 5, k - 20), AbyssalCraft.Darkstone_brick.getDefaultState(), 2);
		world.setBlockState(new BlockPos(i - 3, j + 5, k - 19), AbyssalCraft.Darkstone_brick.getDefaultState(), 2);
		world.setBlockState(new BlockPos(i - 3, j + 5, k - 18), AbyssalCraft.Darkstone_brick.getDefaultState(), 2);
		world.setBlockState(new BlockPos(i - 3, j + 5, k - 17), AbyssalCraft.Darkstone_brick.getDefaultState(), 2);
		world.setBlockState(new BlockPos(i - 3, j + 5, k - 16), AbyssalCraft.Darkstone_brick.getDefaultState(), 2);
		world.setBlockState(new BlockPos(i - 3, j + 5, k - 15), AbyssalCraft.Darkstone_brick.getDefaultState(), 2);
		world.setBlockState(new BlockPos(i - 3, j + 5, k - 14), AbyssalCraft.Darkstone_brick.getDefaultState(), 2);
		world.setBlockState(new BlockPos(i - 3, j + 5, k - 13), AbyssalCraft.Darkstone_brick.getDefaultState(), 2);
		world.setBlockState(new BlockPos(i - 3, j + 5, k - 12), AbyssalCraft.Darkstone_brick.getDefaultState(), 2);
		world.setBlockState(new BlockPos(i - 3, j + 5, k - 11), AbyssalCraft.Darkstone_brick.getDefaultState(), 2);
		world.setBlockState(new BlockPos(i - 3, j + 5, k - 10), AbyssalCraft.Darkstone_brick.getDefaultState(), 2);
		world.setBlockState(new BlockPos(i - 3, j + 5, k - 9), AbyssalCraft.Darkstone_brick.getDefaultState(), 2);
		world.setBlockState(new BlockPos(i - 3, j + 5, k - 8), AbyssalCraft.Darkstone_brick.getDefaultState(), 2);
		world.setBlockState(new BlockPos(i - 3, j + 5, k - 7), AbyssalCraft.Darkstone_brick.getDefaultState(), 2);
		world.setBlockState(new BlockPos(i - 3, j + 5, k - 6), AbyssalCraft.ethaxiumbrick.getDefaultState(), 2);
		world.setBlockState(new BlockPos(i - 3, j + 5, k - 5), AbyssalCraft.ethaxiumbrick.getDefaultState(), 2);
		world.setBlockState(new BlockPos(i - 3, j + 5, k - 4), AbyssalCraft.ethaxiumbrick.getDefaultState(), 2);
		world.setBlockState(new BlockPos(i - 3, j + 5, k - 3), AbyssalCraft.ethaxiumbrick.getDefaultState(), 2);
		world.setBlockState(new BlockPos(i - 3, j + 5, k - 2), AbyssalCraft.ethaxiumbrick.getDefaultState(), 2);
		world.setBlockState(new BlockPos(i - 3, j + 5, k - 1), AbyssalCraft.ethaxiumpillar.getDefaultState(), 2);
		world.setBlockState(new BlockPos(i - 3, j + 6, k - 23), AbyssalCraft.ethaxiumstairs.getStateFromMeta(2), 2); //TODO: 2
		world.setBlockState(new BlockPos(i - 3, j + 6, k - 22), AbyssalCraft.ethaxiumbrick.getDefaultState(), 2);
		world.setBlockState(new BlockPos(i - 3, j + 6, k - 21), AbyssalCraft.ethaxiumbrick.getDefaultState(), 2);
		world.setBlockState(new BlockPos(i - 3, j + 6, k - 20), AbyssalCraft.ethaxiumbrick.getDefaultState(), 2);
		world.setBlockState(new BlockPos(i - 3, j + 6, k - 19), AbyssalCraft.ethaxiumbrick.getDefaultState(), 2);
		world.setBlockState(new BlockPos(i - 3, j + 6, k - 18), AbyssalCraft.ethaxiumbrick.getDefaultState(), 2);
		world.setBlockState(new BlockPos(i - 3, j + 6, k - 17), AbyssalCraft.ethaxiumbrick.getDefaultState(), 2);
		world.setBlockState(new BlockPos(i - 3, j + 6, k - 16), AbyssalCraft.ethaxiumbrick.getDefaultState(), 2);
		world.setBlockState(new BlockPos(i - 3, j + 6, k - 15), AbyssalCraft.ethaxiumbrick.getDefaultState(), 2);
		world.setBlockState(new BlockPos(i - 3, j + 6, k - 14), AbyssalCraft.ethaxiumbrick.getDefaultState(), 2);
		world.setBlockState(new BlockPos(i - 3, j + 6, k - 13), AbyssalCraft.ethaxiumbrick.getDefaultState(), 2);
		world.setBlockState(new BlockPos(i - 3, j + 6, k - 12), AbyssalCraft.ethaxiumbrick.getDefaultState(), 2);
		world.setBlockState(new BlockPos(i - 3, j + 6, k - 11), AbyssalCraft.ethaxiumbrick.getDefaultState(), 2);
		world.setBlockState(new BlockPos(i - 3, j + 6, k - 10), AbyssalCraft.ethaxiumbrick.getDefaultState(), 2);
		world.setBlockState(new BlockPos(i - 3, j + 6, k - 9), AbyssalCraft.ethaxiumbrick.getDefaultState(), 2);
		world.setBlockState(new BlockPos(i - 3, j + 6, k - 8), AbyssalCraft.ethaxiumbrick.getDefaultState(), 2);
		world.setBlockState(new BlockPos(i - 3, j + 6, k - 7), AbyssalCraft.ethaxiumbrick.getDefaultState(), 2);
		world.setBlockState(new BlockPos(i - 3, j + 6, k - 6), AbyssalCraft.ethaxiumbrick.getDefaultState(), 2);
		world.setBlockState(new BlockPos(i - 3, j + 6, k - 5), AbyssalCraft.ethaxiumbrick.getDefaultState(), 2);
		world.setBlockState(new BlockPos(i - 3, j + 6, k - 4), AbyssalCraft.ethaxiumbrick.getDefaultState(), 2);
		world.setBlockState(new BlockPos(i - 3, j + 6, k - 3), AbyssalCraft.ethaxiumbrick.getDefaultState(), 2);
		world.setBlockState(new BlockPos(i - 3, j + 6, k - 2), AbyssalCraft.ethaxiumbrick.getDefaultState(), 2);
		world.setBlockState(new BlockPos(i - 3, j + 6, k - 1), AbyssalCraft.ethaxiumstairs.getStateFromMeta(3), 2); //TODO: 3
		world.setBlockState(new BlockPos(i - 2, j + 0, k - 23), AbyssalCraft.ethaxiumbrick.getDefaultState(), 2);
		world.setBlockState(new BlockPos(i - 2, j + 0, k - 22), AbyssalCraft.ethaxiumbrick.getDefaultState(), 2);
		world.setBlockState(new BlockPos(i - 2, j + 0, k - 21), AbyssalCraft.ethaxiumbrick.getDefaultState(), 2);
		world.setBlockState(new BlockPos(i - 2, j + 0, k - 20), AbyssalCraft.ethaxiumbrick.getDefaultState(), 2);
		world.setBlockState(new BlockPos(i - 2, j + 0, k - 19), AbyssalCraft.ethaxiumbrick.getDefaultState(), 2);
		world.setBlockState(new BlockPos(i - 2, j + 0, k - 18), AbyssalCraft.ethaxiumbrick.getDefaultState(), 2);
		world.setBlockState(new BlockPos(i - 2, j + 0, k - 17), AbyssalCraft.ethaxiumbrick.getDefaultState(), 2);
		world.setBlockState(new BlockPos(i - 2, j + 0, k - 16), AbyssalCraft.ethaxiumbrick.getDefaultState(), 2);
		world.setBlockState(new BlockPos(i - 2, j + 0, k - 15), AbyssalCraft.ethaxiumbrick.getDefaultState(), 2);
		world.setBlockState(new BlockPos(i - 2, j + 0, k - 14), AbyssalCraft.ethaxiumbrick.getDefaultState(), 2);
		world.setBlockState(new BlockPos(i - 2, j + 0, k - 13), AbyssalCraft.ethaxiumbrick.getDefaultState(), 2);
		world.setBlockState(new BlockPos(i - 2, j + 0, k - 12), AbyssalCraft.ethaxiumbrick.getDefaultState(), 2);
		world.setBlockState(new BlockPos(i - 2, j + 0, k - 11), AbyssalCraft.ethaxiumbrick.getDefaultState(), 2);
		world.setBlockState(new BlockPos(i - 2, j + 0, k - 10), AbyssalCraft.ethaxiumbrick.getDefaultState(), 2);
		world.setBlockState(new BlockPos(i - 2, j + 0, k - 9), AbyssalCraft.ethaxiumbrick.getDefaultState(), 2);
		world.setBlockState(new BlockPos(i - 2, j + 0, k - 8), AbyssalCraft.ethaxiumbrick.getDefaultState(), 2);
		world.setBlockState(new BlockPos(i - 2, j + 0, k - 7), AbyssalCraft.ethaxiumbrick.getDefaultState(), 2);
		world.setBlockState(new BlockPos(i - 2, j + 0, k - 6), AbyssalCraft.ethaxiumbrick.getDefaultState(), 2);
